FF
======================================================================
FAIL: test_create_table_1 (ClassEval_14_0.BookManagementDBTestCreateTable.test_create_table_1)
----------------------------------------------------------------------
Traceback (most recent call last):
  File "/Users/snigdhaghoshdastidar/Desktop/CS540/classeval_evaluation/ClassEval_14_0.py", line 92, in test_create_table_1
    self.assertIsNotNone(result)
AssertionError: unexpectedly None

======================================================================
FAIL: test_create_table_2 (ClassEval_14_0.BookManagementDBTestCreateTable.test_create_table_2)
----------------------------------------------------------------------
Traceback (most recent call last):
  File "/Users/snigdhaghoshdastidar/Desktop/CS540/classeval_evaluation/ClassEval_14_0.py", line 101, in test_create_table_2
    self.assertEqual(column_names, expected_column_names)
AssertionError: Lists differ: [] != ['id', 'title', 'author', 'available']

Second list contains 4 additional elements.
First extra element 0:
'id'

- []
+ ['id', 'title', 'author', 'available']

----------------------------------------------------------------------
Ran 2 tests in 0.032s

FAILED (failures=2)
E
======================================================================
ERROR: test_add_book (ClassEval_14_0.BookManagementDBTestAddBook.test_add_book)
----------------------------------------------------------------------
Traceback (most recent call last):
  File "/Users/snigdhaghoshdastidar/Desktop/CS540/classeval_evaluation/ClassEval_14_0.py", line 123, in test_add_book
    self.cursor.execute("SELECT title, author, available FROM books WHERE id=1")
sqlite3.OperationalError: no such table: books

----------------------------------------------------------------------
Ran 1 test in 0.005s

FAILED (errors=1)
E
======================================================================
ERROR: test_remove_book (ClassEval_14_0.BookManagementDBTestRemoveBook.test_remove_book)
----------------------------------------------------------------------
Traceback (most recent call last):
  File "/Users/snigdhaghoshdastidar/Desktop/CS540/classeval_evaluation/ClassEval_14_0.py", line 150, in test_remove_book
    self.cursor.execute("SELECT * FROM books WHERE id=1")
sqlite3.OperationalError: no such table: books

----------------------------------------------------------------------
Ran 1 test in 0.059s

FAILED (errors=1)
E
======================================================================
ERROR: test_borrow_book (ClassEval_14_0.BookManagementDBTestBorrowBook.test_borrow_book)
----------------------------------------------------------------------
Traceback (most recent call last):
  File "/Users/snigdhaghoshdastidar/Desktop/CS540/classeval_evaluation/ClassEval_14_0.py", line 174, in test_borrow_book
    self.cursor.execute("SELECT available FROM books WHERE id=1")
sqlite3.OperationalError: no such table: books

----------------------------------------------------------------------
Ran 1 test in 0.005s

FAILED (errors=1)
E
======================================================================
ERROR: test_return_book (ClassEval_14_0.BookManagementDBTestReturnBook.test_return_book)
----------------------------------------------------------------------
Traceback (most recent call last):
  File "/Users/snigdhaghoshdastidar/Desktop/CS540/classeval_evaluation/ClassEval_14_0.py", line 199, in test_return_book
    self.cursor.execute("SELECT available FROM books WHERE id=1")
sqlite3.OperationalError: no such table: books

----------------------------------------------------------------------
Ran 1 test in 0.007s

FAILED (errors=1)
.
----------------------------------------------------------------------
Ran 1 test in 0.007s

OK
FF
======================================================================
FAIL: test_create_table_1 (ClassEval_14_1.BookManagementDBTestCreateTable.test_create_table_1)
----------------------------------------------------------------------
Traceback (most recent call last):
  File "/Users/snigdhaghoshdastidar/Desktop/CS540/classeval_evaluation/ClassEval_14_1.py", line 92, in test_create_table_1
    self.assertIsNotNone(result)
AssertionError: unexpectedly None

======================================================================
FAIL: test_create_table_2 (ClassEval_14_1.BookManagementDBTestCreateTable.test_create_table_2)
----------------------------------------------------------------------
Traceback (most recent call last):
  File "/Users/snigdhaghoshdastidar/Desktop/CS540/classeval_evaluation/ClassEval_14_1.py", line 101, in test_create_table_2
    self.assertEqual(column_names, expected_column_names)
AssertionError: Lists differ: [] != ['id', 'title', 'author', 'available']

Second list contains 4 additional elements.
First extra element 0:
'id'

- []
+ ['id', 'title', 'author', 'available']

----------------------------------------------------------------------
Ran 2 tests in 0.007s

FAILED (failures=2)
E
======================================================================
ERROR: test_add_book (ClassEval_14_1.BookManagementDBTestAddBook.test_add_book)
----------------------------------------------------------------------
Traceback (most recent call last):
  File "/Users/snigdhaghoshdastidar/Desktop/CS540/classeval_evaluation/ClassEval_14_1.py", line 123, in test_add_book
    self.cursor.execute("SELECT title, author, available FROM books WHERE id=1")
sqlite3.OperationalError: no such table: books

----------------------------------------------------------------------
Ran 1 test in 0.005s

FAILED (errors=1)
E
======================================================================
ERROR: test_remove_book (ClassEval_14_1.BookManagementDBTestRemoveBook.test_remove_book)
----------------------------------------------------------------------
Traceback (most recent call last):
  File "/Users/snigdhaghoshdastidar/Desktop/CS540/classeval_evaluation/ClassEval_14_1.py", line 150, in test_remove_book
    self.cursor.execute("SELECT * FROM books WHERE id=1")
sqlite3.OperationalError: no such table: books

----------------------------------------------------------------------
Ran 1 test in 0.006s

FAILED (errors=1)
E
======================================================================
ERROR: test_borrow_book (ClassEval_14_1.BookManagementDBTestBorrowBook.test_borrow_book)
----------------------------------------------------------------------
Traceback (most recent call last):
  File "/Users/snigdhaghoshdastidar/Desktop/CS540/classeval_evaluation/ClassEval_14_1.py", line 174, in test_borrow_book
    self.cursor.execute("SELECT available FROM books WHERE id=1")
sqlite3.OperationalError: no such table: books

----------------------------------------------------------------------
Ran 1 test in 0.006s

FAILED (errors=1)
E
======================================================================
ERROR: test_return_book (ClassEval_14_1.BookManagementDBTestReturnBook.test_return_book)
----------------------------------------------------------------------
Traceback (most recent call last):
  File "/Users/snigdhaghoshdastidar/Desktop/CS540/classeval_evaluation/ClassEval_14_1.py", line 199, in test_return_book
    self.cursor.execute("SELECT available FROM books WHERE id=1")
sqlite3.OperationalError: no such table: books

----------------------------------------------------------------------
Ran 1 test in 0.007s

FAILED (errors=1)
.
----------------------------------------------------------------------
Ran 1 test in 0.007s

OK
FF
======================================================================
FAIL: test_create_table_1 (ClassEval_14_2.BookManagementDBTestCreateTable.test_create_table_1)
----------------------------------------------------------------------
Traceback (most recent call last):
  File "/Users/snigdhaghoshdastidar/Desktop/CS540/classeval_evaluation/ClassEval_14_2.py", line 87, in test_create_table_1
    self.assertIsNotNone(result)
AssertionError: unexpectedly None

======================================================================
FAIL: test_create_table_2 (ClassEval_14_2.BookManagementDBTestCreateTable.test_create_table_2)
----------------------------------------------------------------------
Traceback (most recent call last):
  File "/Users/snigdhaghoshdastidar/Desktop/CS540/classeval_evaluation/ClassEval_14_2.py", line 96, in test_create_table_2
    self.assertEqual(column_names, expected_column_names)
AssertionError: Lists differ: [] != ['id', 'title', 'author', 'available']

Second list contains 4 additional elements.
First extra element 0:
'id'

- []
+ ['id', 'title', 'author', 'available']

----------------------------------------------------------------------
Ran 2 tests in 0.005s

FAILED (failures=2)
E
======================================================================
ERROR: test_add_book (ClassEval_14_2.BookManagementDBTestAddBook.test_add_book)
----------------------------------------------------------------------
Traceback (most recent call last):
  File "/Users/snigdhaghoshdastidar/Desktop/CS540/classeval_evaluation/ClassEval_14_2.py", line 118, in test_add_book
    self.cursor.execute("SELECT title, author, available FROM books WHERE id=1")
sqlite3.OperationalError: no such table: books

----------------------------------------------------------------------
Ran 1 test in 0.005s

FAILED (errors=1)
E
======================================================================
ERROR: test_remove_book (ClassEval_14_2.BookManagementDBTestRemoveBook.test_remove_book)
----------------------------------------------------------------------
Traceback (most recent call last):
  File "/Users/snigdhaghoshdastidar/Desktop/CS540/classeval_evaluation/ClassEval_14_2.py", line 145, in test_remove_book
    self.cursor.execute("SELECT * FROM books WHERE id=1")
sqlite3.OperationalError: no such table: books

----------------------------------------------------------------------
Ran 1 test in 0.006s

FAILED (errors=1)
E
======================================================================
ERROR: test_borrow_book (ClassEval_14_2.BookManagementDBTestBorrowBook.test_borrow_book)
----------------------------------------------------------------------
Traceback (most recent call last):
  File "/Users/snigdhaghoshdastidar/Desktop/CS540/classeval_evaluation/ClassEval_14_2.py", line 169, in test_borrow_book
    self.cursor.execute("SELECT available FROM books WHERE id=1")
sqlite3.OperationalError: no such table: books

----------------------------------------------------------------------
Ran 1 test in 0.006s

FAILED (errors=1)
E
======================================================================
ERROR: test_return_book (ClassEval_14_2.BookManagementDBTestReturnBook.test_return_book)
----------------------------------------------------------------------
Traceback (most recent call last):
  File "/Users/snigdhaghoshdastidar/Desktop/CS540/classeval_evaluation/ClassEval_14_2.py", line 194, in test_return_book
    self.cursor.execute("SELECT available FROM books WHERE id=1")
sqlite3.OperationalError: no such table: books

----------------------------------------------------------------------
Ran 1 test in 0.006s

FAILED (errors=1)
.
----------------------------------------------------------------------
Ran 1 test in 0.006s

OK
FF
======================================================================
FAIL: test_create_table_1 (ClassEval_14_3.BookManagementDBTestCreateTable.test_create_table_1)
----------------------------------------------------------------------
Traceback (most recent call last):
  File "/Users/snigdhaghoshdastidar/Desktop/CS540/classeval_evaluation/ClassEval_14_3.py", line 92, in test_create_table_1
    self.assertIsNotNone(result)
AssertionError: unexpectedly None

======================================================================
FAIL: test_create_table_2 (ClassEval_14_3.BookManagementDBTestCreateTable.test_create_table_2)
----------------------------------------------------------------------
Traceback (most recent call last):
  File "/Users/snigdhaghoshdastidar/Desktop/CS540/classeval_evaluation/ClassEval_14_3.py", line 101, in test_create_table_2
    self.assertEqual(column_names, expected_column_names)
AssertionError: Lists differ: [] != ['id', 'title', 'author', 'available']

Second list contains 4 additional elements.
First extra element 0:
'id'

- []
+ ['id', 'title', 'author', 'available']

----------------------------------------------------------------------
Ran 2 tests in 0.007s

FAILED (failures=2)
E
======================================================================
ERROR: test_add_book (ClassEval_14_3.BookManagementDBTestAddBook.test_add_book)
----------------------------------------------------------------------
Traceback (most recent call last):
  File "/Users/snigdhaghoshdastidar/Desktop/CS540/classeval_evaluation/ClassEval_14_3.py", line 123, in test_add_book
    self.cursor.execute("SELECT title, author, available FROM books WHERE id=1")
sqlite3.OperationalError: no such table: books

----------------------------------------------------------------------
Ran 1 test in 0.005s

FAILED (errors=1)
E
======================================================================
ERROR: test_remove_book (ClassEval_14_3.BookManagementDBTestRemoveBook.test_remove_book)
----------------------------------------------------------------------
Traceback (most recent call last):
  File "/Users/snigdhaghoshdastidar/Desktop/CS540/classeval_evaluation/ClassEval_14_3.py", line 150, in test_remove_book
    self.cursor.execute("SELECT * FROM books WHERE id=1")
sqlite3.OperationalError: no such table: books

----------------------------------------------------------------------
Ran 1 test in 0.006s

FAILED (errors=1)
E
======================================================================
ERROR: test_borrow_book (ClassEval_14_3.BookManagementDBTestBorrowBook.test_borrow_book)
----------------------------------------------------------------------
Traceback (most recent call last):
  File "/Users/snigdhaghoshdastidar/Desktop/CS540/classeval_evaluation/ClassEval_14_3.py", line 174, in test_borrow_book
    self.cursor.execute("SELECT available FROM books WHERE id=1")
sqlite3.OperationalError: no such table: books

----------------------------------------------------------------------
Ran 1 test in 0.006s

FAILED (errors=1)
E
======================================================================
ERROR: test_return_book (ClassEval_14_3.BookManagementDBTestReturnBook.test_return_book)
----------------------------------------------------------------------
Traceback (most recent call last):
  File "/Users/snigdhaghoshdastidar/Desktop/CS540/classeval_evaluation/ClassEval_14_3.py", line 199, in test_return_book
    self.cursor.execute("SELECT available FROM books WHERE id=1")
sqlite3.OperationalError: no such table: books

----------------------------------------------------------------------
Ran 1 test in 0.011s

FAILED (errors=1)
.
----------------------------------------------------------------------
Ran 1 test in 0.007s

OK
FF
======================================================================
FAIL: test_create_table_1 (ClassEval_14_4.BookManagementDBTestCreateTable.test_create_table_1)
----------------------------------------------------------------------
Traceback (most recent call last):
  File "/Users/snigdhaghoshdastidar/Desktop/CS540/classeval_evaluation/ClassEval_14_4.py", line 87, in test_create_table_1
    self.assertIsNotNone(result)
AssertionError: unexpectedly None

======================================================================
FAIL: test_create_table_2 (ClassEval_14_4.BookManagementDBTestCreateTable.test_create_table_2)
----------------------------------------------------------------------
Traceback (most recent call last):
  File "/Users/snigdhaghoshdastidar/Desktop/CS540/classeval_evaluation/ClassEval_14_4.py", line 96, in test_create_table_2
    self.assertEqual(column_names, expected_column_names)
AssertionError: Lists differ: [] != ['id', 'title', 'author', 'available']

Second list contains 4 additional elements.
First extra element 0:
'id'

- []
+ ['id', 'title', 'author', 'available']

----------------------------------------------------------------------
Ran 2 tests in 0.007s

FAILED (failures=2)
E
======================================================================
ERROR: test_add_book (ClassEval_14_4.BookManagementDBTestAddBook.test_add_book)
----------------------------------------------------------------------
Traceback (most recent call last):
  File "/Users/snigdhaghoshdastidar/Desktop/CS540/classeval_evaluation/ClassEval_14_4.py", line 118, in test_add_book
    self.cursor.execute("SELECT title, author, available FROM books WHERE id=1")
sqlite3.OperationalError: no such table: books

----------------------------------------------------------------------
Ran 1 test in 0.005s

FAILED (errors=1)
E
======================================================================
ERROR: test_remove_book (ClassEval_14_4.BookManagementDBTestRemoveBook.test_remove_book)
----------------------------------------------------------------------
Traceback (most recent call last):
  File "/Users/snigdhaghoshdastidar/Desktop/CS540/classeval_evaluation/ClassEval_14_4.py", line 145, in test_remove_book
    self.cursor.execute("SELECT * FROM books WHERE id=1")
sqlite3.OperationalError: no such table: books

----------------------------------------------------------------------
Ran 1 test in 0.006s

FAILED (errors=1)
E
======================================================================
ERROR: test_borrow_book (ClassEval_14_4.BookManagementDBTestBorrowBook.test_borrow_book)
----------------------------------------------------------------------
Traceback (most recent call last):
  File "/Users/snigdhaghoshdastidar/Desktop/CS540/classeval_evaluation/ClassEval_14_4.py", line 169, in test_borrow_book
    self.cursor.execute("SELECT available FROM books WHERE id=1")
sqlite3.OperationalError: no such table: books

----------------------------------------------------------------------
Ran 1 test in 0.006s

FAILED (errors=1)
E
======================================================================
ERROR: test_return_book (ClassEval_14_4.BookManagementDBTestReturnBook.test_return_book)
----------------------------------------------------------------------
Traceback (most recent call last):
  File "/Users/snigdhaghoshdastidar/Desktop/CS540/classeval_evaluation/ClassEval_14_4.py", line 194, in test_return_book
    self.cursor.execute("SELECT available FROM books WHERE id=1")
sqlite3.OperationalError: no such table: books

----------------------------------------------------------------------
Ran 1 test in 0.007s

FAILED (errors=1)
.
----------------------------------------------------------------------
Ran 1 test in 0.006s

OK
.....
----------------------------------------------------------------------
Ran 5 tests in 0.011s

OK
.....
----------------------------------------------------------------------
Ran 5 tests in 0.023s

OK
..FFF
======================================================================
FAIL: test_search_database_3 (ClassEval_28_0.DatabaseProcessorTestSearchDatabase.test_search_database_3)
----------------------------------------------------------------------
Traceback (most recent call last):
  File "/Users/snigdhaghoshdastidar/Desktop/CS540/classeval_evaluation/ClassEval_28_0.py", line 304, in test_search_database_3
    self.assertIsNone(result)
AssertionError: [] is not None

======================================================================
FAIL: test_search_database_4 (ClassEval_28_0.DatabaseProcessorTestSearchDatabase.test_search_database_4)
----------------------------------------------------------------------
Traceback (most recent call last):
  File "/Users/snigdhaghoshdastidar/Desktop/CS540/classeval_evaluation/ClassEval_28_0.py", line 316, in test_search_database_4
    self.assertIsNone(result)
AssertionError: [] is not None

======================================================================
FAIL: test_search_database_5 (ClassEval_28_0.DatabaseProcessorTestSearchDatabase.test_search_database_5)
----------------------------------------------------------------------
Traceback (most recent call last):
  File "/Users/snigdhaghoshdastidar/Desktop/CS540/classeval_evaluation/ClassEval_28_0.py", line 328, in test_search_database_5
    self.assertIsNone(result)
AssertionError: [] is not None

----------------------------------------------------------------------
Ran 5 tests in 0.023s

FAILED (failures=3)
.....
----------------------------------------------------------------------
Ran 5 tests in 0.045s

OK
.
----------------------------------------------------------------------
Ran 1 test in 0.010s

OK
.....
----------------------------------------------------------------------
Ran 5 tests in 0.010s

OK
.....
----------------------------------------------------------------------
Ran 5 tests in 0.031s

OK
..FFF
======================================================================
FAIL: test_search_database_3 (ClassEval_28_1.DatabaseProcessorTestSearchDatabase.test_search_database_3)
----------------------------------------------------------------------
Traceback (most recent call last):
  File "/Users/snigdhaghoshdastidar/Desktop/CS540/classeval_evaluation/ClassEval_28_1.py", line 317, in test_search_database_3
    self.assertIsNone(result)
AssertionError: [] is not None

======================================================================
FAIL: test_search_database_4 (ClassEval_28_1.DatabaseProcessorTestSearchDatabase.test_search_database_4)
----------------------------------------------------------------------
Traceback (most recent call last):
  File "/Users/snigdhaghoshdastidar/Desktop/CS540/classeval_evaluation/ClassEval_28_1.py", line 329, in test_search_database_4
    self.assertIsNone(result)
AssertionError: [] is not None

======================================================================
FAIL: test_search_database_5 (ClassEval_28_1.DatabaseProcessorTestSearchDatabase.test_search_database_5)
----------------------------------------------------------------------
Traceback (most recent call last):
  File "/Users/snigdhaghoshdastidar/Desktop/CS540/classeval_evaluation/ClassEval_28_1.py", line 341, in test_search_database_5
    self.assertIsNone(result)
AssertionError: [] is not None

----------------------------------------------------------------------
Ran 5 tests in 0.034s

FAILED (failures=3)
.....
----------------------------------------------------------------------
Ran 5 tests in 0.037s

OK
.
----------------------------------------------------------------------
Ran 1 test in 0.006s

OK
.....
----------------------------------------------------------------------
Ran 5 tests in 0.009s

OK
.....
----------------------------------------------------------------------
Ran 5 tests in 0.032s

OK
..FFF
======================================================================
FAIL: test_search_database_3 (ClassEval_28_2.DatabaseProcessorTestSearchDatabase.test_search_database_3)
----------------------------------------------------------------------
Traceback (most recent call last):
  File "/Users/snigdhaghoshdastidar/Desktop/CS540/classeval_evaluation/ClassEval_28_2.py", line 304, in test_search_database_3
    self.assertIsNone(result)
AssertionError: [] is not None

======================================================================
FAIL: test_search_database_4 (ClassEval_28_2.DatabaseProcessorTestSearchDatabase.test_search_database_4)
----------------------------------------------------------------------
Traceback (most recent call last):
  File "/Users/snigdhaghoshdastidar/Desktop/CS540/classeval_evaluation/ClassEval_28_2.py", line 316, in test_search_database_4
    self.assertIsNone(result)
AssertionError: [] is not None

======================================================================
FAIL: test_search_database_5 (ClassEval_28_2.DatabaseProcessorTestSearchDatabase.test_search_database_5)
----------------------------------------------------------------------
Traceback (most recent call last):
  File "/Users/snigdhaghoshdastidar/Desktop/CS540/classeval_evaluation/ClassEval_28_2.py", line 328, in test_search_database_5
    self.assertIsNone(result)
AssertionError: [] is not None

----------------------------------------------------------------------
Ran 5 tests in 0.031s

FAILED (failures=3)
.....
----------------------------------------------------------------------
Ran 5 tests in 0.043s

OK
.
----------------------------------------------------------------------
Ran 1 test in 0.010s

OK
.....
----------------------------------------------------------------------
Ran 5 tests in 0.009s

OK
.....
----------------------------------------------------------------------
Ran 5 tests in 0.026s

OK
..FFF
======================================================================
FAIL: test_search_database_3 (ClassEval_28_3.DatabaseProcessorTestSearchDatabase.test_search_database_3)
----------------------------------------------------------------------
Traceback (most recent call last):
  File "/Users/snigdhaghoshdastidar/Desktop/CS540/classeval_evaluation/ClassEval_28_3.py", line 317, in test_search_database_3
    self.assertIsNone(result)
AssertionError: [] is not None

======================================================================
FAIL: test_search_database_4 (ClassEval_28_3.DatabaseProcessorTestSearchDatabase.test_search_database_4)
----------------------------------------------------------------------
Traceback (most recent call last):
  File "/Users/snigdhaghoshdastidar/Desktop/CS540/classeval_evaluation/ClassEval_28_3.py", line 329, in test_search_database_4
    self.assertIsNone(result)
AssertionError: [] is not None

======================================================================
FAIL: test_search_database_5 (ClassEval_28_3.DatabaseProcessorTestSearchDatabase.test_search_database_5)
----------------------------------------------------------------------
Traceback (most recent call last):
  File "/Users/snigdhaghoshdastidar/Desktop/CS540/classeval_evaluation/ClassEval_28_3.py", line 341, in test_search_database_5
    self.assertIsNone(result)
AssertionError: [] is not None

----------------------------------------------------------------------
Ran 5 tests in 0.021s

FAILED (failures=3)
.....
----------------------------------------------------------------------
Ran 5 tests in 0.028s

OK
.
----------------------------------------------------------------------
Ran 1 test in 0.006s

OK
.....
----------------------------------------------------------------------
Ran 5 tests in 0.006s

OK
.....
----------------------------------------------------------------------
Ran 5 tests in 0.021s

OK
..FFF
======================================================================
FAIL: test_search_database_3 (ClassEval_28_4.DatabaseProcessorTestSearchDatabase.test_search_database_3)
----------------------------------------------------------------------
Traceback (most recent call last):
  File "/Users/snigdhaghoshdastidar/Desktop/CS540/classeval_evaluation/ClassEval_28_4.py", line 304, in test_search_database_3
    self.assertIsNone(result)
AssertionError: [] is not None

======================================================================
FAIL: test_search_database_4 (ClassEval_28_4.DatabaseProcessorTestSearchDatabase.test_search_database_4)
----------------------------------------------------------------------
Traceback (most recent call last):
  File "/Users/snigdhaghoshdastidar/Desktop/CS540/classeval_evaluation/ClassEval_28_4.py", line 316, in test_search_database_4
    self.assertIsNone(result)
AssertionError: [] is not None

======================================================================
FAIL: test_search_database_5 (ClassEval_28_4.DatabaseProcessorTestSearchDatabase.test_search_database_5)
----------------------------------------------------------------------
Traceback (most recent call last):
  File "/Users/snigdhaghoshdastidar/Desktop/CS540/classeval_evaluation/ClassEval_28_4.py", line 328, in test_search_database_5
    self.assertIsNone(result)
AssertionError: [] is not None

----------------------------------------------------------------------
Ran 5 tests in 0.024s

FAILED (failures=3)
.....
----------------------------------------------------------------------
Ran 5 tests in 0.031s

OK
.
----------------------------------------------------------------------
Ran 1 test in 0.009s

OK
.....
----------------------------------------------------------------------
Ran 5 tests in 0.018s

OK
.....
----------------------------------------------------------------------
Ran 5 tests in 0.015s

OK
FFFFF
======================================================================
FAIL: test_delete_ticket_1 (ClassEval_60_0.MovieTicketDBTestDeleteTicket.test_delete_ticket_1)
----------------------------------------------------------------------
Traceback (most recent call last):
  File "/Users/snigdhaghoshdastidar/Desktop/CS540/classeval_evaluation/ClassEval_60_0.py", line 196, in test_delete_ticket_1
    self.assertEqual(len(tickets), 0)
AssertionError: 1 != 0

======================================================================
FAIL: test_delete_ticket_2 (ClassEval_60_0.MovieTicketDBTestDeleteTicket.test_delete_ticket_2)
----------------------------------------------------------------------
Traceback (most recent call last):
  File "/Users/snigdhaghoshdastidar/Desktop/CS540/classeval_evaluation/ClassEval_60_0.py", line 205, in test_delete_ticket_2
    self.assertEqual(len(tickets), 0)
AssertionError: 1 != 0

======================================================================
FAIL: test_delete_ticket_3 (ClassEval_60_0.MovieTicketDBTestDeleteTicket.test_delete_ticket_3)
----------------------------------------------------------------------
Traceback (most recent call last):
  File "/Users/snigdhaghoshdastidar/Desktop/CS540/classeval_evaluation/ClassEval_60_0.py", line 214, in test_delete_ticket_3
    self.assertEqual(len(tickets), 0)
AssertionError: 1 != 0

======================================================================
FAIL: test_delete_ticket_4 (ClassEval_60_0.MovieTicketDBTestDeleteTicket.test_delete_ticket_4)
----------------------------------------------------------------------
Traceback (most recent call last):
  File "/Users/snigdhaghoshdastidar/Desktop/CS540/classeval_evaluation/ClassEval_60_0.py", line 223, in test_delete_ticket_4
    self.assertEqual(len(tickets), 0)
AssertionError: 1 != 0

======================================================================
FAIL: test_delete_ticket_5 (ClassEval_60_0.MovieTicketDBTestDeleteTicket.test_delete_ticket_5)
----------------------------------------------------------------------
Traceback (most recent call last):
  File "/Users/snigdhaghoshdastidar/Desktop/CS540/classeval_evaluation/ClassEval_60_0.py", line 232, in test_delete_ticket_5
    self.assertEqual(len(tickets), 0)
AssertionError: 1 != 0

----------------------------------------------------------------------
Ran 5 tests in 0.013s

FAILED (failures=5)
F
======================================================================
FAIL: test_MovieTicketDB (ClassEval_60_0.MovieTicketDBTest.test_MovieTicketDB)
----------------------------------------------------------------------
Traceback (most recent call last):
  File "/Users/snigdhaghoshdastidar/Desktop/CS540/classeval_evaluation/ClassEval_60_0.py", line 256, in test_MovieTicketDB
    self.assertEqual(len(tickets), 0)
AssertionError: 1 != 0

----------------------------------------------------------------------
Ran 1 test in 0.003s

FAILED (failures=1)
.....
----------------------------------------------------------------------
Ran 5 tests in 0.011s

OK
.....
----------------------------------------------------------------------
Ran 5 tests in 0.011s

OK
FFFFF
======================================================================
FAIL: test_delete_ticket_1 (ClassEval_60_1.MovieTicketDBTestDeleteTicket.test_delete_ticket_1)
----------------------------------------------------------------------
Traceback (most recent call last):
  File "/Users/snigdhaghoshdastidar/Desktop/CS540/classeval_evaluation/ClassEval_60_1.py", line 205, in test_delete_ticket_1
    self.assertEqual(len(tickets), 0)
AssertionError: 1 != 0

======================================================================
FAIL: test_delete_ticket_2 (ClassEval_60_1.MovieTicketDBTestDeleteTicket.test_delete_ticket_2)
----------------------------------------------------------------------
Traceback (most recent call last):
  File "/Users/snigdhaghoshdastidar/Desktop/CS540/classeval_evaluation/ClassEval_60_1.py", line 214, in test_delete_ticket_2
    self.assertEqual(len(tickets), 0)
AssertionError: 1 != 0

======================================================================
FAIL: test_delete_ticket_3 (ClassEval_60_1.MovieTicketDBTestDeleteTicket.test_delete_ticket_3)
----------------------------------------------------------------------
Traceback (most recent call last):
  File "/Users/snigdhaghoshdastidar/Desktop/CS540/classeval_evaluation/ClassEval_60_1.py", line 223, in test_delete_ticket_3
    self.assertEqual(len(tickets), 0)
AssertionError: 1 != 0

======================================================================
FAIL: test_delete_ticket_4 (ClassEval_60_1.MovieTicketDBTestDeleteTicket.test_delete_ticket_4)
----------------------------------------------------------------------
Traceback (most recent call last):
  File "/Users/snigdhaghoshdastidar/Desktop/CS540/classeval_evaluation/ClassEval_60_1.py", line 232, in test_delete_ticket_4
    self.assertEqual(len(tickets), 0)
AssertionError: 1 != 0

======================================================================
FAIL: test_delete_ticket_5 (ClassEval_60_1.MovieTicketDBTestDeleteTicket.test_delete_ticket_5)
----------------------------------------------------------------------
Traceback (most recent call last):
  File "/Users/snigdhaghoshdastidar/Desktop/CS540/classeval_evaluation/ClassEval_60_1.py", line 241, in test_delete_ticket_5
    self.assertEqual(len(tickets), 0)
AssertionError: 1 != 0

----------------------------------------------------------------------
Ran 5 tests in 0.014s

FAILED (failures=5)
F
======================================================================
FAIL: test_MovieTicketDB (ClassEval_60_1.MovieTicketDBTest.test_MovieTicketDB)
----------------------------------------------------------------------
Traceback (most recent call last):
  File "/Users/snigdhaghoshdastidar/Desktop/CS540/classeval_evaluation/ClassEval_60_1.py", line 265, in test_MovieTicketDB
    self.assertEqual(len(tickets), 0)
AssertionError: 1 != 0

----------------------------------------------------------------------
Ran 1 test in 0.003s

FAILED (failures=1)
.....
----------------------------------------------------------------------
Ran 5 tests in 0.011s

OK
.....
----------------------------------------------------------------------
Ran 5 tests in 0.012s

OK
FFFFF
======================================================================
FAIL: test_delete_ticket_1 (ClassEval_60_2.MovieTicketDBTestDeleteTicket.test_delete_ticket_1)
----------------------------------------------------------------------
Traceback (most recent call last):
  File "/Users/snigdhaghoshdastidar/Desktop/CS540/classeval_evaluation/ClassEval_60_2.py", line 205, in test_delete_ticket_1
    self.assertEqual(len(tickets), 0)
AssertionError: 1 != 0

======================================================================
FAIL: test_delete_ticket_2 (ClassEval_60_2.MovieTicketDBTestDeleteTicket.test_delete_ticket_2)
----------------------------------------------------------------------
Traceback (most recent call last):
  File "/Users/snigdhaghoshdastidar/Desktop/CS540/classeval_evaluation/ClassEval_60_2.py", line 214, in test_delete_ticket_2
    self.assertEqual(len(tickets), 0)
AssertionError: 1 != 0

======================================================================
FAIL: test_delete_ticket_3 (ClassEval_60_2.MovieTicketDBTestDeleteTicket.test_delete_ticket_3)
----------------------------------------------------------------------
Traceback (most recent call last):
  File "/Users/snigdhaghoshdastidar/Desktop/CS540/classeval_evaluation/ClassEval_60_2.py", line 223, in test_delete_ticket_3
    self.assertEqual(len(tickets), 0)
AssertionError: 1 != 0

======================================================================
FAIL: test_delete_ticket_4 (ClassEval_60_2.MovieTicketDBTestDeleteTicket.test_delete_ticket_4)
----------------------------------------------------------------------
Traceback (most recent call last):
  File "/Users/snigdhaghoshdastidar/Desktop/CS540/classeval_evaluation/ClassEval_60_2.py", line 232, in test_delete_ticket_4
    self.assertEqual(len(tickets), 0)
AssertionError: 1 != 0

======================================================================
FAIL: test_delete_ticket_5 (ClassEval_60_2.MovieTicketDBTestDeleteTicket.test_delete_ticket_5)
----------------------------------------------------------------------
Traceback (most recent call last):
  File "/Users/snigdhaghoshdastidar/Desktop/CS540/classeval_evaluation/ClassEval_60_2.py", line 241, in test_delete_ticket_5
    self.assertEqual(len(tickets), 0)
AssertionError: 1 != 0

----------------------------------------------------------------------
Ran 5 tests in 0.013s

FAILED (failures=5)
F
======================================================================
FAIL: test_MovieTicketDB (ClassEval_60_2.MovieTicketDBTest.test_MovieTicketDB)
----------------------------------------------------------------------
Traceback (most recent call last):
  File "/Users/snigdhaghoshdastidar/Desktop/CS540/classeval_evaluation/ClassEval_60_2.py", line 265, in test_MovieTicketDB
    self.assertEqual(len(tickets), 0)
AssertionError: 1 != 0

----------------------------------------------------------------------
Ran 1 test in 0.002s

FAILED (failures=1)
.....
----------------------------------------------------------------------
Ran 5 tests in 0.013s

OK
.....
----------------------------------------------------------------------
Ran 5 tests in 0.012s

OK
FFFFF
======================================================================
FAIL: test_delete_ticket_1 (ClassEval_60_3.MovieTicketDBTestDeleteTicket.test_delete_ticket_1)
----------------------------------------------------------------------
Traceback (most recent call last):
  File "/Users/snigdhaghoshdastidar/Desktop/CS540/classeval_evaluation/ClassEval_60_3.py", line 191, in test_delete_ticket_1
    self.assertEqual(len(tickets), 0)
AssertionError: 1 != 0

======================================================================
FAIL: test_delete_ticket_2 (ClassEval_60_3.MovieTicketDBTestDeleteTicket.test_delete_ticket_2)
----------------------------------------------------------------------
Traceback (most recent call last):
  File "/Users/snigdhaghoshdastidar/Desktop/CS540/classeval_evaluation/ClassEval_60_3.py", line 200, in test_delete_ticket_2
    self.assertEqual(len(tickets), 0)
AssertionError: 1 != 0

======================================================================
FAIL: test_delete_ticket_3 (ClassEval_60_3.MovieTicketDBTestDeleteTicket.test_delete_ticket_3)
----------------------------------------------------------------------
Traceback (most recent call last):
  File "/Users/snigdhaghoshdastidar/Desktop/CS540/classeval_evaluation/ClassEval_60_3.py", line 209, in test_delete_ticket_3
    self.assertEqual(len(tickets), 0)
AssertionError: 1 != 0

======================================================================
FAIL: test_delete_ticket_4 (ClassEval_60_3.MovieTicketDBTestDeleteTicket.test_delete_ticket_4)
----------------------------------------------------------------------
Traceback (most recent call last):
  File "/Users/snigdhaghoshdastidar/Desktop/CS540/classeval_evaluation/ClassEval_60_3.py", line 218, in test_delete_ticket_4
    self.assertEqual(len(tickets), 0)
AssertionError: 1 != 0

======================================================================
FAIL: test_delete_ticket_5 (ClassEval_60_3.MovieTicketDBTestDeleteTicket.test_delete_ticket_5)
----------------------------------------------------------------------
Traceback (most recent call last):
  File "/Users/snigdhaghoshdastidar/Desktop/CS540/classeval_evaluation/ClassEval_60_3.py", line 227, in test_delete_ticket_5
    self.assertEqual(len(tickets), 0)
AssertionError: 1 != 0

----------------------------------------------------------------------
Ran 5 tests in 0.033s

FAILED (failures=5)
F
======================================================================
FAIL: test_MovieTicketDB (ClassEval_60_3.MovieTicketDBTest.test_MovieTicketDB)
----------------------------------------------------------------------
Traceback (most recent call last):
  File "/Users/snigdhaghoshdastidar/Desktop/CS540/classeval_evaluation/ClassEval_60_3.py", line 251, in test_MovieTicketDB
    self.assertEqual(len(tickets), 0)
AssertionError: 1 != 0

----------------------------------------------------------------------
Ran 1 test in 0.004s

FAILED (failures=1)
.....
----------------------------------------------------------------------
Ran 5 tests in 0.014s

OK
.....
----------------------------------------------------------------------
Ran 5 tests in 0.011s

OK
FFFFF
======================================================================
FAIL: test_delete_ticket_1 (ClassEval_60_4.MovieTicketDBTestDeleteTicket.test_delete_ticket_1)
----------------------------------------------------------------------
Traceback (most recent call last):
  File "/Users/snigdhaghoshdastidar/Desktop/CS540/classeval_evaluation/ClassEval_60_4.py", line 205, in test_delete_ticket_1
    self.assertEqual(len(tickets), 0)
AssertionError: 1 != 0

======================================================================
FAIL: test_delete_ticket_2 (ClassEval_60_4.MovieTicketDBTestDeleteTicket.test_delete_ticket_2)
----------------------------------------------------------------------
Traceback (most recent call last):
  File "/Users/snigdhaghoshdastidar/Desktop/CS540/classeval_evaluation/ClassEval_60_4.py", line 214, in test_delete_ticket_2
    self.assertEqual(len(tickets), 0)
AssertionError: 1 != 0

======================================================================
FAIL: test_delete_ticket_3 (ClassEval_60_4.MovieTicketDBTestDeleteTicket.test_delete_ticket_3)
----------------------------------------------------------------------
Traceback (most recent call last):
  File "/Users/snigdhaghoshdastidar/Desktop/CS540/classeval_evaluation/ClassEval_60_4.py", line 223, in test_delete_ticket_3
    self.assertEqual(len(tickets), 0)
AssertionError: 1 != 0

======================================================================
FAIL: test_delete_ticket_4 (ClassEval_60_4.MovieTicketDBTestDeleteTicket.test_delete_ticket_4)
----------------------------------------------------------------------
Traceback (most recent call last):
  File "/Users/snigdhaghoshdastidar/Desktop/CS540/classeval_evaluation/ClassEval_60_4.py", line 232, in test_delete_ticket_4
    self.assertEqual(len(tickets), 0)
AssertionError: 1 != 0

======================================================================
FAIL: test_delete_ticket_5 (ClassEval_60_4.MovieTicketDBTestDeleteTicket.test_delete_ticket_5)
----------------------------------------------------------------------
Traceback (most recent call last):
  File "/Users/snigdhaghoshdastidar/Desktop/CS540/classeval_evaluation/ClassEval_60_4.py", line 241, in test_delete_ticket_5
    self.assertEqual(len(tickets), 0)
AssertionError: 1 != 0

----------------------------------------------------------------------
Ran 5 tests in 0.015s

FAILED (failures=5)
F
======================================================================
FAIL: test_MovieTicketDB (ClassEval_60_4.MovieTicketDBTest.test_MovieTicketDB)
----------------------------------------------------------------------
Traceback (most recent call last):
  File "/Users/snigdhaghoshdastidar/Desktop/CS540/classeval_evaluation/ClassEval_60_4.py", line 265, in test_MovieTicketDB
    self.assertEqual(len(tickets), 0)
AssertionError: 1 != 0

----------------------------------------------------------------------
Ran 1 test in 0.002s

FAILED (failures=1)
......
----------------------------------------------------------------------
Ran 6 tests in 0.000s

OK
.....
----------------------------------------------------------------------
Ran 5 tests in 0.000s

OK
.....
----------------------------------------------------------------------
Ran 5 tests in 0.000s

OK
.....
----------------------------------------------------------------------
Ran 5 tests in 0.000s

OK
.....
----------------------------------------------------------------------
Ran 5 tests in 0.000s

OK
.....
----------------------------------------------------------------------
Ran 5 tests in 0.000s

OK
.
----------------------------------------------------------------------
Ran 1 test in 0.000s

OK
......
----------------------------------------------------------------------
Ran 6 tests in 0.000s

OK
.....
----------------------------------------------------------------------
Ran 5 tests in 0.000s

OK
.....
----------------------------------------------------------------------
Ran 5 tests in 0.000s

OK
.....
----------------------------------------------------------------------
Ran 5 tests in 0.000s

OK
.....
----------------------------------------------------------------------
Ran 5 tests in 0.000s

OK
.....
----------------------------------------------------------------------
Ran 5 tests in 0.000s

OK
.
----------------------------------------------------------------------
Ran 1 test in 0.000s

OK
......
----------------------------------------------------------------------
Ran 6 tests in 0.001s

OK
.....
----------------------------------------------------------------------
Ran 5 tests in 0.000s

OK
.....
----------------------------------------------------------------------
Ran 5 tests in 0.000s

OK
.....
----------------------------------------------------------------------
Ran 5 tests in 0.000s

OK
.....
----------------------------------------------------------------------
Ran 5 tests in 0.000s

OK
.....
----------------------------------------------------------------------
Ran 5 tests in 0.000s

OK
.
----------------------------------------------------------------------
Ran 1 test in 0.000s

OK
.....F
======================================================================
FAIL: test_select_6 (ClassEval_79_3.SQLGeneratorTestSelect.test_select_6)
----------------------------------------------------------------------
Traceback (most recent call last):
  File "/Users/snigdhaghoshdastidar/Desktop/CS540/classeval_evaluation/ClassEval_79_3.py", line 119, in test_select_6
    self.assertEqual(result, "SELECT field1 FROM table1;")
AssertionError: 'SELECT field1 FROM table1 ;' != 'SELECT field1 FROM table1;'
- SELECT field1 FROM table1 ;
?                          -
+ SELECT field1 FROM table1;


----------------------------------------------------------------------
Ran 6 tests in 0.001s

FAILED (failures=1)
.....
----------------------------------------------------------------------
Ran 5 tests in 0.000s

OK
.....
----------------------------------------------------------------------
Ran 5 tests in 0.000s

OK
.....
----------------------------------------------------------------------
Ran 5 tests in 0.000s

OK
.....
----------------------------------------------------------------------
Ran 5 tests in 0.000s

OK
.....
----------------------------------------------------------------------
Ran 5 tests in 0.000s

OK
.
----------------------------------------------------------------------
Ran 1 test in 0.000s

OK
......
----------------------------------------------------------------------
Ran 6 tests in 0.000s

OK
.....
----------------------------------------------------------------------
Ran 5 tests in 0.000s

OK
.....
----------------------------------------------------------------------
Ran 5 tests in 0.000s

OK
.....
----------------------------------------------------------------------
Ran 5 tests in 0.000s

OK
.....
----------------------------------------------------------------------
Ran 5 tests in 0.000s

OK
.....
----------------------------------------------------------------------
Ran 5 tests in 0.000s

OK
.
----------------------------------------------------------------------
Ran 1 test in 0.000s

OK
.......
----------------------------------------------------------------------
Ran 7 tests in 0.001s

OK
.....
----------------------------------------------------------------------
Ran 5 tests in 0.000s

OK
......
----------------------------------------------------------------------
Ran 6 tests in 0.001s

OK
......
----------------------------------------------------------------------
Ran 6 tests in 0.000s

OK
.
----------------------------------------------------------------------
Ran 1 test in 0.000s

OK
.......
----------------------------------------------------------------------
Ran 7 tests in 0.000s

OK
.....
----------------------------------------------------------------------
Ran 5 tests in 0.000s

OK
......
----------------------------------------------------------------------
Ran 6 tests in 0.000s

OK
......
----------------------------------------------------------------------
Ran 6 tests in 0.000s

OK
.
----------------------------------------------------------------------
Ran 1 test in 0.000s

OK
.......
----------------------------------------------------------------------
Ran 7 tests in 0.000s

OK
.....
----------------------------------------------------------------------
Ran 5 tests in 0.000s

OK
......
----------------------------------------------------------------------
Ran 6 tests in 0.000s

OK
......
----------------------------------------------------------------------
Ran 6 tests in 0.000s

OK
.
----------------------------------------------------------------------
Ran 1 test in 0.000s

OK
.......
----------------------------------------------------------------------
Ran 7 tests in 0.001s

OK
EEE.E
======================================================================
ERROR: test_insert_1 (ClassEval_80_3.SQLQueryBuilderTestInsert.test_insert_1)
----------------------------------------------------------------------
Traceback (most recent call last):
  File "/Users/snigdhaghoshdastidar/Desktop/CS540/classeval_evaluation/ClassEval_80_3.py", line 133, in test_insert_1
    SQLQueryBuilder.insert('users', {'name': 'Tom', 'age': 30}),
    ^^^^^^^^^^^^^^^^^^^^^^^^^^^^^^^^^^^^^^^^^^^^^^^^^^^^^^^^^^^
  File "/Users/snigdhaghoshdastidar/Desktop/CS540/classeval_evaluation/ClassEval_80_3.py", line 39, in insert
    values = "', '".join(data.values())
             ^^^^^^^^^^^^^^^^^^^^^^^^^^
TypeError: sequence item 1: expected str instance, int found

======================================================================
ERROR: test_insert_2 (ClassEval_80_3.SQLQueryBuilderTestInsert.test_insert_2)
----------------------------------------------------------------------
Traceback (most recent call last):
  File "/Users/snigdhaghoshdastidar/Desktop/CS540/classeval_evaluation/ClassEval_80_3.py", line 139, in test_insert_2
    SQLQueryBuilder.insert('students', {'name': 'Tom', 'age': 18}),
    ^^^^^^^^^^^^^^^^^^^^^^^^^^^^^^^^^^^^^^^^^^^^^^^^^^^^^^^^^^^^^^
  File "/Users/snigdhaghoshdastidar/Desktop/CS540/classeval_evaluation/ClassEval_80_3.py", line 39, in insert
    values = "', '".join(data.values())
             ^^^^^^^^^^^^^^^^^^^^^^^^^^
TypeError: sequence item 1: expected str instance, int found

======================================================================
ERROR: test_insert_3 (ClassEval_80_3.SQLQueryBuilderTestInsert.test_insert_3)
----------------------------------------------------------------------
Traceback (most recent call last):
  File "/Users/snigdhaghoshdastidar/Desktop/CS540/classeval_evaluation/ClassEval_80_3.py", line 145, in test_insert_3
    SQLQueryBuilder.insert('items', {'name': 'apple', 'price': 1.0}),
    ^^^^^^^^^^^^^^^^^^^^^^^^^^^^^^^^^^^^^^^^^^^^^^^^^^^^^^^^^^^^^^^^
  File "/Users/snigdhaghoshdastidar/Desktop/CS540/classeval_evaluation/ClassEval_80_3.py", line 39, in insert
    values = "', '".join(data.values())
             ^^^^^^^^^^^^^^^^^^^^^^^^^^
TypeError: sequence item 1: expected str instance, float found

======================================================================
ERROR: test_insert_5 (ClassEval_80_3.SQLQueryBuilderTestInsert.test_insert_5)
----------------------------------------------------------------------
Traceback (most recent call last):
  File "/Users/snigdhaghoshdastidar/Desktop/CS540/classeval_evaluation/ClassEval_80_3.py", line 157, in test_insert_5
    SQLQueryBuilder.insert('users', {'name': 'Tom', 'age': 30, 'region': 'USA'}),
    ^^^^^^^^^^^^^^^^^^^^^^^^^^^^^^^^^^^^^^^^^^^^^^^^^^^^^^^^^^^^^^^^^^^^^^^^^^^^
  File "/Users/snigdhaghoshdastidar/Desktop/CS540/classeval_evaluation/ClassEval_80_3.py", line 39, in insert
    values = "', '".join(data.values())
             ^^^^^^^^^^^^^^^^^^^^^^^^^^
TypeError: sequence item 1: expected str instance, int found

----------------------------------------------------------------------
Ran 5 tests in 0.002s

FAILED (errors=4)
......
----------------------------------------------------------------------
Ran 6 tests in 0.000s

OK
......
----------------------------------------------------------------------
Ran 6 tests in 0.000s

OK
E
======================================================================
ERROR: test_main (ClassEval_80_3.SQLQueryBuilderTestMain.test_main)
----------------------------------------------------------------------
Traceback (most recent call last):
  File "/Users/snigdhaghoshdastidar/Desktop/CS540/classeval_evaluation/ClassEval_80_3.py", line 245, in test_main
    SQLQueryBuilder.insert('users', {'name': 'Tom', 'age': 30}),
    ^^^^^^^^^^^^^^^^^^^^^^^^^^^^^^^^^^^^^^^^^^^^^^^^^^^^^^^^^^^
  File "/Users/snigdhaghoshdastidar/Desktop/CS540/classeval_evaluation/ClassEval_80_3.py", line 39, in insert
    values = "', '".join(data.values())
             ^^^^^^^^^^^^^^^^^^^^^^^^^^
TypeError: sequence item 1: expected str instance, int found

----------------------------------------------------------------------
Ran 1 test in 0.000s

FAILED (errors=1)
.......
----------------------------------------------------------------------
Ran 7 tests in 0.000s

OK
.....
----------------------------------------------------------------------
Ran 5 tests in 0.000s

OK
......
----------------------------------------------------------------------
Ran 6 tests in 0.000s

OK
......
----------------------------------------------------------------------
Ran 6 tests in 0.000s

OK
.
----------------------------------------------------------------------
Ran 1 test in 0.000s

OK
EEEEE
======================================================================
ERROR: test_insert_student_1 (ClassEval_83_0.StudentDatabaseProcessorTestInsertStudent.test_insert_student_1)
----------------------------------------------------------------------
Traceback (most recent call last):
  File "/Users/snigdhaghoshdastidar/Desktop/CS540/classeval_evaluation/ClassEval_83_0.py", line 102, in test_insert_student_1
    self.processor.insert_student(student_data)
  File "/Users/snigdhaghoshdastidar/Desktop/CS540/classeval_evaluation/ClassEval_83_0.py", line 44, in insert_student
    (student_data['ID'], student_data['name'], student_data['age'], student_data['gender'], student_data['grade']))
     ~~~~~~~~~~~~^^^^^^
KeyError: 'ID'

======================================================================
ERROR: test_insert_student_2 (ClassEval_83_0.StudentDatabaseProcessorTestInsertStudent.test_insert_student_2)
----------------------------------------------------------------------
Traceback (most recent call last):
  File "/Users/snigdhaghoshdastidar/Desktop/CS540/classeval_evaluation/ClassEval_83_0.py", line 120, in test_insert_student_2
    self.processor.insert_student(student_data)
  File "/Users/snigdhaghoshdastidar/Desktop/CS540/classeval_evaluation/ClassEval_83_0.py", line 44, in insert_student
    (student_data['ID'], student_data['name'], student_data['age'], student_data['gender'], student_data['grade']))
     ~~~~~~~~~~~~^^^^^^
KeyError: 'ID'

======================================================================
ERROR: test_insert_student_3 (ClassEval_83_0.StudentDatabaseProcessorTestInsertStudent.test_insert_student_3)
----------------------------------------------------------------------
Traceback (most recent call last):
  File "/Users/snigdhaghoshdastidar/Desktop/CS540/classeval_evaluation/ClassEval_83_0.py", line 138, in test_insert_student_3
    self.processor.insert_student(student_data)
  File "/Users/snigdhaghoshdastidar/Desktop/CS540/classeval_evaluation/ClassEval_83_0.py", line 44, in insert_student
    (student_data['ID'], student_data['name'], student_data['age'], student_data['gender'], student_data['grade']))
     ~~~~~~~~~~~~^^^^^^
KeyError: 'ID'

======================================================================
ERROR: test_insert_student_4 (ClassEval_83_0.StudentDatabaseProcessorTestInsertStudent.test_insert_student_4)
----------------------------------------------------------------------
Traceback (most recent call last):
  File "/Users/snigdhaghoshdastidar/Desktop/CS540/classeval_evaluation/ClassEval_83_0.py", line 156, in test_insert_student_4
    self.processor.insert_student(student_data)
  File "/Users/snigdhaghoshdastidar/Desktop/CS540/classeval_evaluation/ClassEval_83_0.py", line 44, in insert_student
    (student_data['ID'], student_data['name'], student_data['age'], student_data['gender'], student_data['grade']))
     ~~~~~~~~~~~~^^^^^^
KeyError: 'ID'

======================================================================
ERROR: test_insert_student_5 (ClassEval_83_0.StudentDatabaseProcessorTestInsertStudent.test_insert_student_5)
----------------------------------------------------------------------
Traceback (most recent call last):
  File "/Users/snigdhaghoshdastidar/Desktop/CS540/classeval_evaluation/ClassEval_83_0.py", line 174, in test_insert_student_5
    self.processor.insert_student(student_data)
  File "/Users/snigdhaghoshdastidar/Desktop/CS540/classeval_evaluation/ClassEval_83_0.py", line 44, in insert_student
    (student_data['ID'], student_data['name'], student_data['age'], student_data['gender'], student_data['grade']))
     ~~~~~~~~~~~~^^^^^^
KeyError: 'ID'

----------------------------------------------------------------------
Ran 5 tests in 0.019s

FAILED (errors=5)
EEEEE
======================================================================
ERROR: test_search_student_by_name_1 (ClassEval_83_0.StudentDatabaseProcessorTestSearchStudentByName.test_search_student_by_name_1)
----------------------------------------------------------------------
Traceback (most recent call last):
  File "/Users/snigdhaghoshdastidar/Desktop/CS540/classeval_evaluation/ClassEval_83_0.py", line 204, in test_search_student_by_name_1
    self.processor.insert_student(student_data)
  File "/Users/snigdhaghoshdastidar/Desktop/CS540/classeval_evaluation/ClassEval_83_0.py", line 44, in insert_student
    (student_data['ID'], student_data['name'], student_data['age'], student_data['gender'], student_data['grade']))
     ~~~~~~~~~~~~^^^^^^
KeyError: 'ID'

======================================================================
ERROR: test_search_student_by_name_2 (ClassEval_83_0.StudentDatabaseProcessorTestSearchStudentByName.test_search_student_by_name_2)
----------------------------------------------------------------------
Traceback (most recent call last):
  File "/Users/snigdhaghoshdastidar/Desktop/CS540/classeval_evaluation/ClassEval_83_0.py", line 218, in test_search_student_by_name_2
    self.processor.insert_student(student_data)
  File "/Users/snigdhaghoshdastidar/Desktop/CS540/classeval_evaluation/ClassEval_83_0.py", line 44, in insert_student
    (student_data['ID'], student_data['name'], student_data['age'], student_data['gender'], student_data['grade']))
     ~~~~~~~~~~~~^^^^^^
KeyError: 'ID'

======================================================================
ERROR: test_search_student_by_name_3 (ClassEval_83_0.StudentDatabaseProcessorTestSearchStudentByName.test_search_student_by_name_3)
----------------------------------------------------------------------
Traceback (most recent call last):
  File "/Users/snigdhaghoshdastidar/Desktop/CS540/classeval_evaluation/ClassEval_83_0.py", line 232, in test_search_student_by_name_3
    self.processor.insert_student(student_data)
  File "/Users/snigdhaghoshdastidar/Desktop/CS540/classeval_evaluation/ClassEval_83_0.py", line 44, in insert_student
    (student_data['ID'], student_data['name'], student_data['age'], student_data['gender'], student_data['grade']))
     ~~~~~~~~~~~~^^^^^^
KeyError: 'ID'

======================================================================
ERROR: test_search_student_by_name_4 (ClassEval_83_0.StudentDatabaseProcessorTestSearchStudentByName.test_search_student_by_name_4)
----------------------------------------------------------------------
Traceback (most recent call last):
  File "/Users/snigdhaghoshdastidar/Desktop/CS540/classeval_evaluation/ClassEval_83_0.py", line 246, in test_search_student_by_name_4
    self.processor.insert_student(student_data)
  File "/Users/snigdhaghoshdastidar/Desktop/CS540/classeval_evaluation/ClassEval_83_0.py", line 44, in insert_student
    (student_data['ID'], student_data['name'], student_data['age'], student_data['gender'], student_data['grade']))
     ~~~~~~~~~~~~^^^^^^
KeyError: 'ID'

======================================================================
ERROR: test_search_student_by_name_5 (ClassEval_83_0.StudentDatabaseProcessorTestSearchStudentByName.test_search_student_by_name_5)
----------------------------------------------------------------------
Traceback (most recent call last):
  File "/Users/snigdhaghoshdastidar/Desktop/CS540/classeval_evaluation/ClassEval_83_0.py", line 260, in test_search_student_by_name_5
    self.processor.insert_student(student_data)
  File "/Users/snigdhaghoshdastidar/Desktop/CS540/classeval_evaluation/ClassEval_83_0.py", line 44, in insert_student
    (student_data['ID'], student_data['name'], student_data['age'], student_data['gender'], student_data['grade']))
     ~~~~~~~~~~~~^^^^^^
KeyError: 'ID'

----------------------------------------------------------------------
Ran 5 tests in 0.017s

FAILED (errors=5)
EEEEE
======================================================================
ERROR: test_delete_student_by_name_1 (ClassEval_83_0.StudentDatabaseProcessorTestDeleteStudentByName.test_delete_student_by_name_1)
----------------------------------------------------------------------
Traceback (most recent call last):
  File "/Users/snigdhaghoshdastidar/Desktop/CS540/classeval_evaluation/ClassEval_83_0.py", line 286, in test_delete_student_by_name_1
    self.processor.insert_student(student_data)
  File "/Users/snigdhaghoshdastidar/Desktop/CS540/classeval_evaluation/ClassEval_83_0.py", line 44, in insert_student
    (student_data['ID'], student_data['name'], student_data['age'], student_data['gender'], student_data['grade']))
     ~~~~~~~~~~~~^^^^^^
KeyError: 'ID'

======================================================================
ERROR: test_delete_student_by_name_2 (ClassEval_83_0.StudentDatabaseProcessorTestDeleteStudentByName.test_delete_student_by_name_2)
----------------------------------------------------------------------
Traceback (most recent call last):
  File "/Users/snigdhaghoshdastidar/Desktop/CS540/classeval_evaluation/ClassEval_83_0.py", line 305, in test_delete_student_by_name_2
    self.processor.insert_student(student_data)
  File "/Users/snigdhaghoshdastidar/Desktop/CS540/classeval_evaluation/ClassEval_83_0.py", line 44, in insert_student
    (student_data['ID'], student_data['name'], student_data['age'], student_data['gender'], student_data['grade']))
     ~~~~~~~~~~~~^^^^^^
KeyError: 'ID'

======================================================================
ERROR: test_delete_student_by_name_3 (ClassEval_83_0.StudentDatabaseProcessorTestDeleteStudentByName.test_delete_student_by_name_3)
----------------------------------------------------------------------
Traceback (most recent call last):
  File "/Users/snigdhaghoshdastidar/Desktop/CS540/classeval_evaluation/ClassEval_83_0.py", line 324, in test_delete_student_by_name_3
    self.processor.insert_student(student_data)
  File "/Users/snigdhaghoshdastidar/Desktop/CS540/classeval_evaluation/ClassEval_83_0.py", line 44, in insert_student
    (student_data['ID'], student_data['name'], student_data['age'], student_data['gender'], student_data['grade']))
     ~~~~~~~~~~~~^^^^^^
KeyError: 'ID'

======================================================================
ERROR: test_delete_student_by_name_4 (ClassEval_83_0.StudentDatabaseProcessorTestDeleteStudentByName.test_delete_student_by_name_4)
----------------------------------------------------------------------
Traceback (most recent call last):
  File "/Users/snigdhaghoshdastidar/Desktop/CS540/classeval_evaluation/ClassEval_83_0.py", line 343, in test_delete_student_by_name_4
    self.processor.insert_student(student_data)
  File "/Users/snigdhaghoshdastidar/Desktop/CS540/classeval_evaluation/ClassEval_83_0.py", line 44, in insert_student
    (student_data['ID'], student_data['name'], student_data['age'], student_data['gender'], student_data['grade']))
     ~~~~~~~~~~~~^^^^^^
KeyError: 'ID'

======================================================================
ERROR: test_delete_student_by_name_5 (ClassEval_83_0.StudentDatabaseProcessorTestDeleteStudentByName.test_delete_student_by_name_5)
----------------------------------------------------------------------
Traceback (most recent call last):
  File "/Users/snigdhaghoshdastidar/Desktop/CS540/classeval_evaluation/ClassEval_83_0.py", line 362, in test_delete_student_by_name_5
    self.processor.insert_student(student_data)
  File "/Users/snigdhaghoshdastidar/Desktop/CS540/classeval_evaluation/ClassEval_83_0.py", line 44, in insert_student
    (student_data['ID'], student_data['name'], student_data['age'], student_data['gender'], student_data['grade']))
     ~~~~~~~~~~~~^^^^^^
KeyError: 'ID'

----------------------------------------------------------------------
Ran 5 tests in 0.019s

FAILED (errors=5)
E
======================================================================
ERROR: test_StudentDatabaseProcessor (ClassEval_83_0.StudentDatabaseProcessorTest.test_StudentDatabaseProcessor)
----------------------------------------------------------------------
Traceback (most recent call last):
  File "/Users/snigdhaghoshdastidar/Desktop/CS540/classeval_evaluation/ClassEval_83_0.py", line 393, in test_StudentDatabaseProcessor
    self.processor.insert_student(student_data)
  File "/Users/snigdhaghoshdastidar/Desktop/CS540/classeval_evaluation/ClassEval_83_0.py", line 44, in insert_student
    (student_data['ID'], student_data['name'], student_data['age'], student_data['gender'], student_data['grade']))
     ~~~~~~~~~~~~^^^^^^
KeyError: 'ID'

----------------------------------------------------------------------
Ran 1 test in 0.003s

FAILED (errors=1)
EEEEE
======================================================================
ERROR: test_insert_student_1 (ClassEval_83_1.StudentDatabaseProcessorTestInsertStudent.test_insert_student_1)
----------------------------------------------------------------------
Traceback (most recent call last):
  File "/Users/snigdhaghoshdastidar/Desktop/CS540/classeval_evaluation/ClassEval_83_1.py", line 88, in test_insert_student_1
    self.processor.insert_student(student_data)
  File "/Users/snigdhaghoshdastidar/Desktop/CS540/classeval_evaluation/ClassEval_83_1.py", line 38, in insert_student
    (student_data['ID'], student_data['name'], student_data['age'], student_data['gender'], student_data['grade']))
     ~~~~~~~~~~~~^^^^^^
KeyError: 'ID'

======================================================================
ERROR: test_insert_student_2 (ClassEval_83_1.StudentDatabaseProcessorTestInsertStudent.test_insert_student_2)
----------------------------------------------------------------------
Traceback (most recent call last):
  File "/Users/snigdhaghoshdastidar/Desktop/CS540/classeval_evaluation/ClassEval_83_1.py", line 106, in test_insert_student_2
    self.processor.insert_student(student_data)
  File "/Users/snigdhaghoshdastidar/Desktop/CS540/classeval_evaluation/ClassEval_83_1.py", line 38, in insert_student
    (student_data['ID'], student_data['name'], student_data['age'], student_data['gender'], student_data['grade']))
     ~~~~~~~~~~~~^^^^^^
KeyError: 'ID'

======================================================================
ERROR: test_insert_student_3 (ClassEval_83_1.StudentDatabaseProcessorTestInsertStudent.test_insert_student_3)
----------------------------------------------------------------------
Traceback (most recent call last):
  File "/Users/snigdhaghoshdastidar/Desktop/CS540/classeval_evaluation/ClassEval_83_1.py", line 124, in test_insert_student_3
    self.processor.insert_student(student_data)
  File "/Users/snigdhaghoshdastidar/Desktop/CS540/classeval_evaluation/ClassEval_83_1.py", line 38, in insert_student
    (student_data['ID'], student_data['name'], student_data['age'], student_data['gender'], student_data['grade']))
     ~~~~~~~~~~~~^^^^^^
KeyError: 'ID'

======================================================================
ERROR: test_insert_student_4 (ClassEval_83_1.StudentDatabaseProcessorTestInsertStudent.test_insert_student_4)
----------------------------------------------------------------------
Traceback (most recent call last):
  File "/Users/snigdhaghoshdastidar/Desktop/CS540/classeval_evaluation/ClassEval_83_1.py", line 142, in test_insert_student_4
    self.processor.insert_student(student_data)
  File "/Users/snigdhaghoshdastidar/Desktop/CS540/classeval_evaluation/ClassEval_83_1.py", line 38, in insert_student
    (student_data['ID'], student_data['name'], student_data['age'], student_data['gender'], student_data['grade']))
     ~~~~~~~~~~~~^^^^^^
KeyError: 'ID'

======================================================================
ERROR: test_insert_student_5 (ClassEval_83_1.StudentDatabaseProcessorTestInsertStudent.test_insert_student_5)
----------------------------------------------------------------------
Traceback (most recent call last):
  File "/Users/snigdhaghoshdastidar/Desktop/CS540/classeval_evaluation/ClassEval_83_1.py", line 160, in test_insert_student_5
    self.processor.insert_student(student_data)
  File "/Users/snigdhaghoshdastidar/Desktop/CS540/classeval_evaluation/ClassEval_83_1.py", line 38, in insert_student
    (student_data['ID'], student_data['name'], student_data['age'], student_data['gender'], student_data['grade']))
     ~~~~~~~~~~~~^^^^^^
KeyError: 'ID'

----------------------------------------------------------------------
Ran 5 tests in 0.016s

FAILED (errors=5)
EEEEE
======================================================================
ERROR: test_search_student_by_name_1 (ClassEval_83_1.StudentDatabaseProcessorTestSearchStudentByName.test_search_student_by_name_1)
----------------------------------------------------------------------
Traceback (most recent call last):
  File "/Users/snigdhaghoshdastidar/Desktop/CS540/classeval_evaluation/ClassEval_83_1.py", line 190, in test_search_student_by_name_1
    self.processor.insert_student(student_data)
  File "/Users/snigdhaghoshdastidar/Desktop/CS540/classeval_evaluation/ClassEval_83_1.py", line 38, in insert_student
    (student_data['ID'], student_data['name'], student_data['age'], student_data['gender'], student_data['grade']))
     ~~~~~~~~~~~~^^^^^^
KeyError: 'ID'

======================================================================
ERROR: test_search_student_by_name_2 (ClassEval_83_1.StudentDatabaseProcessorTestSearchStudentByName.test_search_student_by_name_2)
----------------------------------------------------------------------
Traceback (most recent call last):
  File "/Users/snigdhaghoshdastidar/Desktop/CS540/classeval_evaluation/ClassEval_83_1.py", line 204, in test_search_student_by_name_2
    self.processor.insert_student(student_data)
  File "/Users/snigdhaghoshdastidar/Desktop/CS540/classeval_evaluation/ClassEval_83_1.py", line 38, in insert_student
    (student_data['ID'], student_data['name'], student_data['age'], student_data['gender'], student_data['grade']))
     ~~~~~~~~~~~~^^^^^^
KeyError: 'ID'

======================================================================
ERROR: test_search_student_by_name_3 (ClassEval_83_1.StudentDatabaseProcessorTestSearchStudentByName.test_search_student_by_name_3)
----------------------------------------------------------------------
Traceback (most recent call last):
  File "/Users/snigdhaghoshdastidar/Desktop/CS540/classeval_evaluation/ClassEval_83_1.py", line 218, in test_search_student_by_name_3
    self.processor.insert_student(student_data)
  File "/Users/snigdhaghoshdastidar/Desktop/CS540/classeval_evaluation/ClassEval_83_1.py", line 38, in insert_student
    (student_data['ID'], student_data['name'], student_data['age'], student_data['gender'], student_data['grade']))
     ~~~~~~~~~~~~^^^^^^
KeyError: 'ID'

======================================================================
ERROR: test_search_student_by_name_4 (ClassEval_83_1.StudentDatabaseProcessorTestSearchStudentByName.test_search_student_by_name_4)
----------------------------------------------------------------------
Traceback (most recent call last):
  File "/Users/snigdhaghoshdastidar/Desktop/CS540/classeval_evaluation/ClassEval_83_1.py", line 232, in test_search_student_by_name_4
    self.processor.insert_student(student_data)
  File "/Users/snigdhaghoshdastidar/Desktop/CS540/classeval_evaluation/ClassEval_83_1.py", line 38, in insert_student
    (student_data['ID'], student_data['name'], student_data['age'], student_data['gender'], student_data['grade']))
     ~~~~~~~~~~~~^^^^^^
KeyError: 'ID'

======================================================================
ERROR: test_search_student_by_name_5 (ClassEval_83_1.StudentDatabaseProcessorTestSearchStudentByName.test_search_student_by_name_5)
----------------------------------------------------------------------
Traceback (most recent call last):
  File "/Users/snigdhaghoshdastidar/Desktop/CS540/classeval_evaluation/ClassEval_83_1.py", line 246, in test_search_student_by_name_5
    self.processor.insert_student(student_data)
  File "/Users/snigdhaghoshdastidar/Desktop/CS540/classeval_evaluation/ClassEval_83_1.py", line 38, in insert_student
    (student_data['ID'], student_data['name'], student_data['age'], student_data['gender'], student_data['grade']))
     ~~~~~~~~~~~~^^^^^^
KeyError: 'ID'

----------------------------------------------------------------------
Ran 5 tests in 0.018s

FAILED (errors=5)
EEEEE
======================================================================
ERROR: test_delete_student_by_name_1 (ClassEval_83_1.StudentDatabaseProcessorTestDeleteStudentByName.test_delete_student_by_name_1)
----------------------------------------------------------------------
Traceback (most recent call last):
  File "/Users/snigdhaghoshdastidar/Desktop/CS540/classeval_evaluation/ClassEval_83_1.py", line 272, in test_delete_student_by_name_1
    self.processor.insert_student(student_data)
  File "/Users/snigdhaghoshdastidar/Desktop/CS540/classeval_evaluation/ClassEval_83_1.py", line 38, in insert_student
    (student_data['ID'], student_data['name'], student_data['age'], student_data['gender'], student_data['grade']))
     ~~~~~~~~~~~~^^^^^^
KeyError: 'ID'

======================================================================
ERROR: test_delete_student_by_name_2 (ClassEval_83_1.StudentDatabaseProcessorTestDeleteStudentByName.test_delete_student_by_name_2)
----------------------------------------------------------------------
Traceback (most recent call last):
  File "/Users/snigdhaghoshdastidar/Desktop/CS540/classeval_evaluation/ClassEval_83_1.py", line 291, in test_delete_student_by_name_2
    self.processor.insert_student(student_data)
  File "/Users/snigdhaghoshdastidar/Desktop/CS540/classeval_evaluation/ClassEval_83_1.py", line 38, in insert_student
    (student_data['ID'], student_data['name'], student_data['age'], student_data['gender'], student_data['grade']))
     ~~~~~~~~~~~~^^^^^^
KeyError: 'ID'

======================================================================
ERROR: test_delete_student_by_name_3 (ClassEval_83_1.StudentDatabaseProcessorTestDeleteStudentByName.test_delete_student_by_name_3)
----------------------------------------------------------------------
Traceback (most recent call last):
  File "/Users/snigdhaghoshdastidar/Desktop/CS540/classeval_evaluation/ClassEval_83_1.py", line 310, in test_delete_student_by_name_3
    self.processor.insert_student(student_data)
  File "/Users/snigdhaghoshdastidar/Desktop/CS540/classeval_evaluation/ClassEval_83_1.py", line 38, in insert_student
    (student_data['ID'], student_data['name'], student_data['age'], student_data['gender'], student_data['grade']))
     ~~~~~~~~~~~~^^^^^^
KeyError: 'ID'

======================================================================
ERROR: test_delete_student_by_name_4 (ClassEval_83_1.StudentDatabaseProcessorTestDeleteStudentByName.test_delete_student_by_name_4)
----------------------------------------------------------------------
Traceback (most recent call last):
  File "/Users/snigdhaghoshdastidar/Desktop/CS540/classeval_evaluation/ClassEval_83_1.py", line 329, in test_delete_student_by_name_4
    self.processor.insert_student(student_data)
  File "/Users/snigdhaghoshdastidar/Desktop/CS540/classeval_evaluation/ClassEval_83_1.py", line 38, in insert_student
    (student_data['ID'], student_data['name'], student_data['age'], student_data['gender'], student_data['grade']))
     ~~~~~~~~~~~~^^^^^^
KeyError: 'ID'

======================================================================
ERROR: test_delete_student_by_name_5 (ClassEval_83_1.StudentDatabaseProcessorTestDeleteStudentByName.test_delete_student_by_name_5)
----------------------------------------------------------------------
Traceback (most recent call last):
  File "/Users/snigdhaghoshdastidar/Desktop/CS540/classeval_evaluation/ClassEval_83_1.py", line 348, in test_delete_student_by_name_5
    self.processor.insert_student(student_data)
  File "/Users/snigdhaghoshdastidar/Desktop/CS540/classeval_evaluation/ClassEval_83_1.py", line 38, in insert_student
    (student_data['ID'], student_data['name'], student_data['age'], student_data['gender'], student_data['grade']))
     ~~~~~~~~~~~~^^^^^^
KeyError: 'ID'

----------------------------------------------------------------------
Ran 5 tests in 0.019s

FAILED (errors=5)
E
======================================================================
ERROR: test_StudentDatabaseProcessor (ClassEval_83_1.StudentDatabaseProcessorTest.test_StudentDatabaseProcessor)
----------------------------------------------------------------------
Traceback (most recent call last):
  File "/Users/snigdhaghoshdastidar/Desktop/CS540/classeval_evaluation/ClassEval_83_1.py", line 379, in test_StudentDatabaseProcessor
    self.processor.insert_student(student_data)
  File "/Users/snigdhaghoshdastidar/Desktop/CS540/classeval_evaluation/ClassEval_83_1.py", line 38, in insert_student
    (student_data['ID'], student_data['name'], student_data['age'], student_data['gender'], student_data['grade']))
     ~~~~~~~~~~~~^^^^^^
KeyError: 'ID'

----------------------------------------------------------------------
Ran 1 test in 0.004s

FAILED (errors=1)
EEEEE
======================================================================
ERROR: test_insert_student_1 (ClassEval_83_2.StudentDatabaseProcessorTestInsertStudent.test_insert_student_1)
----------------------------------------------------------------------
Traceback (most recent call last):
  File "/Users/snigdhaghoshdastidar/Desktop/CS540/classeval_evaluation/ClassEval_83_2.py", line 88, in test_insert_student_1
    self.processor.insert_student(student_data)
  File "/Users/snigdhaghoshdastidar/Desktop/CS540/classeval_evaluation/ClassEval_83_2.py", line 38, in insert_student
    (student_data['ID'], student_data['name'], student_data['age'], student_data['gender'], student_data['grade']))
     ~~~~~~~~~~~~^^^^^^
KeyError: 'ID'

======================================================================
ERROR: test_insert_student_2 (ClassEval_83_2.StudentDatabaseProcessorTestInsertStudent.test_insert_student_2)
----------------------------------------------------------------------
Traceback (most recent call last):
  File "/Users/snigdhaghoshdastidar/Desktop/CS540/classeval_evaluation/ClassEval_83_2.py", line 106, in test_insert_student_2
    self.processor.insert_student(student_data)
  File "/Users/snigdhaghoshdastidar/Desktop/CS540/classeval_evaluation/ClassEval_83_2.py", line 38, in insert_student
    (student_data['ID'], student_data['name'], student_data['age'], student_data['gender'], student_data['grade']))
     ~~~~~~~~~~~~^^^^^^
KeyError: 'ID'

======================================================================
ERROR: test_insert_student_3 (ClassEval_83_2.StudentDatabaseProcessorTestInsertStudent.test_insert_student_3)
----------------------------------------------------------------------
Traceback (most recent call last):
  File "/Users/snigdhaghoshdastidar/Desktop/CS540/classeval_evaluation/ClassEval_83_2.py", line 124, in test_insert_student_3
    self.processor.insert_student(student_data)
  File "/Users/snigdhaghoshdastidar/Desktop/CS540/classeval_evaluation/ClassEval_83_2.py", line 38, in insert_student
    (student_data['ID'], student_data['name'], student_data['age'], student_data['gender'], student_data['grade']))
     ~~~~~~~~~~~~^^^^^^
KeyError: 'ID'

======================================================================
ERROR: test_insert_student_4 (ClassEval_83_2.StudentDatabaseProcessorTestInsertStudent.test_insert_student_4)
----------------------------------------------------------------------
Traceback (most recent call last):
  File "/Users/snigdhaghoshdastidar/Desktop/CS540/classeval_evaluation/ClassEval_83_2.py", line 142, in test_insert_student_4
    self.processor.insert_student(student_data)
  File "/Users/snigdhaghoshdastidar/Desktop/CS540/classeval_evaluation/ClassEval_83_2.py", line 38, in insert_student
    (student_data['ID'], student_data['name'], student_data['age'], student_data['gender'], student_data['grade']))
     ~~~~~~~~~~~~^^^^^^
KeyError: 'ID'

======================================================================
ERROR: test_insert_student_5 (ClassEval_83_2.StudentDatabaseProcessorTestInsertStudent.test_insert_student_5)
----------------------------------------------------------------------
Traceback (most recent call last):
  File "/Users/snigdhaghoshdastidar/Desktop/CS540/classeval_evaluation/ClassEval_83_2.py", line 160, in test_insert_student_5
    self.processor.insert_student(student_data)
  File "/Users/snigdhaghoshdastidar/Desktop/CS540/classeval_evaluation/ClassEval_83_2.py", line 38, in insert_student
    (student_data['ID'], student_data['name'], student_data['age'], student_data['gender'], student_data['grade']))
     ~~~~~~~~~~~~^^^^^^
KeyError: 'ID'

----------------------------------------------------------------------
Ran 5 tests in 0.023s

FAILED (errors=5)
EEEEE
======================================================================
ERROR: test_search_student_by_name_1 (ClassEval_83_2.StudentDatabaseProcessorTestSearchStudentByName.test_search_student_by_name_1)
----------------------------------------------------------------------
Traceback (most recent call last):
  File "/Users/snigdhaghoshdastidar/Desktop/CS540/classeval_evaluation/ClassEval_83_2.py", line 190, in test_search_student_by_name_1
    self.processor.insert_student(student_data)
  File "/Users/snigdhaghoshdastidar/Desktop/CS540/classeval_evaluation/ClassEval_83_2.py", line 38, in insert_student
    (student_data['ID'], student_data['name'], student_data['age'], student_data['gender'], student_data['grade']))
     ~~~~~~~~~~~~^^^^^^
KeyError: 'ID'

======================================================================
ERROR: test_search_student_by_name_2 (ClassEval_83_2.StudentDatabaseProcessorTestSearchStudentByName.test_search_student_by_name_2)
----------------------------------------------------------------------
Traceback (most recent call last):
  File "/Users/snigdhaghoshdastidar/Desktop/CS540/classeval_evaluation/ClassEval_83_2.py", line 204, in test_search_student_by_name_2
    self.processor.insert_student(student_data)
  File "/Users/snigdhaghoshdastidar/Desktop/CS540/classeval_evaluation/ClassEval_83_2.py", line 38, in insert_student
    (student_data['ID'], student_data['name'], student_data['age'], student_data['gender'], student_data['grade']))
     ~~~~~~~~~~~~^^^^^^
KeyError: 'ID'

======================================================================
ERROR: test_search_student_by_name_3 (ClassEval_83_2.StudentDatabaseProcessorTestSearchStudentByName.test_search_student_by_name_3)
----------------------------------------------------------------------
Traceback (most recent call last):
  File "/Users/snigdhaghoshdastidar/Desktop/CS540/classeval_evaluation/ClassEval_83_2.py", line 218, in test_search_student_by_name_3
    self.processor.insert_student(student_data)
  File "/Users/snigdhaghoshdastidar/Desktop/CS540/classeval_evaluation/ClassEval_83_2.py", line 38, in insert_student
    (student_data['ID'], student_data['name'], student_data['age'], student_data['gender'], student_data['grade']))
     ~~~~~~~~~~~~^^^^^^
KeyError: 'ID'

======================================================================
ERROR: test_search_student_by_name_4 (ClassEval_83_2.StudentDatabaseProcessorTestSearchStudentByName.test_search_student_by_name_4)
----------------------------------------------------------------------
Traceback (most recent call last):
  File "/Users/snigdhaghoshdastidar/Desktop/CS540/classeval_evaluation/ClassEval_83_2.py", line 232, in test_search_student_by_name_4
    self.processor.insert_student(student_data)
  File "/Users/snigdhaghoshdastidar/Desktop/CS540/classeval_evaluation/ClassEval_83_2.py", line 38, in insert_student
    (student_data['ID'], student_data['name'], student_data['age'], student_data['gender'], student_data['grade']))
     ~~~~~~~~~~~~^^^^^^
KeyError: 'ID'

======================================================================
ERROR: test_search_student_by_name_5 (ClassEval_83_2.StudentDatabaseProcessorTestSearchStudentByName.test_search_student_by_name_5)
----------------------------------------------------------------------
Traceback (most recent call last):
  File "/Users/snigdhaghoshdastidar/Desktop/CS540/classeval_evaluation/ClassEval_83_2.py", line 246, in test_search_student_by_name_5
    self.processor.insert_student(student_data)
  File "/Users/snigdhaghoshdastidar/Desktop/CS540/classeval_evaluation/ClassEval_83_2.py", line 38, in insert_student
    (student_data['ID'], student_data['name'], student_data['age'], student_data['gender'], student_data['grade']))
     ~~~~~~~~~~~~^^^^^^
KeyError: 'ID'

----------------------------------------------------------------------
Ran 5 tests in 0.021s

FAILED (errors=5)
EEEEE
======================================================================
ERROR: test_delete_student_by_name_1 (ClassEval_83_2.StudentDatabaseProcessorTestDeleteStudentByName.test_delete_student_by_name_1)
----------------------------------------------------------------------
Traceback (most recent call last):
  File "/Users/snigdhaghoshdastidar/Desktop/CS540/classeval_evaluation/ClassEval_83_2.py", line 272, in test_delete_student_by_name_1
    self.processor.insert_student(student_data)
  File "/Users/snigdhaghoshdastidar/Desktop/CS540/classeval_evaluation/ClassEval_83_2.py", line 38, in insert_student
    (student_data['ID'], student_data['name'], student_data['age'], student_data['gender'], student_data['grade']))
     ~~~~~~~~~~~~^^^^^^
KeyError: 'ID'

======================================================================
ERROR: test_delete_student_by_name_2 (ClassEval_83_2.StudentDatabaseProcessorTestDeleteStudentByName.test_delete_student_by_name_2)
----------------------------------------------------------------------
Traceback (most recent call last):
  File "/Users/snigdhaghoshdastidar/Desktop/CS540/classeval_evaluation/ClassEval_83_2.py", line 291, in test_delete_student_by_name_2
    self.processor.insert_student(student_data)
  File "/Users/snigdhaghoshdastidar/Desktop/CS540/classeval_evaluation/ClassEval_83_2.py", line 38, in insert_student
    (student_data['ID'], student_data['name'], student_data['age'], student_data['gender'], student_data['grade']))
     ~~~~~~~~~~~~^^^^^^
KeyError: 'ID'

======================================================================
ERROR: test_delete_student_by_name_3 (ClassEval_83_2.StudentDatabaseProcessorTestDeleteStudentByName.test_delete_student_by_name_3)
----------------------------------------------------------------------
Traceback (most recent call last):
  File "/Users/snigdhaghoshdastidar/Desktop/CS540/classeval_evaluation/ClassEval_83_2.py", line 310, in test_delete_student_by_name_3
    self.processor.insert_student(student_data)
  File "/Users/snigdhaghoshdastidar/Desktop/CS540/classeval_evaluation/ClassEval_83_2.py", line 38, in insert_student
    (student_data['ID'], student_data['name'], student_data['age'], student_data['gender'], student_data['grade']))
     ~~~~~~~~~~~~^^^^^^
KeyError: 'ID'

======================================================================
ERROR: test_delete_student_by_name_4 (ClassEval_83_2.StudentDatabaseProcessorTestDeleteStudentByName.test_delete_student_by_name_4)
----------------------------------------------------------------------
Traceback (most recent call last):
  File "/Users/snigdhaghoshdastidar/Desktop/CS540/classeval_evaluation/ClassEval_83_2.py", line 329, in test_delete_student_by_name_4
    self.processor.insert_student(student_data)
  File "/Users/snigdhaghoshdastidar/Desktop/CS540/classeval_evaluation/ClassEval_83_2.py", line 38, in insert_student
    (student_data['ID'], student_data['name'], student_data['age'], student_data['gender'], student_data['grade']))
     ~~~~~~~~~~~~^^^^^^
KeyError: 'ID'

======================================================================
ERROR: test_delete_student_by_name_5 (ClassEval_83_2.StudentDatabaseProcessorTestDeleteStudentByName.test_delete_student_by_name_5)
----------------------------------------------------------------------
Traceback (most recent call last):
  File "/Users/snigdhaghoshdastidar/Desktop/CS540/classeval_evaluation/ClassEval_83_2.py", line 348, in test_delete_student_by_name_5
    self.processor.insert_student(student_data)
  File "/Users/snigdhaghoshdastidar/Desktop/CS540/classeval_evaluation/ClassEval_83_2.py", line 38, in insert_student
    (student_data['ID'], student_data['name'], student_data['age'], student_data['gender'], student_data['grade']))
     ~~~~~~~~~~~~^^^^^^
KeyError: 'ID'

----------------------------------------------------------------------
Ran 5 tests in 0.025s

FAILED (errors=5)
E
======================================================================
ERROR: test_StudentDatabaseProcessor (ClassEval_83_2.StudentDatabaseProcessorTest.test_StudentDatabaseProcessor)
----------------------------------------------------------------------
Traceback (most recent call last):
  File "/Users/snigdhaghoshdastidar/Desktop/CS540/classeval_evaluation/ClassEval_83_2.py", line 379, in test_StudentDatabaseProcessor
    self.processor.insert_student(student_data)
  File "/Users/snigdhaghoshdastidar/Desktop/CS540/classeval_evaluation/ClassEval_83_2.py", line 38, in insert_student
    (student_data['ID'], student_data['name'], student_data['age'], student_data['gender'], student_data['grade']))
     ~~~~~~~~~~~~^^^^^^
KeyError: 'ID'

----------------------------------------------------------------------
Ran 1 test in 0.004s

FAILED (errors=1)
.....
----------------------------------------------------------------------
Ran 5 tests in 0.034s

OK
.....
----------------------------------------------------------------------
Ran 5 tests in 0.029s

OK
.....
----------------------------------------------------------------------
Ran 5 tests in 0.031s

OK
.
----------------------------------------------------------------------
Ran 1 test in 0.009s

OK
.....
----------------------------------------------------------------------
Ran 5 tests in 0.110s

OK
.....
----------------------------------------------------------------------
Ran 5 tests in 0.041s

OK
.....
----------------------------------------------------------------------
Ran 5 tests in 0.035s

OK
.
----------------------------------------------------------------------
Ran 1 test in 0.010s

OK
FFFFF
======================================================================
FAIL: test_insert_user_1 (ClassEval_92_0.UserLoginDBTestInsertUser.test_insert_user_1)
----------------------------------------------------------------------
Traceback (most recent call last):
  File "/Users/snigdhaghoshdastidar/Desktop/CS540/classeval_evaluation/ClassEval_92_0.py", line 112, in test_insert_user_1
    self.assertEqual(user[0], 'user1')
AssertionError: ('user1', 'pass1') != 'user1'

======================================================================
FAIL: test_insert_user_2 (ClassEval_92_0.UserLoginDBTestInsertUser.test_insert_user_2)
----------------------------------------------------------------------
Traceback (most recent call last):
  File "/Users/snigdhaghoshdastidar/Desktop/CS540/classeval_evaluation/ClassEval_92_0.py", line 119, in test_insert_user_2
    self.assertEqual(user[0], 'user2')
AssertionError: ('user2', 'pass2') != 'user2'

======================================================================
FAIL: test_insert_user_3 (ClassEval_92_0.UserLoginDBTestInsertUser.test_insert_user_3)
----------------------------------------------------------------------
Traceback (most recent call last):
  File "/Users/snigdhaghoshdastidar/Desktop/CS540/classeval_evaluation/ClassEval_92_0.py", line 126, in test_insert_user_3
    self.assertEqual(user[0], 'user3')
AssertionError: ('user3', 'pass3') != 'user3'

======================================================================
FAIL: test_insert_user_4 (ClassEval_92_0.UserLoginDBTestInsertUser.test_insert_user_4)
----------------------------------------------------------------------
Traceback (most recent call last):
  File "/Users/snigdhaghoshdastidar/Desktop/CS540/classeval_evaluation/ClassEval_92_0.py", line 133, in test_insert_user_4
    self.assertEqual(user[0], 'user4')
AssertionError: ('user4', 'pass4') != 'user4'

======================================================================
FAIL: test_insert_user_5 (ClassEval_92_0.UserLoginDBTestInsertUser.test_insert_user_5)
----------------------------------------------------------------------
Traceback (most recent call last):
  File "/Users/snigdhaghoshdastidar/Desktop/CS540/classeval_evaluation/ClassEval_92_0.py", line 140, in test_insert_user_5
    self.assertEqual(user[0], 'user5')
AssertionError: ('user5', 'pass5') != 'user5'

----------------------------------------------------------------------
Ran 5 tests in 0.018s

FAILED (failures=5)
FFFFF
======================================================================
FAIL: test_search_user_by_username_1 (ClassEval_92_0.UserLoginDBTestSearchUserByUsername.test_search_user_by_username_1)
----------------------------------------------------------------------
Traceback (most recent call last):
  File "/Users/snigdhaghoshdastidar/Desktop/CS540/classeval_evaluation/ClassEval_92_0.py", line 169, in test_search_user_by_username_1
    self.assertEqual(user[0], 'user1')
AssertionError: ('user1', 'pass1') != 'user1'

======================================================================
FAIL: test_search_user_by_username_2 (ClassEval_92_0.UserLoginDBTestSearchUserByUsername.test_search_user_by_username_2)
----------------------------------------------------------------------
Traceback (most recent call last):
  File "/Users/snigdhaghoshdastidar/Desktop/CS540/classeval_evaluation/ClassEval_92_0.py", line 176, in test_search_user_by_username_2
    self.assertEqual(user[0], 'user2')
AssertionError: ('user2', 'pass2') != 'user2'

======================================================================
FAIL: test_search_user_by_username_3 (ClassEval_92_0.UserLoginDBTestSearchUserByUsername.test_search_user_by_username_3)
----------------------------------------------------------------------
Traceback (most recent call last):
  File "/Users/snigdhaghoshdastidar/Desktop/CS540/classeval_evaluation/ClassEval_92_0.py", line 183, in test_search_user_by_username_3
    self.assertEqual(user[0], 'user3')
AssertionError: ('user3', 'pass3') != 'user3'

======================================================================
FAIL: test_search_user_by_username_4 (ClassEval_92_0.UserLoginDBTestSearchUserByUsername.test_search_user_by_username_4)
----------------------------------------------------------------------
Traceback (most recent call last):
  File "/Users/snigdhaghoshdastidar/Desktop/CS540/classeval_evaluation/ClassEval_92_0.py", line 190, in test_search_user_by_username_4
    self.assertEqual(user[0], 'user4')
AssertionError: ('user4', 'pass4') != 'user4'

======================================================================
FAIL: test_search_user_by_username_5 (ClassEval_92_0.UserLoginDBTestSearchUserByUsername.test_search_user_by_username_5)
----------------------------------------------------------------------
Traceback (most recent call last):
  File "/Users/snigdhaghoshdastidar/Desktop/CS540/classeval_evaluation/ClassEval_92_0.py", line 197, in test_search_user_by_username_5
    self.assertEqual(user[0], 'user5')
AssertionError: ('user5', 'pass5') != 'user5'

----------------------------------------------------------------------
Ran 5 tests in 0.018s

FAILED (failures=5)
FFFFF
======================================================================
FAIL: test_delete_user_by_username_1 (ClassEval_92_0.UserLoginDBTestDeleteUserByUsername.test_delete_user_by_username_1)
----------------------------------------------------------------------
Traceback (most recent call last):
  File "/Users/snigdhaghoshdastidar/Desktop/CS540/classeval_evaluation/ClassEval_92_0.py", line 226, in test_delete_user_by_username_1
    self.assertIsNone(user)
AssertionError: [] is not None

======================================================================
FAIL: test_delete_user_by_username_2 (ClassEval_92_0.UserLoginDBTestDeleteUserByUsername.test_delete_user_by_username_2)
----------------------------------------------------------------------
Traceback (most recent call last):
  File "/Users/snigdhaghoshdastidar/Desktop/CS540/classeval_evaluation/ClassEval_92_0.py", line 232, in test_delete_user_by_username_2
    self.assertIsNone(user)
AssertionError: [] is not None

======================================================================
FAIL: test_delete_user_by_username_3 (ClassEval_92_0.UserLoginDBTestDeleteUserByUsername.test_delete_user_by_username_3)
----------------------------------------------------------------------
Traceback (most recent call last):
  File "/Users/snigdhaghoshdastidar/Desktop/CS540/classeval_evaluation/ClassEval_92_0.py", line 238, in test_delete_user_by_username_3
    self.assertIsNone(user)
AssertionError: [] is not None

======================================================================
FAIL: test_delete_user_by_username_4 (ClassEval_92_0.UserLoginDBTestDeleteUserByUsername.test_delete_user_by_username_4)
----------------------------------------------------------------------
Traceback (most recent call last):
  File "/Users/snigdhaghoshdastidar/Desktop/CS540/classeval_evaluation/ClassEval_92_0.py", line 244, in test_delete_user_by_username_4
    self.assertIsNone(user)
AssertionError: [] is not None

======================================================================
FAIL: test_delete_user_by_username_5 (ClassEval_92_0.UserLoginDBTestDeleteUserByUsername.test_delete_user_by_username_5)
----------------------------------------------------------------------
Traceback (most recent call last):
  File "/Users/snigdhaghoshdastidar/Desktop/CS540/classeval_evaluation/ClassEval_92_0.py", line 250, in test_delete_user_by_username_5
    self.assertIsNone(user)
AssertionError: [] is not None

----------------------------------------------------------------------
Ran 5 tests in 0.027s

FAILED (failures=5)
.....
----------------------------------------------------------------------
Ran 5 tests in 0.013s

OK
F
======================================================================
FAIL: test_UserLoginDB (ClassEval_92_0.UserLoginDBTest.test_UserLoginDB)
----------------------------------------------------------------------
Traceback (most recent call last):
  File "/Users/snigdhaghoshdastidar/Desktop/CS540/classeval_evaluation/ClassEval_92_0.py", line 324, in test_UserLoginDB
    self.assertEqual(user[0], 'user1')
AssertionError: ('user1', 'pass1') != 'user1'

----------------------------------------------------------------------
Ran 1 test in 0.005s

FAILED (failures=1)
FFFFF
======================================================================
FAIL: test_insert_user_1 (ClassEval_92_1.UserLoginDBTestInsertUser.test_insert_user_1)
----------------------------------------------------------------------
Traceback (most recent call last):
  File "/Users/snigdhaghoshdastidar/Desktop/CS540/classeval_evaluation/ClassEval_92_1.py", line 112, in test_insert_user_1
    self.assertEqual(user[0], 'user1')
AssertionError: ('user1', 'pass1') != 'user1'

======================================================================
FAIL: test_insert_user_2 (ClassEval_92_1.UserLoginDBTestInsertUser.test_insert_user_2)
----------------------------------------------------------------------
Traceback (most recent call last):
  File "/Users/snigdhaghoshdastidar/Desktop/CS540/classeval_evaluation/ClassEval_92_1.py", line 119, in test_insert_user_2
    self.assertEqual(user[0], 'user2')
AssertionError: ('user2', 'pass2') != 'user2'

======================================================================
FAIL: test_insert_user_3 (ClassEval_92_1.UserLoginDBTestInsertUser.test_insert_user_3)
----------------------------------------------------------------------
Traceback (most recent call last):
  File "/Users/snigdhaghoshdastidar/Desktop/CS540/classeval_evaluation/ClassEval_92_1.py", line 126, in test_insert_user_3
    self.assertEqual(user[0], 'user3')
AssertionError: ('user3', 'pass3') != 'user3'

======================================================================
FAIL: test_insert_user_4 (ClassEval_92_1.UserLoginDBTestInsertUser.test_insert_user_4)
----------------------------------------------------------------------
Traceback (most recent call last):
  File "/Users/snigdhaghoshdastidar/Desktop/CS540/classeval_evaluation/ClassEval_92_1.py", line 133, in test_insert_user_4
    self.assertEqual(user[0], 'user4')
AssertionError: ('user4', 'pass4') != 'user4'

======================================================================
FAIL: test_insert_user_5 (ClassEval_92_1.UserLoginDBTestInsertUser.test_insert_user_5)
----------------------------------------------------------------------
Traceback (most recent call last):
  File "/Users/snigdhaghoshdastidar/Desktop/CS540/classeval_evaluation/ClassEval_92_1.py", line 140, in test_insert_user_5
    self.assertEqual(user[0], 'user5')
AssertionError: ('user5', 'pass5') != 'user5'

----------------------------------------------------------------------
Ran 5 tests in 0.020s

FAILED (failures=5)
FFFFF
======================================================================
FAIL: test_search_user_by_username_1 (ClassEval_92_1.UserLoginDBTestSearchUserByUsername.test_search_user_by_username_1)
----------------------------------------------------------------------
Traceback (most recent call last):
  File "/Users/snigdhaghoshdastidar/Desktop/CS540/classeval_evaluation/ClassEval_92_1.py", line 169, in test_search_user_by_username_1
    self.assertEqual(user[0], 'user1')
AssertionError: ('user1', 'pass1') != 'user1'

======================================================================
FAIL: test_search_user_by_username_2 (ClassEval_92_1.UserLoginDBTestSearchUserByUsername.test_search_user_by_username_2)
----------------------------------------------------------------------
Traceback (most recent call last):
  File "/Users/snigdhaghoshdastidar/Desktop/CS540/classeval_evaluation/ClassEval_92_1.py", line 176, in test_search_user_by_username_2
    self.assertEqual(user[0], 'user2')
AssertionError: ('user2', 'pass2') != 'user2'

======================================================================
FAIL: test_search_user_by_username_3 (ClassEval_92_1.UserLoginDBTestSearchUserByUsername.test_search_user_by_username_3)
----------------------------------------------------------------------
Traceback (most recent call last):
  File "/Users/snigdhaghoshdastidar/Desktop/CS540/classeval_evaluation/ClassEval_92_1.py", line 183, in test_search_user_by_username_3
    self.assertEqual(user[0], 'user3')
AssertionError: ('user3', 'pass3') != 'user3'

======================================================================
FAIL: test_search_user_by_username_4 (ClassEval_92_1.UserLoginDBTestSearchUserByUsername.test_search_user_by_username_4)
----------------------------------------------------------------------
Traceback (most recent call last):
  File "/Users/snigdhaghoshdastidar/Desktop/CS540/classeval_evaluation/ClassEval_92_1.py", line 190, in test_search_user_by_username_4
    self.assertEqual(user[0], 'user4')
AssertionError: ('user4', 'pass4') != 'user4'

======================================================================
FAIL: test_search_user_by_username_5 (ClassEval_92_1.UserLoginDBTestSearchUserByUsername.test_search_user_by_username_5)
----------------------------------------------------------------------
Traceback (most recent call last):
  File "/Users/snigdhaghoshdastidar/Desktop/CS540/classeval_evaluation/ClassEval_92_1.py", line 197, in test_search_user_by_username_5
    self.assertEqual(user[0], 'user5')
AssertionError: ('user5', 'pass5') != 'user5'

----------------------------------------------------------------------
Ran 5 tests in 0.021s

FAILED (failures=5)
FFFFF
======================================================================
FAIL: test_delete_user_by_username_1 (ClassEval_92_1.UserLoginDBTestDeleteUserByUsername.test_delete_user_by_username_1)
----------------------------------------------------------------------
Traceback (most recent call last):
  File "/Users/snigdhaghoshdastidar/Desktop/CS540/classeval_evaluation/ClassEval_92_1.py", line 226, in test_delete_user_by_username_1
    self.assertIsNone(user)
AssertionError: [] is not None

======================================================================
FAIL: test_delete_user_by_username_2 (ClassEval_92_1.UserLoginDBTestDeleteUserByUsername.test_delete_user_by_username_2)
----------------------------------------------------------------------
Traceback (most recent call last):
  File "/Users/snigdhaghoshdastidar/Desktop/CS540/classeval_evaluation/ClassEval_92_1.py", line 232, in test_delete_user_by_username_2
    self.assertIsNone(user)
AssertionError: [] is not None

======================================================================
FAIL: test_delete_user_by_username_3 (ClassEval_92_1.UserLoginDBTestDeleteUserByUsername.test_delete_user_by_username_3)
----------------------------------------------------------------------
Traceback (most recent call last):
  File "/Users/snigdhaghoshdastidar/Desktop/CS540/classeval_evaluation/ClassEval_92_1.py", line 238, in test_delete_user_by_username_3
    self.assertIsNone(user)
AssertionError: [] is not None

======================================================================
FAIL: test_delete_user_by_username_4 (ClassEval_92_1.UserLoginDBTestDeleteUserByUsername.test_delete_user_by_username_4)
----------------------------------------------------------------------
Traceback (most recent call last):
  File "/Users/snigdhaghoshdastidar/Desktop/CS540/classeval_evaluation/ClassEval_92_1.py", line 244, in test_delete_user_by_username_4
    self.assertIsNone(user)
AssertionError: [] is not None

======================================================================
FAIL: test_delete_user_by_username_5 (ClassEval_92_1.UserLoginDBTestDeleteUserByUsername.test_delete_user_by_username_5)
----------------------------------------------------------------------
Traceback (most recent call last):
  File "/Users/snigdhaghoshdastidar/Desktop/CS540/classeval_evaluation/ClassEval_92_1.py", line 250, in test_delete_user_by_username_5
    self.assertIsNone(user)
AssertionError: [] is not None

----------------------------------------------------------------------
Ran 5 tests in 0.023s

FAILED (failures=5)
.....
----------------------------------------------------------------------
Ran 5 tests in 0.016s

OK
F
======================================================================
FAIL: test_UserLoginDB (ClassEval_92_1.UserLoginDBTest.test_UserLoginDB)
----------------------------------------------------------------------
Traceback (most recent call last):
  File "/Users/snigdhaghoshdastidar/Desktop/CS540/classeval_evaluation/ClassEval_92_1.py", line 324, in test_UserLoginDB
    self.assertEqual(user[0], 'user1')
AssertionError: ('user1', 'pass1') != 'user1'

----------------------------------------------------------------------
Ran 1 test in 0.004s

FAILED (failures=1)
FFFFF
======================================================================
FAIL: test_insert_user_1 (ClassEval_92_2.UserLoginDBTestInsertUser.test_insert_user_1)
----------------------------------------------------------------------
Traceback (most recent call last):
  File "/Users/snigdhaghoshdastidar/Desktop/CS540/classeval_evaluation/ClassEval_92_2.py", line 112, in test_insert_user_1
    self.assertEqual(user[0], 'user1')
AssertionError: ('user1', 'pass1') != 'user1'

======================================================================
FAIL: test_insert_user_2 (ClassEval_92_2.UserLoginDBTestInsertUser.test_insert_user_2)
----------------------------------------------------------------------
Traceback (most recent call last):
  File "/Users/snigdhaghoshdastidar/Desktop/CS540/classeval_evaluation/ClassEval_92_2.py", line 119, in test_insert_user_2
    self.assertEqual(user[0], 'user2')
AssertionError: ('user2', 'pass2') != 'user2'

======================================================================
FAIL: test_insert_user_3 (ClassEval_92_2.UserLoginDBTestInsertUser.test_insert_user_3)
----------------------------------------------------------------------
Traceback (most recent call last):
  File "/Users/snigdhaghoshdastidar/Desktop/CS540/classeval_evaluation/ClassEval_92_2.py", line 126, in test_insert_user_3
    self.assertEqual(user[0], 'user3')
AssertionError: ('user3', 'pass3') != 'user3'

======================================================================
FAIL: test_insert_user_4 (ClassEval_92_2.UserLoginDBTestInsertUser.test_insert_user_4)
----------------------------------------------------------------------
Traceback (most recent call last):
  File "/Users/snigdhaghoshdastidar/Desktop/CS540/classeval_evaluation/ClassEval_92_2.py", line 133, in test_insert_user_4
    self.assertEqual(user[0], 'user4')
AssertionError: ('user4', 'pass4') != 'user4'

======================================================================
FAIL: test_insert_user_5 (ClassEval_92_2.UserLoginDBTestInsertUser.test_insert_user_5)
----------------------------------------------------------------------
Traceback (most recent call last):
  File "/Users/snigdhaghoshdastidar/Desktop/CS540/classeval_evaluation/ClassEval_92_2.py", line 140, in test_insert_user_5
    self.assertEqual(user[0], 'user5')
AssertionError: ('user5', 'pass5') != 'user5'

----------------------------------------------------------------------
Ran 5 tests in 0.024s

FAILED (failures=5)
FFFFF
======================================================================
FAIL: test_search_user_by_username_1 (ClassEval_92_2.UserLoginDBTestSearchUserByUsername.test_search_user_by_username_1)
----------------------------------------------------------------------
Traceback (most recent call last):
  File "/Users/snigdhaghoshdastidar/Desktop/CS540/classeval_evaluation/ClassEval_92_2.py", line 169, in test_search_user_by_username_1
    self.assertEqual(user[0], 'user1')
AssertionError: ('user1', 'pass1') != 'user1'

======================================================================
FAIL: test_search_user_by_username_2 (ClassEval_92_2.UserLoginDBTestSearchUserByUsername.test_search_user_by_username_2)
----------------------------------------------------------------------
Traceback (most recent call last):
  File "/Users/snigdhaghoshdastidar/Desktop/CS540/classeval_evaluation/ClassEval_92_2.py", line 176, in test_search_user_by_username_2
    self.assertEqual(user[0], 'user2')
AssertionError: ('user2', 'pass2') != 'user2'

======================================================================
FAIL: test_search_user_by_username_3 (ClassEval_92_2.UserLoginDBTestSearchUserByUsername.test_search_user_by_username_3)
----------------------------------------------------------------------
Traceback (most recent call last):
  File "/Users/snigdhaghoshdastidar/Desktop/CS540/classeval_evaluation/ClassEval_92_2.py", line 183, in test_search_user_by_username_3
    self.assertEqual(user[0], 'user3')
AssertionError: ('user3', 'pass3') != 'user3'

======================================================================
FAIL: test_search_user_by_username_4 (ClassEval_92_2.UserLoginDBTestSearchUserByUsername.test_search_user_by_username_4)
----------------------------------------------------------------------
Traceback (most recent call last):
  File "/Users/snigdhaghoshdastidar/Desktop/CS540/classeval_evaluation/ClassEval_92_2.py", line 190, in test_search_user_by_username_4
    self.assertEqual(user[0], 'user4')
AssertionError: ('user4', 'pass4') != 'user4'

======================================================================
FAIL: test_search_user_by_username_5 (ClassEval_92_2.UserLoginDBTestSearchUserByUsername.test_search_user_by_username_5)
----------------------------------------------------------------------
Traceback (most recent call last):
  File "/Users/snigdhaghoshdastidar/Desktop/CS540/classeval_evaluation/ClassEval_92_2.py", line 197, in test_search_user_by_username_5
    self.assertEqual(user[0], 'user5')
AssertionError: ('user5', 'pass5') != 'user5'

----------------------------------------------------------------------
Ran 5 tests in 0.021s

FAILED (failures=5)
FFFFF
======================================================================
FAIL: test_delete_user_by_username_1 (ClassEval_92_2.UserLoginDBTestDeleteUserByUsername.test_delete_user_by_username_1)
----------------------------------------------------------------------
Traceback (most recent call last):
  File "/Users/snigdhaghoshdastidar/Desktop/CS540/classeval_evaluation/ClassEval_92_2.py", line 226, in test_delete_user_by_username_1
    self.assertIsNone(user)
AssertionError: [] is not None

======================================================================
FAIL: test_delete_user_by_username_2 (ClassEval_92_2.UserLoginDBTestDeleteUserByUsername.test_delete_user_by_username_2)
----------------------------------------------------------------------
Traceback (most recent call last):
  File "/Users/snigdhaghoshdastidar/Desktop/CS540/classeval_evaluation/ClassEval_92_2.py", line 232, in test_delete_user_by_username_2
    self.assertIsNone(user)
AssertionError: [] is not None

======================================================================
FAIL: test_delete_user_by_username_3 (ClassEval_92_2.UserLoginDBTestDeleteUserByUsername.test_delete_user_by_username_3)
----------------------------------------------------------------------
Traceback (most recent call last):
  File "/Users/snigdhaghoshdastidar/Desktop/CS540/classeval_evaluation/ClassEval_92_2.py", line 238, in test_delete_user_by_username_3
    self.assertIsNone(user)
AssertionError: [] is not None

======================================================================
FAIL: test_delete_user_by_username_4 (ClassEval_92_2.UserLoginDBTestDeleteUserByUsername.test_delete_user_by_username_4)
----------------------------------------------------------------------
Traceback (most recent call last):
  File "/Users/snigdhaghoshdastidar/Desktop/CS540/classeval_evaluation/ClassEval_92_2.py", line 244, in test_delete_user_by_username_4
    self.assertIsNone(user)
AssertionError: [] is not None

======================================================================
FAIL: test_delete_user_by_username_5 (ClassEval_92_2.UserLoginDBTestDeleteUserByUsername.test_delete_user_by_username_5)
----------------------------------------------------------------------
Traceback (most recent call last):
  File "/Users/snigdhaghoshdastidar/Desktop/CS540/classeval_evaluation/ClassEval_92_2.py", line 250, in test_delete_user_by_username_5
    self.assertIsNone(user)
AssertionError: [] is not None

----------------------------------------------------------------------
Ran 5 tests in 0.026s

FAILED (failures=5)
.....
----------------------------------------------------------------------
Ran 5 tests in 0.014s

OK
F
======================================================================
FAIL: test_UserLoginDB (ClassEval_92_2.UserLoginDBTest.test_UserLoginDB)
----------------------------------------------------------------------
Traceback (most recent call last):
  File "/Users/snigdhaghoshdastidar/Desktop/CS540/classeval_evaluation/ClassEval_92_2.py", line 324, in test_UserLoginDB
    self.assertEqual(user[0], 'user1')
AssertionError: ('user1', 'pass1') != 'user1'

----------------------------------------------------------------------
Ran 1 test in 0.003s

FAILED (failures=1)
FFFFF
======================================================================
FAIL: test_insert_user_1 (ClassEval_92_3.UserLoginDBTestInsertUser.test_insert_user_1)
----------------------------------------------------------------------
Traceback (most recent call last):
  File "/Users/snigdhaghoshdastidar/Desktop/CS540/classeval_evaluation/ClassEval_92_3.py", line 112, in test_insert_user_1
    self.assertEqual(user[0], 'user1')
AssertionError: ('user1', 'pass1') != 'user1'

======================================================================
FAIL: test_insert_user_2 (ClassEval_92_3.UserLoginDBTestInsertUser.test_insert_user_2)
----------------------------------------------------------------------
Traceback (most recent call last):
  File "/Users/snigdhaghoshdastidar/Desktop/CS540/classeval_evaluation/ClassEval_92_3.py", line 119, in test_insert_user_2
    self.assertEqual(user[0], 'user2')
AssertionError: ('user2', 'pass2') != 'user2'

======================================================================
FAIL: test_insert_user_3 (ClassEval_92_3.UserLoginDBTestInsertUser.test_insert_user_3)
----------------------------------------------------------------------
Traceback (most recent call last):
  File "/Users/snigdhaghoshdastidar/Desktop/CS540/classeval_evaluation/ClassEval_92_3.py", line 126, in test_insert_user_3
    self.assertEqual(user[0], 'user3')
AssertionError: ('user3', 'pass3') != 'user3'

======================================================================
FAIL: test_insert_user_4 (ClassEval_92_3.UserLoginDBTestInsertUser.test_insert_user_4)
----------------------------------------------------------------------
Traceback (most recent call last):
  File "/Users/snigdhaghoshdastidar/Desktop/CS540/classeval_evaluation/ClassEval_92_3.py", line 133, in test_insert_user_4
    self.assertEqual(user[0], 'user4')
AssertionError: ('user4', 'pass4') != 'user4'

======================================================================
FAIL: test_insert_user_5 (ClassEval_92_3.UserLoginDBTestInsertUser.test_insert_user_5)
----------------------------------------------------------------------
Traceback (most recent call last):
  File "/Users/snigdhaghoshdastidar/Desktop/CS540/classeval_evaluation/ClassEval_92_3.py", line 140, in test_insert_user_5
    self.assertEqual(user[0], 'user5')
AssertionError: ('user5', 'pass5') != 'user5'

----------------------------------------------------------------------
Ran 5 tests in 0.018s

FAILED (failures=5)
FFFFF
======================================================================
FAIL: test_search_user_by_username_1 (ClassEval_92_3.UserLoginDBTestSearchUserByUsername.test_search_user_by_username_1)
----------------------------------------------------------------------
Traceback (most recent call last):
  File "/Users/snigdhaghoshdastidar/Desktop/CS540/classeval_evaluation/ClassEval_92_3.py", line 169, in test_search_user_by_username_1
    self.assertEqual(user[0], 'user1')
AssertionError: ('user1', 'pass1') != 'user1'

======================================================================
FAIL: test_search_user_by_username_2 (ClassEval_92_3.UserLoginDBTestSearchUserByUsername.test_search_user_by_username_2)
----------------------------------------------------------------------
Traceback (most recent call last):
  File "/Users/snigdhaghoshdastidar/Desktop/CS540/classeval_evaluation/ClassEval_92_3.py", line 176, in test_search_user_by_username_2
    self.assertEqual(user[0], 'user2')
AssertionError: ('user2', 'pass2') != 'user2'

======================================================================
FAIL: test_search_user_by_username_3 (ClassEval_92_3.UserLoginDBTestSearchUserByUsername.test_search_user_by_username_3)
----------------------------------------------------------------------
Traceback (most recent call last):
  File "/Users/snigdhaghoshdastidar/Desktop/CS540/classeval_evaluation/ClassEval_92_3.py", line 183, in test_search_user_by_username_3
    self.assertEqual(user[0], 'user3')
AssertionError: ('user3', 'pass3') != 'user3'

======================================================================
FAIL: test_search_user_by_username_4 (ClassEval_92_3.UserLoginDBTestSearchUserByUsername.test_search_user_by_username_4)
----------------------------------------------------------------------
Traceback (most recent call last):
  File "/Users/snigdhaghoshdastidar/Desktop/CS540/classeval_evaluation/ClassEval_92_3.py", line 190, in test_search_user_by_username_4
    self.assertEqual(user[0], 'user4')
AssertionError: ('user4', 'pass4') != 'user4'

======================================================================
FAIL: test_search_user_by_username_5 (ClassEval_92_3.UserLoginDBTestSearchUserByUsername.test_search_user_by_username_5)
----------------------------------------------------------------------
Traceback (most recent call last):
  File "/Users/snigdhaghoshdastidar/Desktop/CS540/classeval_evaluation/ClassEval_92_3.py", line 197, in test_search_user_by_username_5
    self.assertEqual(user[0], 'user5')
AssertionError: ('user5', 'pass5') != 'user5'

----------------------------------------------------------------------
Ran 5 tests in 0.016s

FAILED (failures=5)
FFFFF
======================================================================
FAIL: test_delete_user_by_username_1 (ClassEval_92_3.UserLoginDBTestDeleteUserByUsername.test_delete_user_by_username_1)
----------------------------------------------------------------------
Traceback (most recent call last):
  File "/Users/snigdhaghoshdastidar/Desktop/CS540/classeval_evaluation/ClassEval_92_3.py", line 226, in test_delete_user_by_username_1
    self.assertIsNone(user)
AssertionError: [] is not None

======================================================================
FAIL: test_delete_user_by_username_2 (ClassEval_92_3.UserLoginDBTestDeleteUserByUsername.test_delete_user_by_username_2)
----------------------------------------------------------------------
Traceback (most recent call last):
  File "/Users/snigdhaghoshdastidar/Desktop/CS540/classeval_evaluation/ClassEval_92_3.py", line 232, in test_delete_user_by_username_2
    self.assertIsNone(user)
AssertionError: [] is not None

======================================================================
FAIL: test_delete_user_by_username_3 (ClassEval_92_3.UserLoginDBTestDeleteUserByUsername.test_delete_user_by_username_3)
----------------------------------------------------------------------
Traceback (most recent call last):
  File "/Users/snigdhaghoshdastidar/Desktop/CS540/classeval_evaluation/ClassEval_92_3.py", line 238, in test_delete_user_by_username_3
    self.assertIsNone(user)
AssertionError: [] is not None

======================================================================
FAIL: test_delete_user_by_username_4 (ClassEval_92_3.UserLoginDBTestDeleteUserByUsername.test_delete_user_by_username_4)
----------------------------------------------------------------------
Traceback (most recent call last):
  File "/Users/snigdhaghoshdastidar/Desktop/CS540/classeval_evaluation/ClassEval_92_3.py", line 244, in test_delete_user_by_username_4
    self.assertIsNone(user)
AssertionError: [] is not None

======================================================================
FAIL: test_delete_user_by_username_5 (ClassEval_92_3.UserLoginDBTestDeleteUserByUsername.test_delete_user_by_username_5)
----------------------------------------------------------------------
Traceback (most recent call last):
  File "/Users/snigdhaghoshdastidar/Desktop/CS540/classeval_evaluation/ClassEval_92_3.py", line 250, in test_delete_user_by_username_5
    self.assertIsNone(user)
AssertionError: [] is not None

----------------------------------------------------------------------
Ran 5 tests in 0.016s

FAILED (failures=5)
.....
----------------------------------------------------------------------
Ran 5 tests in 0.011s

OK
F
======================================================================
FAIL: test_UserLoginDB (ClassEval_92_3.UserLoginDBTest.test_UserLoginDB)
----------------------------------------------------------------------
Traceback (most recent call last):
  File "/Users/snigdhaghoshdastidar/Desktop/CS540/classeval_evaluation/ClassEval_92_3.py", line 324, in test_UserLoginDB
    self.assertEqual(user[0], 'user1')
AssertionError: ('user1', 'pass1') != 'user1'

----------------------------------------------------------------------
Ran 1 test in 0.002s

FAILED (failures=1)
FFFFF
======================================================================
FAIL: test_insert_user_1 (ClassEval_92_4.UserLoginDBTestInsertUser.test_insert_user_1)
----------------------------------------------------------------------
Traceback (most recent call last):
  File "/Users/snigdhaghoshdastidar/Desktop/CS540/classeval_evaluation/ClassEval_92_4.py", line 112, in test_insert_user_1
    self.assertEqual(user[0], 'user1')
AssertionError: ('user1', 'pass1') != 'user1'

======================================================================
FAIL: test_insert_user_2 (ClassEval_92_4.UserLoginDBTestInsertUser.test_insert_user_2)
----------------------------------------------------------------------
Traceback (most recent call last):
  File "/Users/snigdhaghoshdastidar/Desktop/CS540/classeval_evaluation/ClassEval_92_4.py", line 119, in test_insert_user_2
    self.assertEqual(user[0], 'user2')
AssertionError: ('user2', 'pass2') != 'user2'

======================================================================
FAIL: test_insert_user_3 (ClassEval_92_4.UserLoginDBTestInsertUser.test_insert_user_3)
----------------------------------------------------------------------
Traceback (most recent call last):
  File "/Users/snigdhaghoshdastidar/Desktop/CS540/classeval_evaluation/ClassEval_92_4.py", line 126, in test_insert_user_3
    self.assertEqual(user[0], 'user3')
AssertionError: ('user3', 'pass3') != 'user3'

======================================================================
FAIL: test_insert_user_4 (ClassEval_92_4.UserLoginDBTestInsertUser.test_insert_user_4)
----------------------------------------------------------------------
Traceback (most recent call last):
  File "/Users/snigdhaghoshdastidar/Desktop/CS540/classeval_evaluation/ClassEval_92_4.py", line 133, in test_insert_user_4
    self.assertEqual(user[0], 'user4')
AssertionError: ('user4', 'pass4') != 'user4'

======================================================================
FAIL: test_insert_user_5 (ClassEval_92_4.UserLoginDBTestInsertUser.test_insert_user_5)
----------------------------------------------------------------------
Traceback (most recent call last):
  File "/Users/snigdhaghoshdastidar/Desktop/CS540/classeval_evaluation/ClassEval_92_4.py", line 140, in test_insert_user_5
    self.assertEqual(user[0], 'user5')
AssertionError: ('user5', 'pass5') != 'user5'

----------------------------------------------------------------------
Ran 5 tests in 0.014s

FAILED (failures=5)
FFFFF
======================================================================
FAIL: test_search_user_by_username_1 (ClassEval_92_4.UserLoginDBTestSearchUserByUsername.test_search_user_by_username_1)
----------------------------------------------------------------------
Traceback (most recent call last):
  File "/Users/snigdhaghoshdastidar/Desktop/CS540/classeval_evaluation/ClassEval_92_4.py", line 169, in test_search_user_by_username_1
    self.assertEqual(user[0], 'user1')
AssertionError: ('user1', 'pass1') != 'user1'

======================================================================
FAIL: test_search_user_by_username_2 (ClassEval_92_4.UserLoginDBTestSearchUserByUsername.test_search_user_by_username_2)
----------------------------------------------------------------------
Traceback (most recent call last):
  File "/Users/snigdhaghoshdastidar/Desktop/CS540/classeval_evaluation/ClassEval_92_4.py", line 176, in test_search_user_by_username_2
    self.assertEqual(user[0], 'user2')
AssertionError: ('user2', 'pass2') != 'user2'

======================================================================
FAIL: test_search_user_by_username_3 (ClassEval_92_4.UserLoginDBTestSearchUserByUsername.test_search_user_by_username_3)
----------------------------------------------------------------------
Traceback (most recent call last):
  File "/Users/snigdhaghoshdastidar/Desktop/CS540/classeval_evaluation/ClassEval_92_4.py", line 183, in test_search_user_by_username_3
    self.assertEqual(user[0], 'user3')
AssertionError: ('user3', 'pass3') != 'user3'

======================================================================
FAIL: test_search_user_by_username_4 (ClassEval_92_4.UserLoginDBTestSearchUserByUsername.test_search_user_by_username_4)
----------------------------------------------------------------------
Traceback (most recent call last):
  File "/Users/snigdhaghoshdastidar/Desktop/CS540/classeval_evaluation/ClassEval_92_4.py", line 190, in test_search_user_by_username_4
    self.assertEqual(user[0], 'user4')
AssertionError: ('user4', 'pass4') != 'user4'

======================================================================
FAIL: test_search_user_by_username_5 (ClassEval_92_4.UserLoginDBTestSearchUserByUsername.test_search_user_by_username_5)
----------------------------------------------------------------------
Traceback (most recent call last):
  File "/Users/snigdhaghoshdastidar/Desktop/CS540/classeval_evaluation/ClassEval_92_4.py", line 197, in test_search_user_by_username_5
    self.assertEqual(user[0], 'user5')
AssertionError: ('user5', 'pass5') != 'user5'

----------------------------------------------------------------------
Ran 5 tests in 0.012s

FAILED (failures=5)
FFFFF
======================================================================
FAIL: test_delete_user_by_username_1 (ClassEval_92_4.UserLoginDBTestDeleteUserByUsername.test_delete_user_by_username_1)
----------------------------------------------------------------------
Traceback (most recent call last):
  File "/Users/snigdhaghoshdastidar/Desktop/CS540/classeval_evaluation/ClassEval_92_4.py", line 226, in test_delete_user_by_username_1
    self.assertIsNone(user)
AssertionError: [] is not None

======================================================================
FAIL: test_delete_user_by_username_2 (ClassEval_92_4.UserLoginDBTestDeleteUserByUsername.test_delete_user_by_username_2)
----------------------------------------------------------------------
Traceback (most recent call last):
  File "/Users/snigdhaghoshdastidar/Desktop/CS540/classeval_evaluation/ClassEval_92_4.py", line 232, in test_delete_user_by_username_2
    self.assertIsNone(user)
AssertionError: [] is not None

======================================================================
FAIL: test_delete_user_by_username_3 (ClassEval_92_4.UserLoginDBTestDeleteUserByUsername.test_delete_user_by_username_3)
----------------------------------------------------------------------
Traceback (most recent call last):
  File "/Users/snigdhaghoshdastidar/Desktop/CS540/classeval_evaluation/ClassEval_92_4.py", line 238, in test_delete_user_by_username_3
    self.assertIsNone(user)
AssertionError: [] is not None

======================================================================
FAIL: test_delete_user_by_username_4 (ClassEval_92_4.UserLoginDBTestDeleteUserByUsername.test_delete_user_by_username_4)
----------------------------------------------------------------------
Traceback (most recent call last):
  File "/Users/snigdhaghoshdastidar/Desktop/CS540/classeval_evaluation/ClassEval_92_4.py", line 244, in test_delete_user_by_username_4
    self.assertIsNone(user)
AssertionError: [] is not None

======================================================================
FAIL: test_delete_user_by_username_5 (ClassEval_92_4.UserLoginDBTestDeleteUserByUsername.test_delete_user_by_username_5)
----------------------------------------------------------------------
Traceback (most recent call last):
  File "/Users/snigdhaghoshdastidar/Desktop/CS540/classeval_evaluation/ClassEval_92_4.py", line 250, in test_delete_user_by_username_5
    self.assertIsNone(user)
AssertionError: [] is not None

----------------------------------------------------------------------
Ran 5 tests in 0.016s

FAILED (failures=5)
.....
----------------------------------------------------------------------
Ran 5 tests in 0.010s

OK
F
======================================================================
FAIL: test_UserLoginDB (ClassEval_92_4.UserLoginDBTest.test_UserLoginDB)
----------------------------------------------------------------------
Traceback (most recent call last):
  File "/Users/snigdhaghoshdastidar/Desktop/CS540/classeval_evaluation/ClassEval_92_4.py", line 324, in test_UserLoginDB
    self.assertEqual(user[0], 'user1')
AssertionError: ('user1', 'pass1') != 'user1'

----------------------------------------------------------------------
Ran 1 test in 0.002s

FAILED (failures=1)
