FFFF.FF.
======================================================================
FAIL: test_filter_1 (ClassEval_0_0.AccessGatewayFilterTestFilter)
----------------------------------------------------------------------
Traceback (most recent call last):
  File "C:\Users\tanuj\Desktop\CS540\repo\CS540\classeval_evaluation\ClassEval_0_0.py", line 118, in test_filter_1
    self.assertTrue(res)
AssertionError: False is not true

======================================================================
FAIL: test_filter_2 (ClassEval_0_0.AccessGatewayFilterTestFilter)
----------------------------------------------------------------------
Traceback (most recent call last):
  File "C:\Users\tanuj\Desktop\CS540\repo\CS540\classeval_evaluation\ClassEval_0_0.py", line 124, in test_filter_2
    self.assertTrue(res)
AssertionError: False is not true

======================================================================
FAIL: test_filter_3 (ClassEval_0_0.AccessGatewayFilterTestFilter)
----------------------------------------------------------------------
Traceback (most recent call last):
  File "C:\Users\tanuj\Desktop\CS540\repo\CS540\classeval_evaluation\ClassEval_0_0.py", line 130, in test_filter_3
    self.assertTrue(res)
AssertionError: False is not true

======================================================================
FAIL: test_filter_4 (ClassEval_0_0.AccessGatewayFilterTestFilter)
----------------------------------------------------------------------
Traceback (most recent call last):
  File "C:\Users\tanuj\Desktop\CS540\repo\CS540\classeval_evaluation\ClassEval_0_0.py", line 136, in test_filter_4
    self.assertTrue(res)
AssertionError: False is not true

======================================================================
FAIL: test_filter_6 (ClassEval_0_0.AccessGatewayFilterTestFilter)
----------------------------------------------------------------------
Traceback (most recent call last):
  File "C:\Users\tanuj\Desktop\CS540\repo\CS540\classeval_evaluation\ClassEval_0_0.py", line 154, in test_filter_6
    self.assertFalse(res)
AssertionError: True is not false

======================================================================
FAIL: test_filter_7 (ClassEval_0_0.AccessGatewayFilterTestFilter)
----------------------------------------------------------------------
Traceback (most recent call last):
  File "C:\Users\tanuj\Desktop\CS540\repo\CS540\classeval_evaluation\ClassEval_0_0.py", line 163, in test_filter_7
    self.assertIsNone(res)
AssertionError: True is not None

----------------------------------------------------------------------
Ran 8 tests in 0.003s

FAILED (failures=6)
.....
----------------------------------------------------------------------
Ran 5 tests in 0.000s

OK
.....
----------------------------------------------------------------------
Ran 5 tests in 0.001s

OK
F
======================================================================
FAIL: test_AccessGatewayFilter (ClassEval_0_0.AccessGatewayFilterTest)
----------------------------------------------------------------------
Traceback (most recent call last):
  File "C:\Users\tanuj\Desktop\CS540\repo\CS540\classeval_evaluation\ClassEval_0_0.py", line 249, in test_AccessGatewayFilter
    self.assertTrue(res)
AssertionError: False is not true

----------------------------------------------------------------------
Ran 1 test in 0.005s

FAILED (failures=1)
.....
----------------------------------------------------------------------
Ran 5 tests in 0.001s

OK
.....
----------------------------------------------------------------------
Ran 5 tests in 0.001s

OK
.....
----------------------------------------------------------------------
Ran 5 tests in 0.001s

OK
.....
----------------------------------------------------------------------
Ran 5 tests in 0.000s

OK
.....
----------------------------------------------------------------------
Ran 5 tests in 0.002s

OK
.
----------------------------------------------------------------------
Ran 1 test in 0.001s

OK
.....
----------------------------------------------------------------------
Ran 5 tests in 0.001s

OK
.....
----------------------------------------------------------------------
Ran 5 tests in 0.000s

OK
.....
----------------------------------------------------------------------
Ran 5 tests in 0.000s

OK
.....
----------------------------------------------------------------------
Ran 5 tests in 0.000s

OK
.
----------------------------------------------------------------------
Ran 1 test in 0.000s

OK
.....
----------------------------------------------------------------------
Ran 5 tests in 0.001s

OK
.....
----------------------------------------------------------------------
Ran 5 tests in 0.001s

OK
......
----------------------------------------------------------------------
Ran 6 tests in 0.001s

OK
.....
----------------------------------------------------------------------
Ran 5 tests in 0.002s

OK
.....
----------------------------------------------------------------------
Ran 5 tests in 0.001s

OK
.
----------------------------------------------------------------------
Ran 1 test in 0.000s

OK
.....
----------------------------------------------------------------------
Ran 5 tests in 0.001s

OK
.....
----------------------------------------------------------------------
Ran 5 tests in 0.001s

OK
.....
----------------------------------------------------------------------
Ran 5 tests in 0.001s

OK
.....
----------------------------------------------------------------------
Ran 5 tests in 0.001s

OK
.E...
======================================================================
ERROR: test_get_course_average_2 (ClassEval_4_0.AssessmentSystemTestGetCourseAverage)
----------------------------------------------------------------------
Traceback (most recent call last):
  File "C:\Users\tanuj\Desktop\CS540\repo\CS540\classeval_evaluation\ClassEval_4_0.py", line 275, in test_get_course_average_2
    self.assertEqual(assessment_system.get_course_average('Physics'), 85)
  File "C:\Users\tanuj\Desktop\CS540\repo\CS540\classeval_evaluation\ClassEval_4_0.py", line 78, in get_course_average
    total += courses[course]
TypeError: unsupported operand type(s) for +=: 'int' and 'NoneType'

----------------------------------------------------------------------
Ran 5 tests in 0.002s

FAILED (errors=1)
.....
----------------------------------------------------------------------
Ran 5 tests in 0.000s

OK
.
----------------------------------------------------------------------
Ran 1 test in 0.000s

OK
.........
----------------------------------------------------------------------
Ran 9 tests in 0.001s

OK
.....
----------------------------------------------------------------------
Ran 5 tests in 0.001s

OK
.
----------------------------------------------------------------------
Ran 1 test in 0.000s

OK
.....
----------------------------------------------------------------------
Ran 5 tests in 0.001s

OK
.....
----------------------------------------------------------------------
Ran 5 tests in 0.003s

OK
.
----------------------------------------------------------------------
Ran 1 test in 0.001s

OK
.....
----------------------------------------------------------------------
Ran 5 tests in 0.001s

OK
.......
----------------------------------------------------------------------
Ran 7 tests in 0.001s

OK
...
----------------------------------------------------------------------
Ran 3 tests in 0.001s

OK
.....
----------------------------------------------------------------------
Ran 5 tests in 0.001s

OK
.....
----------------------------------------------------------------------
Ran 5 tests in 0.001s

OK
.....
----------------------------------------------------------------------
Ran 5 tests in 0.000s

OK
.....
----------------------------------------------------------------------
Ran 5 tests in 0.000s

OK
..
----------------------------------------------------------------------
Ran 2 tests in 0.000s

OK
.....
----------------------------------------------------------------------
Ran 5 tests in 0.001s

OK
.....
----------------------------------------------------------------------
Ran 5 tests in 0.001s

OK
......
----------------------------------------------------------------------
Ran 6 tests in 0.003s

OK
.
----------------------------------------------------------------------
Ran 1 test in 0.000s

OK
.....
----------------------------------------------------------------------
Ran 5 tests in 0.000s

OK
.FF.F
======================================================================
FAIL: test_calculate_binary_info_2 (ClassEval_10_0.BinaryDataProcessorTestCalculateBinaryInfo)
----------------------------------------------------------------------
Traceback (most recent call last):
  File "C:\Users\tanuj\Desktop\CS540\repo\CS540\classeval_evaluation\ClassEval_10_0.py", line 109, in test_calculate_binary_info_2
    self.assertEqual(bdp.calculate_binary_info(), {'Bit length': 28, 'Ones': 0.5357142857142857, 'Zeroes': 0.4642857142857143})
AssertionError: {'Zeroes': 0.464, 'Ones': 0.536, 'Bit length': 28} != {'Bit length': 28, 'Ones': 0.5357142857142857, 'Zeroes': 0.4642857142857143}
- {'Bit length': 28, 'Ones': 0.536, 'Zeroes': 0.464}
?                                ^

+ {'Bit length': 28, 'Ones': 0.5357142857142857, 'Zeroes': 0.4642857142857143}
?                                ^^^^^^^^^^^^^^                 +++++++++++++


======================================================================
FAIL: test_calculate_binary_info_3 (ClassEval_10_0.BinaryDataProcessorTestCalculateBinaryInfo)
----------------------------------------------------------------------
Traceback (most recent call last):
  File "C:\Users\tanuj\Desktop\CS540\repo\CS540\classeval_evaluation\ClassEval_10_0.py", line 113, in test_calculate_binary_info_3
    self.assertEqual(bdp.calculate_binary_info(), {'Bit length': 29, 'Ones': 0.6206896551724138, 'Zeroes': 0.3793103448275862})
AssertionError: {'Zeroes': 0.379, 'Ones': 0.621, 'Bit length': 29} != {'Bit length': 29, 'Ones': 0.6206896551724138, 'Zeroes': 0.3793103448275862}
- {'Bit length': 29, 'Ones': 0.621, 'Zeroes': 0.379}
+ {'Bit length': 29, 'Ones': 0.6206896551724138, 'Zeroes': 0.3793103448275862}
?                                +++++++ ++++++                 +++++++++++++


======================================================================
FAIL: test_calculate_binary_info_5 (ClassEval_10_0.BinaryDataProcessorTestCalculateBinaryInfo)
----------------------------------------------------------------------
Traceback (most recent call last):
  File "C:\Users\tanuj\Desktop\CS540\repo\CS540\classeval_evaluation\ClassEval_10_0.py", line 121, in test_calculate_binary_info_5
    self.assertEqual(bdp.calculate_binary_info(), {'Bit length': 16, 'Ones': 0.5625, 'Zeroes': 0.4375})
AssertionError: {'Zeroes': 0.438, 'Ones': 0.562, 'Bit length': 16} != {'Bit length': 16, 'Ones': 0.5625, 'Zeroes': 0.4375}
- {'Bit length': 16, 'Ones': 0.562, 'Zeroes': 0.438}
?                                                 ^

+ {'Bit length': 16, 'Ones': 0.5625, 'Zeroes': 0.4375}
?                                 +                ^^


----------------------------------------------------------------------
Ran 5 tests in 0.002s

FAILED (failures=3)
.....
----------------------------------------------------------------------
Ran 5 tests in 0.000s

OK
.....
----------------------------------------------------------------------
Ran 5 tests in 0.000s

OK
.
----------------------------------------------------------------------
Ran 1 test in 0.000s

OK
.....
----------------------------------------------------------------------
Ran 5 tests in 0.000s

OK
.....
----------------------------------------------------------------------
Ran 5 tests in 0.000s

OK
.....
----------------------------------------------------------------------
Ran 5 tests in 0.000s

OK
.....
----------------------------------------------------------------------
Ran 5 tests in 0.000s

OK
.
----------------------------------------------------------------------
Ran 1 test in 0.000s

OK
.....
----------------------------------------------------------------------
Ran 5 tests in 0.001s

OK
.....E
======================================================================
ERROR: test_calculate_hand_value_6 (ClassEval_12_0.BlackjackGameTestCalculateHandValue)
----------------------------------------------------------------------
Traceback (most recent call last):
  File "C:\Users\tanuj\Desktop\CS540\repo\CS540\classeval_evaluation\ClassEval_12_0.py", line 147, in test_calculate_hand_value_6
    self.assertEqual(blackjackGame.calculate_hand_value(hand), 20)
  File "C:\Users\tanuj\Desktop\CS540\repo\CS540\classeval_evaluation\ClassEval_12_0.py", line 48, in calculate_hand_value
    total += int(rank)
ValueError: invalid literal for int() with base 10: 'B'

----------------------------------------------------------------------
Ran 6 tests in 0.001s

FAILED (errors=1)
......
----------------------------------------------------------------------
Ran 6 tests in 0.001s

OK
.
----------------------------------------------------------------------
Ran 1 test in 0.000s

OK
.....
----------------------------------------------------------------------
Ran 5 tests in 0.001s

OK
..FFF
======================================================================
FAIL: test_remove_book_3 (ClassEval_13_0.BookManagementTestRemoveBook)
----------------------------------------------------------------------
Traceback (most recent call last):
  File "C:\Users\tanuj\Desktop\CS540\repo\CS540\classeval_evaluation\ClassEval_13_0.py", line 108, in test_remove_book_3
    with self.assertRaises(Exception):
AssertionError: Exception not raised

======================================================================
FAIL: test_remove_book_4 (ClassEval_13_0.BookManagementTestRemoveBook)
----------------------------------------------------------------------
Traceback (most recent call last):
  File "C:\Users\tanuj\Desktop\CS540\repo\CS540\classeval_evaluation\ClassEval_13_0.py", line 113, in test_remove_book_4
    with self.assertRaises(Exception):
AssertionError: Exception not raised

======================================================================
FAIL: test_remove_book_5 (ClassEval_13_0.BookManagementTestRemoveBook)
----------------------------------------------------------------------
Traceback (most recent call last):
  File "C:\Users\tanuj\Desktop\CS540\repo\CS540\classeval_evaluation\ClassEval_13_0.py", line 117, in test_remove_book_5
    with self.assertRaises(Exception):
AssertionError: Exception not raised

----------------------------------------------------------------------
Ran 5 tests in 0.003s

FAILED (failures=3)
.....
----------------------------------------------------------------------
Ran 5 tests in 0.000s

OK
.....
----------------------------------------------------------------------
Ran 5 tests in 0.001s

OK
.
----------------------------------------------------------------------
Ran 1 test in 0.000s

OK
.F
======================================================================
FAIL: test_create_table_2 (ClassEval_14_0.BookManagementDBTestCreateTable)
----------------------------------------------------------------------
Traceback (most recent call last):
  File "C:\Users\tanuj\Desktop\CS540\repo\CS540\classeval_evaluation\ClassEval_14_0.py", line 113, in test_create_table_2
    self.assertEqual(column_names, expected_column_names)
AssertionError: Lists differ: ['id', 'title', 'author', 'availability'] != ['id', 'title', 'author', 'available']

First differing element 3:
'availability'
'available'

- ['id', 'title', 'author', 'availability']
?                                   - ^^^

+ ['id', 'title', 'author', 'available']
?                                    ^


----------------------------------------------------------------------
Ran 2 tests in 0.025s

FAILED (failures=1)
E
======================================================================
ERROR: test_add_book (ClassEval_14_0.BookManagementDBTestAddBook)
----------------------------------------------------------------------
Traceback (most recent call last):
  File "C:\Users\tanuj\Desktop\CS540\repo\CS540\classeval_evaluation\ClassEval_14_0.py", line 135, in test_add_book
    self.cursor.execute("SELECT title, author, available FROM books WHERE id=1")
sqlite3.OperationalError: no such column: available

----------------------------------------------------------------------
Ran 1 test in 0.031s

FAILED (errors=1)
.
----------------------------------------------------------------------
Ran 1 test in 0.027s

OK
E
======================================================================
ERROR: test_borrow_book (ClassEval_14_0.BookManagementDBTestBorrowBook)
----------------------------------------------------------------------
Traceback (most recent call last):
  File "C:\Users\tanuj\Desktop\CS540\repo\CS540\classeval_evaluation\ClassEval_14_0.py", line 186, in test_borrow_book
    self.cursor.execute("SELECT available FROM books WHERE id=1")
sqlite3.OperationalError: no such column: available

----------------------------------------------------------------------
Ran 1 test in 0.023s

FAILED (errors=1)
E
======================================================================
ERROR: test_return_book (ClassEval_14_0.BookManagementDBTestReturnBook)
----------------------------------------------------------------------
Traceback (most recent call last):
  File "C:\Users\tanuj\Desktop\CS540\repo\CS540\classeval_evaluation\ClassEval_14_0.py", line 211, in test_return_book
    self.cursor.execute("SELECT available FROM books WHERE id=1")
sqlite3.OperationalError: no such column: available

----------------------------------------------------------------------
Ran 1 test in 0.052s

FAILED (errors=1)
.
----------------------------------------------------------------------
Ran 1 test in 0.033s

OK
.....
----------------------------------------------------------------------
Ran 5 tests in 0.000s

OK
....F
======================================================================
FAIL: test_mismatch_in_text_5 (ClassEval_15_0.BoyerMooreSearchTestMismatchInText)
----------------------------------------------------------------------
Traceback (most recent call last):
  File "C:\Users\tanuj\Desktop\CS540\repo\CS540\classeval_evaluation\ClassEval_15_0.py", line 132, in test_mismatch_in_text_5
    self.assertEqual(boyerMooreSearch.mismatch_in_text(3), 5)
AssertionError: 2 != 5

----------------------------------------------------------------------
Ran 5 tests in 0.001s

FAILED (failures=1)
.....
----------------------------------------------------------------------
Ran 5 tests in 0.000s

OK
.
----------------------------------------------------------------------
Ran 1 test in 0.000s

OK
.....F.F
======================================================================
FAIL: test_calculate_6 (ClassEval_16_0.CalculatorTestCalculate)
----------------------------------------------------------------------
Traceback (most recent call last):
  File "C:\Users\tanuj\Desktop\CS540\repo\CS540\classeval_evaluation\ClassEval_16_0.py", line 152, in test_calculate_6
    self.assertEqual(res, 6)
AssertionError: None != 6

======================================================================
FAIL: test_calculate_8 (ClassEval_16_0.CalculatorTestCalculate)
----------------------------------------------------------------------
Traceback (most recent call last):
  File "C:\Users\tanuj\Desktop\CS540\repo\CS540\classeval_evaluation\ClassEval_16_0.py", line 162, in test_calculate_8
    self.assertEqual(res, 3)
AssertionError: None != 3

----------------------------------------------------------------------
Ran 8 tests in 0.002s

FAILED (failures=2)
.....
----------------------------------------------------------------------
Ran 5 tests in 0.001s

OK
.....
----------------------------------------------------------------------
Ran 5 tests in 0.001s

OK
.
----------------------------------------------------------------------
Ran 1 test in 0.000s

OK
.....
----------------------------------------------------------------------
Ran 5 tests in 0.000s

OK
......
----------------------------------------------------------------------
Ran 6 tests in 0.000s

OK
..
----------------------------------------------------------------------
Ran 2 tests in 0.000s

OK
.....
----------------------------------------------------------------------
Ran 5 tests in 0.000s

OK
.FFFF
======================================================================
FAIL: test_get_available_slots_2 (ClassEval_17_0.CalendarTestGetAvailableSlots)
----------------------------------------------------------------------
Traceback (most recent call last):
  File "C:\Users\tanuj\Desktop\CS540\repo\CS540\classeval_evaluation\ClassEval_17_0.py", line 270, in test_get_available_slots_2
    self.assertEqual(len(calendar.get_available_slots(datetime(2023, 1, 1))), 23)
AssertionError: 2 != 23

======================================================================
FAIL: test_get_available_slots_3 (ClassEval_17_0.CalendarTestGetAvailableSlots)
----------------------------------------------------------------------
Traceback (most recent call last):
  File "C:\Users\tanuj\Desktop\CS540\repo\CS540\classeval_evaluation\ClassEval_17_0.py", line 276, in test_get_available_slots_3
    self.assertEqual(len(calendar.get_available_slots(datetime(2023, 1, 1))), 24)
AssertionError: 1 != 24

======================================================================
FAIL: test_get_available_slots_4 (ClassEval_17_0.CalendarTestGetAvailableSlots)
----------------------------------------------------------------------
Traceback (most recent call last):
  File "C:\Users\tanuj\Desktop\CS540\repo\CS540\classeval_evaluation\ClassEval_17_0.py", line 282, in test_get_available_slots_4
    self.assertEqual(len(calendar.get_available_slots(datetime(2023, 1, 1))), 24)
AssertionError: 1 != 24

======================================================================
FAIL: test_get_available_slots_5 (ClassEval_17_0.CalendarTestGetAvailableSlots)
----------------------------------------------------------------------
Traceback (most recent call last):
  File "C:\Users\tanuj\Desktop\CS540\repo\CS540\classeval_evaluation\ClassEval_17_0.py", line 288, in test_get_available_slots_5
    self.assertEqual(len(calendar.get_available_slots(datetime(2023, 1, 1))), 24)
AssertionError: 1 != 24

----------------------------------------------------------------------
Ran 5 tests in 0.001s

FAILED (failures=4)
....F
======================================================================
FAIL: test_get_upcoming_events_5 (ClassEval_17_0.CalendarTestGetUpcomingEvents)
----------------------------------------------------------------------
Traceback (most recent call last):
  File "C:\Users\tanuj\Desktop\CS540\repo\CS540\classeval_evaluation\ClassEval_17_0.py", line 323, in test_get_upcoming_events_5
    self.assertEqual(calendar.get_upcoming_events(1), [
AssertionError: Lists differ: [] != [{'date': datetime.datetime(2024, 1, 2, 0,[129 chars] 2'}]

Second list contains 1 additional elements.
First extra element 0:
{'date': datetime.datetime(2024, 1, 2, 0, 0), 'start_time': datetime.datetime(2024, 1, 2, 1, 0), 'end_time': datetime.datetime(2024, 1, 2, 2, 0), 'description': 'New Year 2'}

- []
+ [{'date': datetime.datetime(2024, 1, 2, 0, 0),
+   'description': 'New Year 2',
+   'end_time': datetime.datetime(2024, 1, 2, 2, 0),
+   'start_time': datetime.datetime(2024, 1, 2, 1, 0)}]

----------------------------------------------------------------------
Ran 5 tests in 0.001s

FAILED (failures=1)
.
----------------------------------------------------------------------
Ran 1 test in 0.000s

OK
.....
----------------------------------------------------------------------
Ran 5 tests in 0.002s

OK
.....
----------------------------------------------------------------------
Ran 5 tests in 0.001s

OK
.....
----------------------------------------------------------------------
Ran 5 tests in 0.000s

OK
.....
----------------------------------------------------------------------
Ran 5 tests in 0.001s

OK
.....
----------------------------------------------------------------------
Ran 5 tests in 0.000s

OK
.....E
======================================================================
ERROR: test_convert_key_6 (ClassEval_18_0.CamelCaseMapTestConvertKey)
----------------------------------------------------------------------
Traceback (most recent call last):
  File "C:\Users\tanuj\Desktop\CS540\repo\CS540\classeval_evaluation\ClassEval_18_0.py", line 293, in test_convert_key_6
    self.assertEqual(camelize_map._convert_key(1234), 1234)
  File "C:\Users\tanuj\Desktop\CS540\repo\CS540\classeval_evaluation\ClassEval_18_0.py", line 53, in _convert_key
    raise KeyError("Keys must be strings")
KeyError: 'Keys must be strings'

----------------------------------------------------------------------
Ran 6 tests in 0.001s

FAILED (errors=1)
.....
----------------------------------------------------------------------
Ran 5 tests in 0.000s

OK
.
----------------------------------------------------------------------
Ran 1 test in 0.000s

OK
.....
----------------------------------------------------------------------
Ran 5 tests in 0.001s

OK
.....
----------------------------------------------------------------------
Ran 5 tests in 0.001s

OK
.
----------------------------------------------------------------------
Ran 1 test in 0.000s

OK
.....
----------------------------------------------------------------------
Ran 5 tests in 0.000s

OK
.....
----------------------------------------------------------------------
Ran 5 tests in 0.000s

OK
F....
======================================================================
FAIL: test_send_message (ClassEval_20_0.ChatTestSendMessage)
----------------------------------------------------------------------
Traceback (most recent call last):
  File "C:\Users\tanuj\Desktop\CS540\repo\CS540\classeval_evaluation\ClassEval_20_0.py", line 138, in test_send_message
    self.assertEqual(chat.users, {'John': [{'sender': 'John', 'receiver': 'Mary', 'message': 'Hello', 'timestamp': timestamp}], 'Mary': [{'sender': 'John', 'receiver': 'Mary', 'message': 'Hello', 'timestamp': timestamp}]})
AssertionError: {'Joh[106 chars]y': []} != {'Joh[106 chars]y': [{'sender': 'John', 'receiver': 'Mary', 'm[50 chars]7'}]}
  {'John': [{'message': 'Hello',
             'receiver': 'Mary',
             'sender': 'John',
             'timestamp': '2025-04-22 19:37:27'}],
-  'Mary': []}
+  'Mary': [{'message': 'Hello',
+            'receiver': 'Mary',
+            'sender': 'John',
+            'timestamp': '2025-04-22 19:37:27'}]}

----------------------------------------------------------------------
Ran 5 tests in 0.008s

FAILED (failures=1)
.....
----------------------------------------------------------------------
Ran 5 tests in 0.001s

OK
FF
======================================================================
FAIL: test_main (ClassEval_20_0.ChatTestMain)
----------------------------------------------------------------------
Traceback (most recent call last):
  File "C:\Users\tanuj\Desktop\CS540\repo\CS540\classeval_evaluation\ClassEval_20_0.py", line 206, in test_main
    self.assertEqual(chat.users, {'John': [{'sender': 'John', 'receiver': 'Mary', 'message': 'Hello', 'timestamp': timestamp}], 'Mary': [{'sender': 'John', 'receiver': 'Mary', 'message': 'Hello', 'timestamp': timestamp}]})
AssertionError: {'Joh[106 chars]y': []} != {'Joh[106 chars]y': [{'sender': 'John', 'receiver': 'Mary', 'm[50 chars]7'}]}
  {'John': [{'message': 'Hello',
             'receiver': 'Mary',
             'sender': 'John',
             'timestamp': '2025-04-22 19:37:27'}],
-  'Mary': []}
+  'Mary': [{'message': 'Hello',
+            'receiver': 'Mary',
+            'sender': 'John',
+            'timestamp': '2025-04-22 19:37:27'}]}

======================================================================
FAIL: test_main_2 (ClassEval_20_0.ChatTestMain)
----------------------------------------------------------------------
Traceback (most recent call last):
  File "C:\Users\tanuj\Desktop\CS540\repo\CS540\classeval_evaluation\ClassEval_20_0.py", line 221, in test_main_2
    self.assertEqual(chat.users, {'John': [{'sender': 'John', 'receiver': 'Mary', 'message': 'Hello', 'timestamp': timestamp}], 'Mary': [{'sender': 'John', 'receiver': 'Mary', 'message': 'Hello', 'timestamp': timestamp}]})
AssertionError: {'Joh[106 chars]y': []} != {'Joh[106 chars]y': [{'sender': 'John', 'receiver': 'Mary', 'm[50 chars]7'}]}
  {'John': [{'message': 'Hello',
             'receiver': 'Mary',
             'sender': 'John',
             'timestamp': '2025-04-22 19:37:27'}],
-  'Mary': []}
+  'Mary': [{'message': 'Hello',
+            'receiver': 'Mary',
+            'sender': 'John',
+            'timestamp': '2025-04-22 19:37:27'}]}

----------------------------------------------------------------------
Ran 2 tests in 0.002s

FAILED (failures=2)
......
----------------------------------------------------------------------
Ran 6 tests in 0.002s

OK
......
----------------------------------------------------------------------
Ran 6 tests in 0.001s

OK
.....
----------------------------------------------------------------------
Ran 5 tests in 0.001s

OK
......
----------------------------------------------------------------------
Ran 6 tests in 0.001s

OK
.
----------------------------------------------------------------------
Ran 1 test in 0.000s

OK
...
----------------------------------------------------------------------
Ran 3 tests in 0.000s

OK
...
----------------------------------------------------------------------
Ran 3 tests in 0.000s

OK
....
----------------------------------------------------------------------
Ran 4 tests in 0.000s

OK
.FF
======================================================================
FAIL: test_get_all_major2 (ClassEval_22_0.ClassRegistrationSystemTestGetMajor)
----------------------------------------------------------------------
Traceback (most recent call last):
  File "C:\Users\tanuj\Desktop\CS540\repo\CS540\classeval_evaluation\ClassEval_22_0.py", line 199, in test_get_all_major2
    self.assertEqual(majors, ["Computer Science", "Mathematics"])
AssertionError: Lists differ: ['Mathematics', 'Computer Science'] != ['Computer Science', 'Mathematics']

First differing element 0:
'Mathematics'
'Computer Science'

- ['Mathematics', 'Computer Science']
+ ['Computer Science', 'Mathematics']

======================================================================
FAIL: test_get_all_major3 (ClassEval_22_0.ClassRegistrationSystemTestGetMajor)
----------------------------------------------------------------------
Traceback (most recent call last):
  File "C:\Users\tanuj\Desktop\CS540\repo\CS540\classeval_evaluation\ClassEval_22_0.py", line 210, in test_get_all_major3
    self.assertEqual(majors, ["Computer Science", "Mathematics", "Physics"])
AssertionError: Lists differ: ['Physics', 'Mathematics', 'Computer Science'] != ['Computer Science', 'Mathematics', 'Physics']

First differing element 0:
'Physics'
'Computer Science'

- ['Physics', 'Mathematics', 'Computer Science']
+ ['Computer Science', 'Mathematics', 'Physics']

----------------------------------------------------------------------
Ran 3 tests in 0.001s

FAILED (failures=2)
..
----------------------------------------------------------------------
Ran 2 tests in 0.000s

OK
F
======================================================================
FAIL: test (ClassEval_22_0.ClassRegistrationSystemTest)
----------------------------------------------------------------------
Traceback (most recent call last):
  File "C:\Users\tanuj\Desktop\CS540\repo\CS540\classeval_evaluation\ClassEval_22_0.py", line 270, in test
    self.assertEqual(self.registration_system.get_all_major(), ["Computer Science", "Mathematics"])
AssertionError: Lists differ: ['Mathematics', 'Computer Science'] != ['Computer Science', 'Mathematics']

First differing element 0:
'Mathematics'
'Computer Science'

- ['Mathematics', 'Computer Science']
+ ['Computer Science', 'Mathematics']

----------------------------------------------------------------------
Ran 1 test in 0.000s

FAILED (failures=1)
.....
----------------------------------------------------------------------
Ran 5 tests in 0.000s

OK
..F.F
======================================================================
FAIL: test_count_all_3 (ClassEval_23_0.CombinationCalculatorTestCountAll)
----------------------------------------------------------------------
Traceback (most recent call last):
  File "C:\Users\tanuj\Desktop\CS540\repo\CS540\classeval_evaluation\ClassEval_23_0.py", line 125, in test_count_all_3
    self.assertEqual(CombinationCalculator.count_all(65), False)
AssertionError: inf != False

======================================================================
FAIL: test_count_all_5 (ClassEval_23_0.CombinationCalculatorTestCountAll)
----------------------------------------------------------------------
Traceback (most recent call last):
  File "C:\Users\tanuj\Desktop\CS540\repo\CS540\classeval_evaluation\ClassEval_23_0.py", line 131, in test_count_all_5
    self.assertEqual(CombinationCalculator.count_all(63), float("inf"))
AssertionError: 9223372036854775807 != inf

----------------------------------------------------------------------
Ran 5 tests in 0.001s

FAILED (failures=2)
.....
----------------------------------------------------------------------
Ran 5 tests in 0.000s

OK
.....
----------------------------------------------------------------------
Ran 5 tests in 0.000s

OK
.....
----------------------------------------------------------------------
Ran 5 tests in 0.000s

OK
.
----------------------------------------------------------------------
Ran 1 test in 0.000s

OK
.....
----------------------------------------------------------------------
Ran 5 tests in 0.000s

OK
.....
----------------------------------------------------------------------
Ran 5 tests in 0.000s

OK
.....
----------------------------------------------------------------------
Ran 5 tests in 0.001s

OK
.....
----------------------------------------------------------------------
Ran 5 tests in 0.000s

OK
.
----------------------------------------------------------------------
Ran 1 test in 0.001s

OK
.....
----------------------------------------------------------------------
Ran 5 tests in 0.004s

OK
......
----------------------------------------------------------------------
Ran 6 tests in 0.002s

OK
......
----------------------------------------------------------------------
Ran 6 tests in 0.003s

OK
E
======================================================================
ERROR: test_set_cookies (ClassEval_25_0.CookiesUtilTestSetCookies)
----------------------------------------------------------------------
Traceback (most recent call last):
  File "C:\Users\tanuj\Desktop\CS540\repo\CS540\classeval_evaluation\ClassEval_25_0.py", line 203, in test_set_cookies
    self.cookies_util.set_cookies(request)
AttributeError: 'CookiesUtil' object has no attribute 'set_cookies'

----------------------------------------------------------------------
Ran 1 test in 0.000s

FAILED (errors=1)
.
----------------------------------------------------------------------
Ran 1 test in 0.001s

OK
.....
----------------------------------------------------------------------
Ran 5 tests in 0.015s

OK
......
----------------------------------------------------------------------
Ran 6 tests in 0.009s

OK
.....
----------------------------------------------------------------------
Ran 5 tests in 0.008s

OK
.
----------------------------------------------------------------------
Ran 1 test in 0.003s

OK
.....E
======================================================================
ERROR: test_convert_6 (ClassEval_27_0.CurrencyConverterTestConvert)
----------------------------------------------------------------------
Traceback (most recent call last):
  File "C:\Users\tanuj\Desktop\CS540\repo\CS540\classeval_evaluation\ClassEval_27_0.py", line 111, in test_convert_6
    res = cc.convert(64, '???', 'USD')
  File "C:\Users\tanuj\Desktop\CS540\repo\CS540\classeval_evaluation\ClassEval_27_0.py", line 35, in convert
    raise ValueError(f"Unsupported source currency: {from_currency}")
ValueError: Unsupported source currency: ???

----------------------------------------------------------------------
Ran 6 tests in 0.004s

FAILED (errors=1)
.....
----------------------------------------------------------------------
Ran 5 tests in 0.001s

OK
......
----------------------------------------------------------------------
Ran 6 tests in 0.000s

OK
......
----------------------------------------------------------------------
Ran 6 tests in 0.001s

OK
.
----------------------------------------------------------------------
Ran 1 test in 0.000s

OK
.....
----------------------------------------------------------------------
Ran 5 tests in 0.000s

OK
.....
----------------------------------------------------------------------
Ran 5 tests in 0.000s

OK
.....
----------------------------------------------------------------------
Ran 5 tests in 0.000s

OK
.
----------------------------------------------------------------------
Ran 1 test in 0.000s

OK
.....
----------------------------------------------------------------------
Ran 5 tests in 0.001s

OK
.....
----------------------------------------------------------------------
Ran 5 tests in 0.001s

OK
.....
----------------------------------------------------------------------
Ran 5 tests in 0.001s

OK
.....
----------------------------------------------------------------------
Ran 5 tests in 0.001s

OK
.....
----------------------------------------------------------------------
Ran 5 tests in 0.001s

OK
.FFFF
======================================================================
FAIL: test_get_correlation_2 (ClassEval_30_0.DataStatistics2TestGetCorrelation)
----------------------------------------------------------------------
Traceback (most recent call last):
  File "C:\Users\tanuj\Desktop\CS540\repo\CS540\classeval_evaluation\ClassEval_30_0.py", line 239, in test_get_correlation_2
    self.assertEqual(res, 1.0)
AssertionError: -0.49 != 1.0

======================================================================
FAIL: test_get_correlation_3 (ClassEval_30_0.DataStatistics2TestGetCorrelation)
----------------------------------------------------------------------
Traceback (most recent call last):
  File "C:\Users\tanuj\Desktop\CS540\repo\CS540\classeval_evaluation\ClassEval_30_0.py", line 244, in test_get_correlation_3
    self.assertEqual(res, 1.0)
AssertionError: -0.65 != 1.0

======================================================================
FAIL: test_get_correlation_4 (ClassEval_30_0.DataStatistics2TestGetCorrelation)
----------------------------------------------------------------------
Traceback (most recent call last):
  File "C:\Users\tanuj\Desktop\CS540\repo\CS540\classeval_evaluation\ClassEval_30_0.py", line 249, in test_get_correlation_4
    self.assertEqual(res, 1.0)
AssertionError: -0.65 != 1.0

======================================================================
FAIL: test_get_correlation_5 (ClassEval_30_0.DataStatistics2TestGetCorrelation)
----------------------------------------------------------------------
Traceback (most recent call last):
  File "C:\Users\tanuj\Desktop\CS540\repo\CS540\classeval_evaluation\ClassEval_30_0.py", line 254, in test_get_correlation_5
    self.assertEqual(res, 1.0)
AssertionError: -0.65 != 1.0

----------------------------------------------------------------------
Ran 5 tests in 0.002s

FAILED (failures=4)
.
----------------------------------------------------------------------
Ran 1 test in 0.000s

OK
FEF.F
======================================================================
ERROR: test_correlation_coefficient_2 (ClassEval_31_0.DataStatistics4TestCorrelationCoefficient)
----------------------------------------------------------------------
Traceback (most recent call last):
  File "C:\Users\tanuj\Desktop\CS540\repo\CS540\classeval_evaluation\ClassEval_31_0.py", line 124, in test_correlation_coefficient_2
    self.assertEqual(DataStatistics4.correlation_coefficient([1, 1, 1], [2, 2, 2]), 0)
  File "C:\Users\tanuj\Desktop\CS540\repo\CS540\classeval_evaluation\ClassEval_31_0.py", line 39, in correlation_coefficient
    raise ValueError("division by zero in correlation calculation")
ValueError: division by zero in correlation calculation

======================================================================
FAIL: test_correlation_coefficient (ClassEval_31_0.DataStatistics4TestCorrelationCoefficient)
----------------------------------------------------------------------
Traceback (most recent call last):
  File "C:\Users\tanuj\Desktop\CS540\repo\CS540\classeval_evaluation\ClassEval_31_0.py", line 121, in test_correlation_coefficient
    self.assertEqual(DataStatistics4.correlation_coefficient([1, 2, 3], [4, 5, 6]), 0.9999999999999998)
AssertionError: 1.0 != 0.9999999999999998

======================================================================
FAIL: test_correlation_coefficient_3 (ClassEval_31_0.DataStatistics4TestCorrelationCoefficient)
----------------------------------------------------------------------
Traceback (most recent call last):
  File "C:\Users\tanuj\Desktop\CS540\repo\CS540\classeval_evaluation\ClassEval_31_0.py", line 127, in test_correlation_coefficient_3
    self.assertEqual(DataStatistics4.correlation_coefficient([1, 2, 3], [1, 2, 3]), 0.9999999999999998)
AssertionError: 1.0 != 0.9999999999999998

======================================================================
FAIL: test_correlation_coefficient_5 (ClassEval_31_0.DataStatistics4TestCorrelationCoefficient)
----------------------------------------------------------------------
Traceback (most recent call last):
  File "C:\Users\tanuj\Desktop\CS540\repo\CS540\classeval_evaluation\ClassEval_31_0.py", line 133, in test_correlation_coefficient_5
    self.assertEqual(DataStatistics4.correlation_coefficient([1, 2, 3], [1, 5, 3]), 0.4999999999999999)
AssertionError: 0.5 != 0.4999999999999999

----------------------------------------------------------------------
Ran 5 tests in 0.001s

FAILED (failures=3, errors=1)
F..F.
======================================================================
FAIL: test_skewness (ClassEval_31_0.DataStatistics4TestSkewness)
----------------------------------------------------------------------
Traceback (most recent call last):
  File "C:\Users\tanuj\Desktop\CS540\repo\CS540\classeval_evaluation\ClassEval_31_0.py", line 138, in test_skewness
    self.assertEqual(DataStatistics4.skewness([1, 2, 5]), 2.3760224064818463)
AssertionError: 2.3760224064818467 != 2.3760224064818463

======================================================================
FAIL: test_skewness_4 (ClassEval_31_0.DataStatistics4TestSkewness)
----------------------------------------------------------------------
Traceback (most recent call last):
  File "C:\Users\tanuj\Desktop\CS540\repo\CS540\classeval_evaluation\ClassEval_31_0.py", line 147, in test_skewness_4
    self.assertEqual(DataStatistics4.skewness([1, 2, 4]), 1.7181079837227264)
AssertionError: 1.7181079837227267 != 1.7181079837227264

----------------------------------------------------------------------
Ran 5 tests in 0.001s

FAILED (failures=2)
F.F.F
======================================================================
FAIL: test_kurtosis (ClassEval_31_0.DataStatistics4TestKurtosis)
----------------------------------------------------------------------
Traceback (most recent call last):
  File "C:\Users\tanuj\Desktop\CS540\repo\CS540\classeval_evaluation\ClassEval_31_0.py", line 155, in test_kurtosis
    self.assertEqual(DataStatistics4.kurtosis([1, 2, 5]), -1.5000000000000002)
AssertionError: -1.5 != -1.5000000000000002

======================================================================
FAIL: test_kurtosis_3 (ClassEval_31_0.DataStatistics4TestKurtosis)
----------------------------------------------------------------------
Traceback (most recent call last):
  File "C:\Users\tanuj\Desktop\CS540\repo\CS540\classeval_evaluation\ClassEval_31_0.py", line 161, in test_kurtosis_3
    self.assertEqual(DataStatistics4.kurtosis([1, 2, 3]), -1.5000000000000002)
AssertionError: -1.5 != -1.5000000000000002

======================================================================
FAIL: test_kurtosis_5 (ClassEval_31_0.DataStatistics4TestKurtosis)
----------------------------------------------------------------------
Traceback (most recent call last):
  File "C:\Users\tanuj\Desktop\CS540\repo\CS540\classeval_evaluation\ClassEval_31_0.py", line 167, in test_kurtosis_5
    self.assertEqual(DataStatistics4.kurtosis([1, 5, 3]), -1.5000000000000002)
AssertionError: -1.5 != -1.5000000000000002

----------------------------------------------------------------------
Ran 5 tests in 0.001s

FAILED (failures=3)
.....
----------------------------------------------------------------------
Ran 5 tests in 0.000s

OK
F
======================================================================
FAIL: test_main (ClassEval_31_0.DataStatistics4TestMain)
----------------------------------------------------------------------
Traceback (most recent call last):
  File "C:\Users\tanuj\Desktop\CS540\repo\CS540\classeval_evaluation\ClassEval_31_0.py", line 194, in test_main
    self.assertEqual(DataStatistics4.correlation_coefficient([1, 2, 3], [4, 5, 6]), 0.9999999999999998)
AssertionError: 1.0 != 0.9999999999999998

----------------------------------------------------------------------
Ran 1 test in 0.000s

FAILED (failures=1)
.......
----------------------------------------------------------------------
Ran 7 tests in 0.000s

OK
......
----------------------------------------------------------------------
Ran 6 tests in 0.001s

OK
.....
----------------------------------------------------------------------
Ran 5 tests in 0.001s

OK
.
----------------------------------------------------------------------
Ran 1 test in 0.001s

OK
.....
----------------------------------------------------------------------
Ran 5 tests in 0.000s

OK
.....
----------------------------------------------------------------------
Ran 5 tests in 0.000s

OK
.....
----------------------------------------------------------------------
Ran 5 tests in 0.000s

OK
.....
----------------------------------------------------------------------
Ran 5 tests in 0.000s

OK
.....
----------------------------------------------------------------------
Ran 5 tests in 0.001s

OK
.
----------------------------------------------------------------------
Ran 1 test in 0.000s

OK
..EEE
======================================================================
ERROR: test_find_blank_3 (ClassEval_35_0.EightPuzzleTestFindBlank)
----------------------------------------------------------------------
Traceback (most recent call last):
  File "C:\Users\tanuj\Desktop\CS540\repo\CS540\classeval_evaluation\ClassEval_35_0.py", line 132, in test_find_blank_3
    self.assertEqual(eightPuzzle.find_blank(state), None)
  File "C:\Users\tanuj\Desktop\CS540\repo\CS540\classeval_evaluation\ClassEval_35_0.py", line 31, in find_blank
    raise ValueError("No blank space (0) found in the state.")
ValueError: No blank space (0) found in the state.

======================================================================
ERROR: test_find_blank_4 (ClassEval_35_0.EightPuzzleTestFindBlank)
----------------------------------------------------------------------
Traceback (most recent call last):
  File "C:\Users\tanuj\Desktop\CS540\repo\CS540\classeval_evaluation\ClassEval_35_0.py", line 137, in test_find_blank_4
    self.assertEqual(eightPuzzle.find_blank(state), None)
  File "C:\Users\tanuj\Desktop\CS540\repo\CS540\classeval_evaluation\ClassEval_35_0.py", line 31, in find_blank
    raise ValueError("No blank space (0) found in the state.")
ValueError: No blank space (0) found in the state.

======================================================================
ERROR: test_find_blank_5 (ClassEval_35_0.EightPuzzleTestFindBlank)
----------------------------------------------------------------------
Traceback (most recent call last):
  File "C:\Users\tanuj\Desktop\CS540\repo\CS540\classeval_evaluation\ClassEval_35_0.py", line 142, in test_find_blank_5
    self.assertEqual(eightPuzzle.find_blank(state), None)
  File "C:\Users\tanuj\Desktop\CS540\repo\CS540\classeval_evaluation\ClassEval_35_0.py", line 31, in find_blank
    raise ValueError("No blank space (0) found in the state.")
ValueError: No blank space (0) found in the state.

----------------------------------------------------------------------
Ran 5 tests in 0.001s

FAILED (errors=3)
.....
----------------------------------------------------------------------
Ran 5 tests in 0.001s

OK
.....
----------------------------------------------------------------------
Ran 5 tests in 0.001s

OK
.....F
======================================================================
FAIL: test_solve_6 (ClassEval_35_0.EightPuzzleTestSolve)
----------------------------------------------------------------------
Traceback (most recent call last):
  File "C:\Users\tanuj\Desktop\CS540\repo\CS540\classeval_evaluation\ClassEval_35_0.py", line 253, in test_solve_6
    self.assertEqual(result, expected)
AssertionError: [] != None

----------------------------------------------------------------------
Ran 6 tests in 0.227s

FAILED (failures=1)
.....
----------------------------------------------------------------------
Ran 5 tests in 0.000s

OK
.....
----------------------------------------------------------------------
Ran 5 tests in 0.001s

OK
.....
----------------------------------------------------------------------
Ran 5 tests in 0.000s

OK
.....
----------------------------------------------------------------------
Ran 5 tests in 0.001s

OK
.F...
======================================================================
FAIL: test_clear_inbox_2 (ClassEval_36_0.EmailClientTestClearInbox)
----------------------------------------------------------------------
Traceback (most recent call last):
  File "C:\Users\tanuj\Desktop\CS540\repo\CS540\classeval_evaluation\ClassEval_36_0.py", line 249, in test_clear_inbox_2
    self.assertEqual(receiver.inbox, [{'size': 10},{'size': 20},{'size': 15}])
AssertionError: Lists differ: [{'size': 15}] != [{'size': 10}, {'size': 20}, {'size': 15}]

First differing element 0:
{'size': 15}
{'size': 10}

Second list contains 2 additional elements.
First extra element 1:
{'size': 20}

- [{'size': 15}]
+ [{'size': 10}, {'size': 20}, {'size': 15}]

----------------------------------------------------------------------
Ran 5 tests in 0.007s

FAILED (failures=1)
.
----------------------------------------------------------------------
Ran 1 test in 0.000s

OK
......
----------------------------------------------------------------------
Ran 6 tests in 0.002s

OK
.....
----------------------------------------------------------------------
Ran 5 tests in 0.000s

OK
......
----------------------------------------------------------------------
Ran 6 tests in 0.001s

OK
.
----------------------------------------------------------------------
Ran 1 test in 0.000s

OK
.....
----------------------------------------------------------------------
Ran 5 tests in 0.001s

OK
......
----------------------------------------------------------------------
Ran 6 tests in 0.004s

OK
.....
----------------------------------------------------------------------
Ran 5 tests in 0.000s

OK
..FFFFF
======================================================================
FAIL: test_compare_3 (ClassEval_39_0.ExpressionCalculatorTestCompare)
----------------------------------------------------------------------
Traceback (most recent call last):
  File "C:\Users\tanuj\Desktop\CS540\repo\CS540\classeval_evaluation\ClassEval_39_0.py", line 251, in test_compare_3
    self.assertTrue(result)
AssertionError: False is not true

======================================================================
FAIL: test_compare_4 (ClassEval_39_0.ExpressionCalculatorTestCompare)
----------------------------------------------------------------------
Traceback (most recent call last):
  File "C:\Users\tanuj\Desktop\CS540\repo\CS540\classeval_evaluation\ClassEval_39_0.py", line 255, in test_compare_4
    self.assertFalse(result)
AssertionError: True is not false

======================================================================
FAIL: test_compare_5 (ClassEval_39_0.ExpressionCalculatorTestCompare)
----------------------------------------------------------------------
Traceback (most recent call last):
  File "C:\Users\tanuj\Desktop\CS540\repo\CS540\classeval_evaluation\ClassEval_39_0.py", line 259, in test_compare_5
    self.assertFalse(result)
AssertionError: True is not false

======================================================================
FAIL: test_compare_6 (ClassEval_39_0.ExpressionCalculatorTestCompare)
----------------------------------------------------------------------
Traceback (most recent call last):
  File "C:\Users\tanuj\Desktop\CS540\repo\CS540\classeval_evaluation\ClassEval_39_0.py", line 263, in test_compare_6
    self.assertFalse(result)
AssertionError: True is not false

======================================================================
FAIL: test_compare_7 (ClassEval_39_0.ExpressionCalculatorTestCompare)
----------------------------------------------------------------------
Traceback (most recent call last):
  File "C:\Users\tanuj\Desktop\CS540\repo\CS540\classeval_evaluation\ClassEval_39_0.py", line 267, in test_compare_7
    self.assertTrue(result)
AssertionError: False is not true

----------------------------------------------------------------------
Ran 7 tests in 0.001s

FAILED (failures=5)
.......
----------------------------------------------------------------------
Ran 7 tests in 0.001s

OK
....FF
======================================================================
FAIL: test_transform_5 (ClassEval_39_0.ExpressionCalculatorTestTransform)
----------------------------------------------------------------------
Traceback (most recent call last):
  File "C:\Users\tanuj\Desktop\CS540\repo\CS540\classeval_evaluation\ClassEval_39_0.py", line 327, in test_transform_5
    self.assertEqual(result, "~2+(~3)*4")
AssertionError: '-2+(-3)*4' != '~2+(~3)*4'
- -2+(-3)*4
? ^   ^
+ ~2+(~3)*4
? ^   ^


======================================================================
FAIL: test_transform_6 (ClassEval_39_0.ExpressionCalculatorTestTransform)
----------------------------------------------------------------------
Traceback (most recent call last):
  File "C:\Users\tanuj\Desktop\CS540\repo\CS540\classeval_evaluation\ClassEval_39_0.py", line 331, in test_transform_6
    self.assertEqual(result, "0-(1+1)")
AssertionError: '~(1+1)' != '0-(1+1)'
- ~(1+1)
? ^
+ 0-(1+1)
? ^^


----------------------------------------------------------------------
Ran 6 tests in 0.004s

FAILED (failures=2)
.
----------------------------------------------------------------------
Ran 1 test in 0.000s

OK
.....
----------------------------------------------------------------------
Ran 5 tests in 0.000s

OK
.....
----------------------------------------------------------------------
Ran 5 tests in 0.000s

OK
.....
----------------------------------------------------------------------
Ran 5 tests in 0.001s

OK
.
----------------------------------------------------------------------
Ran 1 test in 0.000s

OK
.....
----------------------------------------------------------------------
Ran 5 tests in 0.001s

OK
.....
----------------------------------------------------------------------
Ran 5 tests in 0.002s

OK
.....
----------------------------------------------------------------------
Ran 5 tests in 0.002s

OK
.
----------------------------------------------------------------------
Ran 1 test in 0.000s

OK
......
----------------------------------------------------------------------
Ran 6 tests in 0.001s

OK
......
----------------------------------------------------------------------
Ran 6 tests in 0.000s

OK
.....
----------------------------------------------------------------------
Ran 5 tests in 0.000s

OK
.....
----------------------------------------------------------------------
Ran 5 tests in 0.000s

OK
.
----------------------------------------------------------------------
Ran 1 test in 0.000s

OK
.....
----------------------------------------------------------------------
Ran 5 tests in 0.001s

OK
.....
----------------------------------------------------------------------
Ran 5 tests in 0.000s

OK
.....F
======================================================================
FAIL: test_update_employee_6 (ClassEval_43_0.HRManagementSystemTestUpdateEmployee)
----------------------------------------------------------------------
Traceback (most recent call last):
  File "C:\Users\tanuj\Desktop\CS540\repo\CS540\classeval_evaluation\ClassEval_43_0.py", line 217, in test_update_employee_6
    self.assertEqual(hr_system.update_employee(1, {'Name': 'John', 'position': 'Manager', 'department': 'Sales', 'salary': 20000}), False)
AssertionError: True != False

----------------------------------------------------------------------
Ran 6 tests in 0.001s

FAILED (failures=1)
.....
----------------------------------------------------------------------
Ran 5 tests in 0.000s

OK
.....
----------------------------------------------------------------------
Ran 5 tests in 0.000s

OK
..
----------------------------------------------------------------------
Ran 2 tests in 0.000s

OK
.....
----------------------------------------------------------------------
Ran 5 tests in 0.020s

OK
.....
----------------------------------------------------------------------
Ran 5 tests in 0.022s

OK
.....
----------------------------------------------------------------------
Ran 5 tests in 0.012s

OK
....F
======================================================================
FAIL: test_rotate_image_5 (ClassEval_45_0.ImageProcessorTestRotateImage)
----------------------------------------------------------------------
Traceback (most recent call last):
  File "C:\Users\tanuj\Desktop\CS540\repo\CS540\classeval_evaluation\ClassEval_45_0.py", line 235, in test_rotate_image_5
    self.assertTrue(ImageChops.difference(original_image.rotate(45), self.processor.image).getbbox() is None)
AssertionError: False is not true

----------------------------------------------------------------------
Ran 5 tests in 0.011s

FAILED (failures=1)
.....
----------------------------------------------------------------------
Ran 5 tests in 0.013s

OK
F
======================================================================
FAIL: test_main (ClassEval_45_0.ImageProcessorTestMain)
----------------------------------------------------------------------
Traceback (most recent call last):
  File "C:\Users\tanuj\Desktop\CS540\repo\CS540\classeval_evaluation\ClassEval_45_0.py", line 308, in test_main
    self.assertTrue(ImageChops.difference(original_image.rotate(90), self.processor.image).getbbox() is None)
AssertionError: False is not true

----------------------------------------------------------------------
Ran 1 test in 0.002s

FAILED (failures=1)
....F.E
======================================================================
ERROR: test_interpolate_1d_7 (ClassEval_46_0.InterpolationTestInterpolate1d)
----------------------------------------------------------------------
Traceback (most recent call last):
  File "C:\Users\tanuj\Desktop\CS540\repo\CS540\classeval_evaluation\ClassEval_46_0.py", line 151, in test_interpolate_1d_7
    self.assertEqual(interpolation.interpolate_1d([], [], [[], []]), [])
  File "C:\Users\tanuj\Desktop\CS540\repo\CS540\classeval_evaluation\ClassEval_46_0.py", line 28, in interpolate_1d
    raise ValueError("At least two data points are required for interpolation")
ValueError: At least two data points are required for interpolation

======================================================================
FAIL: test_interpolate_1d_5 (ClassEval_46_0.InterpolationTestInterpolate1d)
----------------------------------------------------------------------
Traceback (most recent call last):
  File "C:\Users\tanuj\Desktop\CS540\repo\CS540\classeval_evaluation\ClassEval_46_0.py", line 143, in test_interpolate_1d_5
    self.assertEqual(interpolation.interpolate_1d([1, 6, 4], [1, 7, 5], [2, 3]), [2.2, 3.4])
AssertionError: Lists differ: [2.2, 3.4000000000000004] != [2.2, 3.4]

First differing element 1:
3.4000000000000004
3.4

- [2.2, 3.4000000000000004]
+ [2.2, 3.4]

----------------------------------------------------------------------
Ran 7 tests in 0.001s

FAILED (failures=1, errors=1)
.EEE.
======================================================================
ERROR: test_interpolate_2d_2 (ClassEval_46_0.InterpolationTestInterpolate2d)
----------------------------------------------------------------------
Traceback (most recent call last):
  File "C:\Users\tanuj\Desktop\CS540\repo\CS540\classeval_evaluation\ClassEval_46_0.py", line 164, in test_interpolate_2d_2
    interpolation.interpolate_2d([1, 2, 3], [1, 2, 3], [[1, 2, 3], [4, 5, 6], [7, 8, 9]], [1.5, 2.5], [3, 4]),
  File "C:\Users\tanuj\Desktop\CS540\repo\CS540\classeval_evaluation\ClassEval_46_0.py", line 97, in interpolate_2d
    raise ValueError(f"yi={yi} is outside y-range [{y[0]}, {y[-1]}]")
ValueError: yi=4 is outside y-range [1, 3]

======================================================================
ERROR: test_interpolate_2d_3 (ClassEval_46_0.InterpolationTestInterpolate2d)
----------------------------------------------------------------------
Traceback (most recent call last):
  File "C:\Users\tanuj\Desktop\CS540\repo\CS540\classeval_evaluation\ClassEval_46_0.py", line 170, in test_interpolate_2d_3
    interpolation.interpolate_2d([1, 2, 3], [1, 2, 3], [[1, 2, 3], [4, 5, 6], [7, 8, 9]], [3, 4], [1.5, 2.5]),
  File "C:\Users\tanuj\Desktop\CS540\repo\CS540\classeval_evaluation\ClassEval_46_0.py", line 88, in interpolate_2d
    raise ValueError(f"xi={xi} is outside x-range [{x[0]}, {x[-1]}]")
ValueError: xi=4 is outside x-range [1, 3]

======================================================================
ERROR: test_interpolate_2d_4 (ClassEval_46_0.InterpolationTestInterpolate2d)
----------------------------------------------------------------------
Traceback (most recent call last):
  File "C:\Users\tanuj\Desktop\CS540\repo\CS540\classeval_evaluation\ClassEval_46_0.py", line 176, in test_interpolate_2d_4
    interpolation.interpolate_2d([1, 2, 3], [1, 2, 3], [[1, 2, 3], [4, 5, 6], [7, 8, 9]], [3, 4], [3, 4]),
  File "C:\Users\tanuj\Desktop\CS540\repo\CS540\classeval_evaluation\ClassEval_46_0.py", line 88, in interpolate_2d
    raise ValueError(f"xi={xi} is outside x-range [{x[0]}, {x[-1]}]")
ValueError: xi=4 is outside x-range [1, 3]

----------------------------------------------------------------------
Ran 5 tests in 0.003s

FAILED (errors=3)
.
----------------------------------------------------------------------
Ran 1 test in 0.000s

OK
.....
----------------------------------------------------------------------
Ran 5 tests in 0.000s

OK
.....
----------------------------------------------------------------------
Ran 5 tests in 0.003s

OK
.....
----------------------------------------------------------------------
Ran 5 tests in 0.001s

OK
.
----------------------------------------------------------------------
Ran 1 test in 0.000s

OK
.....
----------------------------------------------------------------------
Ran 5 tests in 0.000s

OK
.....
----------------------------------------------------------------------
Ran 5 tests in 0.000s

OK
.....
----------------------------------------------------------------------
Ran 5 tests in 0.000s

OK
.....
----------------------------------------------------------------------
Ran 5 tests in 0.001s

OK
.....
----------------------------------------------------------------------
Ran 5 tests in 0.000s

OK
.....
----------------------------------------------------------------------
Ran 5 tests in 0.001s

OK
EEEEE
======================================================================
ERROR: test_matches_requirements (ClassEval_49_0.JobMarketplaceTestMatchesRequirements)
----------------------------------------------------------------------
Traceback (most recent call last):
  File "C:\Users\tanuj\Desktop\CS540\repo\CS540\classeval_evaluation\ClassEval_49_0.py", line 283, in test_matches_requirements
    self.assertEqual(jobMarketplace.matches_requirements({"name": "Tom", "skills": ['skill1', 'skill2'], "experience": "experience"}, ['skill1', 'skill2']), True)
  File "C:\Users\tanuj\Desktop\CS540\repo\CS540\classeval_evaluation\ClassEval_49_0.py", line 69, in matches_requirements
    skills = resume.get('skills', [])
AttributeError: 'list' object has no attribute 'get'

======================================================================
ERROR: test_matches_requirements_2 (ClassEval_49_0.JobMarketplaceTestMatchesRequirements)
----------------------------------------------------------------------
Traceback (most recent call last):
  File "C:\Users\tanuj\Desktop\CS540\repo\CS540\classeval_evaluation\ClassEval_49_0.py", line 287, in test_matches_requirements_2
    self.assertEqual(jobMarketplace.matches_requirements({"name": "Tom", "skills": ['skill1', 'skill2'], "experience": "experience"}, ['skill3', 'skill4']), False)
  File "C:\Users\tanuj\Desktop\CS540\repo\CS540\classeval_evaluation\ClassEval_49_0.py", line 69, in matches_requirements
    skills = resume.get('skills', [])
AttributeError: 'list' object has no attribute 'get'

======================================================================
ERROR: test_matches_requirements_3 (ClassEval_49_0.JobMarketplaceTestMatchesRequirements)
----------------------------------------------------------------------
Traceback (most recent call last):
  File "C:\Users\tanuj\Desktop\CS540\repo\CS540\classeval_evaluation\ClassEval_49_0.py", line 291, in test_matches_requirements_3
    self.assertEqual(jobMarketplace.matches_requirements({"name": "Tom", "skills": ['skill1', 'skill2'], "experience": "experience"}, ['skill5', 'skill6']), False)
  File "C:\Users\tanuj\Desktop\CS540\repo\CS540\classeval_evaluation\ClassEval_49_0.py", line 69, in matches_requirements
    skills = resume.get('skills', [])
AttributeError: 'list' object has no attribute 'get'

======================================================================
ERROR: test_matches_requirements_4 (ClassEval_49_0.JobMarketplaceTestMatchesRequirements)
----------------------------------------------------------------------
Traceback (most recent call last):
  File "C:\Users\tanuj\Desktop\CS540\repo\CS540\classeval_evaluation\ClassEval_49_0.py", line 295, in test_matches_requirements_4
    self.assertEqual(jobMarketplace.matches_requirements({"name": "Tom", "skills": ['skill1', 'skill2'], "experience": "experience"}, ['skill1', 'skill3']), False)
  File "C:\Users\tanuj\Desktop\CS540\repo\CS540\classeval_evaluation\ClassEval_49_0.py", line 69, in matches_requirements
    skills = resume.get('skills', [])
AttributeError: 'list' object has no attribute 'get'

======================================================================
ERROR: test_matches_requirements_5 (ClassEval_49_0.JobMarketplaceTestMatchesRequirements)
----------------------------------------------------------------------
Traceback (most recent call last):
  File "C:\Users\tanuj\Desktop\CS540\repo\CS540\classeval_evaluation\ClassEval_49_0.py", line 299, in test_matches_requirements_5
    self.assertEqual(jobMarketplace.matches_requirements({"name": "Tom", "skills": ['skill1', 'skill2'], "experience": "experience"}, ['skill1']), False)
  File "C:\Users\tanuj\Desktop\CS540\repo\CS540\classeval_evaluation\ClassEval_49_0.py", line 69, in matches_requirements
    skills = resume.get('skills', [])
AttributeError: 'list' object has no attribute 'get'

----------------------------------------------------------------------
Ran 5 tests in 0.007s

FAILED (errors=5)
E
======================================================================
ERROR: test_main (ClassEval_49_0.JobMarketplaceTestMain)
----------------------------------------------------------------------
Traceback (most recent call last):
  File "C:\Users\tanuj\Desktop\CS540\repo\CS540\classeval_evaluation\ClassEval_49_0.py", line 316, in test_main
    self.assertEqual(jobMarketplace.matches_requirements({"name": "Tom", "skills": ['skill1', 'skill2'], "experience": "experience"}, ['skill1', 'skill2']), True)
  File "C:\Users\tanuj\Desktop\CS540\repo\CS540\classeval_evaluation\ClassEval_49_0.py", line 69, in matches_requirements
    skills = resume.get('skills', [])
AttributeError: 'list' object has no attribute 'get'

----------------------------------------------------------------------
Ran 1 test in 0.001s

FAILED (errors=1)
.....
----------------------------------------------------------------------
Ran 5 tests in 0.004s

OK
.....
----------------------------------------------------------------------
Ran 5 tests in 0.010s

OK
..F..
======================================================================
FAIL: test_process_json_3 (ClassEval_50_0.JSONProcessorTestProcessJsonExistingKey)
----------------------------------------------------------------------
Traceback (most recent call last):
  File "C:\Users\tanuj\Desktop\CS540\repo\CS540\classeval_evaluation\ClassEval_50_0.py", line 227, in test_process_json_3
    self.assertEqual(self.processor.process_json(self.file_path, remove_key), 0)
AssertionError: -1 != 0

----------------------------------------------------------------------
Ran 5 tests in 0.029s

FAILED (failures=1)
.
----------------------------------------------------------------------
Ran 1 test in 0.006s

OK
.....
----------------------------------------------------------------------
Ran 5 tests in 0.001s

OK
.FFFF
======================================================================
FAIL: test_fleiss_kappa_2 (ClassEval_51_0.KappaCalculatorTestFleissKappa)
----------------------------------------------------------------------
Traceback (most recent call last):
  File "C:\Users\tanuj\Desktop\CS540\repo\CS540\classeval_evaluation\ClassEval_51_0.py", line 113, in test_fleiss_kappa_2
    self.assertEqual(KappaCalculator.fleiss_kappa([[1, 0, 0, 0, 14],
AssertionError: np.float64(0.20852557021248944) != 0.2115748928799344

======================================================================
FAIL: test_fleiss_kappa_3 (ClassEval_51_0.KappaCalculatorTestFleissKappa)
----------------------------------------------------------------------
Traceback (most recent call last):
  File "C:\Users\tanuj\Desktop\CS540\repo\CS540\classeval_evaluation\ClassEval_51_0.py", line 125, in test_fleiss_kappa_3
    self.assertEqual(KappaCalculator.fleiss_kappa([[0, 1, 0, 0, 14],
AssertionError: np.float64(0.20770181487022701) != 0.21076904123090398

======================================================================
FAIL: test_fleiss_kappa_4 (ClassEval_51_0.KappaCalculatorTestFleissKappa)
----------------------------------------------------------------------
Traceback (most recent call last):
  File "C:\Users\tanuj\Desktop\CS540\repo\CS540\classeval_evaluation\ClassEval_51_0.py", line 137, in test_fleiss_kappa_4
    self.assertEqual(KappaCalculator.fleiss_kappa([[0, 0, 1, 0, 14],
AssertionError: np.float64(0.20656634746922026) != 0.2096583016522883

======================================================================
FAIL: test_fleiss_kappa_5 (ClassEval_51_0.KappaCalculatorTestFleissKappa)
----------------------------------------------------------------------
Traceback (most recent call last):
  File "C:\Users\tanuj\Desktop\CS540\repo\CS540\classeval_evaluation\ClassEval_51_0.py", line 149, in test_fleiss_kappa_5
    self.assertEqual(KappaCalculator.fleiss_kappa([[0, 0, 0, 1, 14],
AssertionError: np.float64(0.2084226944823552) != 0.21147425143148907

----------------------------------------------------------------------
Ran 5 tests in 0.004s

FAILED (failures=4)
.
----------------------------------------------------------------------
Ran 1 test in 0.002s

OK
.....
----------------------------------------------------------------------
Ran 5 tests in 0.000s

OK
...FF
======================================================================
FAIL: test_find_longest_word_4 (ClassEval_53_0.LongestWordTestFindLongestWord)
----------------------------------------------------------------------
Traceback (most recent call last):
  File "C:\Users\tanuj\Desktop\CS540\repo\CS540\classeval_evaluation\ClassEval_53_0.py", line 119, in test_find_longest_word_4
    self.assertEqual('apple', longestWord.find_longest_word(sentence))
AssertionError: 'apple' != ''
- apple
+ 


======================================================================
FAIL: test_find_longest_word_5 (ClassEval_53_0.LongestWordTestFindLongestWord)
----------------------------------------------------------------------
Traceback (most recent call last):
  File "C:\Users\tanuj\Desktop\CS540\repo\CS540\classeval_evaluation\ClassEval_53_0.py", line 126, in test_find_longest_word_5
    self.assertEqual('apple', longestWord.find_longest_word(sentence))
AssertionError: 'apple' != 'red'
- apple
+ red


----------------------------------------------------------------------
Ran 5 tests in 0.001s

FAILED (failures=2)
.....
----------------------------------------------------------------------
Ran 5 tests in 0.000s

OK
......
----------------------------------------------------------------------
Ran 6 tests in 0.001s

OK
.FF..F
======================================================================
FAIL: test_has_path_2 (ClassEval_54_0.MahjongConnectTestHasPath)
----------------------------------------------------------------------
Traceback (most recent call last):
  File "C:\Users\tanuj\Desktop\CS540\repo\CS540\classeval_evaluation\ClassEval_54_0.py", line 245, in test_has_path_2
    self.assertEqual(res, True)
AssertionError: False != True

======================================================================
FAIL: test_has_path_3 (ClassEval_54_0.MahjongConnectTestHasPath)
----------------------------------------------------------------------
Traceback (most recent call last):
  File "C:\Users\tanuj\Desktop\CS540\repo\CS540\classeval_evaluation\ClassEval_54_0.py", line 254, in test_has_path_3
    self.assertEqual(res, True)
AssertionError: False != True

======================================================================
FAIL: test_has_path_6 (ClassEval_54_0.MahjongConnectTestHasPath)
----------------------------------------------------------------------
Traceback (most recent call last):
  File "C:\Users\tanuj\Desktop\CS540\repo\CS540\classeval_evaluation\ClassEval_54_0.py", line 281, in test_has_path_6
    self.assertEqual(res, True)
AssertionError: False != True

----------------------------------------------------------------------
Ran 6 tests in 0.003s

FAILED (failures=3)
.....
----------------------------------------------------------------------
Ran 5 tests in 0.000s

OK
.....
----------------------------------------------------------------------
Ran 5 tests in 0.000s

OK
.
----------------------------------------------------------------------
Ran 1 test in 0.000s

OK
..FF.
======================================================================
FAIL: test_palindromic_length_3 (ClassEval_55_0.ManacherTestPalindromicLength)
----------------------------------------------------------------------
Traceback (most recent call last):
  File "C:\Users\tanuj\Desktop\CS540\repo\CS540\classeval_evaluation\ClassEval_55_0.py", line 82, in test_palindromic_length_3
    self.assertEqual(manacher.palindromic_length(2, 3, 'a|b|a|b|a|x'), 0)
AssertionError: 2 != 0

======================================================================
FAIL: test_palindromic_length_4 (ClassEval_55_0.ManacherTestPalindromicLength)
----------------------------------------------------------------------
Traceback (most recent call last):
  File "C:\Users\tanuj\Desktop\CS540\repo\CS540\classeval_evaluation\ClassEval_55_0.py", line 86, in test_palindromic_length_4
    self.assertEqual(manacher.palindromic_length(9, 2, 'a|b|a|b|a|x'), 0)
AssertionError: 1 != 0

----------------------------------------------------------------------
Ran 5 tests in 0.001s

FAILED (failures=2)
.....
----------------------------------------------------------------------
Ran 5 tests in 0.000s

OK
.
----------------------------------------------------------------------
Ran 1 test in 0.000s

OK
.....
----------------------------------------------------------------------
Ran 5 tests in 0.001s

OK
......
----------------------------------------------------------------------
Ran 6 tests in 0.000s

OK
......
----------------------------------------------------------------------
Ran 6 tests in 0.001s

OK
......
----------------------------------------------------------------------
Ran 6 tests in 0.000s

OK
.F....
======================================================================
FAIL: test_accuracy_2 (ClassEval_56_0.MetricsCalculatorTestAccuracy)
----------------------------------------------------------------------
Traceback (most recent call last):
  File "C:\Users\tanuj\Desktop\CS540\repo\CS540\classeval_evaluation\ClassEval_56_0.py", line 229, in test_accuracy_2
    self.assertAlmostEqual(temp, 0.3333333333333333)
AssertionError: 0.25 != 0.3333333333333333 within 7 places (0.08333333333333331 difference)

----------------------------------------------------------------------
Ran 6 tests in 0.010s

FAILED (failures=1)
.
----------------------------------------------------------------------
Ran 1 test in 0.000s

OK
......FF
======================================================================
FAIL: test_mrr_7 (ClassEval_57_0.MetricsCalculator2TestMrr)
----------------------------------------------------------------------
Traceback (most recent call last):
  File "C:\Users\tanuj\Desktop\CS540\repo\CS540\classeval_evaluation\ClassEval_57_0.py", line 133, in test_mrr_7
    self.assertEqual(res1, 0.0)
AssertionError: nan != 0.0

======================================================================
FAIL: test_mrr_8 (ClassEval_57_0.MetricsCalculator2TestMrr)
----------------------------------------------------------------------
Traceback (most recent call last):
  File "C:\Users\tanuj\Desktop\CS540\repo\CS540\classeval_evaluation\ClassEval_57_0.py", line 138, in test_mrr_8
    self.assertEqual(res1, 0.0)
AssertionError: 0.75 != 0.0

----------------------------------------------------------------------
Ran 8 tests in 0.004s

FAILED (failures=2)
......F.
======================================================================
FAIL: test_map_7 (ClassEval_57_0.MetricsCalculator2TestMap)
----------------------------------------------------------------------
Traceback (most recent call last):
  File "C:\Users\tanuj\Desktop\CS540\repo\CS540\classeval_evaluation\ClassEval_57_0.py", line 176, in test_map_7
    self.assertEqual(res1, 0.0)
AssertionError: nan != 0.0

----------------------------------------------------------------------
Ran 8 tests in 0.010s

FAILED (failures=1)
....
----------------------------------------------------------------------
Ran 4 tests in 0.002s

OK
.....
----------------------------------------------------------------------
Ran 5 tests in 0.001s

OK
...EE
======================================================================
ERROR: test_generate_playerMap_4 (ClassEval_58_0.MinesweeperGameTestGeneratePlayerMap)
----------------------------------------------------------------------
Traceback (most recent call last):
  File "C:\Users\tanuj\Desktop\CS540\repo\CS540\classeval_evaluation\ClassEval_58_0.py", line 180, in test_generate_playerMap_4
    minesweeper_game = MinesweeperGame(1, 4)
  File "C:\Users\tanuj\Desktop\CS540\repo\CS540\classeval_evaluation\ClassEval_58_0.py", line 15, in __init__
    self.minesweeper_map = self.generate_mine_sweeper_map()
  File "C:\Users\tanuj\Desktop\CS540\repo\CS540\classeval_evaluation\ClassEval_58_0.py", line 28, in generate_mine_sweeper_map
    mine_positions = random.sample(all_positions, self.k)
  File "C:\Users\tanuj\AppData\Local\Programs\Python\Python310\lib\random.py", line 482, in sample
    raise ValueError("Sample larger than population or is negative")
ValueError: Sample larger than population or is negative

======================================================================
ERROR: test_generate_playerMap_5 (ClassEval_58_0.MinesweeperGameTestGeneratePlayerMap)
----------------------------------------------------------------------
Traceback (most recent call last):
  File "C:\Users\tanuj\Desktop\CS540\repo\CS540\classeval_evaluation\ClassEval_58_0.py", line 184, in test_generate_playerMap_5
    minesweeper_game = MinesweeperGame(2, 5)
  File "C:\Users\tanuj\Desktop\CS540\repo\CS540\classeval_evaluation\ClassEval_58_0.py", line 15, in __init__
    self.minesweeper_map = self.generate_mine_sweeper_map()
  File "C:\Users\tanuj\Desktop\CS540\repo\CS540\classeval_evaluation\ClassEval_58_0.py", line 28, in generate_mine_sweeper_map
    mine_positions = random.sample(all_positions, self.k)
  File "C:\Users\tanuj\AppData\Local\Programs\Python\Python310\lib\random.py", line 482, in sample
    raise ValueError("Sample larger than population or is negative")
ValueError: Sample larger than population or is negative

----------------------------------------------------------------------
Ran 5 tests in 0.002s

FAILED (errors=2)
.....
----------------------------------------------------------------------
Ran 5 tests in 0.001s

OK
F.FFF
======================================================================
FAIL: test_sweep (ClassEval_58_0.MinesweeperGameTestSweep)
----------------------------------------------------------------------
Traceback (most recent call last):
  File "C:\Users\tanuj\Desktop\CS540\repo\CS540\classeval_evaluation\ClassEval_58_0.py", line 224, in test_sweep
    self.assertEqual(minesweeper_game.score, 1)
AssertionError: 0 != 1

======================================================================
FAIL: test_sweep_3 (ClassEval_58_0.MinesweeperGameTestSweep)
----------------------------------------------------------------------
Traceback (most recent call last):
  File "C:\Users\tanuj\Desktop\CS540\repo\CS540\classeval_evaluation\ClassEval_58_0.py", line 238, in test_sweep_3
    self.assertEqual(minesweeper_game.score, 1)
AssertionError: 0 != 1

======================================================================
FAIL: test_sweep_4 (ClassEval_58_0.MinesweeperGameTestSweep)
----------------------------------------------------------------------
Traceback (most recent call last):
  File "C:\Users\tanuj\Desktop\CS540\repo\CS540\classeval_evaluation\ClassEval_58_0.py", line 244, in test_sweep_4
    self.assertEqual(minesweeper_game.sweep(0,2), [['-', '-', 0], ['-', '-', '0'], ['0', '0', '0']])
AssertionError: Lists differ: [['-', 1, 0], ['-', 1, '0'], ['0', '0', '0']] != [['-', '-', 0], ['-', '-', '0'], ['0', '0', '0']]

First differing element 0:
['-', 1, 0]
['-', '-', 0]

- [['-', 1, 0], ['-', 1, '0'], ['0', '0', '0']]
?        ^            ^

+ [['-', '-', 0], ['-', '-', '0'], ['0', '0', '0']]
?        ^^^            ^^^


======================================================================
FAIL: test_sweep_5 (ClassEval_58_0.MinesweeperGameTestSweep)
----------------------------------------------------------------------
Traceback (most recent call last):
  File "C:\Users\tanuj\Desktop\CS540\repo\CS540\classeval_evaluation\ClassEval_58_0.py", line 252, in test_sweep_5
    self.assertEqual(minesweeper_game.score, 1)
AssertionError: 0 != 1

----------------------------------------------------------------------
Ran 5 tests in 0.002s

FAILED (failures=4)
FF
======================================================================
FAIL: test_minesweeper_main (ClassEval_58_0.MinesweeperGameTestMain)
----------------------------------------------------------------------
Traceback (most recent call last):
  File "C:\Users\tanuj\Desktop\CS540\repo\CS540\classeval_evaluation\ClassEval_58_0.py", line 270, in test_minesweeper_main
    self.assertEqual(minesweeper_game.score, 1)
AssertionError: 0 != 1

======================================================================
FAIL: test_minesweeper_main_2 (ClassEval_58_0.MinesweeperGameTestMain)
----------------------------------------------------------------------
Traceback (most recent call last):
  File "C:\Users\tanuj\Desktop\CS540\repo\CS540\classeval_evaluation\ClassEval_58_0.py", line 286, in test_minesweeper_main_2
    self.assertEqual(minesweeper_game.score, 1)
AssertionError: 0 != 1

----------------------------------------------------------------------
Ran 2 tests in 0.001s

FAILED (failures=2)
.....
----------------------------------------------------------------------
Ran 5 tests in 0.004s

OK
.....
----------------------------------------------------------------------
Ran 5 tests in 0.001s

OK
.....
----------------------------------------------------------------------
Ran 5 tests in 0.001s

OK
.
----------------------------------------------------------------------
Ran 1 test in 0.000s

OK
.....
----------------------------------------------------------------------
Ran 5 tests in 0.378s

OK
.....
----------------------------------------------------------------------
Ran 5 tests in 0.120s

OK
.....
----------------------------------------------------------------------
Ran 5 tests in 0.141s

OK
.
----------------------------------------------------------------------
Ran 1 test in 0.027s

OK
.....
----------------------------------------------------------------------
Ran 5 tests in 0.000s

OK
......
----------------------------------------------------------------------
Ran 6 tests in 0.001s

OK
.F.F.
======================================================================
FAIL: test_play_2 (ClassEval_61_0.MusicPlayerTestPlay)
----------------------------------------------------------------------
Traceback (most recent call last):
  File "C:\Users\tanuj\Desktop\CS540\repo\CS540\classeval_evaluation\ClassEval_61_0.py", line 180, in test_play_2
    self.assertEqual(musicPlayer.play(), None)
AssertionError: False != None

======================================================================
FAIL: test_play_4 (ClassEval_61_0.MusicPlayerTestPlay)
----------------------------------------------------------------------
Traceback (most recent call last):
  File "C:\Users\tanuj\Desktop\CS540\repo\CS540\classeval_evaluation\ClassEval_61_0.py", line 191, in test_play_4
    self.assertEqual(musicPlayer.play(), "song1")
AssertionError: False != 'song1'

----------------------------------------------------------------------
Ran 5 tests in 0.002s

FAILED (failures=2)
.....
----------------------------------------------------------------------
Ran 5 tests in 0.001s

OK
.....
----------------------------------------------------------------------
Ran 5 tests in 0.001s

OK
.....
----------------------------------------------------------------------
Ran 5 tests in 0.001s

OK
FFF..
======================================================================
FAIL: test_set_volume (ClassEval_61_0.MusicPlayerTestSetVolume)
----------------------------------------------------------------------
Traceback (most recent call last):
  File "C:\Users\tanuj\Desktop\CS540\repo\CS540\classeval_evaluation\ClassEval_61_0.py", line 290, in test_set_volume
    self.assertEqual(musicPlayer.set_volume(50), None)
AssertionError: True != None

======================================================================
FAIL: test_set_volume2 (ClassEval_61_0.MusicPlayerTestSetVolume)
----------------------------------------------------------------------
Traceback (most recent call last):
  File "C:\Users\tanuj\Desktop\CS540\repo\CS540\classeval_evaluation\ClassEval_61_0.py", line 295, in test_set_volume2
    self.assertEqual(musicPlayer.set_volume(100), None)
AssertionError: True != None

======================================================================
FAIL: test_set_volume3 (ClassEval_61_0.MusicPlayerTestSetVolume)
----------------------------------------------------------------------
Traceback (most recent call last):
  File "C:\Users\tanuj\Desktop\CS540\repo\CS540\classeval_evaluation\ClassEval_61_0.py", line 300, in test_set_volume3
    self.assertEqual(musicPlayer.set_volume(0), None)
AssertionError: True != None

----------------------------------------------------------------------
Ran 5 tests in 0.003s

FAILED (failures=3)
.....
----------------------------------------------------------------------
Ran 5 tests in 0.001s

OK
.
----------------------------------------------------------------------
Ran 1 test in 0.000s

OK
.
----------------------------------------------------------------------
Ran 1 test in 0.000s

OK
....F
======================================================================
FAIL: test_remove_stop_words_5 (ClassEval_62_0.NLPDataProcessorTestRemove)
----------------------------------------------------------------------
Traceback (most recent call last):
  File "C:\Users\tanuj\Desktop\CS540\repo\CS540\classeval_evaluation\ClassEval_62_0.py", line 91, in test_remove_stop_words_5
    self.assertEqual(words_list, expected_words_list)
AssertionError: Lists differ: [['This', 'test'], ['This', 'apple'], ['This', 'dog']] != [['is', 'test'], ['is', 'apple'], ['is', 'dog']]

First differing element 0:
['This', 'test']
['is', 'test']

- [['This', 'test'], ['This', 'apple'], ['This', 'dog']]
?    --                --                 --

+ [['is', 'test'], ['is', 'apple'], ['is', 'dog']]

----------------------------------------------------------------------
Ran 5 tests in 0.001s

FAILED (failures=1)
.....
----------------------------------------------------------------------
Ran 5 tests in 0.000s

OK
.....
----------------------------------------------------------------------
Ran 5 tests in 0.000s

OK
.....
----------------------------------------------------------------------
Ran 5 tests in 0.001s

OK
......
----------------------------------------------------------------------
Ran 6 tests in 0.001s

OK
.....
----------------------------------------------------------------------
Ran 5 tests in 0.000s

OK
.....
----------------------------------------------------------------------
Ran 5 tests in 0.000s

OK
.....
----------------------------------------------------------------------
Ran 5 tests in 0.002s

OK
.....
----------------------------------------------------------------------
Ran 5 tests in 0.000s

OK
.....
----------------------------------------------------------------------
Ran 5 tests in 0.001s

OK
.....
----------------------------------------------------------------------
Ran 5 tests in 0.000s

OK
.
----------------------------------------------------------------------
Ran 1 test in 0.000s

OK
...F.E
======================================================================
ERROR: test_format_6 (ClassEval_65_0.NumberWordFormatterTestFormat)
----------------------------------------------------------------------
Traceback (most recent call last):
  File "C:\Users\tanuj\Desktop\CS540\repo\CS540\classeval_evaluation\ClassEval_65_0.py", line 189, in test_format_6
    self.assertEqual(formatter.format(None), "")
  File "C:\Users\tanuj\Desktop\CS540\repo\CS540\classeval_evaluation\ClassEval_65_0.py", line 34, in format
    return self.format_string(s)
  File "C:\Users\tanuj\Desktop\CS540\repo\CS540\classeval_evaluation\ClassEval_65_0.py", line 80, in format_string
    w = self.trans_three(s3)
  File "C:\Users\tanuj\Desktop\CS540\repo\CS540\classeval_evaluation\ClassEval_65_0.py", line 149, in trans_three
    words.append(self.trans_two(rem))
  File "C:\Users\tanuj\Desktop\CS540\repo\CS540\classeval_evaluation\ClassEval_65_0.py", line 121, in trans_two
    ones = int(s[1])
ValueError: invalid literal for int() with base 10: 'N'

======================================================================
FAIL: test_format_4 (ClassEval_65_0.NumberWordFormatterTestFormat)
----------------------------------------------------------------------
Traceback (most recent call last):
  File "C:\Users\tanuj\Desktop\CS540\repo\CS540\classeval_evaluation\ClassEval_65_0.py", line 181, in test_format_4
    self.assertEqual(formatter.format(1.23), "ONE AND CENTS TWENTY THREE ONLY")
AssertionError: 'ONE POINT TWO THREE ONLY' != 'ONE AND CENTS TWENTY THREE ONLY'
- ONE POINT TWO THREE ONLY
+ ONE AND CENTS TWENTY THREE ONLY


----------------------------------------------------------------------
Ran 6 tests in 0.001s

FAILED (failures=1, errors=1)
...F..
======================================================================
FAIL: test_format_string_4 (ClassEval_65_0.NumberWordFormatterTestFormatString)
----------------------------------------------------------------------
Traceback (most recent call last):
  File "C:\Users\tanuj\Desktop\CS540\repo\CS540\classeval_evaluation\ClassEval_65_0.py", line 208, in test_format_string_4
    self.assertEqual(formatter.format_string('1.23'), "ONE AND CENTS TWENTY THREE ONLY")
AssertionError: 'ONE POINT TWO THREE ONLY' != 'ONE AND CENTS TWENTY THREE ONLY'
- ONE POINT TWO THREE ONLY
+ ONE AND CENTS TWENTY THREE ONLY


----------------------------------------------------------------------
Ran 6 tests in 0.001s

FAILED (failures=1)
......
----------------------------------------------------------------------
Ran 6 tests in 0.000s

OK
.....
----------------------------------------------------------------------
Ran 5 tests in 0.000s

OK
....
----------------------------------------------------------------------
Ran 4 tests in 0.000s

OK
.
----------------------------------------------------------------------
Ran 1 test in 0.000s

OK
.FF....FF.F
======================================================================
FAIL: test_replace_10 (ClassEval_66_0.NumericEntityUnescaperTestReplace)
----------------------------------------------------------------------
Traceback (most recent call last):
  File "C:\Users\tanuj\Desktop\CS540\repo\CS540\classeval_evaluation\ClassEval_66_0.py", line 109, in test_replace_10
    self.assertEqual(res, "")
AssertionError: '&#X' != ''
- &#X
+ 


======================================================================
FAIL: test_replace_11 (ClassEval_66_0.NumericEntityUnescaperTestReplace)
----------------------------------------------------------------------
Traceback (most recent call last):
  File "C:\Users\tanuj\Desktop\CS540\repo\CS540\classeval_evaluation\ClassEval_66_0.py", line 114, in test_replace_11
    self.assertEqual(res, "")
AssertionError: '&#c1d;BC' != ''
- &#c1d;BC
+ 


======================================================================
FAIL: test_replace_6 (ClassEval_66_0.NumericEntityUnescaperTestReplace)
----------------------------------------------------------------------
Traceback (most recent call last):
  File "C:\Users\tanuj\Desktop\CS540\repo\CS540\classeval_evaluation\ClassEval_66_0.py", line 89, in test_replace_6
    self.assertEqual(res, "")
AssertionError: '&#' != ''
- &#
+ 


======================================================================
FAIL: test_replace_7 (ClassEval_66_0.NumericEntityUnescaperTestReplace)
----------------------------------------------------------------------
Traceback (most recent call last):
  File "C:\Users\tanuj\Desktop\CS540\repo\CS540\classeval_evaluation\ClassEval_66_0.py", line 94, in test_replace_7
    self.assertEqual(res, "eBC")
AssertionError: '&#X65;BC' != 'eBC'
- &#X65;BC
+ eBC


======================================================================
FAIL: test_replace_9 (ClassEval_66_0.NumericEntityUnescaperTestReplace)
----------------------------------------------------------------------
Traceback (most recent call last):
  File "C:\Users\tanuj\Desktop\CS540\repo\CS540\classeval_evaluation\ClassEval_66_0.py", line 104, in test_replace_9
    self.assertEqual(res, "CCC")
AssertionError: 'CCC;' != 'CCC'
- CCC;
?    -
+ CCC


----------------------------------------------------------------------
Ran 11 tests in 0.002s

FAILED (failures=5)
.....
----------------------------------------------------------------------
Ran 5 tests in 0.001s

OK
.
----------------------------------------------------------------------
Ran 1 test in 0.000s

OK
F.FFFF
======================================================================
FAIL: test_add_dish_1 (ClassEval_67_0.OrderTestAddDish)
----------------------------------------------------------------------
Traceback (most recent call last):
  File "C:\Users\tanuj\Desktop\CS540\repo\CS540\classeval_evaluation\ClassEval_67_0.py", line 93, in test_add_dish_1
    self.assertTrue(result)
AssertionError: False is not true

======================================================================
FAIL: test_add_dish_3 (ClassEval_67_0.OrderTestAddDish)
----------------------------------------------------------------------
Traceback (most recent call last):
  File "C:\Users\tanuj\Desktop\CS540\repo\CS540\classeval_evaluation\ClassEval_67_0.py", line 123, in test_add_dish_3
    self.assertTrue(result)
AssertionError: False is not true

======================================================================
FAIL: test_add_dish_4 (ClassEval_67_0.OrderTestAddDish)
----------------------------------------------------------------------
Traceback (most recent call last):
  File "C:\Users\tanuj\Desktop\CS540\repo\CS540\classeval_evaluation\ClassEval_67_0.py", line 138, in test_add_dish_4
    self.assertTrue(result)
AssertionError: False is not true

======================================================================
FAIL: test_add_dish_5 (ClassEval_67_0.OrderTestAddDish)
----------------------------------------------------------------------
Traceback (most recent call last):
  File "C:\Users\tanuj\Desktop\CS540\repo\CS540\classeval_evaluation\ClassEval_67_0.py", line 153, in test_add_dish_5
    self.assertTrue(result)
AssertionError: False is not true

======================================================================
FAIL: test_add_dish_6 (ClassEval_67_0.OrderTestAddDish)
----------------------------------------------------------------------
Traceback (most recent call last):
  File "C:\Users\tanuj\Desktop\CS540\repo\CS540\classeval_evaluation\ClassEval_67_0.py", line 169, in test_add_dish_6
    self.assertTrue(result)
AssertionError: False is not true

----------------------------------------------------------------------
Ran 6 tests in 0.003s

FAILED (failures=5)
.....
----------------------------------------------------------------------
Ran 5 tests in 0.000s

OK
F.FFF
======================================================================
FAIL: test_checkout_1 (ClassEval_67_0.OrderTestCheckout)
----------------------------------------------------------------------
Traceback (most recent call last):
  File "C:\Users\tanuj\Desktop\CS540\repo\CS540\classeval_evaluation\ClassEval_67_0.py", line 234, in test_checkout_1
    self.assertEqual([], self.order.selected_dishes)
AssertionError: Lists differ: [] != [{'dish': 'dish1', 'price': 10, 'count': 2[41 chars]: 2}]

Second list contains 2 additional elements.
First extra element 0:
{'dish': 'dish1', 'price': 10, 'count': 2}

- []
+ [{'count': 2, 'dish': 'dish1', 'price': 10},
+  {'count': 2, 'dish': 'dish3', 'price': 20}]

======================================================================
FAIL: test_checkout_3 (ClassEval_67_0.OrderTestCheckout)
----------------------------------------------------------------------
Traceback (most recent call last):
  File "C:\Users\tanuj\Desktop\CS540\repo\CS540\classeval_evaluation\ClassEval_67_0.py", line 256, in test_checkout_3
    self.assertEqual([], self.order.selected_dishes)
AssertionError: Lists differ: [] != [{'dish': 'dish1', 'price': 10, 'count': 1[41 chars]: 1}]

Second list contains 2 additional elements.
First extra element 0:
{'dish': 'dish1', 'price': 10, 'count': 1}

- []
+ [{'count': 1, 'dish': 'dish1', 'price': 10},
+  {'count': 1, 'dish': 'dish3', 'price': 20}]

======================================================================
FAIL: test_checkout_4 (ClassEval_67_0.OrderTestCheckout)
----------------------------------------------------------------------
Traceback (most recent call last):
  File "C:\Users\tanuj\Desktop\CS540\repo\CS540\classeval_evaluation\ClassEval_67_0.py", line 272, in test_checkout_4
    self.assertEqual([], self.order.selected_dishes)
AssertionError: Lists differ: [] != [{'dish': 'dish1', 'price': 10, 'count': 3[41 chars]: 3}]

Second list contains 2 additional elements.
First extra element 0:
{'dish': 'dish1', 'price': 10, 'count': 3}

- []
+ [{'count': 3, 'dish': 'dish1', 'price': 10},
+  {'count': 3, 'dish': 'dish3', 'price': 20}]

======================================================================
FAIL: test_checkout_5 (ClassEval_67_0.OrderTestCheckout)
----------------------------------------------------------------------
Traceback (most recent call last):
  File "C:\Users\tanuj\Desktop\CS540\repo\CS540\classeval_evaluation\ClassEval_67_0.py", line 288, in test_checkout_5
    self.assertEqual([], self.order.selected_dishes)
AssertionError: Lists differ: [] != [{'dish': 'dish1', 'price': 10, 'count': 5[41 chars]: 5}]

Second list contains 2 additional elements.
First extra element 0:
{'dish': 'dish1', 'price': 10, 'count': 5}

- []
+ [{'count': 5, 'dish': 'dish1', 'price': 10},
+  {'count': 5, 'dish': 'dish3', 'price': 20}]

----------------------------------------------------------------------
Ran 5 tests in 0.001s

FAILED (failures=4)
F
======================================================================
FAIL: test_order (ClassEval_67_0.OrderTest)
----------------------------------------------------------------------
Traceback (most recent call last):
  File "C:\Users\tanuj\Desktop\CS540\repo\CS540\classeval_evaluation\ClassEval_67_0.py", line 314, in test_order
    self.assertEqual([], self.order.selected_dishes)
AssertionError: Lists differ: [] != [{'dish': 'dish1', 'price': 10, 'count': 2[41 chars]: 2}]

Second list contains 2 additional elements.
First extra element 0:
{'dish': 'dish1', 'price': 10, 'count': 2}

- []
+ [{'count': 2, 'dish': 'dish1', 'price': 10},
+  {'count': 2, 'dish': 'dish3', 'price': 20}]

----------------------------------------------------------------------
Ran 1 test in 0.000s

FAILED (failures=1)
.....
----------------------------------------------------------------------
Ran 5 tests in 0.000s

OK
....F
======================================================================
FAIL: test_get_page_info_5 (ClassEval_68_0.PageUtilTestGetPageInfo)
----------------------------------------------------------------------
Traceback (most recent call last):
  File "C:\Users\tanuj\Desktop\CS540\repo\CS540\classeval_evaluation\ClassEval_68_0.py", line 194, in test_get_page_info_5
    self.assertEqual(actual_info, empty_info)
AssertionError: {'current_page': 5, 'per_page': 3, 'total_[77 chars]: []} != {}
+ {}
- {'current_page': 5,
-  'data': [],
-  'has_next': False,
-  'has_previous': True,
-  'per_page': 3,
-  'total_items': 10,
-  'total_pages': 4}

----------------------------------------------------------------------
Ran 5 tests in 0.001s

FAILED (failures=1)
.....
----------------------------------------------------------------------
Ran 5 tests in 0.000s

OK
.
----------------------------------------------------------------------
Ran 1 test in 0.000s

OK
.....
----------------------------------------------------------------------
Ran 5 tests in 0.000s

OK
.....
----------------------------------------------------------------------
Ran 5 tests in 0.001s

OK
.....
----------------------------------------------------------------------
Ran 5 tests in 0.000s

OK
.
----------------------------------------------------------------------
Ran 1 test in 0.000s

OK
.......
----------------------------------------------------------------------
Ran 7 tests in 0.001s

OK
..
----------------------------------------------------------------------
Ran 2 tests in 0.000s

OK
.......
----------------------------------------------------------------------
Ran 7 tests in 0.000s

OK
.....
----------------------------------------------------------------------
Ran 5 tests in 0.000s

OK
.....
----------------------------------------------------------------------
Ran 5 tests in 0.000s

OK
.....
----------------------------------------------------------------------
Ran 5 tests in 0.000s

OK
.....
----------------------------------------------------------------------
Ran 5 tests in 0.000s

OK
.....
----------------------------------------------------------------------
Ran 5 tests in 0.001s

OK
.....
----------------------------------------------------------------------
Ran 5 tests in 0.000s

OK
FF...
======================================================================
FAIL: test_generate_split_sentences_pattern_1 (ClassEval_72_0.RegexUtilsTestGenerateSplitSentencesPattern)
----------------------------------------------------------------------
Traceback (most recent call last):
  File "C:\Users\tanuj\Desktop\CS540\repo\CS540\classeval_evaluation\ClassEval_72_0.py", line 266, in test_generate_split_sentences_pattern_1
    self.assertEqual(res, True)
AssertionError: False != True

======================================================================
FAIL: test_generate_split_sentences_pattern_2 (ClassEval_72_0.RegexUtilsTestGenerateSplitSentencesPattern)
----------------------------------------------------------------------
Traceback (most recent call last):
  File "C:\Users\tanuj\Desktop\CS540\repo\CS540\classeval_evaluation\ClassEval_72_0.py", line 272, in test_generate_split_sentences_pattern_2
    self.assertEqual(res, True)
AssertionError: False != True

----------------------------------------------------------------------
Ran 5 tests in 0.008s

FAILED (failures=2)
.....
----------------------------------------------------------------------
Ran 5 tests in 0.000s

OK
.....
----------------------------------------------------------------------
Ran 5 tests in 0.000s

OK
.....
----------------------------------------------------------------------
Ran 5 tests in 0.000s

OK
F
======================================================================
FAIL: test_regexutils (ClassEval_72_0.RegexUtilsTest)
----------------------------------------------------------------------
Traceback (most recent call last):
  File "C:\Users\tanuj\Desktop\CS540\repo\CS540\classeval_evaluation\ClassEval_72_0.py", line 400, in test_regexutils
    self.assertEqual(res, True)
AssertionError: False != True

----------------------------------------------------------------------
Ran 1 test in 0.000s

FAILED (failures=1)
.....
----------------------------------------------------------------------
Ran 5 tests in 0.000s

OK
FF...
======================================================================
FAIL: test_heal_1 (ClassEval_73_0.RPGCharacterTestHeal)
----------------------------------------------------------------------
Traceback (most recent call last):
  File "C:\Users\tanuj\Desktop\CS540\repo\CS540\classeval_evaluation\ClassEval_73_0.py", line 126, in test_heal_1
    self.assertEqual(character.hp, 100)
AssertionError: 90 != 100

======================================================================
FAIL: test_heal_2 (ClassEval_73_0.RPGCharacterTestHeal)
----------------------------------------------------------------------
Traceback (most recent call last):
  File "C:\Users\tanuj\Desktop\CS540\repo\CS540\classeval_evaluation\ClassEval_73_0.py", line 132, in test_heal_2
    self.assertEqual(character.hp, 100)
AssertionError: 97 != 100

----------------------------------------------------------------------
Ran 5 tests in 0.001s

FAILED (failures=2)
.....
----------------------------------------------------------------------
Ran 5 tests in 0.000s

OK
.....
----------------------------------------------------------------------
Ran 5 tests in 0.000s

OK
.....
----------------------------------------------------------------------
Ran 5 tests in 0.000s

OK
.
----------------------------------------------------------------------
Ran 1 test in 0.000s

OK
.....
----------------------------------------------------------------------
Ran 5 tests in 0.000s

OK
.....
----------------------------------------------------------------------
Ran 5 tests in 0.000s

OK
..FFF
======================================================================
FAIL: test_recv_3 (ClassEval_74_0.ServerTestRecv)
----------------------------------------------------------------------
Traceback (most recent call last):
  File "C:\Users\tanuj\Desktop\CS540\repo\CS540\classeval_evaluation\ClassEval_74_0.py", line 184, in test_recv_3
    self.assertEqual(flag, -1)
AssertionError: False != -1

======================================================================
FAIL: test_recv_4 (ClassEval_74_0.ServerTestRecv)
----------------------------------------------------------------------
Traceback (most recent call last):
  File "C:\Users\tanuj\Desktop\CS540\repo\CS540\classeval_evaluation\ClassEval_74_0.py", line 190, in test_recv_4
    self.assertEqual(flag, -1)
AssertionError: False != -1

======================================================================
FAIL: test_recv_5 (ClassEval_74_0.ServerTestRecv)
----------------------------------------------------------------------
Traceback (most recent call last):
  File "C:\Users\tanuj\Desktop\CS540\repo\CS540\classeval_evaluation\ClassEval_74_0.py", line 196, in test_recv_5
    self.assertEqual(flag, -1)
AssertionError: False != -1

----------------------------------------------------------------------
Ran 5 tests in 0.001s

FAILED (failures=3)
.FFF.
======================================================================
FAIL: test_send_2 (ClassEval_74_0.ServerTestSend)
----------------------------------------------------------------------
Traceback (most recent call last):
  File "C:\Users\tanuj\Desktop\CS540\repo\CS540\classeval_evaluation\ClassEval_74_0.py", line 208, in test_send_2
    self.assertEqual(flag, "info structure is not correct")
AssertionError: "Error: info must contain 'addr' and 'content'" != 'info structure is not correct'
- Error: info must contain 'addr' and 'content'
+ info structure is not correct


======================================================================
FAIL: test_send_3 (ClassEval_74_0.ServerTestSend)
----------------------------------------------------------------------
Traceback (most recent call last):
  File "C:\Users\tanuj\Desktop\CS540\repo\CS540\classeval_evaluation\ClassEval_74_0.py", line 213, in test_send_3
    self.assertEqual(flag, "info structure is not correct")
AssertionError: "Error: info must contain 'addr' and 'content'" != 'info structure is not correct'
- Error: info must contain 'addr' and 'content'
+ info structure is not correct


======================================================================
FAIL: test_send_4 (ClassEval_74_0.ServerTestSend)
----------------------------------------------------------------------
Traceback (most recent call last):
  File "C:\Users\tanuj\Desktop\CS540\repo\CS540\classeval_evaluation\ClassEval_74_0.py", line 218, in test_send_4
    self.assertEqual(flag, "info structure is not correct")
AssertionError: 'Error: info must be a dict' != 'info structure is not correct'
- Error: info must be a dict
+ info structure is not correct


----------------------------------------------------------------------
Ran 5 tests in 0.002s

FAILED (failures=3)
.....
----------------------------------------------------------------------
Ran 5 tests in 0.000s

OK
.
----------------------------------------------------------------------
Ran 1 test in 0.000s

OK
.....F
======================================================================
FAIL: test_add_item_6 (ClassEval_75_0.ShoppingCartTestAddItem)
----------------------------------------------------------------------
Traceback (most recent call last):
  File "C:\Users\tanuj\Desktop\CS540\repo\CS540\classeval_evaluation\ClassEval_75_0.py", line 95, in test_add_item_6
    self.assertEqual(shoppingcart.items, {"apple": {"price": 1, "quantity": 5}})
AssertionError: {'apple': {'price': 1, 'quantity': 10}} != {'apple': {'price': 1, 'quantity': 5}}
- {'apple': {'price': 1, 'quantity': 10}}
?                                    ^^

+ {'apple': {'price': 1, 'quantity': 5}}
?                                    ^


----------------------------------------------------------------------
Ran 6 tests in 0.001s

FAILED (failures=1)
......
----------------------------------------------------------------------
Ran 6 tests in 0.000s

OK
.....
----------------------------------------------------------------------
Ran 5 tests in 0.000s

OK
.....
----------------------------------------------------------------------
Ran 5 tests in 0.001s

OK
.
----------------------------------------------------------------------
Ran 1 test in 0.000s

OK
.....
----------------------------------------------------------------------
Ran 5 tests in 0.000s

OK
.....
----------------------------------------------------------------------
Ran 5 tests in 0.000s

OK
.....
----------------------------------------------------------------------
Ran 5 tests in 0.000s

OK
.....
----------------------------------------------------------------------
Ran 5 tests in 0.000s

OK
.....
----------------------------------------------------------------------
Ran 5 tests in 0.000s

OK
.
----------------------------------------------------------------------
Ran 1 test in 0.000s

OK
.....
----------------------------------------------------------------------
Ran 5 tests in 0.001s

OK
.....
----------------------------------------------------------------------
Ran 5 tests in 0.000s

OK
.....
----------------------------------------------------------------------
Ran 5 tests in 0.000s

OK
.....
----------------------------------------------------------------------
Ran 5 tests in 0.002s

OK
.
----------------------------------------------------------------------
Ran 1 test in 0.000s

OK
.....
----------------------------------------------------------------------
Ran 5 tests in 0.000s

OK
.....
----------------------------------------------------------------------
Ran 5 tests in 0.000s

OK
.....
----------------------------------------------------------------------
Ran 5 tests in 0.000s

OK
.
----------------------------------------------------------------------
Ran 1 test in 0.000s

OK
......
----------------------------------------------------------------------
Ran 6 tests in 0.000s

OK
.....
----------------------------------------------------------------------
Ran 5 tests in 0.000s

OK
.....
----------------------------------------------------------------------
Ran 5 tests in 0.000s

OK
.....
----------------------------------------------------------------------
Ran 5 tests in 0.000s

OK
.....
----------------------------------------------------------------------
Ran 5 tests in 0.000s

OK
.....
----------------------------------------------------------------------
Ran 5 tests in 0.000s

OK
.
----------------------------------------------------------------------
Ran 1 test in 0.000s

OK
.......
----------------------------------------------------------------------
Ran 7 tests in 0.000s

OK
.....
----------------------------------------------------------------------
Ran 5 tests in 0.001s

OK
......
----------------------------------------------------------------------
Ran 6 tests in 0.000s

OK
......
----------------------------------------------------------------------
Ran 6 tests in 0.000s

OK
.
----------------------------------------------------------------------
Ran 1 test in 0.000s

OK
.....
----------------------------------------------------------------------
Ran 5 tests in 0.000s

OK
.....
----------------------------------------------------------------------
Ran 5 tests in 0.000s

OK
...EE
======================================================================
ERROR: test_correlation_4 (ClassEval_81_0.Statistics3TestCorrelation)
----------------------------------------------------------------------
Traceback (most recent call last):
  File "C:\Users\tanuj\Desktop\CS540\repo\CS540\classeval_evaluation\ClassEval_81_0.py", line 214, in test_correlation_4
    self.assertEqual(statistics3.correlation([1, 1,1], [2,2,2]), None)
  File "C:\Users\tanuj\Desktop\CS540\repo\CS540\classeval_evaluation\ClassEval_81_0.py", line 104, in correlation
    raise ValueError("division by zero in correlation calculation")
ValueError: division by zero in correlation calculation

======================================================================
ERROR: test_correlation_5 (ClassEval_81_0.Statistics3TestCorrelation)
----------------------------------------------------------------------
Traceback (most recent call last):
  File "C:\Users\tanuj\Desktop\CS540\repo\CS540\classeval_evaluation\ClassEval_81_0.py", line 218, in test_correlation_5
    self.assertEqual(statistics3.correlation([1, 1,1], [1,1,1]), None)
  File "C:\Users\tanuj\Desktop\CS540\repo\CS540\classeval_evaluation\ClassEval_81_0.py", line 104, in correlation
    raise ValueError("division by zero in correlation calculation")
ValueError: division by zero in correlation calculation

----------------------------------------------------------------------
Ran 5 tests in 0.001s

FAILED (errors=2)
.E...
======================================================================
ERROR: test_mean_2 (ClassEval_81_0.Statistics3TestMean)
----------------------------------------------------------------------
Traceback (most recent call last):
  File "C:\Users\tanuj\Desktop\CS540\repo\CS540\classeval_evaluation\ClassEval_81_0.py", line 227, in test_mean_2
    self.assertEqual(statistics3.mean([]), None)
  File "C:\Users\tanuj\Desktop\CS540\repo\CS540\classeval_evaluation\ClassEval_81_0.py", line 60, in mean
    raise ValueError("mean requires at least one data point")
ValueError: mean requires at least one data point

----------------------------------------------------------------------
Ran 5 tests in 0.000s

FAILED (errors=1)
.FFFF
======================================================================
FAIL: test_correlation_matrix_2 (ClassEval_81_0.Statistics3TestCorrelationMatrix)
----------------------------------------------------------------------
Traceback (most recent call last):
  File "C:\Users\tanuj\Desktop\CS540\repo\CS540\classeval_evaluation\ClassEval_81_0.py", line 248, in test_correlation_matrix_2
    self.assertEqual(statistics3.correlation_matrix([[1, 2, 3], [4, 5, 6]]), [[1.0, 1.0, 1.0], [1.0, 1.0, 1.0], [1.0, 1.0, 1.0]])
AssertionError: Lists differ: [[1.0, 1.0], [1.0, 1.0]] != [[1.0, 1.0, 1.0], [1.0, 1.0, 1.0], [1.0, 1.0, 1.0]]

First differing element 0:
[1.0, 1.0]
[1.0, 1.0, 1.0]

Second list contains 1 additional elements.
First extra element 2:
[1.0, 1.0, 1.0]

- [[1.0, 1.0], [1.0, 1.0]]
+ [[1.0, 1.0, 1.0], [1.0, 1.0, 1.0], [1.0, 1.0, 1.0]]

======================================================================
FAIL: test_correlation_matrix_3 (ClassEval_81_0.Statistics3TestCorrelationMatrix)
----------------------------------------------------------------------
Traceback (most recent call last):
  File "C:\Users\tanuj\Desktop\CS540\repo\CS540\classeval_evaluation\ClassEval_81_0.py", line 252, in test_correlation_matrix_3
    self.assertEqual(statistics3.correlation_matrix([[1, 2, 3]]), [[None, None, None], [None, None, None], [None, None, None]])
AssertionError: Lists differ: [[1.0]] != [[None, None, None], [None, None, None], [None, None, None]]

First differing element 0:
[1.0]
[None, None, None]

Second list contains 2 additional elements.
First extra element 1:
[None, None, None]

- [[1.0]]
+ [[None, None, None], [None, None, None], [None, None, None]]

======================================================================
FAIL: test_correlation_matrix_4 (ClassEval_81_0.Statistics3TestCorrelationMatrix)
----------------------------------------------------------------------
Traceback (most recent call last):
  File "C:\Users\tanuj\Desktop\CS540\repo\CS540\classeval_evaluation\ClassEval_81_0.py", line 256, in test_correlation_matrix_4
    self.assertEqual(statistics3.correlation_matrix([[1, 2, 3], [4, 5, 6], [7, 8, 9], [10, 11,12]]), [[1.0, 1.0, 1.0], [1.0, 1.0, 1.0], [1.0, 1.0, 1.0]])
AssertionError: Lists differ: [[1.0, 1.0, 1.0, 1.0], [1.0, 1.0, 1.0, 1.0], [1.0, 1.0, [27 chars]1.0]] != [[1.0, 1.0, 1.0], [1.0, 1.0, 1.0], [1.0, 1.0, 1.0]]

First differing element 0:
[1.0, 1.0, 1.0, 1.0]
[1.0, 1.0, 1.0]

First list contains 1 additional elements.
First extra element 3:
[1.0, 1.0, 1.0, 1.0]

+ [[1.0, 1.0, 1.0], [1.0, 1.0, 1.0], [1.0, 1.0, 1.0]]
- [[1.0, 1.0, 1.0, 1.0],
-  [1.0, 1.0, 1.0, 1.0],
-  [1.0, 1.0, 1.0, 1.0],
-  [1.0, 1.0, 1.0, 1.0]]

======================================================================
FAIL: test_correlation_matrix_5 (ClassEval_81_0.Statistics3TestCorrelationMatrix)
----------------------------------------------------------------------
Traceback (most recent call last):
  File "C:\Users\tanuj\Desktop\CS540\repo\CS540\classeval_evaluation\ClassEval_81_0.py", line 260, in test_correlation_matrix_5
    self.assertEqual(statistics3.correlation_matrix([[1, 2, 3], [4, 5, 6], [7, 8, 9], [10, 11,12], [13, 14, 15]]), [[1.0, 1.0, 1.0], [1.0, 1.0, 1.0], [1.0, 1.0, 1.0]])
AssertionError: Lists differ: [[1.0, 1.0, 1.0, 1.0, 1.0], [1.0, 1.0, 1.0, 1.0, 1.0], [[74 chars]1.0]] != [[1.0, 1.0, 1.0], [1.0, 1.0, 1.0], [1.0, 1.0, 1.0]]

First differing element 0:
[1.0, 1.0, 1.0, 1.0, 1.0]
[1.0, 1.0, 1.0]

First list contains 2 additional elements.
First extra element 3:
[1.0, 1.0, 1.0, 1.0, 1.0]

+ [[1.0, 1.0, 1.0], [1.0, 1.0, 1.0], [1.0, 1.0, 1.0]]
- [[1.0, 1.0, 1.0, 1.0, 1.0],
-  [1.0, 1.0, 1.0, 1.0, 1.0],
-  [1.0, 1.0, 1.0, 1.0, 1.0],
-  [1.0, 1.0, 1.0, 1.0, 1.0],
-  [1.0, 1.0, 1.0, 1.0, 1.0]]

----------------------------------------------------------------------
Ran 5 tests in 0.001s

FAILED (failures=4)
.....
----------------------------------------------------------------------
Ran 5 tests in 0.000s

OK
.EE.E
======================================================================
ERROR: test_z_score_2 (ClassEval_81_0.Statistics3TestZScore)
----------------------------------------------------------------------
Traceback (most recent call last):
  File "C:\Users\tanuj\Desktop\CS540\repo\CS540\classeval_evaluation\ClassEval_81_0.py", line 291, in test_z_score_2
    self.assertEqual(statistics3.z_score([1, 1, 1, 1]), None)
  File "C:\Users\tanuj\Desktop\CS540\repo\CS540\classeval_evaluation\ClassEval_81_0.py", line 152, in z_score
    raise ValueError("standard deviation is zero, z-score undefined")
ValueError: standard deviation is zero, z-score undefined

======================================================================
ERROR: test_z_score_3 (ClassEval_81_0.Statistics3TestZScore)
----------------------------------------------------------------------
Traceback (most recent call last):
  File "C:\Users\tanuj\Desktop\CS540\repo\CS540\classeval_evaluation\ClassEval_81_0.py", line 295, in test_z_score_3
    self.assertEqual(statistics3.z_score([1]),None)
  File "C:\Users\tanuj\Desktop\CS540\repo\CS540\classeval_evaluation\ClassEval_81_0.py", line 148, in z_score
    raise ValueError("z-score requires at least two data points")
ValueError: z-score requires at least two data points

======================================================================
ERROR: test_z_score_5 (ClassEval_81_0.Statistics3TestZScore)
----------------------------------------------------------------------
Traceback (most recent call last):
  File "C:\Users\tanuj\Desktop\CS540\repo\CS540\classeval_evaluation\ClassEval_81_0.py", line 303, in test_z_score_5
    self.assertEqual(statistics3.z_score([1, 1, 1, 1, 1]), None)
  File "C:\Users\tanuj\Desktop\CS540\repo\CS540\classeval_evaluation\ClassEval_81_0.py", line 152, in z_score
    raise ValueError("standard deviation is zero, z-score undefined")
ValueError: standard deviation is zero, z-score undefined

----------------------------------------------------------------------
Ran 5 tests in 0.001s

FAILED (errors=3)
.
----------------------------------------------------------------------
Ran 1 test in 0.000s

OK
.F.FF
======================================================================
FAIL: test_add_stock_2 (ClassEval_82_0.StockPortfolioTrackerTestAddStock)
----------------------------------------------------------------------
Traceback (most recent call last):
  File "C:\Users\tanuj\Desktop\CS540\repo\CS540\classeval_evaluation\ClassEval_82_0.py", line 137, in test_add_stock_2
    self.assertEqual(tracker.portfolio, [{'name': 'AAPL', 'price': 150.0, 'quantity': 20}])
AssertionError: Lists differ: [{'na[32 chars]antity': 10}, {'name': 'AAPL', 'price': 150.0, 'quantity': 10}] != [{'na[32 chars]antity': 20}]

First differing element 0:
{'name': 'AAPL', 'price': 150.0, 'quantity': 10}
{'name': 'AAPL', 'price': 150.0, 'quantity': 20}

First list contains 1 additional elements.
First extra element 1:
{'name': 'AAPL', 'price': 150.0, 'quantity': 10}

- [{'name': 'AAPL', 'price': 150.0, 'quantity': 10},
?                                               ^  ^

+ [{'name': 'AAPL', 'price': 150.0, 'quantity': 20}]
?                                               ^  ^

-  {'name': 'AAPL', 'price': 150.0, 'quantity': 10}]

======================================================================
FAIL: test_add_stock_4 (ClassEval_82_0.StockPortfolioTrackerTestAddStock)
----------------------------------------------------------------------
Traceback (most recent call last):
  File "C:\Users\tanuj\Desktop\CS540\repo\CS540\classeval_evaluation\ClassEval_82_0.py", line 151, in test_add_stock_4
    self.assertEqual(tracker.portfolio, [{'name': 'AAPL', 'price': 150.0, 'quantity': 20},
AssertionError: Lists differ: [{'na[36 chars]ty': 10}, {'name': 'AAPL', 'price': 150.0, 'qu[58 chars] 10}] != [{'na[36 chars]ty': 20}, {'name': 'MSFT', 'price': 150.0, 'quantity': 10}]

First differing element 0:
{'name': 'AAPL', 'price': 150.0, 'quantity': 10}
{'name': 'AAPL', 'price': 150.0, 'quantity': 20}

First list contains 1 additional elements.
First extra element 2:
{'name': 'MSFT', 'price': 150.0, 'quantity': 10}

- [{'name': 'AAPL', 'price': 150.0, 'quantity': 10},
?                                               ^

+ [{'name': 'AAPL', 'price': 150.0, 'quantity': 20},
?                                               ^

-  {'name': 'AAPL', 'price': 150.0, 'quantity': 10},
   {'name': 'MSFT', 'price': 150.0, 'quantity': 10}]

======================================================================
FAIL: test_add_stock_5 (ClassEval_82_0.StockPortfolioTrackerTestAddStock)
----------------------------------------------------------------------
Traceback (most recent call last):
  File "C:\Users\tanuj\Desktop\CS540\repo\CS540\classeval_evaluation\ClassEval_82_0.py", line 160, in test_add_stock_5
    self.assertEqual(tracker.portfolio, [{'name': 'AAPL', 'price': 150.0, 'quantity': 20},
AssertionError: Lists differ: [{'na[36 chars]ty': 10}, {'name': 'AAPL', 'price': 150.0, 'qu[108 chars] 10}] != [{'na[36 chars]ty': 20}, {'name': 'MSFT', 'price': 150.0, 'quantity': 20}]

First differing element 0:
{'name': 'AAPL', 'price': 150.0, 'quantity': 10}
{'name': 'AAPL', 'price': 150.0, 'quantity': 20}

First list contains 2 additional elements.
First extra element 2:
{'name': 'MSFT', 'price': 150.0, 'quantity': 10}

- [{'name': 'AAPL', 'price': 150.0, 'quantity': 10},
?                                               ^

+ [{'name': 'AAPL', 'price': 150.0, 'quantity': 20},
?                                               ^

-  {'name': 'AAPL', 'price': 150.0, 'quantity': 10},
-  {'name': 'MSFT', 'price': 150.0, 'quantity': 10},
-  {'name': 'MSFT', 'price': 150.0, 'quantity': 10}]
?                                               ^

+  {'name': 'MSFT', 'price': 150.0, 'quantity': 20}]
?                                               ^


----------------------------------------------------------------------
Ran 5 tests in 0.004s

FAILED (failures=3)
.....
----------------------------------------------------------------------
Ran 5 tests in 0.000s

OK
.....
----------------------------------------------------------------------
Ran 5 tests in 0.001s

OK
.....
----------------------------------------------------------------------
Ran 5 tests in 0.000s

OK
.....
----------------------------------------------------------------------
Ran 5 tests in 0.001s

OK
.....
----------------------------------------------------------------------
Ran 5 tests in 0.000s

OK
.....
----------------------------------------------------------------------
Ran 5 tests in 0.000s

OK
...
----------------------------------------------------------------------
Ran 3 tests in 0.001s

OK
.....
----------------------------------------------------------------------
Ran 5 tests in 0.155s

OK
.....
----------------------------------------------------------------------
Ran 5 tests in 0.120s

OK
.....
----------------------------------------------------------------------
Ran 5 tests in 0.194s

OK
.
----------------------------------------------------------------------
Ran 1 test in 0.062s

OK
.....
----------------------------------------------------------------------
Ran 5 tests in 0.013s

OK
.....
----------------------------------------------------------------------
Ran 5 tests in 0.010s

OK
.....
----------------------------------------------------------------------
Ran 5 tests in 0.008s

OK
FFFFF
======================================================================
FAIL: test_process_file_1 (ClassEval_84_0.TextFileProcessorTestProcessFile)
----------------------------------------------------------------------
Traceback (most recent call last):
  File "C:\Users\tanuj\Desktop\CS540\repo\CS540\classeval_evaluation\ClassEval_84_0.py", line 212, in test_process_file_1
    textFileProcessor.write_file.assert_called_once_with(self.expected_result)
  File "C:\Users\tanuj\AppData\Local\Programs\Python\Python310\lib\unittest\mock.py", line 930, in assert_called_once_with
    raise AssertionError(msg)
AssertionError: Expected 'mock' to be called once. Called 0 times.

======================================================================
FAIL: test_process_file_2 (ClassEval_84_0.TextFileProcessorTestProcessFile)
----------------------------------------------------------------------
Traceback (most recent call last):
  File "C:\Users\tanuj\Desktop\CS540\repo\CS540\classeval_evaluation\ClassEval_84_0.py", line 226, in test_process_file_2
    textFileProcessor.write_file.assert_called_once_with(self.expected_result)
  File "C:\Users\tanuj\AppData\Local\Programs\Python\Python310\lib\unittest\mock.py", line 930, in assert_called_once_with
    raise AssertionError(msg)
AssertionError: Expected 'mock' to be called once. Called 0 times.

======================================================================
FAIL: test_process_file_3 (ClassEval_84_0.TextFileProcessorTestProcessFile)
----------------------------------------------------------------------
Traceback (most recent call last):
  File "C:\Users\tanuj\Desktop\CS540\repo\CS540\classeval_evaluation\ClassEval_84_0.py", line 240, in test_process_file_3
    textFileProcessor.write_file.assert_called_once_with(self.expected_result)
  File "C:\Users\tanuj\AppData\Local\Programs\Python\Python310\lib\unittest\mock.py", line 930, in assert_called_once_with
    raise AssertionError(msg)
AssertionError: Expected 'mock' to be called once. Called 0 times.

======================================================================
FAIL: test_process_file_4 (ClassEval_84_0.TextFileProcessorTestProcessFile)
----------------------------------------------------------------------
Traceback (most recent call last):
  File "C:\Users\tanuj\Desktop\CS540\repo\CS540\classeval_evaluation\ClassEval_84_0.py", line 254, in test_process_file_4
    textFileProcessor.write_file.assert_called_once_with(self.expected_result)
  File "C:\Users\tanuj\AppData\Local\Programs\Python\Python310\lib\unittest\mock.py", line 930, in assert_called_once_with
    raise AssertionError(msg)
AssertionError: Expected 'mock' to be called once. Called 0 times.

======================================================================
FAIL: test_process_file_5 (ClassEval_84_0.TextFileProcessorTestProcessFile)
----------------------------------------------------------------------
Traceback (most recent call last):
  File "C:\Users\tanuj\Desktop\CS540\repo\CS540\classeval_evaluation\ClassEval_84_0.py", line 268, in test_process_file_5
    textFileProcessor.write_file.assert_called_once_with(self.expected_result)
  File "C:\Users\tanuj\AppData\Local\Programs\Python\Python310\lib\unittest\mock.py", line 930, in assert_called_once_with
    raise AssertionError(msg)
AssertionError: Expected 'mock' to be called once. Called 0 times.

----------------------------------------------------------------------
Ran 5 tests in 0.011s

FAILED (failures=5)
.
----------------------------------------------------------------------
Ran 1 test in 0.006s

OK
..E..
======================================================================
ERROR: test_get_target_temperature_3 (ClassEval_85_0.ThermostatTestGetTargetTemperature)
----------------------------------------------------------------------
Traceback (most recent call last):
  File "C:\Users\tanuj\Desktop\CS540\repo\CS540\classeval_evaluation\ClassEval_85_0.py", line 141, in test_get_target_temperature_3
    t = Thermostat(20, 25, 'test')
  File "C:\Users\tanuj\Desktop\CS540\repo\CS540\classeval_evaluation\ClassEval_85_0.py", line 24, in __init__
    self.set_mode(mode)
  File "C:\Users\tanuj\Desktop\CS540\repo\CS540\classeval_evaluation\ClassEval_85_0.py", line 64, in set_mode
    raise ValueError(f"Invalid mode '{mode}', must be one of {self.VALID_MODES}")
ValueError: Invalid mode 'test', must be one of ('heat', 'cool')

----------------------------------------------------------------------
Ran 5 tests in 0.001s

FAILED (errors=1)
..E..
======================================================================
ERROR: test_set_target_temperature_3 (ClassEval_85_0.ThermostatTestSetTargetTemperature)
----------------------------------------------------------------------
Traceback (most recent call last):
  File "C:\Users\tanuj\Desktop\CS540\repo\CS540\classeval_evaluation\ClassEval_85_0.py", line 165, in test_set_target_temperature_3
    t = Thermostat(20, 25, 'test')
  File "C:\Users\tanuj\Desktop\CS540\repo\CS540\classeval_evaluation\ClassEval_85_0.py", line 24, in __init__
    self.set_mode(mode)
  File "C:\Users\tanuj\Desktop\CS540\repo\CS540\classeval_evaluation\ClassEval_85_0.py", line 64, in set_mode
    raise ValueError(f"Invalid mode '{mode}', must be one of {self.VALID_MODES}")
ValueError: Invalid mode 'test', must be one of ('heat', 'cool')

----------------------------------------------------------------------
Ran 5 tests in 0.000s

FAILED (errors=1)
..E..
======================================================================
ERROR: test_get_mode_3 (ClassEval_85_0.ThermostatTestGetMode)
----------------------------------------------------------------------
Traceback (most recent call last):
  File "C:\Users\tanuj\Desktop\CS540\repo\CS540\classeval_evaluation\ClassEval_85_0.py", line 190, in test_get_mode_3
    t = Thermostat(20, 25, 'test')
  File "C:\Users\tanuj\Desktop\CS540\repo\CS540\classeval_evaluation\ClassEval_85_0.py", line 24, in __init__
    self.set_mode(mode)
  File "C:\Users\tanuj\Desktop\CS540\repo\CS540\classeval_evaluation\ClassEval_85_0.py", line 64, in set_mode
    raise ValueError(f"Invalid mode '{mode}', must be one of {self.VALID_MODES}")
ValueError: Invalid mode 'test', must be one of ('heat', 'cool')

----------------------------------------------------------------------
Ran 5 tests in 0.000s

FAILED (errors=1)
.E.E.
======================================================================
ERROR: test_set_mode_2 (ClassEval_85_0.ThermostatTestSetMode)
----------------------------------------------------------------------
Traceback (most recent call last):
  File "C:\Users\tanuj\Desktop\CS540\repo\CS540\classeval_evaluation\ClassEval_85_0.py", line 211, in test_set_mode_2
    self.assertFalse(t.set_mode('test'))
  File "C:\Users\tanuj\Desktop\CS540\repo\CS540\classeval_evaluation\ClassEval_85_0.py", line 64, in set_mode
    raise ValueError(f"Invalid mode '{mode}', must be one of {self.VALID_MODES}")
ValueError: Invalid mode 'test', must be one of ('heat', 'cool')

======================================================================
ERROR: test_set_mode_4 (ClassEval_85_0.ThermostatTestSetMode)
----------------------------------------------------------------------
Traceback (most recent call last):
  File "C:\Users\tanuj\Desktop\CS540\repo\CS540\classeval_evaluation\ClassEval_85_0.py", line 219, in test_set_mode_4
    t = Thermostat(20, 25, 'test')
  File "C:\Users\tanuj\Desktop\CS540\repo\CS540\classeval_evaluation\ClassEval_85_0.py", line 24, in __init__
    self.set_mode(mode)
  File "C:\Users\tanuj\Desktop\CS540\repo\CS540\classeval_evaluation\ClassEval_85_0.py", line 64, in set_mode
    raise ValueError(f"Invalid mode '{mode}', must be one of {self.VALID_MODES}")
ValueError: Invalid mode 'test', must be one of ('heat', 'cool')

----------------------------------------------------------------------
Ran 5 tests in 0.001s

FAILED (errors=2)
.....
----------------------------------------------------------------------
Ran 5 tests in 0.000s

OK
....F
======================================================================
FAIL: test_auto_check_conflict_5 (ClassEval_85_0.ThermostatTestAutoCheckConflict)
----------------------------------------------------------------------
Traceback (most recent call last):
  File "C:\Users\tanuj\Desktop\CS540\repo\CS540\classeval_evaluation\ClassEval_85_0.py", line 276, in test_auto_check_conflict_5
    self.assertFalse(t.auto_check_conflict())
AssertionError: True is not false

----------------------------------------------------------------------
Ran 5 tests in 0.000s

FAILED (failures=1)
....E
======================================================================
ERROR: test_simulate_operation_5 (ClassEval_85_0.ThermostatTestSimulateOperation)
----------------------------------------------------------------------
Traceback (most recent call last):
  File "C:\Users\tanuj\Desktop\CS540\repo\CS540\classeval_evaluation\ClassEval_85_0.py", line 306, in test_simulate_operation_5
    t = Thermostat(25, 25, 'test')
  File "C:\Users\tanuj\Desktop\CS540\repo\CS540\classeval_evaluation\ClassEval_85_0.py", line 24, in __init__
    self.set_mode(mode)
  File "C:\Users\tanuj\Desktop\CS540\repo\CS540\classeval_evaluation\ClassEval_85_0.py", line 64, in set_mode
    raise ValueError(f"Invalid mode '{mode}', must be one of {self.VALID_MODES}")
ValueError: Invalid mode 'test', must be one of ('heat', 'cool')

----------------------------------------------------------------------
Ran 5 tests in 0.000s

FAILED (errors=1)
E
======================================================================
ERROR: test_main (ClassEval_85_0.ThermostatTestMain)
----------------------------------------------------------------------
Traceback (most recent call last):
  File "C:\Users\tanuj\Desktop\CS540\repo\CS540\classeval_evaluation\ClassEval_85_0.py", line 320, in test_main
    self.assertFalse(t.set_mode('test'))
  File "C:\Users\tanuj\Desktop\CS540\repo\CS540\classeval_evaluation\ClassEval_85_0.py", line 64, in set_mode
    raise ValueError(f"Invalid mode '{mode}', must be one of {self.VALID_MODES}")
ValueError: Invalid mode 'test', must be one of ('heat', 'cool')

----------------------------------------------------------------------
Ran 1 test in 0.001s

FAILED (errors=1)
.....
----------------------------------------------------------------------
Ran 5 tests in 0.000s

OK
.....
----------------------------------------------------------------------
Ran 5 tests in 0.000s

OK
.....
----------------------------------------------------------------------
Ran 5 tests in 0.000s

OK
.
----------------------------------------------------------------------
Ran 1 test in 0.000s

OK
.....
----------------------------------------------------------------------
Ran 5 tests in 0.001s

OK
.....
----------------------------------------------------------------------
Ran 5 tests in 0.000s

OK
.....
----------------------------------------------------------------------
Ran 5 tests in 0.000s

OK
.....
----------------------------------------------------------------------
Ran 5 tests in 0.001s

OK
.....
----------------------------------------------------------------------
Ran 5 tests in 0.000s

OK
.....
----------------------------------------------------------------------
Ran 5 tests in 0.000s

OK
.....
----------------------------------------------------------------------
Ran 5 tests in 0.000s

OK
.
----------------------------------------------------------------------
Ran 1 test in 0.000s

OK
F..F.
======================================================================
FAIL: test_cos_1 (ClassEval_88_0.TriCalculatorTestCos)
----------------------------------------------------------------------
Traceback (most recent call last):
  File "C:\Users\tanuj\Desktop\CS540\repo\CS540\classeval_evaluation\ClassEval_88_0.py", line 115, in test_cos_1
    self.assertEqual(tricalculator.cos(60), 0.5)
AssertionError: 0.49999999999990047 != 0.5

======================================================================
FAIL: test_cos_4 (ClassEval_88_0.TriCalculatorTestCos)
----------------------------------------------------------------------
Traceback (most recent call last):
  File "C:\Users\tanuj\Desktop\CS540\repo\CS540\classeval_evaluation\ClassEval_88_0.py", line 127, in test_cos_4
    self.assertEqual(tricalculator.cos(90), 0.0)
AssertionError: 5.260664662720962e-13 != 0.0

----------------------------------------------------------------------
Ran 5 tests in 0.001s

FAILED (failures=2)
.....
----------------------------------------------------------------------
Ran 5 tests in 0.000s

OK
.....
----------------------------------------------------------------------
Ran 5 tests in 0.002s

OK
F..F.
======================================================================
FAIL: test_sin_1 (ClassEval_88_0.TriCalculatorTestSin)
----------------------------------------------------------------------
Traceback (most recent call last):
  File "C:\Users\tanuj\Desktop\CS540\repo\CS540\classeval_evaluation\ClassEval_88_0.py", line 181, in test_sin_1
    self.assertEqual(tricalculator.sin(30), 0.5)
AssertionError: 0.4999999999999643 != 0.5

======================================================================
FAIL: test_sin_4 (ClassEval_88_0.TriCalculatorTestSin)
----------------------------------------------------------------------
Traceback (most recent call last):
  File "C:\Users\tanuj\Desktop\CS540\repo\CS540\classeval_evaluation\ClassEval_88_0.py", line 193, in test_sin_4
    self.assertEqual(tricalculator.sin(90), 1.0)
AssertionError: 1.0000000000000437 != 1.0

----------------------------------------------------------------------
Ran 5 tests in 0.001s

FAILED (failures=2)
FE...
======================================================================
ERROR: test_tan_2 (ClassEval_88_0.TriCalculatorTestTan)
----------------------------------------------------------------------
Traceback (most recent call last):
  File "C:\Users\tanuj\Desktop\CS540\repo\CS540\classeval_evaluation\ClassEval_88_0.py", line 207, in test_tan_2
    self.assertEqual(tricalculator.tan(90), False)
  File "C:\Users\tanuj\Desktop\CS540\repo\CS540\classeval_evaluation\ClassEval_88_0.py", line 106, in tan
    raise ValueError(f"Tangent undefined for angle {x}")
ValueError: Tangent undefined for angle 90

======================================================================
FAIL: test_tan_1 (ClassEval_88_0.TriCalculatorTestTan)
----------------------------------------------------------------------
Traceback (most recent call last):
  File "C:\Users\tanuj\Desktop\CS540\repo\CS540\classeval_evaluation\ClassEval_88_0.py", line 203, in test_tan_1
    self.assertEqual(tricalculator.tan(45), 1.0)
AssertionError: 0.9999999999994791 != 1.0

----------------------------------------------------------------------
Ran 5 tests in 0.001s

FAILED (failures=1, errors=1)
F
======================================================================
FAIL: test_tricalculator (ClassEval_88_0.TriCalculatorTest)
----------------------------------------------------------------------
Traceback (most recent call last):
  File "C:\Users\tanuj\Desktop\CS540\repo\CS540\classeval_evaluation\ClassEval_88_0.py", line 225, in test_tricalculator
    self.assertEqual(tricalculator.cos(60), 0.5)
AssertionError: 0.49999999999990047 != 0.5

----------------------------------------------------------------------
Ran 1 test in 0.000s

FAILED (failures=1)
.....
----------------------------------------------------------------------
Ran 5 tests in 0.000s

OK
EF.....
======================================================================
ERROR: test_answer_1 (ClassEval_89_0.TwentyFourPointGameTestAnswer)
----------------------------------------------------------------------
Traceback (most recent call last):
  File "C:\Users\tanuj\Desktop\CS540\repo\CS540\classeval_evaluation\ClassEval_89_0.py", line 151, in test_answer_1
    self.assertEqual(len(cards), 4)
TypeError: object of type 'bool' has no len()

======================================================================
FAIL: test_answer_2 (ClassEval_89_0.TwentyFourPointGameTestAnswer)
----------------------------------------------------------------------
Traceback (most recent call last):
  File "C:\Users\tanuj\Desktop\CS540\repo\CS540\classeval_evaluation\ClassEval_89_0.py", line 156, in test_answer_2
    self.assertTrue(result)
AssertionError: False is not true

----------------------------------------------------------------------
Ran 7 tests in 0.003s

FAILED (failures=1, errors=1)
.F...
======================================================================
FAIL: test_evaluate_expression_2 (ClassEval_89_0.TwentyFourPointGameTestEvaluateExpression)
----------------------------------------------------------------------
Traceback (most recent call last):
  File "C:\Users\tanuj\Desktop\CS540\repo\CS540\classeval_evaluation\ClassEval_89_0.py", line 195, in test_evaluate_expression_2
    self.assertTrue(result)
AssertionError: False is not true

----------------------------------------------------------------------
Ran 5 tests in 0.001s

FAILED (failures=1)
F
======================================================================
FAIL: test_TwentyFourPointGame (ClassEval_89_0.TwentyFourPointGameTest)
----------------------------------------------------------------------
Traceback (most recent call last):
  File "C:\Users\tanuj\Desktop\CS540\repo\CS540\classeval_evaluation\ClassEval_89_0.py", line 222, in test_TwentyFourPointGame
    self.assertTrue(result)
AssertionError: False is not true

----------------------------------------------------------------------
Ran 1 test in 0.000s

FAILED (failures=1)
.....F
======================================================================
FAIL: test_get_scheme_6 (ClassEval_90_0.URLHandlerTestGetScheme)
----------------------------------------------------------------------
Traceback (most recent call last):
  File "C:\Users\tanuj\Desktop\CS540\repo\CS540\classeval_evaluation\ClassEval_90_0.py", line 88, in test_get_scheme_6
    self.assertIsNone(temp)
AssertionError: '' is not None

----------------------------------------------------------------------
Ran 6 tests in 0.002s

FAILED (failures=1)
.....F..
======================================================================
FAIL: test_get_host_6 (ClassEval_90_0.URLHandlerTestGetHost)
----------------------------------------------------------------------
Traceback (most recent call last):
  File "C:\Users\tanuj\Desktop\CS540\repo\CS540\classeval_evaluation\ClassEval_90_0.py", line 121, in test_get_host_6
    self.assertIsNone(temp)
AssertionError: '' is not None

----------------------------------------------------------------------
Ran 8 tests in 0.001s

FAILED (failures=1)
.....F
======================================================================
FAIL: test_get_path_6 (ClassEval_90_0.URLHandlerTestGetPath)
----------------------------------------------------------------------
Traceback (most recent call last):
  File "C:\Users\tanuj\Desktop\CS540\repo\CS540\classeval_evaluation\ClassEval_90_0.py", line 165, in test_get_path_6
    self.assertIsNone(temp)
AssertionError: 'abcdefg' is not None

----------------------------------------------------------------------
Ran 6 tests in 0.001s

FAILED (failures=1)
..F...
======================================================================
FAIL: test_get_query_params_3 (ClassEval_90_0.URLHandlerTestGetQueryParams)
----------------------------------------------------------------------
Traceback (most recent call last):
  File "C:\Users\tanuj\Desktop\CS540\repo\CS540\classeval_evaluation\ClassEval_90_0.py", line 184, in test_get_query_params_3
    self.assertEqual(temp, None)
AssertionError: {} != None

----------------------------------------------------------------------
Ran 6 tests in 0.001s

FAILED (failures=1)
.F...
======================================================================
FAIL: test_get_fragment_2 (ClassEval_90_0.URLHandlerTestGetFragment)
----------------------------------------------------------------------
Traceback (most recent call last):
  File "C:\Users\tanuj\Desktop\CS540\repo\CS540\classeval_evaluation\ClassEval_90_0.py", line 212, in test_get_fragment_2
    self.assertEqual(temp, None)
AssertionError: '' != None

----------------------------------------------------------------------
Ran 5 tests in 0.001s

FAILED (failures=1)
.
----------------------------------------------------------------------
Ran 1 test in 0.000s

OK
.....
----------------------------------------------------------------------
Ran 5 tests in 0.000s

OK
.......
----------------------------------------------------------------------
Ran 7 tests in 0.000s

OK
......
----------------------------------------------------------------------
Ran 6 tests in 0.000s

OK
.
----------------------------------------------------------------------
Ran 1 test in 0.000s

OK
FFFFF
======================================================================
FAIL: test_insert_user_1 (ClassEval_92_0.UserLoginDBTestInsertUser)
----------------------------------------------------------------------
Traceback (most recent call last):
  File "C:\Users\tanuj\Desktop\CS540\repo\CS540\classeval_evaluation\ClassEval_92_0.py", line 115, in test_insert_user_1
    self.assertEqual(user[0], 'user1')
AssertionError: ('user1', 'pass1') != 'user1'

======================================================================
FAIL: test_insert_user_2 (ClassEval_92_0.UserLoginDBTestInsertUser)
----------------------------------------------------------------------
Traceback (most recent call last):
  File "C:\Users\tanuj\Desktop\CS540\repo\CS540\classeval_evaluation\ClassEval_92_0.py", line 122, in test_insert_user_2
    self.assertEqual(user[0], 'user2')
AssertionError: ('user2', 'pass2') != 'user2'

======================================================================
FAIL: test_insert_user_3 (ClassEval_92_0.UserLoginDBTestInsertUser)
----------------------------------------------------------------------
Traceback (most recent call last):
  File "C:\Users\tanuj\Desktop\CS540\repo\CS540\classeval_evaluation\ClassEval_92_0.py", line 129, in test_insert_user_3
    self.assertEqual(user[0], 'user3')
AssertionError: ('user3', 'pass3') != 'user3'

======================================================================
FAIL: test_insert_user_4 (ClassEval_92_0.UserLoginDBTestInsertUser)
----------------------------------------------------------------------
Traceback (most recent call last):
  File "C:\Users\tanuj\Desktop\CS540\repo\CS540\classeval_evaluation\ClassEval_92_0.py", line 136, in test_insert_user_4
    self.assertEqual(user[0], 'user4')
AssertionError: ('user4', 'pass4') != 'user4'

======================================================================
FAIL: test_insert_user_5 (ClassEval_92_0.UserLoginDBTestInsertUser)
----------------------------------------------------------------------
Traceback (most recent call last):
  File "C:\Users\tanuj\Desktop\CS540\repo\CS540\classeval_evaluation\ClassEval_92_0.py", line 143, in test_insert_user_5
    self.assertEqual(user[0], 'user5')
AssertionError: ('user5', 'pass5') != 'user5'

----------------------------------------------------------------------
Ran 5 tests in 0.140s

FAILED (failures=5)
FFFFF
======================================================================
FAIL: test_search_user_by_username_1 (ClassEval_92_0.UserLoginDBTestSearchUserByUsername)
----------------------------------------------------------------------
Traceback (most recent call last):
  File "C:\Users\tanuj\Desktop\CS540\repo\CS540\classeval_evaluation\ClassEval_92_0.py", line 172, in test_search_user_by_username_1
    self.assertEqual(user[0], 'user1')
AssertionError: ('user1', 'pass1') != 'user1'

======================================================================
FAIL: test_search_user_by_username_2 (ClassEval_92_0.UserLoginDBTestSearchUserByUsername)
----------------------------------------------------------------------
Traceback (most recent call last):
  File "C:\Users\tanuj\Desktop\CS540\repo\CS540\classeval_evaluation\ClassEval_92_0.py", line 179, in test_search_user_by_username_2
    self.assertEqual(user[0], 'user2')
AssertionError: ('user2', 'pass2') != 'user2'

======================================================================
FAIL: test_search_user_by_username_3 (ClassEval_92_0.UserLoginDBTestSearchUserByUsername)
----------------------------------------------------------------------
Traceback (most recent call last):
  File "C:\Users\tanuj\Desktop\CS540\repo\CS540\classeval_evaluation\ClassEval_92_0.py", line 186, in test_search_user_by_username_3
    self.assertEqual(user[0], 'user3')
AssertionError: ('user3', 'pass3') != 'user3'

======================================================================
FAIL: test_search_user_by_username_4 (ClassEval_92_0.UserLoginDBTestSearchUserByUsername)
----------------------------------------------------------------------
Traceback (most recent call last):
  File "C:\Users\tanuj\Desktop\CS540\repo\CS540\classeval_evaluation\ClassEval_92_0.py", line 193, in test_search_user_by_username_4
    self.assertEqual(user[0], 'user4')
AssertionError: ('user4', 'pass4') != 'user4'

======================================================================
FAIL: test_search_user_by_username_5 (ClassEval_92_0.UserLoginDBTestSearchUserByUsername)
----------------------------------------------------------------------
Traceback (most recent call last):
  File "C:\Users\tanuj\Desktop\CS540\repo\CS540\classeval_evaluation\ClassEval_92_0.py", line 200, in test_search_user_by_username_5
    self.assertEqual(user[0], 'user5')
AssertionError: ('user5', 'pass5') != 'user5'

----------------------------------------------------------------------
Ran 5 tests in 0.117s

FAILED (failures=5)
FFFFF
======================================================================
FAIL: test_delete_user_by_username_1 (ClassEval_92_0.UserLoginDBTestDeleteUserByUsername)
----------------------------------------------------------------------
Traceback (most recent call last):
  File "C:\Users\tanuj\Desktop\CS540\repo\CS540\classeval_evaluation\ClassEval_92_0.py", line 229, in test_delete_user_by_username_1
    self.assertIsNone(user)
AssertionError: [] is not None

======================================================================
FAIL: test_delete_user_by_username_2 (ClassEval_92_0.UserLoginDBTestDeleteUserByUsername)
----------------------------------------------------------------------
Traceback (most recent call last):
  File "C:\Users\tanuj\Desktop\CS540\repo\CS540\classeval_evaluation\ClassEval_92_0.py", line 235, in test_delete_user_by_username_2
    self.assertIsNone(user)
AssertionError: [] is not None

======================================================================
FAIL: test_delete_user_by_username_3 (ClassEval_92_0.UserLoginDBTestDeleteUserByUsername)
----------------------------------------------------------------------
Traceback (most recent call last):
  File "C:\Users\tanuj\Desktop\CS540\repo\CS540\classeval_evaluation\ClassEval_92_0.py", line 241, in test_delete_user_by_username_3
    self.assertIsNone(user)
AssertionError: [] is not None

======================================================================
FAIL: test_delete_user_by_username_4 (ClassEval_92_0.UserLoginDBTestDeleteUserByUsername)
----------------------------------------------------------------------
Traceback (most recent call last):
  File "C:\Users\tanuj\Desktop\CS540\repo\CS540\classeval_evaluation\ClassEval_92_0.py", line 247, in test_delete_user_by_username_4
    self.assertIsNone(user)
AssertionError: [] is not None

======================================================================
FAIL: test_delete_user_by_username_5 (ClassEval_92_0.UserLoginDBTestDeleteUserByUsername)
----------------------------------------------------------------------
Traceback (most recent call last):
  File "C:\Users\tanuj\Desktop\CS540\repo\CS540\classeval_evaluation\ClassEval_92_0.py", line 253, in test_delete_user_by_username_5
    self.assertIsNone(user)
AssertionError: [] is not None

----------------------------------------------------------------------
Ran 5 tests in 0.138s

FAILED (failures=5)
.....
----------------------------------------------------------------------
Ran 5 tests in 0.174s

OK
F
======================================================================
FAIL: test_UserLoginDB (ClassEval_92_0.UserLoginDBTest)
----------------------------------------------------------------------
Traceback (most recent call last):
  File "C:\Users\tanuj\Desktop\CS540\repo\CS540\classeval_evaluation\ClassEval_92_0.py", line 327, in test_UserLoginDB
    self.assertEqual(user[0], 'user1')
AssertionError: ('user1', 'pass1') != 'user1'

----------------------------------------------------------------------
Ran 1 test in 0.026s

FAILED (failures=1)
.....
----------------------------------------------------------------------
Ran 5 tests in 0.001s

OK
.....
----------------------------------------------------------------------
Ran 5 tests in 0.000s

OK
.....
----------------------------------------------------------------------
Ran 5 tests in 0.000s

OK
.....
----------------------------------------------------------------------
Ran 5 tests in 0.000s

OK
.....
----------------------------------------------------------------------
Ran 5 tests in 0.000s

OK
..
----------------------------------------------------------------------
Ran 2 tests in 0.000s

OK
......
----------------------------------------------------------------------
Ran 6 tests in 0.001s

OK
.....
----------------------------------------------------------------------
Ran 5 tests in 0.000s

OK
.....
----------------------------------------------------------------------
Ran 5 tests in 0.000s

OK
.....
----------------------------------------------------------------------
Ran 5 tests in 0.000s

OK
.....
----------------------------------------------------------------------
Ran 5 tests in 0.002s

OK
.....
----------------------------------------------------------------------
Ran 5 tests in 0.000s

OK
.
----------------------------------------------------------------------
Ran 1 test in 0.000s

OK
.E....
======================================================================
ERROR: test_query_2 (ClassEval_96_0.WeatherSystemTestQuery)
----------------------------------------------------------------------
Traceback (most recent call last):
  File "C:\Users\tanuj\Desktop\CS540\repo\CS540\classeval_evaluation\ClassEval_96_0.py", line 119, in test_query_2
    self.assertEqual(weatherSystem.query(weather_list), False)
  File "C:\Users\tanuj\Desktop\CS540\repo\CS540\classeval_evaluation\ClassEval_96_0.py", line 31, in query
    raise KeyError(f"City '{self.city}' not found in weather data.")
KeyError: "City 'Shanghai' not found in weather data."

----------------------------------------------------------------------
Ran 6 tests in 0.002s

FAILED (errors=1)
.....
----------------------------------------------------------------------
Ran 5 tests in 0.000s

OK
.....
----------------------------------------------------------------------
Ran 5 tests in 0.000s

OK
.....
----------------------------------------------------------------------
Ran 5 tests in 0.000s

OK
.
----------------------------------------------------------------------
Ran 1 test in 0.000s

OK
......
----------------------------------------------------------------------
Ran 6 tests in 0.000s

OK
F.F...
======================================================================
FAIL: test_is_valid_input (ClassEval_97_0.Words2NumbersTestIsValidInput)
----------------------------------------------------------------------
Traceback (most recent call last):
  File "C:\Users\tanuj\Desktop\CS540\repo\CS540\classeval_evaluation\ClassEval_97_0.py", line 159, in test_is_valid_input
    self.assertTrue(w2n.is_valid_input("twenty-five thousand three hundred and forty-two"))
AssertionError: False is not true

======================================================================
FAIL: test_is_valid_input3 (ClassEval_97_0.Words2NumbersTestIsValidInput)
----------------------------------------------------------------------
Traceback (most recent call last):
  File "C:\Users\tanuj\Desktop\CS540\repo\CS540\classeval_evaluation\ClassEval_97_0.py", line 167, in test_is_valid_input3
    self.assertTrue(w2n.is_valid_input("twenty-fifth thousand three hundred and forty-second"))
AssertionError: False is not true

----------------------------------------------------------------------
Ran 6 tests in 0.001s

FAILED (failures=2)
......
----------------------------------------------------------------------
Ran 6 tests in 0.008s

OK
......
----------------------------------------------------------------------
Ran 6 tests in 0.012s

OK
.....
----------------------------------------------------------------------
Ran 5 tests in 0.030s

OK
.....
----------------------------------------------------------------------
Ran 5 tests in 0.014s

OK
.
----------------------------------------------------------------------
Ran 1 test in 0.005s

OK
......
----------------------------------------------------------------------
Ran 6 tests in 0.016s

OK
......
----------------------------------------------------------------------
Ran 6 tests in 0.037s

OK
......
----------------------------------------------------------------------
Ran 6 tests in 0.040s

OK
......
----------------------------------------------------------------------
Ran 6 tests in 0.038s

OK
.
----------------------------------------------------------------------
Ran 1 test in 0.008s

OK
