.....
----------------------------------------------------------------------
Ran 5 tests in 0.000s

OK
.....
----------------------------------------------------------------------
Ran 5 tests in 0.000s

OK
.....
----------------------------------------------------------------------
Ran 5 tests in 0.000s

OK
.....
----------------------------------------------------------------------
Ran 5 tests in 0.000s

OK
.....
----------------------------------------------------------------------
Ran 5 tests in 0.000s

OK
.
----------------------------------------------------------------------
Ran 1 test in 0.000s

OK
.....
----------------------------------------------------------------------
Ran 5 tests in 0.000s

OK
.....
----------------------------------------------------------------------
Ran 5 tests in 0.000s

OK
FFFFFF
======================================================================
FAIL: test_select_1 (ClassEval_3_0.ArrangementCalculatorTestSelect.test_select_1)
----------------------------------------------------------------------
Traceback (most recent call last):
  File "/Users/snigdhaghoshdastidar/Desktop/CS540/classeval_evaluation/ClassEval_3_0.py", line 145, in test_select_1
    self.assertEqual(res, expected)
AssertionError: Lists differ: [(1, 2), (1, 3), (1, 4), (2, 1), (2, 3), ([49 chars], 3)] != [[1, 2], [1, 3], [1, 4], [2, 1], [2, 3], [[49 chars], 3]]

First differing element 0:
(1, 2)
[1, 2]

- [(1, 2),
?  ^    ^

+ [[1, 2],
?  ^    ^

-  (1, 3),
?  ^    ^

+  [1, 3],
?  ^    ^

-  (1, 4),
?  ^    ^

+  [1, 4],
?  ^    ^

-  (2, 1),
?  ^    ^

+  [2, 1],
?  ^    ^

-  (2, 3),
?  ^    ^

+  [2, 3],
?  ^    ^

-  (2, 4),
?  ^    ^

+  [2, 4],
?  ^    ^

-  (3, 1),
?  ^    ^

+  [3, 1],
?  ^    ^

-  (3, 2),
?  ^    ^

+  [3, 2],
?  ^    ^

-  (3, 4),
?  ^    ^

+  [3, 4],
?  ^    ^

-  (4, 1),
?  ^    ^

+  [4, 1],
?  ^    ^

-  (4, 2),
?  ^    ^

+  [4, 2],
?  ^    ^

-  (4, 3)]
?  ^    -

+  [4, 3]]
?  ^     +


======================================================================
FAIL: test_select_2 (ClassEval_3_0.ArrangementCalculatorTestSelect.test_select_2)
----------------------------------------------------------------------
Traceback (most recent call last):
  File "/Users/snigdhaghoshdastidar/Desktop/CS540/classeval_evaluation/ClassEval_3_0.py", line 151, in test_select_2
    self.assertEqual(res, expected)
AssertionError: Lists differ: [(1, 2), (1, 3), (2, 1), (2, 3), (3, 1), (3, 2)] != [[1, 2], [1, 3], [2, 1], [2, 3], [3, 1], [3, 2]]

First differing element 0:
(1, 2)
[1, 2]

- [(1, 2), (1, 3), (2, 1), (2, 3), (3, 1), (3, 2)]
?  ^    ^  ^    ^  ^    ^  ^    ^  ^    ^  ^    -

+ [[1, 2], [1, 3], [2, 1], [2, 3], [3, 1], [3, 2]]
?  ^    ^  ^    ^  ^    ^  ^    ^  ^    ^  ^     +


======================================================================
FAIL: test_select_3 (ClassEval_3_0.ArrangementCalculatorTestSelect.test_select_3)
----------------------------------------------------------------------
Traceback (most recent call last):
  File "/Users/snigdhaghoshdastidar/Desktop/CS540/classeval_evaluation/ClassEval_3_0.py", line 157, in test_select_3
    self.assertEqual(res, expected)
AssertionError: Lists differ: [(2, 3), (2, 4), (3, 2), (3, 4), (4, 2), (4, 3)] != [[2, 3], [2, 4], [3, 2], [3, 4], [4, 2], [4, 3]]

First differing element 0:
(2, 3)
[2, 3]

- [(2, 3), (2, 4), (3, 2), (3, 4), (4, 2), (4, 3)]
?  ^    ^  ^    ^  ^    ^  ^    ^  ^    ^  ^    -

+ [[2, 3], [2, 4], [3, 2], [3, 4], [4, 2], [4, 3]]
?  ^    ^  ^    ^  ^    ^  ^    ^  ^    ^  ^     +


======================================================================
FAIL: test_select_4 (ClassEval_3_0.ArrangementCalculatorTestSelect.test_select_4)
----------------------------------------------------------------------
Traceback (most recent call last):
  File "/Users/snigdhaghoshdastidar/Desktop/CS540/classeval_evaluation/ClassEval_3_0.py", line 163, in test_select_4
    self.assertEqual(res, expected)
AssertionError: Lists differ: [(1, 2), (2, 1)] != [[1, 2], [2, 1]]

First differing element 0:
(1, 2)
[1, 2]

- [(1, 2), (2, 1)]
?  ^    ^  ^    -

+ [[1, 2], [2, 1]]
?  ^    ^  ^     +


======================================================================
FAIL: test_select_5 (ClassEval_3_0.ArrangementCalculatorTestSelect.test_select_5)
----------------------------------------------------------------------
Traceback (most recent call last):
  File "/Users/snigdhaghoshdastidar/Desktop/CS540/classeval_evaluation/ClassEval_3_0.py", line 169, in test_select_5
    self.assertEqual(res, expected)
AssertionError: Lists differ: [(1,), (2,), (3,), (4,)] != [[1], [2], [3], [4]]

First differing element 0:
(1,)
[1]

- [(1,), (2,), (3,), (4,)]
+ [[1], [2], [3], [4]]

======================================================================
FAIL: test_select_6 (ClassEval_3_0.ArrangementCalculatorTestSelect.test_select_6)
----------------------------------------------------------------------
Traceback (most recent call last):
  File "/Users/snigdhaghoshdastidar/Desktop/CS540/classeval_evaluation/ClassEval_3_0.py", line 175, in test_select_6
    self.assertEqual(res, expected)
AssertionError: Lists differ: [(1, 2), (2, 1)] != [[1, 2], [2, 1]]

First differing element 0:
(1, 2)
[1, 2]

- [(1, 2), (2, 1)]
?  ^    ^  ^    -

+ [[1, 2], [2, 1]]
?  ^    ^  ^     +


----------------------------------------------------------------------
Ran 6 tests in 0.007s

FAILED (failures=6)
FFFFF
======================================================================
FAIL: test_select_all_1 (ClassEval_3_0.ArrangementCalculatorTestSelectAll.test_select_all_1)
----------------------------------------------------------------------
Traceback (most recent call last):
  File "/Users/snigdhaghoshdastidar/Desktop/CS540/classeval_evaluation/ClassEval_3_0.py", line 184, in test_select_all_1
    self.assertEqual(res, expected)
AssertionError: Lists differ: [(1,), (2,), (3,), (1, 2), (1, 3), (2, 1),[85 chars], 1)] != [[1], [2], [3], [1, 2], [1, 3], [2, 1], [2[82 chars], 1]]

First differing element 0:
(1,)
[1]

Diff is 652 characters long. Set self.maxDiff to None to see it.

======================================================================
FAIL: test_select_all_2 (ClassEval_3_0.ArrangementCalculatorTestSelectAll.test_select_all_2)
----------------------------------------------------------------------
Traceback (most recent call last):
  File "/Users/snigdhaghoshdastidar/Desktop/CS540/classeval_evaluation/ClassEval_3_0.py", line 191, in test_select_all_2
    self.assertEqual(res, expected)
AssertionError: Lists differ: [(1,), (2,), (4,), (1, 2), (1, 4), (2, 1),[85 chars], 1)] != [[1], [2], [4], [1, 2], [1, 4], [2, 1], [2[82 chars], 1]]

First differing element 0:
(1,)
[1]

Diff is 652 characters long. Set self.maxDiff to None to see it.

======================================================================
FAIL: test_select_all_3 (ClassEval_3_0.ArrangementCalculatorTestSelectAll.test_select_all_3)
----------------------------------------------------------------------
Traceback (most recent call last):
  File "/Users/snigdhaghoshdastidar/Desktop/CS540/classeval_evaluation/ClassEval_3_0.py", line 197, in test_select_all_3
    self.assertEqual(res, expected)
AssertionError: Lists differ: [(1,), (2,), (1, 2), (2, 1)] != [[1], [2], [1, 2], [2, 1]]

First differing element 0:
(1,)
[1]

- [(1,), (2,), (1, 2), (2, 1)]
+ [[1], [2], [1, 2], [2, 1]]

======================================================================
FAIL: test_select_all_4 (ClassEval_3_0.ArrangementCalculatorTestSelectAll.test_select_all_4)
----------------------------------------------------------------------
Traceback (most recent call last):
  File "/Users/snigdhaghoshdastidar/Desktop/CS540/classeval_evaluation/ClassEval_3_0.py", line 203, in test_select_all_4
    self.assertEqual(res, expected)
AssertionError: Lists differ: [(1,), (3,), (1, 3), (3, 1)] != [[1], [3], [1, 3], [3, 1]]

First differing element 0:
(1,)
[1]

- [(1,), (3,), (1, 3), (3, 1)]
+ [[1], [3], [1, 3], [3, 1]]

======================================================================
FAIL: test_select_all_5 (ClassEval_3_0.ArrangementCalculatorTestSelectAll.test_select_all_5)
----------------------------------------------------------------------
Traceback (most recent call last):
  File "/Users/snigdhaghoshdastidar/Desktop/CS540/classeval_evaluation/ClassEval_3_0.py", line 209, in test_select_all_5
    self.assertEqual(res, expected)
AssertionError: Lists differ: [(1,)] != [[1]]

First differing element 0:
(1,)
[1]

- [(1,)]
+ [[1]]

----------------------------------------------------------------------
Ran 5 tests in 0.007s

FAILED (failures=5)
.....
----------------------------------------------------------------------
Ran 5 tests in 0.000s

OK
F
======================================================================
FAIL: test_arrangementcalculator (ClassEval_3_0.ArrangementCalculatorTest.test_arrangementcalculator)
----------------------------------------------------------------------
Traceback (most recent call last):
  File "/Users/snigdhaghoshdastidar/Desktop/CS540/classeval_evaluation/ClassEval_3_0.py", line 245, in test_arrangementcalculator
    self.assertEqual(res, expected)
AssertionError: Lists differ: [(1, 2), (1, 3), (1, 4), (2, 1), (2, 3), ([49 chars], 3)] != [[1, 2], [1, 3], [1, 4], [2, 1], [2, 3], [[49 chars], 3]]

First differing element 0:
(1, 2)
[1, 2]

- [(1, 2),
?  ^    ^

+ [[1, 2],
?  ^    ^

-  (1, 3),
?  ^    ^

+  [1, 3],
?  ^    ^

-  (1, 4),
?  ^    ^

+  [1, 4],
?  ^    ^

-  (2, 1),
?  ^    ^

+  [2, 1],
?  ^    ^

-  (2, 3),
?  ^    ^

+  [2, 3],
?  ^    ^

-  (2, 4),
?  ^    ^

+  [2, 4],
?  ^    ^

-  (3, 1),
?  ^    ^

+  [3, 1],
?  ^    ^

-  (3, 2),
?  ^    ^

+  [3, 2],
?  ^    ^

-  (3, 4),
?  ^    ^

+  [3, 4],
?  ^    ^

-  (4, 1),
?  ^    ^

+  [4, 1],
?  ^    ^

-  (4, 2),
?  ^    ^

+  [4, 2],
?  ^    ^

-  (4, 3)]
?  ^    -

+  [4, 3]]
?  ^     +


----------------------------------------------------------------------
Ran 1 test in 0.004s

FAILED (failures=1)
.....
----------------------------------------------------------------------
Ran 5 tests in 0.001s

OK
.....
----------------------------------------------------------------------
Ran 5 tests in 0.000s

OK
......
----------------------------------------------------------------------
Ran 6 tests in 0.000s

OK
.
----------------------------------------------------------------------
Ran 1 test in 0.000s

OK
EEEEEEEE
======================================================================
ERROR: test_calculate_1 (ClassEval_16_0.CalculatorTestCalculate.test_calculate_1)
----------------------------------------------------------------------
Traceback (most recent call last):
  File "/Users/snigdhaghoshdastidar/Desktop/CS540/classeval_evaluation/ClassEval_16_0.py", line 102, in test_calculate_1
    res = calculator.calculate('1+2')
          ^^^^^^^^^^^^^^^^^^^^^^^^^^^
  File "/Users/snigdhaghoshdastidar/Desktop/CS540/classeval_evaluation/ClassEval_16_0.py", line 58, in calculate
    return operand_stack[0]
           ~~~~~~~~~~~~~^^^
IndexError: list index out of range

======================================================================
ERROR: test_calculate_2 (ClassEval_16_0.CalculatorTestCalculate.test_calculate_2)
----------------------------------------------------------------------
Traceback (most recent call last):
  File "/Users/snigdhaghoshdastidar/Desktop/CS540/classeval_evaluation/ClassEval_16_0.py", line 107, in test_calculate_2
    res = calculator.calculate('1+2*3')
          ^^^^^^^^^^^^^^^^^^^^^^^^^^^^^
  File "/Users/snigdhaghoshdastidar/Desktop/CS540/classeval_evaluation/ClassEval_16_0.py", line 58, in calculate
    return operand_stack[0]
           ~~~~~~~~~~~~~^^^
IndexError: list index out of range

======================================================================
ERROR: test_calculate_3 (ClassEval_16_0.CalculatorTestCalculate.test_calculate_3)
----------------------------------------------------------------------
Traceback (most recent call last):
  File "/Users/snigdhaghoshdastidar/Desktop/CS540/classeval_evaluation/ClassEval_16_0.py", line 112, in test_calculate_3
    res = calculator.calculate('1+2*3+4')
          ^^^^^^^^^^^^^^^^^^^^^^^^^^^^^^^
  File "/Users/snigdhaghoshdastidar/Desktop/CS540/classeval_evaluation/ClassEval_16_0.py", line 58, in calculate
    return operand_stack[0]
           ~~~~~~~~~~~~~^^^
IndexError: list index out of range

======================================================================
ERROR: test_calculate_4 (ClassEval_16_0.CalculatorTestCalculate.test_calculate_4)
----------------------------------------------------------------------
Traceback (most recent call last):
  File "/Users/snigdhaghoshdastidar/Desktop/CS540/classeval_evaluation/ClassEval_16_0.py", line 117, in test_calculate_4
    res = calculator.calculate('1+2^3*2+4*5')
          ^^^^^^^^^^^^^^^^^^^^^^^^^^^^^^^^^^^
  File "/Users/snigdhaghoshdastidar/Desktop/CS540/classeval_evaluation/ClassEval_16_0.py", line 58, in calculate
    return operand_stack[0]
           ~~~~~~~~~~~~~^^^
IndexError: list index out of range

======================================================================
ERROR: test_calculate_5 (ClassEval_16_0.CalculatorTestCalculate.test_calculate_5)
----------------------------------------------------------------------
Traceback (most recent call last):
  File "/Users/snigdhaghoshdastidar/Desktop/CS540/classeval_evaluation/ClassEval_16_0.py", line 122, in test_calculate_5
    res = calculator.calculate('1+2+3')
          ^^^^^^^^^^^^^^^^^^^^^^^^^^^^^
  File "/Users/snigdhaghoshdastidar/Desktop/CS540/classeval_evaluation/ClassEval_16_0.py", line 58, in calculate
    return operand_stack[0]
           ~~~~~~~~~~~~~^^^
IndexError: list index out of range

======================================================================
ERROR: test_calculate_6 (ClassEval_16_0.CalculatorTestCalculate.test_calculate_6)
----------------------------------------------------------------------
Traceback (most recent call last):
  File "/Users/snigdhaghoshdastidar/Desktop/CS540/classeval_evaluation/ClassEval_16_0.py", line 127, in test_calculate_6
    res = calculator.calculate('(1+2)+3')
          ^^^^^^^^^^^^^^^^^^^^^^^^^^^^^^^
  File "/Users/snigdhaghoshdastidar/Desktop/CS540/classeval_evaluation/ClassEval_16_0.py", line 58, in calculate
    return operand_stack[0]
           ~~~~~~~~~~~~~^^^
IndexError: list index out of range

======================================================================
ERROR: test_calculate_7 (ClassEval_16_0.CalculatorTestCalculate.test_calculate_7)
----------------------------------------------------------------------
Traceback (most recent call last):
  File "/Users/snigdhaghoshdastidar/Desktop/CS540/classeval_evaluation/ClassEval_16_0.py", line 132, in test_calculate_7
    res = calculator.calculate('')
          ^^^^^^^^^^^^^^^^^^^^^^^^
  File "/Users/snigdhaghoshdastidar/Desktop/CS540/classeval_evaluation/ClassEval_16_0.py", line 58, in calculate
    return operand_stack[0]
           ~~~~~~~~~~~~~^^^
IndexError: list index out of range

======================================================================
ERROR: test_calculate_8 (ClassEval_16_0.CalculatorTestCalculate.test_calculate_8)
----------------------------------------------------------------------
Traceback (most recent call last):
  File "/Users/snigdhaghoshdastidar/Desktop/CS540/classeval_evaluation/ClassEval_16_0.py", line 137, in test_calculate_8
    res = calculator.calculate('1+2?')
          ^^^^^^^^^^^^^^^^^^^^^^^^^^^^
  File "/Users/snigdhaghoshdastidar/Desktop/CS540/classeval_evaluation/ClassEval_16_0.py", line 58, in calculate
    return operand_stack[0]
           ~~~~~~~~~~~~~^^^
IndexError: list index out of range

----------------------------------------------------------------------
Ran 8 tests in 0.002s

FAILED (errors=8)
.....
----------------------------------------------------------------------
Ran 5 tests in 0.000s

OK
.....
----------------------------------------------------------------------
Ran 5 tests in 0.000s

OK
E
======================================================================
ERROR: test_calculator (ClassEval_16_0.CalculatorTest.test_calculator)
----------------------------------------------------------------------
Traceback (most recent call last):
  File "/Users/snigdhaghoshdastidar/Desktop/CS540/classeval_evaluation/ClassEval_16_0.py", line 218, in test_calculator
    res = calculator.calculate('1+2')
          ^^^^^^^^^^^^^^^^^^^^^^^^^^^
  File "/Users/snigdhaghoshdastidar/Desktop/CS540/classeval_evaluation/ClassEval_16_0.py", line 58, in calculate
    return operand_stack[0]
           ~~~~~~~~~~~~~^^^
IndexError: list index out of range

----------------------------------------------------------------------
Ran 1 test in 0.000s

FAILED (errors=1)
EEEEE
======================================================================
ERROR: test_generate_primes_1 (ClassEval_19_0.ChandrasekharSieveTestGeneratePrimes.test_generate_primes_1)
----------------------------------------------------------------------
Traceback (most recent call last):
  File "/Users/snigdhaghoshdastidar/Desktop/CS540/classeval_evaluation/ClassEval_19_0.py", line 28, in test_generate_primes_1
    cs = ChandrasekharSieve(20)
         ^^^^^^^^^^^^^^^^^^
NameError: name 'ChandrasekharSieve' is not defined. Did you mean: 'ChandrasekharSieveTest'?

======================================================================
ERROR: test_generate_primes_2 (ClassEval_19_0.ChandrasekharSieveTestGeneratePrimes.test_generate_primes_2)
----------------------------------------------------------------------
Traceback (most recent call last):
  File "/Users/snigdhaghoshdastidar/Desktop/CS540/classeval_evaluation/ClassEval_19_0.py", line 33, in test_generate_primes_2
    cs = ChandrasekharSieve(18)
         ^^^^^^^^^^^^^^^^^^
NameError: name 'ChandrasekharSieve' is not defined. Did you mean: 'ChandrasekharSieveTest'?

======================================================================
ERROR: test_generate_primes_3 (ClassEval_19_0.ChandrasekharSieveTestGeneratePrimes.test_generate_primes_3)
----------------------------------------------------------------------
Traceback (most recent call last):
  File "/Users/snigdhaghoshdastidar/Desktop/CS540/classeval_evaluation/ClassEval_19_0.py", line 38, in test_generate_primes_3
    cs = ChandrasekharSieve(15)
         ^^^^^^^^^^^^^^^^^^
NameError: name 'ChandrasekharSieve' is not defined. Did you mean: 'ChandrasekharSieveTest'?

======================================================================
ERROR: test_generate_primes_4 (ClassEval_19_0.ChandrasekharSieveTestGeneratePrimes.test_generate_primes_4)
----------------------------------------------------------------------
Traceback (most recent call last):
  File "/Users/snigdhaghoshdastidar/Desktop/CS540/classeval_evaluation/ClassEval_19_0.py", line 43, in test_generate_primes_4
    cs = ChandrasekharSieve(10)
         ^^^^^^^^^^^^^^^^^^
NameError: name 'ChandrasekharSieve' is not defined. Did you mean: 'ChandrasekharSieveTest'?

======================================================================
ERROR: test_generate_primes_5 (ClassEval_19_0.ChandrasekharSieveTestGeneratePrimes.test_generate_primes_5)
----------------------------------------------------------------------
Traceback (most recent call last):
  File "/Users/snigdhaghoshdastidar/Desktop/CS540/classeval_evaluation/ClassEval_19_0.py", line 48, in test_generate_primes_5
    cs = ChandrasekharSieve(1)
         ^^^^^^^^^^^^^^^^^^
NameError: name 'ChandrasekharSieve' is not defined. Did you mean: 'ChandrasekharSieveTest'?

----------------------------------------------------------------------
Ran 5 tests in 0.016s

FAILED (errors=5)
EEEEE
======================================================================
ERROR: test_get_primes_1 (ClassEval_19_0.ChandrasekharSieveTestGetPrimes.test_get_primes_1)
----------------------------------------------------------------------
Traceback (most recent call last):
  File "/Users/snigdhaghoshdastidar/Desktop/CS540/classeval_evaluation/ClassEval_19_0.py", line 55, in test_get_primes_1
    cs = ChandrasekharSieve(20)
         ^^^^^^^^^^^^^^^^^^
NameError: name 'ChandrasekharSieve' is not defined. Did you mean: 'ChandrasekharSieveTest'?

======================================================================
ERROR: test_get_primes_2 (ClassEval_19_0.ChandrasekharSieveTestGetPrimes.test_get_primes_2)
----------------------------------------------------------------------
Traceback (most recent call last):
  File "/Users/snigdhaghoshdastidar/Desktop/CS540/classeval_evaluation/ClassEval_19_0.py", line 61, in test_get_primes_2
    cs = ChandrasekharSieve(18)
         ^^^^^^^^^^^^^^^^^^
NameError: name 'ChandrasekharSieve' is not defined. Did you mean: 'ChandrasekharSieveTest'?

======================================================================
ERROR: test_get_primes_3 (ClassEval_19_0.ChandrasekharSieveTestGetPrimes.test_get_primes_3)
----------------------------------------------------------------------
Traceback (most recent call last):
  File "/Users/snigdhaghoshdastidar/Desktop/CS540/classeval_evaluation/ClassEval_19_0.py", line 67, in test_get_primes_3
    cs = ChandrasekharSieve(15)
         ^^^^^^^^^^^^^^^^^^
NameError: name 'ChandrasekharSieve' is not defined. Did you mean: 'ChandrasekharSieveTest'?

======================================================================
ERROR: test_get_primes_4 (ClassEval_19_0.ChandrasekharSieveTestGetPrimes.test_get_primes_4)
----------------------------------------------------------------------
Traceback (most recent call last):
  File "/Users/snigdhaghoshdastidar/Desktop/CS540/classeval_evaluation/ClassEval_19_0.py", line 73, in test_get_primes_4
    cs = ChandrasekharSieve(10)
         ^^^^^^^^^^^^^^^^^^
NameError: name 'ChandrasekharSieve' is not defined. Did you mean: 'ChandrasekharSieveTest'?

======================================================================
ERROR: test_get_primes_5 (ClassEval_19_0.ChandrasekharSieveTestGetPrimes.test_get_primes_5)
----------------------------------------------------------------------
Traceback (most recent call last):
  File "/Users/snigdhaghoshdastidar/Desktop/CS540/classeval_evaluation/ClassEval_19_0.py", line 79, in test_get_primes_5
    cs = ChandrasekharSieve(1)
         ^^^^^^^^^^^^^^^^^^
NameError: name 'ChandrasekharSieve' is not defined. Did you mean: 'ChandrasekharSieveTest'?

----------------------------------------------------------------------
Ran 5 tests in 0.015s

FAILED (errors=5)
E
======================================================================
ERROR: test_chandrasekharsieve (ClassEval_19_0.ChandrasekharSieveTest.test_chandrasekharsieve)
----------------------------------------------------------------------
Traceback (most recent call last):
  File "/Users/snigdhaghoshdastidar/Desktop/CS540/classeval_evaluation/ClassEval_19_0.py", line 86, in test_chandrasekharsieve
    cs = ChandrasekharSieve(20)
         ^^^^^^^^^^^^^^^^^^
NameError: name 'ChandrasekharSieve' is not defined. Did you mean: 'ChandrasekharSieveTest'?

----------------------------------------------------------------------
Ran 1 test in 0.003s

FAILED (errors=1)
.....
----------------------------------------------------------------------
Ran 5 tests in 0.000s

OK
FEFFF
======================================================================
ERROR: test_count_all_2 (ClassEval_23_0.CombinationCalculatorTestCountAll.test_count_all_2)
----------------------------------------------------------------------
Traceback (most recent call last):
  File "/Users/snigdhaghoshdastidar/Desktop/CS540/classeval_evaluation/ClassEval_23_0.py", line 107, in test_count_all_2
    self.assertEqual(CombinationCalculator.count_all(-1), False)
                     ^^^^^^^^^^^^^^^^^^^^^^^^^^^^^^^^^^^
  File "/Users/snigdhaghoshdastidar/Desktop/CS540/classeval_evaluation/ClassEval_23_0.py", line 34, in count_all
    combinations = math.comb(n, n)
                   ^^^^^^^^^^^^^^^
ValueError: n must be a non-negative integer

======================================================================
FAIL: test_count_all (ClassEval_23_0.CombinationCalculatorTestCountAll.test_count_all)
----------------------------------------------------------------------
Traceback (most recent call last):
  File "/Users/snigdhaghoshdastidar/Desktop/CS540/classeval_evaluation/ClassEval_23_0.py", line 104, in test_count_all
    self.assertEqual(CombinationCalculator.count_all(4), 15)
AssertionError: 1 != 15

======================================================================
FAIL: test_count_all_3 (ClassEval_23_0.CombinationCalculatorTestCountAll.test_count_all_3)
----------------------------------------------------------------------
Traceback (most recent call last):
  File "/Users/snigdhaghoshdastidar/Desktop/CS540/classeval_evaluation/ClassEval_23_0.py", line 110, in test_count_all_3
    self.assertEqual(CombinationCalculator.count_all(65), False)
AssertionError: 1 != False

======================================================================
FAIL: test_count_all_4 (ClassEval_23_0.CombinationCalculatorTestCountAll.test_count_all_4)
----------------------------------------------------------------------
Traceback (most recent call last):
  File "/Users/snigdhaghoshdastidar/Desktop/CS540/classeval_evaluation/ClassEval_23_0.py", line 113, in test_count_all_4
    self.assertEqual(CombinationCalculator.count_all(0), 0)
AssertionError: 1 != 0

======================================================================
FAIL: test_count_all_5 (ClassEval_23_0.CombinationCalculatorTestCountAll.test_count_all_5)
----------------------------------------------------------------------
Traceback (most recent call last):
  File "/Users/snigdhaghoshdastidar/Desktop/CS540/classeval_evaluation/ClassEval_23_0.py", line 116, in test_count_all_5
    self.assertEqual(CombinationCalculator.count_all(63), float("inf"))
AssertionError: 1 != inf

----------------------------------------------------------------------
Ran 5 tests in 0.002s

FAILED (failures=4, errors=1)
.....
----------------------------------------------------------------------
Ran 5 tests in 0.000s

OK
.....
----------------------------------------------------------------------
Ran 5 tests in 0.000s

OK
.....
----------------------------------------------------------------------
Ran 5 tests in 0.000s

OK
F
======================================================================
FAIL: test_main (ClassEval_23_0.CombinationCalculatorTestMain.test_main)
----------------------------------------------------------------------
Traceback (most recent call last):
  File "/Users/snigdhaghoshdastidar/Desktop/CS540/classeval_evaluation/ClassEval_23_0.py", line 196, in test_main
    self.assertEqual(calc.count_all(4), 15)
AssertionError: 1 != 15

----------------------------------------------------------------------
Ran 1 test in 0.000s

FAILED (failures=1)
.....
----------------------------------------------------------------------
Ran 5 tests in 0.000s

OK
.....
----------------------------------------------------------------------
Ran 5 tests in 0.000s

OK
.....
----------------------------------------------------------------------
Ran 5 tests in 0.000s

OK
.....
----------------------------------------------------------------------
Ran 5 tests in 0.001s

OK
.
----------------------------------------------------------------------
Ran 1 test in 0.000s

OK
.....
----------------------------------------------------------------------
Ran 5 tests in 0.000s

OK
.....
----------------------------------------------------------------------
Ran 5 tests in 0.000s

OK
.....
----------------------------------------------------------------------
Ran 5 tests in 0.000s

OK
.
----------------------------------------------------------------------
Ran 1 test in 0.000s

OK
EEEEE
======================================================================
ERROR: test_get_sum_1 (ClassEval_30_0.DataStatistics2TestGetSum.test_get_sum_1)
----------------------------------------------------------------------
Traceback (most recent call last):
  File "/Users/snigdhaghoshdastidar/Desktop/CS540/classeval_evaluation/ClassEval_30_0.py", line 15, in test_get_sum_1
    ds2 = DataStatistics2([1, 2, 3, 4])
          ^^^^^^^^^^^^^^^
NameError: name 'DataStatistics2' is not defined. Did you mean: 'DataStatistics2Test'?

======================================================================
ERROR: test_get_sum_2 (ClassEval_30_0.DataStatistics2TestGetSum.test_get_sum_2)
----------------------------------------------------------------------
Traceback (most recent call last):
  File "/Users/snigdhaghoshdastidar/Desktop/CS540/classeval_evaluation/ClassEval_30_0.py", line 20, in test_get_sum_2
    ds2 = DataStatistics2([1, 2, 203, 4])
          ^^^^^^^^^^^^^^^
NameError: name 'DataStatistics2' is not defined. Did you mean: 'DataStatistics2Test'?

======================================================================
ERROR: test_get_sum_3 (ClassEval_30_0.DataStatistics2TestGetSum.test_get_sum_3)
----------------------------------------------------------------------
Traceback (most recent call last):
  File "/Users/snigdhaghoshdastidar/Desktop/CS540/classeval_evaluation/ClassEval_30_0.py", line 25, in test_get_sum_3
    ds2 = DataStatistics2([1, 2, 33, 4])
          ^^^^^^^^^^^^^^^
NameError: name 'DataStatistics2' is not defined. Did you mean: 'DataStatistics2Test'?

======================================================================
ERROR: test_get_sum_4 (ClassEval_30_0.DataStatistics2TestGetSum.test_get_sum_4)
----------------------------------------------------------------------
Traceback (most recent call last):
  File "/Users/snigdhaghoshdastidar/Desktop/CS540/classeval_evaluation/ClassEval_30_0.py", line 30, in test_get_sum_4
    ds2 = DataStatistics2([1, 2, 333, 4])
          ^^^^^^^^^^^^^^^
NameError: name 'DataStatistics2' is not defined. Did you mean: 'DataStatistics2Test'?

======================================================================
ERROR: test_get_sum_5 (ClassEval_30_0.DataStatistics2TestGetSum.test_get_sum_5)
----------------------------------------------------------------------
Traceback (most recent call last):
  File "/Users/snigdhaghoshdastidar/Desktop/CS540/classeval_evaluation/ClassEval_30_0.py", line 35, in test_get_sum_5
    ds2 = DataStatistics2([1, 2, 6, 4])
          ^^^^^^^^^^^^^^^
NameError: name 'DataStatistics2' is not defined. Did you mean: 'DataStatistics2Test'?

----------------------------------------------------------------------
Ran 5 tests in 0.018s

FAILED (errors=5)
EEEEE
======================================================================
ERROR: test_get_min_1 (ClassEval_30_0.DataStatistics2TestGetMin.test_get_min_1)
----------------------------------------------------------------------
Traceback (most recent call last):
  File "/Users/snigdhaghoshdastidar/Desktop/CS540/classeval_evaluation/ClassEval_30_0.py", line 42, in test_get_min_1
    ds2 = DataStatistics2([1, 2, 3, 4])
          ^^^^^^^^^^^^^^^
NameError: name 'DataStatistics2' is not defined. Did you mean: 'DataStatistics2Test'?

======================================================================
ERROR: test_get_min_2 (ClassEval_30_0.DataStatistics2TestGetMin.test_get_min_2)
----------------------------------------------------------------------
Traceback (most recent call last):
  File "/Users/snigdhaghoshdastidar/Desktop/CS540/classeval_evaluation/ClassEval_30_0.py", line 47, in test_get_min_2
    ds2 = DataStatistics2([1, 2, 203, 4])
          ^^^^^^^^^^^^^^^
NameError: name 'DataStatistics2' is not defined. Did you mean: 'DataStatistics2Test'?

======================================================================
ERROR: test_get_min_3 (ClassEval_30_0.DataStatistics2TestGetMin.test_get_min_3)
----------------------------------------------------------------------
Traceback (most recent call last):
  File "/Users/snigdhaghoshdastidar/Desktop/CS540/classeval_evaluation/ClassEval_30_0.py", line 52, in test_get_min_3
    ds2 = DataStatistics2([0, -1, -3, 2])
          ^^^^^^^^^^^^^^^
NameError: name 'DataStatistics2' is not defined. Did you mean: 'DataStatistics2Test'?

======================================================================
ERROR: test_get_min_4 (ClassEval_30_0.DataStatistics2TestGetMin.test_get_min_4)
----------------------------------------------------------------------
Traceback (most recent call last):
  File "/Users/snigdhaghoshdastidar/Desktop/CS540/classeval_evaluation/ClassEval_30_0.py", line 57, in test_get_min_4
    ds2 = DataStatistics2([-111, -1, -3, 2])
          ^^^^^^^^^^^^^^^
NameError: name 'DataStatistics2' is not defined. Did you mean: 'DataStatistics2Test'?

======================================================================
ERROR: test_get_min_5 (ClassEval_30_0.DataStatistics2TestGetMin.test_get_min_5)
----------------------------------------------------------------------
Traceback (most recent call last):
  File "/Users/snigdhaghoshdastidar/Desktop/CS540/classeval_evaluation/ClassEval_30_0.py", line 62, in test_get_min_5
    ds2 = DataStatistics2([0, -1111, -3, 2])
          ^^^^^^^^^^^^^^^
NameError: name 'DataStatistics2' is not defined. Did you mean: 'DataStatistics2Test'?

----------------------------------------------------------------------
Ran 5 tests in 0.016s

FAILED (errors=5)
EEEEE
======================================================================
ERROR: test_get_max_1 (ClassEval_30_0.DataStatistics2TestGetMax.test_get_max_1)
----------------------------------------------------------------------
Traceback (most recent call last):
  File "/Users/snigdhaghoshdastidar/Desktop/CS540/classeval_evaluation/ClassEval_30_0.py", line 69, in test_get_max_1
    ds2 = DataStatistics2([1, 2, 3, 4])
          ^^^^^^^^^^^^^^^
NameError: name 'DataStatistics2' is not defined. Did you mean: 'DataStatistics2Test'?

======================================================================
ERROR: test_get_max_2 (ClassEval_30_0.DataStatistics2TestGetMax.test_get_max_2)
----------------------------------------------------------------------
Traceback (most recent call last):
  File "/Users/snigdhaghoshdastidar/Desktop/CS540/classeval_evaluation/ClassEval_30_0.py", line 74, in test_get_max_2
    ds2 = DataStatistics2([1, 2, 203, 4])
          ^^^^^^^^^^^^^^^
NameError: name 'DataStatistics2' is not defined. Did you mean: 'DataStatistics2Test'?

======================================================================
ERROR: test_get_max_3 (ClassEval_30_0.DataStatistics2TestGetMax.test_get_max_3)
----------------------------------------------------------------------
Traceback (most recent call last):
  File "/Users/snigdhaghoshdastidar/Desktop/CS540/classeval_evaluation/ClassEval_30_0.py", line 79, in test_get_max_3
    ds2 = DataStatistics2([-1, -4, 3, 2])
          ^^^^^^^^^^^^^^^
NameError: name 'DataStatistics2' is not defined. Did you mean: 'DataStatistics2Test'?

======================================================================
ERROR: test_get_max_4 (ClassEval_30_0.DataStatistics2TestGetMax.test_get_max_4)
----------------------------------------------------------------------
Traceback (most recent call last):
  File "/Users/snigdhaghoshdastidar/Desktop/CS540/classeval_evaluation/ClassEval_30_0.py", line 84, in test_get_max_4
    ds2 = DataStatistics2([-1, 4, 3, 2])
          ^^^^^^^^^^^^^^^
NameError: name 'DataStatistics2' is not defined. Did you mean: 'DataStatistics2Test'?

======================================================================
ERROR: test_get_max_5 (ClassEval_30_0.DataStatistics2TestGetMax.test_get_max_5)
----------------------------------------------------------------------
Traceback (most recent call last):
  File "/Users/snigdhaghoshdastidar/Desktop/CS540/classeval_evaluation/ClassEval_30_0.py", line 89, in test_get_max_5
    ds2 = DataStatistics2([-1, 444, 3, 2])
          ^^^^^^^^^^^^^^^
NameError: name 'DataStatistics2' is not defined. Did you mean: 'DataStatistics2Test'?

----------------------------------------------------------------------
Ran 5 tests in 0.017s

FAILED (errors=5)
EEEEE
======================================================================
ERROR: test_get_variance_1 (ClassEval_30_0.DataStatistics2TestGetVariance.test_get_variance_1)
----------------------------------------------------------------------
Traceback (most recent call last):
  File "/Users/snigdhaghoshdastidar/Desktop/CS540/classeval_evaluation/ClassEval_30_0.py", line 96, in test_get_variance_1
    ds2 = DataStatistics2([1, 2, 3, 4])
          ^^^^^^^^^^^^^^^
NameError: name 'DataStatistics2' is not defined. Did you mean: 'DataStatistics2Test'?

======================================================================
ERROR: test_get_variance_2 (ClassEval_30_0.DataStatistics2TestGetVariance.test_get_variance_2)
----------------------------------------------------------------------
Traceback (most recent call last):
  File "/Users/snigdhaghoshdastidar/Desktop/CS540/classeval_evaluation/ClassEval_30_0.py", line 101, in test_get_variance_2
    ds2 = DataStatistics2([1, 2, 203, 4])
          ^^^^^^^^^^^^^^^
NameError: name 'DataStatistics2' is not defined. Did you mean: 'DataStatistics2Test'?

======================================================================
ERROR: test_get_variance_3 (ClassEval_30_0.DataStatistics2TestGetVariance.test_get_variance_3)
----------------------------------------------------------------------
Traceback (most recent call last):
  File "/Users/snigdhaghoshdastidar/Desktop/CS540/classeval_evaluation/ClassEval_30_0.py", line 106, in test_get_variance_3
    ds2 = DataStatistics2([1, 4, 3, 2])
          ^^^^^^^^^^^^^^^
NameError: name 'DataStatistics2' is not defined. Did you mean: 'DataStatistics2Test'?

======================================================================
ERROR: test_get_variance_4 (ClassEval_30_0.DataStatistics2TestGetVariance.test_get_variance_4)
----------------------------------------------------------------------
Traceback (most recent call last):
  File "/Users/snigdhaghoshdastidar/Desktop/CS540/classeval_evaluation/ClassEval_30_0.py", line 111, in test_get_variance_4
    ds2 = DataStatistics2([11, 14, 13, 12])
          ^^^^^^^^^^^^^^^
NameError: name 'DataStatistics2' is not defined. Did you mean: 'DataStatistics2Test'?

======================================================================
ERROR: test_get_variance_5 (ClassEval_30_0.DataStatistics2TestGetVariance.test_get_variance_5)
----------------------------------------------------------------------
Traceback (most recent call last):
  File "/Users/snigdhaghoshdastidar/Desktop/CS540/classeval_evaluation/ClassEval_30_0.py", line 116, in test_get_variance_5
    ds2 = DataStatistics2([111, 114, 113, 112])
          ^^^^^^^^^^^^^^^
NameError: name 'DataStatistics2' is not defined. Did you mean: 'DataStatistics2Test'?

----------------------------------------------------------------------
Ran 5 tests in 0.011s

FAILED (errors=5)
EEEEE
======================================================================
ERROR: test_get_std_deviation_1 (ClassEval_30_0.DataStatistics2TestGetStdDeviation.test_get_std_deviation_1)
----------------------------------------------------------------------
Traceback (most recent call last):
  File "/Users/snigdhaghoshdastidar/Desktop/CS540/classeval_evaluation/ClassEval_30_0.py", line 123, in test_get_std_deviation_1
    ds2 = DataStatistics2([1, 2, 3, 4])
          ^^^^^^^^^^^^^^^
NameError: name 'DataStatistics2' is not defined. Did you mean: 'DataStatistics2Test'?

======================================================================
ERROR: test_get_std_deviation_2 (ClassEval_30_0.DataStatistics2TestGetStdDeviation.test_get_std_deviation_2)
----------------------------------------------------------------------
Traceback (most recent call last):
  File "/Users/snigdhaghoshdastidar/Desktop/CS540/classeval_evaluation/ClassEval_30_0.py", line 128, in test_get_std_deviation_2
    ds2 = DataStatistics2([1, 2, 203, 4])
          ^^^^^^^^^^^^^^^
NameError: name 'DataStatistics2' is not defined. Did you mean: 'DataStatistics2Test'?

======================================================================
ERROR: test_get_std_deviation_3 (ClassEval_30_0.DataStatistics2TestGetStdDeviation.test_get_std_deviation_3)
----------------------------------------------------------------------
Traceback (most recent call last):
  File "/Users/snigdhaghoshdastidar/Desktop/CS540/classeval_evaluation/ClassEval_30_0.py", line 133, in test_get_std_deviation_3
    ds2 = DataStatistics2([1, 4, 3, 2])
          ^^^^^^^^^^^^^^^
NameError: name 'DataStatistics2' is not defined. Did you mean: 'DataStatistics2Test'?

======================================================================
ERROR: test_get_std_deviation_4 (ClassEval_30_0.DataStatistics2TestGetStdDeviation.test_get_std_deviation_4)
----------------------------------------------------------------------
Traceback (most recent call last):
  File "/Users/snigdhaghoshdastidar/Desktop/CS540/classeval_evaluation/ClassEval_30_0.py", line 138, in test_get_std_deviation_4
    ds2 = DataStatistics2([11, 14, 13, 12])
          ^^^^^^^^^^^^^^^
NameError: name 'DataStatistics2' is not defined. Did you mean: 'DataStatistics2Test'?

======================================================================
ERROR: test_get_std_deviation_5 (ClassEval_30_0.DataStatistics2TestGetStdDeviation.test_get_std_deviation_5)
----------------------------------------------------------------------
Traceback (most recent call last):
  File "/Users/snigdhaghoshdastidar/Desktop/CS540/classeval_evaluation/ClassEval_30_0.py", line 143, in test_get_std_deviation_5
    ds2 = DataStatistics2([111, 114, 113, 112])
          ^^^^^^^^^^^^^^^
NameError: name 'DataStatistics2' is not defined. Did you mean: 'DataStatistics2Test'?

----------------------------------------------------------------------
Ran 5 tests in 0.011s

FAILED (errors=5)
EEEEE
======================================================================
ERROR: test_get_correlation_1 (ClassEval_30_0.DataStatistics2TestGetCorrelation.test_get_correlation_1)
----------------------------------------------------------------------
Traceback (most recent call last):
  File "/Users/snigdhaghoshdastidar/Desktop/CS540/classeval_evaluation/ClassEval_30_0.py", line 150, in test_get_correlation_1
    ds2 = DataStatistics2([1, 2, 3, 4])
          ^^^^^^^^^^^^^^^
NameError: name 'DataStatistics2' is not defined. Did you mean: 'DataStatistics2Test'?

======================================================================
ERROR: test_get_correlation_2 (ClassEval_30_0.DataStatistics2TestGetCorrelation.test_get_correlation_2)
----------------------------------------------------------------------
Traceback (most recent call last):
  File "/Users/snigdhaghoshdastidar/Desktop/CS540/classeval_evaluation/ClassEval_30_0.py", line 155, in test_get_correlation_2
    ds2 = DataStatistics2([1, 2, 203, 4])
          ^^^^^^^^^^^^^^^
NameError: name 'DataStatistics2' is not defined. Did you mean: 'DataStatistics2Test'?

======================================================================
ERROR: test_get_correlation_3 (ClassEval_30_0.DataStatistics2TestGetCorrelation.test_get_correlation_3)
----------------------------------------------------------------------
Traceback (most recent call last):
  File "/Users/snigdhaghoshdastidar/Desktop/CS540/classeval_evaluation/ClassEval_30_0.py", line 160, in test_get_correlation_3
    ds2 = DataStatistics2([1, 4, 3, 2])
          ^^^^^^^^^^^^^^^
NameError: name 'DataStatistics2' is not defined. Did you mean: 'DataStatistics2Test'?

======================================================================
ERROR: test_get_correlation_4 (ClassEval_30_0.DataStatistics2TestGetCorrelation.test_get_correlation_4)
----------------------------------------------------------------------
Traceback (most recent call last):
  File "/Users/snigdhaghoshdastidar/Desktop/CS540/classeval_evaluation/ClassEval_30_0.py", line 165, in test_get_correlation_4
    ds2 = DataStatistics2([11, 14, 13, 12])
          ^^^^^^^^^^^^^^^
NameError: name 'DataStatistics2' is not defined. Did you mean: 'DataStatistics2Test'?

======================================================================
ERROR: test_get_correlation_5 (ClassEval_30_0.DataStatistics2TestGetCorrelation.test_get_correlation_5)
----------------------------------------------------------------------
Traceback (most recent call last):
  File "/Users/snigdhaghoshdastidar/Desktop/CS540/classeval_evaluation/ClassEval_30_0.py", line 170, in test_get_correlation_5
    ds2 = DataStatistics2([111, 114, 113, 112])
          ^^^^^^^^^^^^^^^
NameError: name 'DataStatistics2' is not defined. Did you mean: 'DataStatistics2Test'?

----------------------------------------------------------------------
Ran 5 tests in 0.013s

FAILED (errors=5)
E
======================================================================
ERROR: test_datastatistics2 (ClassEval_30_0.DataStatistics2Test.test_datastatistics2)
----------------------------------------------------------------------
Traceback (most recent call last):
  File "/Users/snigdhaghoshdastidar/Desktop/CS540/classeval_evaluation/ClassEval_30_0.py", line 177, in test_datastatistics2
    ds2 = DataStatistics2([1, 2, 3, 4])
          ^^^^^^^^^^^^^^^
NameError: name 'DataStatistics2' is not defined. Did you mean: 'DataStatistics2Test'?

----------------------------------------------------------------------
Ran 1 test in 0.003s

FAILED (errors=1)
.E.F.
======================================================================
ERROR: test_correlation_coefficient_2 (ClassEval_31_0.DataStatistics4TestCorrelationCoefficient.test_correlation_coefficient_2)
----------------------------------------------------------------------
Traceback (most recent call last):
  File "/Users/snigdhaghoshdastidar/Desktop/CS540/classeval_evaluation/ClassEval_31_0.py", line 79, in test_correlation_coefficient_2
    self.assertEqual(DataStatistics4.correlation_coefficient([1, 1, 1], [2, 2, 2]), 0)
                     ^^^^^^^^^^^^^^^^^^^^^^^^^^^^^^^^^^^^^^^^^^^^^^^^^^^^^^^^^^^^^
  File "/Users/snigdhaghoshdastidar/Desktop/CS540/classeval_evaluation/ClassEval_31_0.py", line 22, in correlation_coefficient
    correlation_coefficient = numerator / denominator
                              ~~~~~~~~~~^~~~~~~~~~~~~
ZeroDivisionError: float division by zero

======================================================================
FAIL: test_correlation_coefficient_4 (ClassEval_31_0.DataStatistics4TestCorrelationCoefficient.test_correlation_coefficient_4)
----------------------------------------------------------------------
Traceback (most recent call last):
  File "/Users/snigdhaghoshdastidar/Desktop/CS540/classeval_evaluation/ClassEval_31_0.py", line 85, in test_correlation_coefficient_4
    self.assertEqual(DataStatistics4.correlation_coefficient([1, 2, 3], [1, 2, 4]), 0.9819805060619659)
AssertionError: 0.9819805060619655 != 0.9819805060619659

----------------------------------------------------------------------
Ran 5 tests in 0.001s

FAILED (failures=1, errors=1)
FE.F.
======================================================================
ERROR: test_skewness_2 (ClassEval_31_0.DataStatistics4TestSkewness.test_skewness_2)
----------------------------------------------------------------------
Traceback (most recent call last):
  File "/Users/snigdhaghoshdastidar/Desktop/CS540/classeval_evaluation/ClassEval_31_0.py", line 96, in test_skewness_2
    self.assertEqual(DataStatistics4.skewness([1, 1, 1]), 0)
                     ^^^^^^^^^^^^^^^^^^^^^^^^^^^^^^^^^^^
  File "/Users/snigdhaghoshdastidar/Desktop/CS540/classeval_evaluation/ClassEval_31_0.py", line 37, in skewness
    skewness = sum((x - mean) ** 3 for x in data) / (n * std_dev ** 3)
               ~~~~~~~~~~~~~~~~~~~~~~~~~~~~~~~~~~~^~~~~~~~~~~~~~~~~~~~
ZeroDivisionError: float division by zero

======================================================================
FAIL: test_skewness (ClassEval_31_0.DataStatistics4TestSkewness.test_skewness)
----------------------------------------------------------------------
Traceback (most recent call last):
  File "/Users/snigdhaghoshdastidar/Desktop/CS540/classeval_evaluation/ClassEval_31_0.py", line 93, in test_skewness
    self.assertEqual(DataStatistics4.skewness([1, 2, 5]), 2.3760224064818463)
AssertionError: 0.528004979218188 != 2.3760224064818463

======================================================================
FAIL: test_skewness_4 (ClassEval_31_0.DataStatistics4TestSkewness.test_skewness_4)
----------------------------------------------------------------------
Traceback (most recent call last):
  File "/Users/snigdhaghoshdastidar/Desktop/CS540/classeval_evaluation/ClassEval_31_0.py", line 102, in test_skewness_4
    self.assertEqual(DataStatistics4.skewness([1, 2, 4]), 1.7181079837227264)
AssertionError: 0.38180177416060584 != 1.7181079837227264

----------------------------------------------------------------------
Ran 5 tests in 0.001s

FAILED (failures=2, errors=1)
.E.F.
======================================================================
ERROR: test_kurtosis_2 (ClassEval_31_0.DataStatistics4TestKurtosis.test_kurtosis_2)
----------------------------------------------------------------------
Traceback (most recent call last):
  File "/Users/snigdhaghoshdastidar/Desktop/CS540/classeval_evaluation/ClassEval_31_0.py", line 113, in test_kurtosis_2
    self.assertTrue(math.isnan(DataStatistics4.kurtosis([1, 1, 1])))
                               ^^^^^^^^^^^^^^^^^^^^^^^^^^^^^^^^^^^
  File "/Users/snigdhaghoshdastidar/Desktop/CS540/classeval_evaluation/ClassEval_31_0.py", line 52, in kurtosis
    kurtosis = sum((x - mean) ** 4 for x in data) / (n * std_dev ** 4) - 3
               ~~~~~~~~~~~~~~~~~~~~~~~~~~~~~~~~~~~^~~~~~~~~~~~~~~~~~~~
ZeroDivisionError: float division by zero

======================================================================
FAIL: test_kurtosis_4 (ClassEval_31_0.DataStatistics4TestKurtosis.test_kurtosis_4)
----------------------------------------------------------------------
Traceback (most recent call last):
  File "/Users/snigdhaghoshdastidar/Desktop/CS540/classeval_evaluation/ClassEval_31_0.py", line 119, in test_kurtosis_4
    self.assertEqual(DataStatistics4.kurtosis([1, 2, 4]), -1.4999999999999996)
AssertionError: -1.4999999999999998 != -1.4999999999999996

----------------------------------------------------------------------
Ran 5 tests in 0.001s

FAILED (failures=1, errors=1)
.....
----------------------------------------------------------------------
Ran 5 tests in 0.000s

OK
F
======================================================================
FAIL: test_main (ClassEval_31_0.DataStatistics4TestMain.test_main)
----------------------------------------------------------------------
Traceback (most recent call last):
  File "/Users/snigdhaghoshdastidar/Desktop/CS540/classeval_evaluation/ClassEval_31_0.py", line 150, in test_main
    self.assertEqual(DataStatistics4.skewness([1, 2, 5]), 2.3760224064818463)
AssertionError: 0.528004979218188 != 2.3760224064818463

----------------------------------------------------------------------
Ran 1 test in 0.000s

FAILED (failures=1)
EEEEE
======================================================================
ERROR: test_calculate_1 (ClassEval_39_0.ExpressionCalculatorTestCalculate.test_calculate_1)
----------------------------------------------------------------------
Traceback (most recent call last):
  File "/Users/snigdhaghoshdastidar/Desktop/CS540/classeval_evaluation/ClassEval_39_0.py", line 141, in test_calculate_1
    result = self.expression_calculator.calculate("2 + 3 * 4")
             ^^^^^^^^^^^^^^^^^^^^^^^^^^^^^^^^^^^^^^^^^^^^^^^^^
  File "/Users/snigdhaghoshdastidar/Desktop/CS540/classeval_evaluation/ClassEval_39_0.py", line 30, in calculate
    self.prepare(expression)
  File "/Users/snigdhaghoshdastidar/Desktop/CS540/classeval_evaluation/ClassEval_39_0.py", line 62, in prepare
    while operator_stack and self.compare(token, operator_stack[-1]):
                             ^^^^^^^^^^^^^^^^^^^^^^^^^^^^^^^^^^^^^^^
  File "/Users/snigdhaghoshdastidar/Desktop/CS540/classeval_evaluation/ClassEval_39_0.py", line 92, in compare
    return self.operat_priority.index(cur) >= self.operat_priority.index(peek)
           ^^^^^^^^^^^^^^^^^^^^^^^^^^^^^^^
ValueError: '*' is not in list

======================================================================
ERROR: test_calculate_2 (ClassEval_39_0.ExpressionCalculatorTestCalculate.test_calculate_2)
----------------------------------------------------------------------
Traceback (most recent call last):
  File "/Users/snigdhaghoshdastidar/Desktop/CS540/classeval_evaluation/ClassEval_39_0.py", line 145, in test_calculate_2
    result = self.expression_calculator.calculate("2 + 3 + 4")
             ^^^^^^^^^^^^^^^^^^^^^^^^^^^^^^^^^^^^^^^^^^^^^^^^^
  File "/Users/snigdhaghoshdastidar/Desktop/CS540/classeval_evaluation/ClassEval_39_0.py", line 30, in calculate
    self.prepare(expression)
  File "/Users/snigdhaghoshdastidar/Desktop/CS540/classeval_evaluation/ClassEval_39_0.py", line 62, in prepare
    while operator_stack and self.compare(token, operator_stack[-1]):
                             ^^^^^^^^^^^^^^^^^^^^^^^^^^^^^^^^^^^^^^^
  File "/Users/snigdhaghoshdastidar/Desktop/CS540/classeval_evaluation/ClassEval_39_0.py", line 92, in compare
    return self.operat_priority.index(cur) >= self.operat_priority.index(peek)
           ^^^^^^^^^^^^^^^^^^^^^^^^^^^^^^^
ValueError: '+' is not in list

======================================================================
ERROR: test_calculate_3 (ClassEval_39_0.ExpressionCalculatorTestCalculate.test_calculate_3)
----------------------------------------------------------------------
Traceback (most recent call last):
  File "/Users/snigdhaghoshdastidar/Desktop/CS540/classeval_evaluation/ClassEval_39_0.py", line 149, in test_calculate_3
    result = self.expression_calculator.calculate("2 * 3 * 4")
             ^^^^^^^^^^^^^^^^^^^^^^^^^^^^^^^^^^^^^^^^^^^^^^^^^
  File "/Users/snigdhaghoshdastidar/Desktop/CS540/classeval_evaluation/ClassEval_39_0.py", line 30, in calculate
    self.prepare(expression)
  File "/Users/snigdhaghoshdastidar/Desktop/CS540/classeval_evaluation/ClassEval_39_0.py", line 62, in prepare
    while operator_stack and self.compare(token, operator_stack[-1]):
                             ^^^^^^^^^^^^^^^^^^^^^^^^^^^^^^^^^^^^^^^
  File "/Users/snigdhaghoshdastidar/Desktop/CS540/classeval_evaluation/ClassEval_39_0.py", line 92, in compare
    return self.operat_priority.index(cur) >= self.operat_priority.index(peek)
           ^^^^^^^^^^^^^^^^^^^^^^^^^^^^^^^
ValueError: '*' is not in list

======================================================================
ERROR: test_calculate_4 (ClassEval_39_0.ExpressionCalculatorTestCalculate.test_calculate_4)
----------------------------------------------------------------------
Traceback (most recent call last):
  File "/Users/snigdhaghoshdastidar/Desktop/CS540/classeval_evaluation/ClassEval_39_0.py", line 153, in test_calculate_4
    result = self.expression_calculator.calculate("2 + 4 / 4")
             ^^^^^^^^^^^^^^^^^^^^^^^^^^^^^^^^^^^^^^^^^^^^^^^^^
  File "/Users/snigdhaghoshdastidar/Desktop/CS540/classeval_evaluation/ClassEval_39_0.py", line 30, in calculate
    self.prepare(expression)
  File "/Users/snigdhaghoshdastidar/Desktop/CS540/classeval_evaluation/ClassEval_39_0.py", line 62, in prepare
    while operator_stack and self.compare(token, operator_stack[-1]):
                             ^^^^^^^^^^^^^^^^^^^^^^^^^^^^^^^^^^^^^^^
  File "/Users/snigdhaghoshdastidar/Desktop/CS540/classeval_evaluation/ClassEval_39_0.py", line 92, in compare
    return self.operat_priority.index(cur) >= self.operat_priority.index(peek)
           ^^^^^^^^^^^^^^^^^^^^^^^^^^^^^^^
ValueError: '/' is not in list

======================================================================
ERROR: test_calculate_5 (ClassEval_39_0.ExpressionCalculatorTestCalculate.test_calculate_5)
----------------------------------------------------------------------
Traceback (most recent call last):
  File "/Users/snigdhaghoshdastidar/Desktop/CS540/classeval_evaluation/ClassEval_39_0.py", line 157, in test_calculate_5
    result = self.expression_calculator.calculate("(2 + 3) * 4")
             ^^^^^^^^^^^^^^^^^^^^^^^^^^^^^^^^^^^^^^^^^^^^^^^^^^^
  File "/Users/snigdhaghoshdastidar/Desktop/CS540/classeval_evaluation/ClassEval_39_0.py", line 30, in calculate
    self.prepare(expression)
  File "/Users/snigdhaghoshdastidar/Desktop/CS540/classeval_evaluation/ClassEval_39_0.py", line 62, in prepare
    while operator_stack and self.compare(token, operator_stack[-1]):
                             ^^^^^^^^^^^^^^^^^^^^^^^^^^^^^^^^^^^^^^^
  File "/Users/snigdhaghoshdastidar/Desktop/CS540/classeval_evaluation/ClassEval_39_0.py", line 92, in compare
    return self.operat_priority.index(cur) >= self.operat_priority.index(peek)
           ^^^^^^^^^^^^^^^^^^^^^^^^^^^^^^^
ValueError: '+' is not in list

----------------------------------------------------------------------
Ran 5 tests in 0.002s

FAILED (errors=5)
EEEEE.
======================================================================
ERROR: test_prepare_1 (ClassEval_39_0.ExpressionCalculatorTestPrepare.test_prepare_1)
----------------------------------------------------------------------
Traceback (most recent call last):
  File "/Users/snigdhaghoshdastidar/Desktop/CS540/classeval_evaluation/ClassEval_39_0.py", line 166, in test_prepare_1
    self.expression_calculator.prepare("2+3*4")
  File "/Users/snigdhaghoshdastidar/Desktop/CS540/classeval_evaluation/ClassEval_39_0.py", line 62, in prepare
    while operator_stack and self.compare(token, operator_stack[-1]):
                             ^^^^^^^^^^^^^^^^^^^^^^^^^^^^^^^^^^^^^^^
  File "/Users/snigdhaghoshdastidar/Desktop/CS540/classeval_evaluation/ClassEval_39_0.py", line 92, in compare
    return self.operat_priority.index(cur) >= self.operat_priority.index(peek)
           ^^^^^^^^^^^^^^^^^^^^^^^^^^^^^^^
ValueError: '*' is not in list

======================================================================
ERROR: test_prepare_2 (ClassEval_39_0.ExpressionCalculatorTestPrepare.test_prepare_2)
----------------------------------------------------------------------
Traceback (most recent call last):
  File "/Users/snigdhaghoshdastidar/Desktop/CS540/classeval_evaluation/ClassEval_39_0.py", line 170, in test_prepare_2
    self.expression_calculator.prepare("2+3/4")
  File "/Users/snigdhaghoshdastidar/Desktop/CS540/classeval_evaluation/ClassEval_39_0.py", line 62, in prepare
    while operator_stack and self.compare(token, operator_stack[-1]):
                             ^^^^^^^^^^^^^^^^^^^^^^^^^^^^^^^^^^^^^^^
  File "/Users/snigdhaghoshdastidar/Desktop/CS540/classeval_evaluation/ClassEval_39_0.py", line 92, in compare
    return self.operat_priority.index(cur) >= self.operat_priority.index(peek)
           ^^^^^^^^^^^^^^^^^^^^^^^^^^^^^^^
ValueError: '/' is not in list

======================================================================
ERROR: test_prepare_3 (ClassEval_39_0.ExpressionCalculatorTestPrepare.test_prepare_3)
----------------------------------------------------------------------
Traceback (most recent call last):
  File "/Users/snigdhaghoshdastidar/Desktop/CS540/classeval_evaluation/ClassEval_39_0.py", line 174, in test_prepare_3
    self.expression_calculator.prepare("2-3*4")
  File "/Users/snigdhaghoshdastidar/Desktop/CS540/classeval_evaluation/ClassEval_39_0.py", line 62, in prepare
    while operator_stack and self.compare(token, operator_stack[-1]):
                             ^^^^^^^^^^^^^^^^^^^^^^^^^^^^^^^^^^^^^^^
  File "/Users/snigdhaghoshdastidar/Desktop/CS540/classeval_evaluation/ClassEval_39_0.py", line 92, in compare
    return self.operat_priority.index(cur) >= self.operat_priority.index(peek)
           ^^^^^^^^^^^^^^^^^^^^^^^^^^^^^^^
ValueError: '*' is not in list

======================================================================
ERROR: test_prepare_4 (ClassEval_39_0.ExpressionCalculatorTestPrepare.test_prepare_4)
----------------------------------------------------------------------
Traceback (most recent call last):
  File "/Users/snigdhaghoshdastidar/Desktop/CS540/classeval_evaluation/ClassEval_39_0.py", line 178, in test_prepare_4
    self.expression_calculator.prepare("1+3*4")
  File "/Users/snigdhaghoshdastidar/Desktop/CS540/classeval_evaluation/ClassEval_39_0.py", line 62, in prepare
    while operator_stack and self.compare(token, operator_stack[-1]):
                             ^^^^^^^^^^^^^^^^^^^^^^^^^^^^^^^^^^^^^^^
  File "/Users/snigdhaghoshdastidar/Desktop/CS540/classeval_evaluation/ClassEval_39_0.py", line 92, in compare
    return self.operat_priority.index(cur) >= self.operat_priority.index(peek)
           ^^^^^^^^^^^^^^^^^^^^^^^^^^^^^^^
ValueError: '*' is not in list

======================================================================
ERROR: test_prepare_5 (ClassEval_39_0.ExpressionCalculatorTestPrepare.test_prepare_5)
----------------------------------------------------------------------
Traceback (most recent call last):
  File "/Users/snigdhaghoshdastidar/Desktop/CS540/classeval_evaluation/ClassEval_39_0.py", line 182, in test_prepare_5
    self.expression_calculator.prepare("(2+3)*4")
  File "/Users/snigdhaghoshdastidar/Desktop/CS540/classeval_evaluation/ClassEval_39_0.py", line 62, in prepare
    while operator_stack and self.compare(token, operator_stack[-1]):
                             ^^^^^^^^^^^^^^^^^^^^^^^^^^^^^^^^^^^^^^^
  File "/Users/snigdhaghoshdastidar/Desktop/CS540/classeval_evaluation/ClassEval_39_0.py", line 92, in compare
    return self.operat_priority.index(cur) >= self.operat_priority.index(peek)
           ^^^^^^^^^^^^^^^^^^^^^^^^^^^^^^^
ValueError: '+' is not in list

----------------------------------------------------------------------
Ran 6 tests in 0.001s

FAILED (errors=5)
.....
----------------------------------------------------------------------
Ran 5 tests in 0.000s

OK
EEEEEEE
======================================================================
ERROR: test_compare_1 (ClassEval_39_0.ExpressionCalculatorTestCompare.test_compare_1)
----------------------------------------------------------------------
Traceback (most recent call last):
  File "/Users/snigdhaghoshdastidar/Desktop/CS540/classeval_evaluation/ClassEval_39_0.py", line 215, in test_compare_1
    result = self.expression_calculator.compare("+", "-")
             ^^^^^^^^^^^^^^^^^^^^^^^^^^^^^^^^^^^^^^^^^^^^
  File "/Users/snigdhaghoshdastidar/Desktop/CS540/classeval_evaluation/ClassEval_39_0.py", line 92, in compare
    return self.operat_priority.index(cur) >= self.operat_priority.index(peek)
           ^^^^^^^^^^^^^^^^^^^^^^^^^^^^^^^
ValueError: '+' is not in list

======================================================================
ERROR: test_compare_2 (ClassEval_39_0.ExpressionCalculatorTestCompare.test_compare_2)
----------------------------------------------------------------------
Traceback (most recent call last):
  File "/Users/snigdhaghoshdastidar/Desktop/CS540/classeval_evaluation/ClassEval_39_0.py", line 219, in test_compare_2
    result = self.expression_calculator.compare("*", "/")
             ^^^^^^^^^^^^^^^^^^^^^^^^^^^^^^^^^^^^^^^^^^^^
  File "/Users/snigdhaghoshdastidar/Desktop/CS540/classeval_evaluation/ClassEval_39_0.py", line 92, in compare
    return self.operat_priority.index(cur) >= self.operat_priority.index(peek)
           ^^^^^^^^^^^^^^^^^^^^^^^^^^^^^^^
ValueError: '*' is not in list

======================================================================
ERROR: test_compare_3 (ClassEval_39_0.ExpressionCalculatorTestCompare.test_compare_3)
----------------------------------------------------------------------
Traceback (most recent call last):
  File "/Users/snigdhaghoshdastidar/Desktop/CS540/classeval_evaluation/ClassEval_39_0.py", line 223, in test_compare_3
    result = self.expression_calculator.compare("+", "*")
             ^^^^^^^^^^^^^^^^^^^^^^^^^^^^^^^^^^^^^^^^^^^^
  File "/Users/snigdhaghoshdastidar/Desktop/CS540/classeval_evaluation/ClassEval_39_0.py", line 92, in compare
    return self.operat_priority.index(cur) >= self.operat_priority.index(peek)
           ^^^^^^^^^^^^^^^^^^^^^^^^^^^^^^^
ValueError: '+' is not in list

======================================================================
ERROR: test_compare_4 (ClassEval_39_0.ExpressionCalculatorTestCompare.test_compare_4)
----------------------------------------------------------------------
Traceback (most recent call last):
  File "/Users/snigdhaghoshdastidar/Desktop/CS540/classeval_evaluation/ClassEval_39_0.py", line 227, in test_compare_4
    result = self.expression_calculator.compare("*", "+")
             ^^^^^^^^^^^^^^^^^^^^^^^^^^^^^^^^^^^^^^^^^^^^
  File "/Users/snigdhaghoshdastidar/Desktop/CS540/classeval_evaluation/ClassEval_39_0.py", line 92, in compare
    return self.operat_priority.index(cur) >= self.operat_priority.index(peek)
           ^^^^^^^^^^^^^^^^^^^^^^^^^^^^^^^
ValueError: '*' is not in list

======================================================================
ERROR: test_compare_5 (ClassEval_39_0.ExpressionCalculatorTestCompare.test_compare_5)
----------------------------------------------------------------------
Traceback (most recent call last):
  File "/Users/snigdhaghoshdastidar/Desktop/CS540/classeval_evaluation/ClassEval_39_0.py", line 231, in test_compare_5
    result = self.expression_calculator.compare("/", "+")
             ^^^^^^^^^^^^^^^^^^^^^^^^^^^^^^^^^^^^^^^^^^^^
  File "/Users/snigdhaghoshdastidar/Desktop/CS540/classeval_evaluation/ClassEval_39_0.py", line 92, in compare
    return self.operat_priority.index(cur) >= self.operat_priority.index(peek)
           ^^^^^^^^^^^^^^^^^^^^^^^^^^^^^^^
ValueError: '/' is not in list

======================================================================
ERROR: test_compare_6 (ClassEval_39_0.ExpressionCalculatorTestCompare.test_compare_6)
----------------------------------------------------------------------
Traceback (most recent call last):
  File "/Users/snigdhaghoshdastidar/Desktop/CS540/classeval_evaluation/ClassEval_39_0.py", line 235, in test_compare_6
    result = self.expression_calculator.compare("%", "+")
             ^^^^^^^^^^^^^^^^^^^^^^^^^^^^^^^^^^^^^^^^^^^^
  File "/Users/snigdhaghoshdastidar/Desktop/CS540/classeval_evaluation/ClassEval_39_0.py", line 92, in compare
    return self.operat_priority.index(cur) >= self.operat_priority.index(peek)
           ^^^^^^^^^^^^^^^^^^^^^^^^^^^^^^^
ValueError: '%' is not in list

======================================================================
ERROR: test_compare_7 (ClassEval_39_0.ExpressionCalculatorTestCompare.test_compare_7)
----------------------------------------------------------------------
Traceback (most recent call last):
  File "/Users/snigdhaghoshdastidar/Desktop/CS540/classeval_evaluation/ClassEval_39_0.py", line 239, in test_compare_7
    result = self.expression_calculator.compare("+", "%")
             ^^^^^^^^^^^^^^^^^^^^^^^^^^^^^^^^^^^^^^^^^^^^
  File "/Users/snigdhaghoshdastidar/Desktop/CS540/classeval_evaluation/ClassEval_39_0.py", line 92, in compare
    return self.operat_priority.index(cur) >= self.operat_priority.index(peek)
           ^^^^^^^^^^^^^^^^^^^^^^^^^^^^^^^
ValueError: '+' is not in list

----------------------------------------------------------------------
Ran 7 tests in 0.002s

FAILED (errors=7)
.......
----------------------------------------------------------------------
Ran 7 tests in 0.001s

OK
....FF
======================================================================
FAIL: test_transform_5 (ClassEval_39_0.ExpressionCalculatorTestTransform.test_transform_5)
----------------------------------------------------------------------
Traceback (most recent call last):
  File "/Users/snigdhaghoshdastidar/Desktop/CS540/classeval_evaluation/ClassEval_39_0.py", line 300, in test_transform_5
    self.assertEqual(result, "~2+(~3)*4")
AssertionError: '-2+(-3)*4' != '~2+(~3)*4'
- -2+(-3)*4
? ^   ^
+ ~2+(~3)*4
? ^   ^


======================================================================
FAIL: test_transform_6 (ClassEval_39_0.ExpressionCalculatorTestTransform.test_transform_6)
----------------------------------------------------------------------
Traceback (most recent call last):
  File "/Users/snigdhaghoshdastidar/Desktop/CS540/classeval_evaluation/ClassEval_39_0.py", line 304, in test_transform_6
    self.assertEqual(result, "0-(1+1)")
AssertionError: '~(1+1)' != '0-(1+1)'
- ~(1+1)
? ^
+ 0-(1+1)
? ^^


----------------------------------------------------------------------
Ran 6 tests in 0.001s

FAILED (failures=2)
E
======================================================================
ERROR: test_ExpressionCalculator (ClassEval_39_0.ExpressionCalculatorTest.test_ExpressionCalculator)
----------------------------------------------------------------------
Traceback (most recent call last):
  File "/Users/snigdhaghoshdastidar/Desktop/CS540/classeval_evaluation/ClassEval_39_0.py", line 312, in test_ExpressionCalculator
    result = self.expression_calculator.calculate("2 + 3 * 4")
             ^^^^^^^^^^^^^^^^^^^^^^^^^^^^^^^^^^^^^^^^^^^^^^^^^
  File "/Users/snigdhaghoshdastidar/Desktop/CS540/classeval_evaluation/ClassEval_39_0.py", line 30, in calculate
    self.prepare(expression)
  File "/Users/snigdhaghoshdastidar/Desktop/CS540/classeval_evaluation/ClassEval_39_0.py", line 62, in prepare
    while operator_stack and self.compare(token, operator_stack[-1]):
                             ^^^^^^^^^^^^^^^^^^^^^^^^^^^^^^^^^^^^^^^
  File "/Users/snigdhaghoshdastidar/Desktop/CS540/classeval_evaluation/ClassEval_39_0.py", line 92, in compare
    return self.operat_priority.index(cur) >= self.operat_priority.index(peek)
           ^^^^^^^^^^^^^^^^^^^^^^^^^^^^^^^
ValueError: '*' is not in list

----------------------------------------------------------------------
Ran 1 test in 0.000s

FAILED (errors=1)
FFFFF
======================================================================
FAIL: test_kappa_1 (ClassEval_51_0.KappaCalculatorTestKappa.test_kappa_1)
----------------------------------------------------------------------
Traceback (most recent call last):
  File "/Users/snigdhaghoshdastidar/Desktop/CS540/classeval_evaluation/ClassEval_51_0.py", line 60, in test_kappa_1
    self.assertEqual(KappaCalculator.kappa([[2, 1, 1], [1, 2, 1], [1, 1, 2]], 3), 0.25)
AssertionError: 0.48571428571428577 != 0.25

======================================================================
FAIL: test_kappa_2 (ClassEval_51_0.KappaCalculatorTestKappa.test_kappa_2)
----------------------------------------------------------------------
Traceback (most recent call last):
  File "/Users/snigdhaghoshdastidar/Desktop/CS540/classeval_evaluation/ClassEval_51_0.py", line 63, in test_kappa_2
    self.assertAlmostEqual(KappaCalculator.kappa([[2, 2, 1], [1, 2, 1], [1, 1, 2]], 3), 0.19469026548672572)
AssertionError: 0.44745446053246146 != 0.19469026548672572 within 7 places (0.2527641950457358 difference)

======================================================================
FAIL: test_kappa_3 (ClassEval_51_0.KappaCalculatorTestKappa.test_kappa_3)
----------------------------------------------------------------------
Traceback (most recent call last):
  File "/Users/snigdhaghoshdastidar/Desktop/CS540/classeval_evaluation/ClassEval_51_0.py", line 66, in test_kappa_3
    self.assertAlmostEqual(KappaCalculator.kappa([[2, 1, 2], [1, 2, 1], [1, 1, 2]], 3), 0.19469026548672572)
AssertionError: 0.44745446053246146 != 0.19469026548672572 within 7 places (0.2527641950457358 difference)

======================================================================
FAIL: test_kappa_4 (ClassEval_51_0.KappaCalculatorTestKappa.test_kappa_4)
----------------------------------------------------------------------
Traceback (most recent call last):
  File "/Users/snigdhaghoshdastidar/Desktop/CS540/classeval_evaluation/ClassEval_51_0.py", line 69, in test_kappa_4
    self.assertAlmostEqual(KappaCalculator.kappa([[2, 1, 1], [2, 2, 1], [1, 1, 2]], 3), 0.19469026548672572)
AssertionError: 0.44745446053246146 != 0.19469026548672572 within 7 places (0.2527641950457358 difference)

======================================================================
FAIL: test_kappa_5 (ClassEval_51_0.KappaCalculatorTestKappa.test_kappa_5)
----------------------------------------------------------------------
Traceback (most recent call last):
  File "/Users/snigdhaghoshdastidar/Desktop/CS540/classeval_evaluation/ClassEval_51_0.py", line 72, in test_kappa_5
    self.assertAlmostEqual(KappaCalculator.kappa([[2, 1, 1], [1, 2, 2], [1, 1, 2]], 3), 0.19469026548672572)
AssertionError: 0.44745446053246146 != 0.19469026548672572 within 7 places (0.2527641950457358 difference)

----------------------------------------------------------------------
Ran 5 tests in 0.002s

FAILED (failures=5)
EEEEE
======================================================================
ERROR: test_fleiss_kappa_1 (ClassEval_51_0.KappaCalculatorTestFleissKappa.test_fleiss_kappa_1)
----------------------------------------------------------------------
Traceback (most recent call last):
  File "/Users/snigdhaghoshdastidar/Desktop/CS540/classeval_evaluation/ClassEval_51_0.py", line 77, in test_fleiss_kappa_1
    self.assertEqual(KappaCalculator.fleiss_kappa([[0, 0, 0, 0, 14],
                     ^^^^^^^^^^^^^^^^^^^^^^^^^^^^^^^^^^^^^^^^^^^^^^^
  File "/Users/snigdhaghoshdastidar/Desktop/CS540/classeval_evaluation/ClassEval_51_0.py", line 50, in fleiss_kappa
    observed_agreement = np.sum(np.sum(testData * testData, axis=1) - n) / (n * (n - 1))
                                       ~~~~~~~~~^~~~~~~~~~
TypeError: can't multiply sequence by non-int of type 'list'

======================================================================
ERROR: test_fleiss_kappa_2 (ClassEval_51_0.KappaCalculatorTestFleissKappa.test_fleiss_kappa_2)
----------------------------------------------------------------------
Traceback (most recent call last):
  File "/Users/snigdhaghoshdastidar/Desktop/CS540/classeval_evaluation/ClassEval_51_0.py", line 89, in test_fleiss_kappa_2
    self.assertEqual(KappaCalculator.fleiss_kappa([[1, 0, 0, 0, 14],
                     ^^^^^^^^^^^^^^^^^^^^^^^^^^^^^^^^^^^^^^^^^^^^^^^
  File "/Users/snigdhaghoshdastidar/Desktop/CS540/classeval_evaluation/ClassEval_51_0.py", line 50, in fleiss_kappa
    observed_agreement = np.sum(np.sum(testData * testData, axis=1) - n) / (n * (n - 1))
                                       ~~~~~~~~~^~~~~~~~~~
TypeError: can't multiply sequence by non-int of type 'list'

======================================================================
ERROR: test_fleiss_kappa_3 (ClassEval_51_0.KappaCalculatorTestFleissKappa.test_fleiss_kappa_3)
----------------------------------------------------------------------
Traceback (most recent call last):
  File "/Users/snigdhaghoshdastidar/Desktop/CS540/classeval_evaluation/ClassEval_51_0.py", line 101, in test_fleiss_kappa_3
    self.assertEqual(KappaCalculator.fleiss_kappa([[0, 1, 0, 0, 14],
                     ^^^^^^^^^^^^^^^^^^^^^^^^^^^^^^^^^^^^^^^^^^^^^^^
  File "/Users/snigdhaghoshdastidar/Desktop/CS540/classeval_evaluation/ClassEval_51_0.py", line 50, in fleiss_kappa
    observed_agreement = np.sum(np.sum(testData * testData, axis=1) - n) / (n * (n - 1))
                                       ~~~~~~~~~^~~~~~~~~~
TypeError: can't multiply sequence by non-int of type 'list'

======================================================================
ERROR: test_fleiss_kappa_4 (ClassEval_51_0.KappaCalculatorTestFleissKappa.test_fleiss_kappa_4)
----------------------------------------------------------------------
Traceback (most recent call last):
  File "/Users/snigdhaghoshdastidar/Desktop/CS540/classeval_evaluation/ClassEval_51_0.py", line 113, in test_fleiss_kappa_4
    self.assertEqual(KappaCalculator.fleiss_kappa([[0, 0, 1, 0, 14],
                     ^^^^^^^^^^^^^^^^^^^^^^^^^^^^^^^^^^^^^^^^^^^^^^^
  File "/Users/snigdhaghoshdastidar/Desktop/CS540/classeval_evaluation/ClassEval_51_0.py", line 50, in fleiss_kappa
    observed_agreement = np.sum(np.sum(testData * testData, axis=1) - n) / (n * (n - 1))
                                       ~~~~~~~~~^~~~~~~~~~
TypeError: can't multiply sequence by non-int of type 'list'

======================================================================
ERROR: test_fleiss_kappa_5 (ClassEval_51_0.KappaCalculatorTestFleissKappa.test_fleiss_kappa_5)
----------------------------------------------------------------------
Traceback (most recent call last):
  File "/Users/snigdhaghoshdastidar/Desktop/CS540/classeval_evaluation/ClassEval_51_0.py", line 125, in test_fleiss_kappa_5
    self.assertEqual(KappaCalculator.fleiss_kappa([[0, 0, 0, 1, 14],
                     ^^^^^^^^^^^^^^^^^^^^^^^^^^^^^^^^^^^^^^^^^^^^^^^
  File "/Users/snigdhaghoshdastidar/Desktop/CS540/classeval_evaluation/ClassEval_51_0.py", line 50, in fleiss_kappa
    observed_agreement = np.sum(np.sum(testData * testData, axis=1) - n) / (n * (n - 1))
                                       ~~~~~~~~~^~~~~~~~~~
TypeError: can't multiply sequence by non-int of type 'list'

----------------------------------------------------------------------
Ran 5 tests in 0.001s

FAILED (errors=5)
F
======================================================================
FAIL: test_kappacalculator (ClassEval_51_0.KappaCalculatorTest.test_kappacalculator)
----------------------------------------------------------------------
Traceback (most recent call last):
  File "/Users/snigdhaghoshdastidar/Desktop/CS540/classeval_evaluation/ClassEval_51_0.py", line 139, in test_kappacalculator
    self.assertEqual(KappaCalculator.kappa([[2, 1, 1], [1, 2, 1], [1, 1, 2]], 3), 0.25)
AssertionError: 0.48571428571428577 != 0.25

----------------------------------------------------------------------
Ran 1 test in 0.001s

FAILED (failures=1)
.....
----------------------------------------------------------------------
Ran 5 tests in 0.000s

OK
......
----------------------------------------------------------------------
Ran 6 tests in 0.000s

OK
......
----------------------------------------------------------------------
Ran 6 tests in 0.000s

OK
......
----------------------------------------------------------------------
Ran 6 tests in 0.000s

OK
.F....
======================================================================
FAIL: test_accuracy_2 (ClassEval_56_0.MetricsCalculatorTestAccuracy.test_accuracy_2)
----------------------------------------------------------------------
Traceback (most recent call last):
  File "/Users/snigdhaghoshdastidar/Desktop/CS540/classeval_evaluation/ClassEval_56_0.py", line 239, in test_accuracy_2
    self.assertAlmostEqual(temp, 0.3333333333333333)
AssertionError: 0.25 != 0.3333333333333333 within 7 places (0.08333333333333331 difference)

----------------------------------------------------------------------
Ran 6 tests in 0.001s

FAILED (failures=1)
F
======================================================================
FAIL: test_metricscalculator (ClassEval_56_0.MetricsCalculatorTest.test_metricscalculator)
----------------------------------------------------------------------
Traceback (most recent call last):
  File "/Users/snigdhaghoshdastidar/Desktop/CS540/classeval_evaluation/ClassEval_56_0.py", line 275, in test_metricscalculator
    self.assertEqual(temp, 0.5)
AssertionError: 3.0 != 0.5

----------------------------------------------------------------------
Ran 1 test in 0.000s

FAILED (failures=1)
EEFFF.FF
======================================================================
ERROR: test_mrr_1 (ClassEval_57_0.MetricsCalculator2TestMrr.test_mrr_1)
----------------------------------------------------------------------
Traceback (most recent call last):
  File "/Users/snigdhaghoshdastidar/Desktop/CS540/classeval_evaluation/ClassEval_57_0.py", line 100, in test_mrr_1
    res1, res2 = MetricsCalculator2.mrr(([1, 0, 1, 0], 4))
    ^^^^^^^^^^
TypeError: cannot unpack non-iterable float object

======================================================================
ERROR: test_mrr_2 (ClassEval_57_0.MetricsCalculator2TestMrr.test_mrr_2)
----------------------------------------------------------------------
Traceback (most recent call last):
  File "/Users/snigdhaghoshdastidar/Desktop/CS540/classeval_evaluation/ClassEval_57_0.py", line 105, in test_mrr_2
    res1, res2 = MetricsCalculator2.mrr(([0, 0, 0, 1], 4))
    ^^^^^^^^^^
TypeError: cannot unpack non-iterable float object

======================================================================
FAIL: test_mrr_3 (ClassEval_57_0.MetricsCalculator2TestMrr.test_mrr_3)
----------------------------------------------------------------------
Traceback (most recent call last):
  File "/Users/snigdhaghoshdastidar/Desktop/CS540/classeval_evaluation/ClassEval_57_0.py", line 112, in test_mrr_3
    self.assertEqual(res2, [1.0, 0.5])
AssertionError: Lists differ: [1, 1] != [1.0, 0.5]

First differing element 1:
1
0.5

- [1, 1]
+ [1.0, 0.5]

======================================================================
FAIL: test_mrr_4 (ClassEval_57_0.MetricsCalculator2TestMrr.test_mrr_4)
----------------------------------------------------------------------
Traceback (most recent call last):
  File "/Users/snigdhaghoshdastidar/Desktop/CS540/classeval_evaluation/ClassEval_57_0.py", line 117, in test_mrr_4
    self.assertEqual(res2, [1.0, 0.25])
AssertionError: Lists differ: [1, 1] != [1.0, 0.25]

First differing element 1:
1
0.25

- [1, 1]
+ [1.0, 0.25]

======================================================================
FAIL: test_mrr_5 (ClassEval_57_0.MetricsCalculator2TestMrr.test_mrr_5)
----------------------------------------------------------------------
Traceback (most recent call last):
  File "/Users/snigdhaghoshdastidar/Desktop/CS540/classeval_evaluation/ClassEval_57_0.py", line 122, in test_mrr_5
    self.assertEqual(res2, [1.0, 0.5])
AssertionError: Lists differ: [1, 1] != [1.0, 0.5]

First differing element 1:
1
0.5

- [1, 1]
+ [1.0, 0.5]

======================================================================
FAIL: test_mrr_7 (ClassEval_57_0.MetricsCalculator2TestMrr.test_mrr_7)
----------------------------------------------------------------------
Traceback (most recent call last):
  File "/Users/snigdhaghoshdastidar/Desktop/CS540/classeval_evaluation/ClassEval_57_0.py", line 132, in test_mrr_7
    self.assertEqual(res1, 0.0)
AssertionError: nan != 0.0

======================================================================
FAIL: test_mrr_8 (ClassEval_57_0.MetricsCalculator2TestMrr.test_mrr_8)
----------------------------------------------------------------------
Traceback (most recent call last):
  File "/Users/snigdhaghoshdastidar/Desktop/CS540/classeval_evaluation/ClassEval_57_0.py", line 137, in test_mrr_8
    self.assertEqual(res1, 0.0)
AssertionError: 0.75 != 0.0

----------------------------------------------------------------------
Ran 8 tests in 0.005s

FAILED (failures=5, errors=2)
EE....FE
======================================================================
ERROR: test_map_1 (ClassEval_57_0.MetricsCalculator2TestMap.test_map_1)
----------------------------------------------------------------------
Traceback (most recent call last):
  File "/Users/snigdhaghoshdastidar/Desktop/CS540/classeval_evaluation/ClassEval_57_0.py", line 143, in test_map_1
    res1, res2 = MetricsCalculator2.map(([1, 0, 1, 0], 4))
    ^^^^^^^^^^
TypeError: cannot unpack non-iterable float object

======================================================================
ERROR: test_map_2 (ClassEval_57_0.MetricsCalculator2TestMap.test_map_2)
----------------------------------------------------------------------
Traceback (most recent call last):
  File "/Users/snigdhaghoshdastidar/Desktop/CS540/classeval_evaluation/ClassEval_57_0.py", line 148, in test_map_2
    res1, res2 = MetricsCalculator2.map(([0, 0, 0, 1], 4))
    ^^^^^^^^^^
TypeError: cannot unpack non-iterable float object

======================================================================
ERROR: test_map_8 (ClassEval_57_0.MetricsCalculator2TestMap.test_map_8)
----------------------------------------------------------------------
Traceback (most recent call last):
  File "/Users/snigdhaghoshdastidar/Desktop/CS540/classeval_evaluation/ClassEval_57_0.py", line 179, in test_map_8
    res1, res2 = MetricsCalculator2.map([([1, 0, 1, 1], 0), ([0, 1, 0, 0], 0)])
                 ^^^^^^^^^^^^^^^^^^^^^^^^^^^^^^^^^^^^^^^^^^^^^^^^^^^^^^^^^^^^^^
  File "/Users/snigdhaghoshdastidar/Desktop/CS540/classeval_evaluation/ClassEval_57_0.py", line 89, in map
    average_precision /= ground_truth_num
ZeroDivisionError: float division by zero

======================================================================
FAIL: test_map_7 (ClassEval_57_0.MetricsCalculator2TestMap.test_map_7)
----------------------------------------------------------------------
Traceback (most recent call last):
  File "/Users/snigdhaghoshdastidar/Desktop/CS540/classeval_evaluation/ClassEval_57_0.py", line 175, in test_map_7
    self.assertEqual(res1, 0.0)
AssertionError: nan != 0.0

----------------------------------------------------------------------
Ran 8 tests in 0.003s

FAILED (failures=1, errors=3)
EFE.
======================================================================
ERROR: test_metricscalculator2_1 (ClassEval_57_0.MetricsCalculator2Test.test_metricscalculator2_1)
----------------------------------------------------------------------
Traceback (most recent call last):
  File "/Users/snigdhaghoshdastidar/Desktop/CS540/classeval_evaluation/ClassEval_57_0.py", line 186, in test_metricscalculator2_1
    res1, res2 = MetricsCalculator2.mrr(([1, 0, 1, 0], 4))
    ^^^^^^^^^^
TypeError: cannot unpack non-iterable float object

======================================================================
ERROR: test_metricscalculator2_3 (ClassEval_57_0.MetricsCalculator2Test.test_metricscalculator2_3)
----------------------------------------------------------------------
Traceback (most recent call last):
  File "/Users/snigdhaghoshdastidar/Desktop/CS540/classeval_evaluation/ClassEval_57_0.py", line 196, in test_metricscalculator2_3
    res1, res2 = MetricsCalculator2.map(([1, 0, 1, 0], 4))
    ^^^^^^^^^^
TypeError: cannot unpack non-iterable float object

======================================================================
FAIL: test_metricscalculator2_2 (ClassEval_57_0.MetricsCalculator2Test.test_metricscalculator2_2)
----------------------------------------------------------------------
Traceback (most recent call last):
  File "/Users/snigdhaghoshdastidar/Desktop/CS540/classeval_evaluation/ClassEval_57_0.py", line 193, in test_metricscalculator2_2
    self.assertEqual(res2, [1.0, 0.5])
AssertionError: Lists differ: [1, 1] != [1.0, 0.5]

First differing element 1:
1
0.5

- [1, 1]
+ [1.0, 0.5]

----------------------------------------------------------------------
Ran 4 tests in 0.001s

FAILED (failures=1, errors=2)
.....
----------------------------------------------------------------------
Ran 5 tests in 0.000s

OK
.....
----------------------------------------------------------------------
Ran 5 tests in 0.000s

OK
...EE
======================================================================
ERROR: test_correlation_4 (ClassEval_81_0.Statistics3TestCorrelation.test_correlation_4)
----------------------------------------------------------------------
Traceback (most recent call last):
  File "/Users/snigdhaghoshdastidar/Desktop/CS540/classeval_evaluation/ClassEval_81_0.py", line 196, in test_correlation_4
    self.assertEqual(statistics3.correlation([1, 1,1], [2,2,2]), None)
                     ^^^^^^^^^^^^^^^^^^^^^^^^^^^^^^^^^^^^^^^^^^
  File "/Users/snigdhaghoshdastidar/Desktop/CS540/classeval_evaluation/ClassEval_81_0.py", line 70, in correlation
    correlation = numerator / denominator
                  ~~~~~~~~~~^~~~~~~~~~~~~
ZeroDivisionError: float division by zero

======================================================================
ERROR: test_correlation_5 (ClassEval_81_0.Statistics3TestCorrelation.test_correlation_5)
----------------------------------------------------------------------
Traceback (most recent call last):
  File "/Users/snigdhaghoshdastidar/Desktop/CS540/classeval_evaluation/ClassEval_81_0.py", line 200, in test_correlation_5
    self.assertEqual(statistics3.correlation([1, 1,1], [1,1,1]), None)
                     ^^^^^^^^^^^^^^^^^^^^^^^^^^^^^^^^^^^^^^^^^^
  File "/Users/snigdhaghoshdastidar/Desktop/CS540/classeval_evaluation/ClassEval_81_0.py", line 70, in correlation
    correlation = numerator / denominator
                  ~~~~~~~~~~^~~~~~~~~~~~~
ZeroDivisionError: float division by zero

----------------------------------------------------------------------
Ran 5 tests in 0.001s

FAILED (errors=2)
.E...
======================================================================
ERROR: test_mean_2 (ClassEval_81_0.Statistics3TestMean.test_mean_2)
----------------------------------------------------------------------
Traceback (most recent call last):
  File "/Users/snigdhaghoshdastidar/Desktop/CS540/classeval_evaluation/ClassEval_81_0.py", line 209, in test_mean_2
    self.assertEqual(statistics3.mean([]), None)
                     ^^^^^^^^^^^^^^^^^^^^
  File "/Users/snigdhaghoshdastidar/Desktop/CS540/classeval_evaluation/ClassEval_81_0.py", line 84, in mean
    mean = sum(data) / len(data)
           ~~~~~~~~~~^~~~~~~~~~~
ZeroDivisionError: division by zero

----------------------------------------------------------------------
Ran 5 tests in 0.001s

FAILED (errors=1)
.FFFF
======================================================================
FAIL: test_correlation_matrix_2 (ClassEval_81_0.Statistics3TestCorrelationMatrix.test_correlation_matrix_2)
----------------------------------------------------------------------
Traceback (most recent call last):
  File "/Users/snigdhaghoshdastidar/Desktop/CS540/classeval_evaluation/ClassEval_81_0.py", line 230, in test_correlation_matrix_2
    self.assertEqual(statistics3.correlation_matrix([[1, 2, 3], [4, 5, 6]]), [[1.0, 1.0, 1.0], [1.0, 1.0, 1.0], [1.0, 1.0, 1.0]])
AssertionError: Lists differ: [[1.0, 1.0], [1.0, 1.0]] != [[1.0, 1.0, 1.0], [1.0, 1.0, 1.0], [1.0, 1.0, 1.0]]

First differing element 0:
[1.0, 1.0]
[1.0, 1.0, 1.0]

Second list contains 1 additional elements.
First extra element 2:
[1.0, 1.0, 1.0]

- [[1.0, 1.0], [1.0, 1.0]]
+ [[1.0, 1.0, 1.0], [1.0, 1.0, 1.0], [1.0, 1.0, 1.0]]

======================================================================
FAIL: test_correlation_matrix_3 (ClassEval_81_0.Statistics3TestCorrelationMatrix.test_correlation_matrix_3)
----------------------------------------------------------------------
Traceback (most recent call last):
  File "/Users/snigdhaghoshdastidar/Desktop/CS540/classeval_evaluation/ClassEval_81_0.py", line 234, in test_correlation_matrix_3
    self.assertEqual(statistics3.correlation_matrix([[1, 2, 3]]), [[None, None, None], [None, None, None], [None, None, None]])
AssertionError: Lists differ: [[1.0]] != [[None, None, None], [None, None, None], [None, None, None]]

First differing element 0:
[1.0]
[None, None, None]

Second list contains 2 additional elements.
First extra element 1:
[None, None, None]

- [[1.0]]
+ [[None, None, None], [None, None, None], [None, None, None]]

======================================================================
FAIL: test_correlation_matrix_4 (ClassEval_81_0.Statistics3TestCorrelationMatrix.test_correlation_matrix_4)
----------------------------------------------------------------------
Traceback (most recent call last):
  File "/Users/snigdhaghoshdastidar/Desktop/CS540/classeval_evaluation/ClassEval_81_0.py", line 238, in test_correlation_matrix_4
    self.assertEqual(statistics3.correlation_matrix([[1, 2, 3], [4, 5, 6], [7, 8, 9], [10, 11,12]]), [[1.0, 1.0, 1.0], [1.0, 1.0, 1.0], [1.0, 1.0, 1.0]])
AssertionError: Lists differ: [[1.0, 1.0, 1.0, 1.0], [1.0, 1.0, 1.0, 1.0], [1.0, 1.0, [27 chars]1.0]] != [[1.0, 1.0, 1.0], [1.0, 1.0, 1.0], [1.0, 1.0, 1.0]]

First differing element 0:
[1.0, 1.0, 1.0, 1.0]
[1.0, 1.0, 1.0]

First list contains 1 additional elements.
First extra element 3:
[1.0, 1.0, 1.0, 1.0]

+ [[1.0, 1.0, 1.0], [1.0, 1.0, 1.0], [1.0, 1.0, 1.0]]
- [[1.0, 1.0, 1.0, 1.0],
-  [1.0, 1.0, 1.0, 1.0],
-  [1.0, 1.0, 1.0, 1.0],
-  [1.0, 1.0, 1.0, 1.0]]

======================================================================
FAIL: test_correlation_matrix_5 (ClassEval_81_0.Statistics3TestCorrelationMatrix.test_correlation_matrix_5)
----------------------------------------------------------------------
Traceback (most recent call last):
  File "/Users/snigdhaghoshdastidar/Desktop/CS540/classeval_evaluation/ClassEval_81_0.py", line 242, in test_correlation_matrix_5
    self.assertEqual(statistics3.correlation_matrix([[1, 2, 3], [4, 5, 6], [7, 8, 9], [10, 11,12], [13, 14, 15]]), [[1.0, 1.0, 1.0], [1.0, 1.0, 1.0], [1.0, 1.0, 1.0]])
AssertionError: Lists differ: [[1.0, 1.0, 1.0, 1.0, 1.0], [1.0, 1.0, 1.0, 1.0, 1.0], [[74 chars]1.0]] != [[1.0, 1.0, 1.0], [1.0, 1.0, 1.0], [1.0, 1.0, 1.0]]

First differing element 0:
[1.0, 1.0, 1.0, 1.0, 1.0]
[1.0, 1.0, 1.0]

First list contains 2 additional elements.
First extra element 3:
[1.0, 1.0, 1.0, 1.0, 1.0]

+ [[1.0, 1.0, 1.0], [1.0, 1.0, 1.0], [1.0, 1.0, 1.0]]
- [[1.0, 1.0, 1.0, 1.0, 1.0],
-  [1.0, 1.0, 1.0, 1.0, 1.0],
-  [1.0, 1.0, 1.0, 1.0, 1.0],
-  [1.0, 1.0, 1.0, 1.0, 1.0],
-  [1.0, 1.0, 1.0, 1.0, 1.0]]

----------------------------------------------------------------------
Ran 5 tests in 0.002s

FAILED (failures=4)
F...F
======================================================================
FAIL: test_standard_deviation (ClassEval_81_0.Statistics3TestStandardDeviation.test_standard_deviation)
----------------------------------------------------------------------
Traceback (most recent call last):
  File "/Users/snigdhaghoshdastidar/Desktop/CS540/classeval_evaluation/ClassEval_81_0.py", line 247, in test_standard_deviation
    self.assertEqual(statistics3.standard_deviation([1, 2, 3]), 1.0)
AssertionError: 0.816496580927726 != 1.0

======================================================================
FAIL: test_standard_deviation_5 (ClassEval_81_0.Statistics3TestStandardDeviation.test_standard_deviation_5)
----------------------------------------------------------------------
Traceback (most recent call last):
  File "/Users/snigdhaghoshdastidar/Desktop/CS540/classeval_evaluation/ClassEval_81_0.py", line 263, in test_standard_deviation_5
    self.assertEqual(statistics3.standard_deviation([1, 1, 2, 1, 4]), 1.3038404810405297)
AssertionError: 1.1661903789690602 != 1.3038404810405297

----------------------------------------------------------------------
Ran 5 tests in 0.001s

FAILED (failures=2)
FEEFE
======================================================================
ERROR: test_z_score_2 (ClassEval_81_0.Statistics3TestZScore.test_z_score_2)
----------------------------------------------------------------------
Traceback (most recent call last):
  File "/Users/snigdhaghoshdastidar/Desktop/CS540/classeval_evaluation/ClassEval_81_0.py", line 273, in test_z_score_2
    self.assertEqual(statistics3.z_score([1, 1, 1, 1]), None)
                     ^^^^^^^^^^^^^^^^^^^^^^^^^^^^^^^^^
  File "/Users/snigdhaghoshdastidar/Desktop/CS540/classeval_evaluation/ClassEval_81_0.py", line 134, in z_score
    z_scores = [(x - mean) / standard_deviation for x in data]
                ~~~~~~~~~~~^~~~~~~~~~~~~~~~~~~~
ZeroDivisionError: float division by zero

======================================================================
ERROR: test_z_score_3 (ClassEval_81_0.Statistics3TestZScore.test_z_score_3)
----------------------------------------------------------------------
Traceback (most recent call last):
  File "/Users/snigdhaghoshdastidar/Desktop/CS540/classeval_evaluation/ClassEval_81_0.py", line 277, in test_z_score_3
    self.assertEqual(statistics3.z_score([1]),None)
                     ^^^^^^^^^^^^^^^^^^^^^^^^
  File "/Users/snigdhaghoshdastidar/Desktop/CS540/classeval_evaluation/ClassEval_81_0.py", line 134, in z_score
    z_scores = [(x - mean) / standard_deviation for x in data]
                ~~~~~~~~~~~^~~~~~~~~~~~~~~~~~~~
ZeroDivisionError: float division by zero

======================================================================
ERROR: test_z_score_5 (ClassEval_81_0.Statistics3TestZScore.test_z_score_5)
----------------------------------------------------------------------
Traceback (most recent call last):
  File "/Users/snigdhaghoshdastidar/Desktop/CS540/classeval_evaluation/ClassEval_81_0.py", line 285, in test_z_score_5
    self.assertEqual(statistics3.z_score([1, 1, 1, 1, 1]), None)
                     ^^^^^^^^^^^^^^^^^^^^^^^^^^^^^^^^^^^^
  File "/Users/snigdhaghoshdastidar/Desktop/CS540/classeval_evaluation/ClassEval_81_0.py", line 134, in z_score
    z_scores = [(x - mean) / standard_deviation for x in data]
                ~~~~~~~~~~~^~~~~~~~~~~~~~~~~~~~
ZeroDivisionError: float division by zero

======================================================================
FAIL: test_z_score (ClassEval_81_0.Statistics3TestZScore.test_z_score)
----------------------------------------------------------------------
Traceback (most recent call last):
  File "/Users/snigdhaghoshdastidar/Desktop/CS540/classeval_evaluation/ClassEval_81_0.py", line 269, in test_z_score
    self.assertEqual(statistics3.z_score([1, 2, 3, 4]), [-1.161895003862225, -0.3872983346207417, 0.3872983346207417, 1.161895003862225])
AssertionError: Lists differ: [-1.3416407864998738, -0.4472135954999579, 0.[32 chars]8738] != [-1.161895003862225, -0.3872983346207417, 0.3[30 chars]2225]

First differing element 0:
-1.3416407864998738
-1.161895003862225

+ [-1.161895003862225, -0.3872983346207417, 0.3872983346207417, 1.161895003862225]
- [-1.3416407864998738,
-  -0.4472135954999579,
-  0.4472135954999579,
-  1.3416407864998738]

======================================================================
FAIL: test_z_score_4 (ClassEval_81_0.Statistics3TestZScore.test_z_score_4)
----------------------------------------------------------------------
Traceback (most recent call last):
  File "/Users/snigdhaghoshdastidar/Desktop/CS540/classeval_evaluation/ClassEval_81_0.py", line 281, in test_z_score_4
    self.assertEqual(statistics3.z_score([1, 1, 2, 3]), [-0.7833494518006403,-0.7833494518006403,0.26111648393354675,1.3055824196677337])
AssertionError: Lists differ: [-0.9045340337332909, -0.9045340337332909, 0.[32 chars]8818] != [-0.7833494518006403, -0.7833494518006403, 0.[33 chars]7337]

First differing element 0:
-0.9045340337332909
-0.7833494518006403

- [-0.9045340337332909,
-  -0.9045340337332909,
-  0.30151134457776363,
-  1.507556722888818]
+ [-0.7833494518006403,
+  -0.7833494518006403,
+  0.26111648393354675,
+  1.3055824196677337]

----------------------------------------------------------------------
Ran 5 tests in 0.002s

FAILED (failures=2, errors=3)
F
======================================================================
FAIL: test_main (ClassEval_81_0.Statistics3TestMain.test_main)
----------------------------------------------------------------------
Traceback (most recent call last):
  File "/Users/snigdhaghoshdastidar/Desktop/CS540/classeval_evaluation/ClassEval_81_0.py", line 296, in test_main
    self.assertEqual(statistics3.standard_deviation([1, 2, 3]), 1.0)
AssertionError: 0.816496580927726 != 1.0

----------------------------------------------------------------------
Ran 1 test in 0.001s

FAILED (failures=1)
EEEEE
======================================================================
ERROR: test_cos_1 (ClassEval_88_0.TriCalculatorTestCos.test_cos_1)
----------------------------------------------------------------------
Traceback (most recent call last):
  File "/Users/snigdhaghoshdastidar/Desktop/CS540/classeval_evaluation/ClassEval_88_0.py", line 8, in test_cos_1
    tricalculator = TriCalculator()
                    ^^^^^^^^^^^^^
NameError: name 'TriCalculator' is not defined. Did you mean: 'TriCalculatorTest'?

======================================================================
ERROR: test_cos_2 (ClassEval_88_0.TriCalculatorTestCos.test_cos_2)
----------------------------------------------------------------------
Traceback (most recent call last):
  File "/Users/snigdhaghoshdastidar/Desktop/CS540/classeval_evaluation/ClassEval_88_0.py", line 12, in test_cos_2
    tricalculator = TriCalculator()
                    ^^^^^^^^^^^^^
NameError: name 'TriCalculator' is not defined. Did you mean: 'TriCalculatorTest'?

======================================================================
ERROR: test_cos_3 (ClassEval_88_0.TriCalculatorTestCos.test_cos_3)
----------------------------------------------------------------------
Traceback (most recent call last):
  File "/Users/snigdhaghoshdastidar/Desktop/CS540/classeval_evaluation/ClassEval_88_0.py", line 16, in test_cos_3
    tricalculator = TriCalculator()
                    ^^^^^^^^^^^^^
NameError: name 'TriCalculator' is not defined. Did you mean: 'TriCalculatorTest'?

======================================================================
ERROR: test_cos_4 (ClassEval_88_0.TriCalculatorTestCos.test_cos_4)
----------------------------------------------------------------------
Traceback (most recent call last):
  File "/Users/snigdhaghoshdastidar/Desktop/CS540/classeval_evaluation/ClassEval_88_0.py", line 20, in test_cos_4
    tricalculator = TriCalculator()
                    ^^^^^^^^^^^^^
NameError: name 'TriCalculator' is not defined. Did you mean: 'TriCalculatorTest'?

======================================================================
ERROR: test_cos_5 (ClassEval_88_0.TriCalculatorTestCos.test_cos_5)
----------------------------------------------------------------------
Traceback (most recent call last):
  File "/Users/snigdhaghoshdastidar/Desktop/CS540/classeval_evaluation/ClassEval_88_0.py", line 24, in test_cos_5
    tricalculator = TriCalculator()
                    ^^^^^^^^^^^^^
NameError: name 'TriCalculator' is not defined. Did you mean: 'TriCalculatorTest'?

----------------------------------------------------------------------
Ran 5 tests in 0.012s

FAILED (errors=5)
EEEEE
======================================================================
ERROR: test_factorial_1 (ClassEval_88_0.TriCalculatorTestFactorial.test_factorial_1)
----------------------------------------------------------------------
Traceback (most recent call last):
  File "/Users/snigdhaghoshdastidar/Desktop/CS540/classeval_evaluation/ClassEval_88_0.py", line 30, in test_factorial_1
    tricalculator = TriCalculator()
                    ^^^^^^^^^^^^^
NameError: name 'TriCalculator' is not defined. Did you mean: 'TriCalculatorTest'?

======================================================================
ERROR: test_factorial_2 (ClassEval_88_0.TriCalculatorTestFactorial.test_factorial_2)
----------------------------------------------------------------------
Traceback (most recent call last):
  File "/Users/snigdhaghoshdastidar/Desktop/CS540/classeval_evaluation/ClassEval_88_0.py", line 34, in test_factorial_2
    tricalculator = TriCalculator()
                    ^^^^^^^^^^^^^
NameError: name 'TriCalculator' is not defined. Did you mean: 'TriCalculatorTest'?

======================================================================
ERROR: test_factorial_3 (ClassEval_88_0.TriCalculatorTestFactorial.test_factorial_3)
----------------------------------------------------------------------
Traceback (most recent call last):
  File "/Users/snigdhaghoshdastidar/Desktop/CS540/classeval_evaluation/ClassEval_88_0.py", line 38, in test_factorial_3
    tricalculator = TriCalculator()
                    ^^^^^^^^^^^^^
NameError: name 'TriCalculator' is not defined. Did you mean: 'TriCalculatorTest'?

======================================================================
ERROR: test_factorial_4 (ClassEval_88_0.TriCalculatorTestFactorial.test_factorial_4)
----------------------------------------------------------------------
Traceback (most recent call last):
  File "/Users/snigdhaghoshdastidar/Desktop/CS540/classeval_evaluation/ClassEval_88_0.py", line 42, in test_factorial_4
    tricalculator = TriCalculator()
                    ^^^^^^^^^^^^^
NameError: name 'TriCalculator' is not defined. Did you mean: 'TriCalculatorTest'?

======================================================================
ERROR: test_factorial_5 (ClassEval_88_0.TriCalculatorTestFactorial.test_factorial_5)
----------------------------------------------------------------------
Traceback (most recent call last):
  File "/Users/snigdhaghoshdastidar/Desktop/CS540/classeval_evaluation/ClassEval_88_0.py", line 46, in test_factorial_5
    tricalculator = TriCalculator()
                    ^^^^^^^^^^^^^
NameError: name 'TriCalculator' is not defined. Did you mean: 'TriCalculatorTest'?

----------------------------------------------------------------------
Ran 5 tests in 0.012s

FAILED (errors=5)
EEEEE
======================================================================
ERROR: test_taylor_1 (ClassEval_88_0.TriCalculatorTestTaylor.test_taylor_1)
----------------------------------------------------------------------
Traceback (most recent call last):
  File "/Users/snigdhaghoshdastidar/Desktop/CS540/classeval_evaluation/ClassEval_88_0.py", line 52, in test_taylor_1
    tricalculator = TriCalculator()
                    ^^^^^^^^^^^^^
NameError: name 'TriCalculator' is not defined. Did you mean: 'TriCalculatorTest'?

======================================================================
ERROR: test_taylor_2 (ClassEval_88_0.TriCalculatorTestTaylor.test_taylor_2)
----------------------------------------------------------------------
Traceback (most recent call last):
  File "/Users/snigdhaghoshdastidar/Desktop/CS540/classeval_evaluation/ClassEval_88_0.py", line 56, in test_taylor_2
    tricalculator = TriCalculator()
                    ^^^^^^^^^^^^^
NameError: name 'TriCalculator' is not defined. Did you mean: 'TriCalculatorTest'?

======================================================================
ERROR: test_taylor_3 (ClassEval_88_0.TriCalculatorTestTaylor.test_taylor_3)
----------------------------------------------------------------------
Traceback (most recent call last):
  File "/Users/snigdhaghoshdastidar/Desktop/CS540/classeval_evaluation/ClassEval_88_0.py", line 60, in test_taylor_3
    tricalculator = TriCalculator()
                    ^^^^^^^^^^^^^
NameError: name 'TriCalculator' is not defined. Did you mean: 'TriCalculatorTest'?

======================================================================
ERROR: test_taylor_4 (ClassEval_88_0.TriCalculatorTestTaylor.test_taylor_4)
----------------------------------------------------------------------
Traceback (most recent call last):
  File "/Users/snigdhaghoshdastidar/Desktop/CS540/classeval_evaluation/ClassEval_88_0.py", line 64, in test_taylor_4
    tricalculator = TriCalculator()
                    ^^^^^^^^^^^^^
NameError: name 'TriCalculator' is not defined. Did you mean: 'TriCalculatorTest'?

======================================================================
ERROR: test_taylor_5 (ClassEval_88_0.TriCalculatorTestTaylor.test_taylor_5)
----------------------------------------------------------------------
Traceback (most recent call last):
  File "/Users/snigdhaghoshdastidar/Desktop/CS540/classeval_evaluation/ClassEval_88_0.py", line 68, in test_taylor_5
    tricalculator = TriCalculator()
                    ^^^^^^^^^^^^^
NameError: name 'TriCalculator' is not defined. Did you mean: 'TriCalculatorTest'?

----------------------------------------------------------------------
Ran 5 tests in 0.015s

FAILED (errors=5)
EEEEE
======================================================================
ERROR: test_sin_1 (ClassEval_88_0.TriCalculatorTestSin.test_sin_1)
----------------------------------------------------------------------
Traceback (most recent call last):
  File "/Users/snigdhaghoshdastidar/Desktop/CS540/classeval_evaluation/ClassEval_88_0.py", line 74, in test_sin_1
    tricalculator = TriCalculator()
                    ^^^^^^^^^^^^^
NameError: name 'TriCalculator' is not defined. Did you mean: 'TriCalculatorTest'?

======================================================================
ERROR: test_sin_2 (ClassEval_88_0.TriCalculatorTestSin.test_sin_2)
----------------------------------------------------------------------
Traceback (most recent call last):
  File "/Users/snigdhaghoshdastidar/Desktop/CS540/classeval_evaluation/ClassEval_88_0.py", line 78, in test_sin_2
    tricalculator = TriCalculator()
                    ^^^^^^^^^^^^^
NameError: name 'TriCalculator' is not defined. Did you mean: 'TriCalculatorTest'?

======================================================================
ERROR: test_sin_3 (ClassEval_88_0.TriCalculatorTestSin.test_sin_3)
----------------------------------------------------------------------
Traceback (most recent call last):
  File "/Users/snigdhaghoshdastidar/Desktop/CS540/classeval_evaluation/ClassEval_88_0.py", line 82, in test_sin_3
    tricalculator = TriCalculator()
                    ^^^^^^^^^^^^^
NameError: name 'TriCalculator' is not defined. Did you mean: 'TriCalculatorTest'?

======================================================================
ERROR: test_sin_4 (ClassEval_88_0.TriCalculatorTestSin.test_sin_4)
----------------------------------------------------------------------
Traceback (most recent call last):
  File "/Users/snigdhaghoshdastidar/Desktop/CS540/classeval_evaluation/ClassEval_88_0.py", line 86, in test_sin_4
    tricalculator = TriCalculator()
                    ^^^^^^^^^^^^^
NameError: name 'TriCalculator' is not defined. Did you mean: 'TriCalculatorTest'?

======================================================================
ERROR: test_sin_5 (ClassEval_88_0.TriCalculatorTestSin.test_sin_5)
----------------------------------------------------------------------
Traceback (most recent call last):
  File "/Users/snigdhaghoshdastidar/Desktop/CS540/classeval_evaluation/ClassEval_88_0.py", line 90, in test_sin_5
    tricalculator = TriCalculator()
                    ^^^^^^^^^^^^^
NameError: name 'TriCalculator' is not defined. Did you mean: 'TriCalculatorTest'?

----------------------------------------------------------------------
Ran 5 tests in 0.013s

FAILED (errors=5)
EEEEE
======================================================================
ERROR: test_tan_1 (ClassEval_88_0.TriCalculatorTestTan.test_tan_1)
----------------------------------------------------------------------
Traceback (most recent call last):
  File "/Users/snigdhaghoshdastidar/Desktop/CS540/classeval_evaluation/ClassEval_88_0.py", line 96, in test_tan_1
    tricalculator = TriCalculator()
                    ^^^^^^^^^^^^^
NameError: name 'TriCalculator' is not defined. Did you mean: 'TriCalculatorTest'?

======================================================================
ERROR: test_tan_2 (ClassEval_88_0.TriCalculatorTestTan.test_tan_2)
----------------------------------------------------------------------
Traceback (most recent call last):
  File "/Users/snigdhaghoshdastidar/Desktop/CS540/classeval_evaluation/ClassEval_88_0.py", line 100, in test_tan_2
    tricalculator = TriCalculator()
                    ^^^^^^^^^^^^^
NameError: name 'TriCalculator' is not defined. Did you mean: 'TriCalculatorTest'?

======================================================================
ERROR: test_tan_3 (ClassEval_88_0.TriCalculatorTestTan.test_tan_3)
----------------------------------------------------------------------
Traceback (most recent call last):
  File "/Users/snigdhaghoshdastidar/Desktop/CS540/classeval_evaluation/ClassEval_88_0.py", line 104, in test_tan_3
    tricalculator = TriCalculator()
                    ^^^^^^^^^^^^^
NameError: name 'TriCalculator' is not defined. Did you mean: 'TriCalculatorTest'?

======================================================================
ERROR: test_tan_4 (ClassEval_88_0.TriCalculatorTestTan.test_tan_4)
----------------------------------------------------------------------
Traceback (most recent call last):
  File "/Users/snigdhaghoshdastidar/Desktop/CS540/classeval_evaluation/ClassEval_88_0.py", line 108, in test_tan_4
    tricalculator = TriCalculator()
                    ^^^^^^^^^^^^^
NameError: name 'TriCalculator' is not defined. Did you mean: 'TriCalculatorTest'?

======================================================================
ERROR: test_tan_5 (ClassEval_88_0.TriCalculatorTestTan.test_tan_5)
----------------------------------------------------------------------
Traceback (most recent call last):
  File "/Users/snigdhaghoshdastidar/Desktop/CS540/classeval_evaluation/ClassEval_88_0.py", line 112, in test_tan_5
    tricalculator = TriCalculator()
                    ^^^^^^^^^^^^^
NameError: name 'TriCalculator' is not defined. Did you mean: 'TriCalculatorTest'?

----------------------------------------------------------------------
Ran 5 tests in 0.013s

FAILED (errors=5)
E
======================================================================
ERROR: test_tricalculator (ClassEval_88_0.TriCalculatorTest.test_tricalculator)
----------------------------------------------------------------------
Traceback (most recent call last):
  File "/Users/snigdhaghoshdastidar/Desktop/CS540/classeval_evaluation/ClassEval_88_0.py", line 118, in test_tricalculator
    tricalculator = TriCalculator()
                    ^^^^^^^^^^^^^
NameError: name 'TriCalculator' is not defined. Did you mean: 'TriCalculatorTest'?

----------------------------------------------------------------------
Ran 1 test in 0.002s

FAILED (errors=1)
