.F
======================================================================
FAIL: test_create_table_2 (ClassEval_14_0.BookManagementDBTestCreateTable)
----------------------------------------------------------------------
Traceback (most recent call last):
  File "C:\Users\tanuj\Desktop\CS540\repo\CS540\classeval_evaluation\ClassEval_14_0.py", line 113, in test_create_table_2
    self.assertEqual(column_names, expected_column_names)
AssertionError: Lists differ: ['id', 'title', 'author', 'availability'] != ['id', 'title', 'author', 'available']

First differing element 3:
'availability'
'available'

- ['id', 'title', 'author', 'availability']
?                                   - ^^^

+ ['id', 'title', 'author', 'available']
?                                    ^


----------------------------------------------------------------------
Ran 2 tests in 0.032s

FAILED (failures=1)
E
======================================================================
ERROR: test_add_book (ClassEval_14_0.BookManagementDBTestAddBook)
----------------------------------------------------------------------
Traceback (most recent call last):
  File "C:\Users\tanuj\Desktop\CS540\repo\CS540\classeval_evaluation\ClassEval_14_0.py", line 135, in test_add_book
    self.cursor.execute("SELECT title, author, available FROM books WHERE id=1")
sqlite3.OperationalError: no such column: available

----------------------------------------------------------------------
Ran 1 test in 0.018s

FAILED (errors=1)
.
----------------------------------------------------------------------
Ran 1 test in 0.030s

OK
E
======================================================================
ERROR: test_borrow_book (ClassEval_14_0.BookManagementDBTestBorrowBook)
----------------------------------------------------------------------
Traceback (most recent call last):
  File "C:\Users\tanuj\Desktop\CS540\repo\CS540\classeval_evaluation\ClassEval_14_0.py", line 186, in test_borrow_book
    self.cursor.execute("SELECT available FROM books WHERE id=1")
sqlite3.OperationalError: no such column: available

----------------------------------------------------------------------
Ran 1 test in 0.035s

FAILED (errors=1)
E
======================================================================
ERROR: test_return_book (ClassEval_14_0.BookManagementDBTestReturnBook)
----------------------------------------------------------------------
Traceback (most recent call last):
  File "C:\Users\tanuj\Desktop\CS540\repo\CS540\classeval_evaluation\ClassEval_14_0.py", line 211, in test_return_book
    self.cursor.execute("SELECT available FROM books WHERE id=1")
sqlite3.OperationalError: no such column: available

----------------------------------------------------------------------
Ran 1 test in 0.053s

FAILED (errors=1)
.
----------------------------------------------------------------------
Ran 1 test in 0.044s

OK
..
----------------------------------------------------------------------
Ran 2 tests in 0.032s

OK
.
----------------------------------------------------------------------
Ran 1 test in 0.021s

OK
.
----------------------------------------------------------------------
Ran 1 test in 0.045s

OK
.
----------------------------------------------------------------------
Ran 1 test in 0.042s

OK
.
----------------------------------------------------------------------
Ran 1 test in 0.066s

OK
.
----------------------------------------------------------------------
Ran 1 test in 0.052s

OK
FF
======================================================================
FAIL: test_create_table_1 (ClassEval_14_2.BookManagementDBTestCreateTable)
----------------------------------------------------------------------
Traceback (most recent call last):
  File "C:\Users\tanuj\Desktop\CS540\repo\CS540\classeval_evaluation\ClassEval_14_2.py", line 114, in test_create_table_1
    self.assertIsNotNone(result)
AssertionError: unexpectedly None

======================================================================
FAIL: test_create_table_2 (ClassEval_14_2.BookManagementDBTestCreateTable)
----------------------------------------------------------------------
Traceback (most recent call last):
  File "C:\Users\tanuj\Desktop\CS540\repo\CS540\classeval_evaluation\ClassEval_14_2.py", line 123, in test_create_table_2
    self.assertEqual(column_names, expected_column_names)
AssertionError: Lists differ: [] != ['id', 'title', 'author', 'available']

Second list contains 4 additional elements.
First extra element 0:
'id'

- []
+ ['id', 'title', 'author', 'available']

----------------------------------------------------------------------
Ran 2 tests in 0.030s

FAILED (failures=2)
E
======================================================================
ERROR: test_add_book (ClassEval_14_2.BookManagementDBTestAddBook)
----------------------------------------------------------------------
Traceback (most recent call last):
  File "C:\Users\tanuj\Desktop\CS540\repo\CS540\classeval_evaluation\ClassEval_14_2.py", line 145, in test_add_book
    self.cursor.execute("SELECT title, author, available FROM books WHERE id=1")
sqlite3.OperationalError: no such table: books

----------------------------------------------------------------------
Ran 1 test in 0.062s

FAILED (errors=1)
E
======================================================================
ERROR: test_remove_book (ClassEval_14_2.BookManagementDBTestRemoveBook)
----------------------------------------------------------------------
Traceback (most recent call last):
  File "C:\Users\tanuj\Desktop\CS540\repo\CS540\classeval_evaluation\ClassEval_14_2.py", line 172, in test_remove_book
    self.cursor.execute("SELECT * FROM books WHERE id=1")
sqlite3.OperationalError: no such table: books

----------------------------------------------------------------------
Ran 1 test in 0.043s

FAILED (errors=1)
E
======================================================================
ERROR: test_borrow_book (ClassEval_14_2.BookManagementDBTestBorrowBook)
----------------------------------------------------------------------
Traceback (most recent call last):
  File "C:\Users\tanuj\Desktop\CS540\repo\CS540\classeval_evaluation\ClassEval_14_2.py", line 196, in test_borrow_book
    self.cursor.execute("SELECT available FROM books WHERE id=1")
sqlite3.OperationalError: no such table: books

----------------------------------------------------------------------
Ran 1 test in 0.035s

FAILED (errors=1)
E
======================================================================
ERROR: test_return_book (ClassEval_14_2.BookManagementDBTestReturnBook)
----------------------------------------------------------------------
Traceback (most recent call last):
  File "C:\Users\tanuj\Desktop\CS540\repo\CS540\classeval_evaluation\ClassEval_14_2.py", line 221, in test_return_book
    self.cursor.execute("SELECT available FROM books WHERE id=1")
sqlite3.OperationalError: no such table: books

----------------------------------------------------------------------
Ran 1 test in 0.042s

FAILED (errors=1)
.
----------------------------------------------------------------------
Ran 1 test in 0.092s

OK
.F
======================================================================
FAIL: test_create_table_2 (ClassEval_14_3.BookManagementDBTestCreateTable)
----------------------------------------------------------------------
Traceback (most recent call last):
  File "C:\Users\tanuj\Desktop\CS540\repo\CS540\classeval_evaluation\ClassEval_14_3.py", line 113, in test_create_table_2
    self.assertEqual(column_names, expected_column_names)
AssertionError: Lists differ: ['id', 'title', 'author', 'availability'] != ['id', 'title', 'author', 'available']

First differing element 3:
'availability'
'available'

- ['id', 'title', 'author', 'availability']
?                                   - ^^^

+ ['id', 'title', 'author', 'available']
?                                    ^


----------------------------------------------------------------------
Ran 2 tests in 0.034s

FAILED (failures=1)
E
======================================================================
ERROR: test_add_book (ClassEval_14_3.BookManagementDBTestAddBook)
----------------------------------------------------------------------
Traceback (most recent call last):
  File "C:\Users\tanuj\Desktop\CS540\repo\CS540\classeval_evaluation\ClassEval_14_3.py", line 135, in test_add_book
    self.cursor.execute("SELECT title, author, available FROM books WHERE id=1")
sqlite3.OperationalError: no such column: available

----------------------------------------------------------------------
Ran 1 test in 0.024s

FAILED (errors=1)
.
----------------------------------------------------------------------
Ran 1 test in 0.025s

OK
E
======================================================================
ERROR: test_borrow_book (ClassEval_14_3.BookManagementDBTestBorrowBook)
----------------------------------------------------------------------
Traceback (most recent call last):
  File "C:\Users\tanuj\Desktop\CS540\repo\CS540\classeval_evaluation\ClassEval_14_3.py", line 186, in test_borrow_book
    self.cursor.execute("SELECT available FROM books WHERE id=1")
sqlite3.OperationalError: no such column: available

----------------------------------------------------------------------
Ran 1 test in 0.053s

FAILED (errors=1)
E
======================================================================
ERROR: test_return_book (ClassEval_14_3.BookManagementDBTestReturnBook)
----------------------------------------------------------------------
Traceback (most recent call last):
  File "C:\Users\tanuj\Desktop\CS540\repo\CS540\classeval_evaluation\ClassEval_14_3.py", line 211, in test_return_book
    self.cursor.execute("SELECT available FROM books WHERE id=1")
sqlite3.OperationalError: no such column: available

----------------------------------------------------------------------
Ran 1 test in 0.045s

FAILED (errors=1)
.
----------------------------------------------------------------------
Ran 1 test in 0.050s

OK
.F
======================================================================
FAIL: test_create_table_2 (ClassEval_14_4.BookManagementDBTestCreateTable)
----------------------------------------------------------------------
Traceback (most recent call last):
  File "C:\Users\tanuj\Desktop\CS540\repo\CS540\classeval_evaluation\ClassEval_14_4.py", line 122, in test_create_table_2
    self.assertEqual(column_names, expected_column_names)
AssertionError: Lists differ: ['id', 'title', 'author', 'availability'] != ['id', 'title', 'author', 'available']

First differing element 3:
'availability'
'available'

- ['id', 'title', 'author', 'availability']
?                                   - ^^^

+ ['id', 'title', 'author', 'available']
?                                    ^


----------------------------------------------------------------------
Ran 2 tests in 0.031s

FAILED (failures=1)
E
======================================================================
ERROR: test_add_book (ClassEval_14_4.BookManagementDBTestAddBook)
----------------------------------------------------------------------
Traceback (most recent call last):
  File "C:\Users\tanuj\Desktop\CS540\repo\CS540\classeval_evaluation\ClassEval_14_4.py", line 144, in test_add_book
    self.cursor.execute("SELECT title, author, available FROM books WHERE id=1")
sqlite3.OperationalError: no such column: available

----------------------------------------------------------------------
Ran 1 test in 0.033s

FAILED (errors=1)
.
----------------------------------------------------------------------
Ran 1 test in 0.060s

OK
E
======================================================================
ERROR: test_borrow_book (ClassEval_14_4.BookManagementDBTestBorrowBook)
----------------------------------------------------------------------
Traceback (most recent call last):
  File "C:\Users\tanuj\Desktop\CS540\repo\CS540\classeval_evaluation\ClassEval_14_4.py", line 195, in test_borrow_book
    self.cursor.execute("SELECT available FROM books WHERE id=1")
sqlite3.OperationalError: no such column: available

----------------------------------------------------------------------
Ran 1 test in 0.042s

FAILED (errors=1)
E
======================================================================
ERROR: test_return_book (ClassEval_14_4.BookManagementDBTestReturnBook)
----------------------------------------------------------------------
Traceback (most recent call last):
  File "C:\Users\tanuj\Desktop\CS540\repo\CS540\classeval_evaluation\ClassEval_14_4.py", line 220, in test_return_book
    self.cursor.execute("SELECT available FROM books WHERE id=1")
sqlite3.OperationalError: no such column: available

----------------------------------------------------------------------
Ran 1 test in 0.064s

FAILED (errors=1)
.
----------------------------------------------------------------------
Ran 1 test in 0.046s

OK
.....
----------------------------------------------------------------------
Ran 5 tests in 0.141s

OK
.....
----------------------------------------------------------------------
Ran 5 tests in 0.130s

OK
.....
----------------------------------------------------------------------
Ran 5 tests in 0.250s

OK
.
----------------------------------------------------------------------
Ran 1 test in 0.073s

OK
.....
----------------------------------------------------------------------
Ran 5 tests in 0.138s

OK
.....
----------------------------------------------------------------------
Ran 5 tests in 0.132s

OK
.....
----------------------------------------------------------------------
Ran 5 tests in 0.195s

OK
.
----------------------------------------------------------------------
Ran 1 test in 0.050s

OK
.....
----------------------------------------------------------------------
Ran 5 tests in 0.143s

OK
.....
----------------------------------------------------------------------
Ran 5 tests in 0.153s

OK
.....
----------------------------------------------------------------------
Ran 5 tests in 0.117s

OK
.
----------------------------------------------------------------------
Ran 1 test in 0.022s

OK
.....
----------------------------------------------------------------------
Ran 5 tests in 0.087s

OK
.....
----------------------------------------------------------------------
Ran 5 tests in 0.081s

OK
.....
----------------------------------------------------------------------
Ran 5 tests in 0.134s

OK
.
----------------------------------------------------------------------
Ran 1 test in 0.034s

OK
.....
----------------------------------------------------------------------
Ran 5 tests in 0.101s

OK
.....
----------------------------------------------------------------------
Ran 5 tests in 0.096s

OK
.....
----------------------------------------------------------------------
Ran 5 tests in 0.145s

OK
.
----------------------------------------------------------------------
Ran 1 test in 0.037s

OK
......
----------------------------------------------------------------------
Ran 6 tests in 0.001s

OK
.....
----------------------------------------------------------------------
Ran 5 tests in 0.001s

OK
.....
----------------------------------------------------------------------
Ran 5 tests in 0.001s

OK
.....
----------------------------------------------------------------------
Ran 5 tests in 0.001s

OK
.....
----------------------------------------------------------------------
Ran 5 tests in 0.001s

OK
.....
----------------------------------------------------------------------
Ran 5 tests in 0.001s

OK
.
----------------------------------------------------------------------
Ran 1 test in 0.000s

OK
......
----------------------------------------------------------------------
Ran 6 tests in 0.003s

OK
.....
----------------------------------------------------------------------
Ran 5 tests in 0.001s

OK
.....
----------------------------------------------------------------------
Ran 5 tests in 0.001s

OK
.....
----------------------------------------------------------------------
Ran 5 tests in 0.001s

OK
.....
----------------------------------------------------------------------
Ran 5 tests in 0.000s

OK
.....
----------------------------------------------------------------------
Ran 5 tests in 0.000s

OK
.
----------------------------------------------------------------------
Ran 1 test in 0.000s

OK
......
----------------------------------------------------------------------
Ran 6 tests in 0.000s

OK
.....
----------------------------------------------------------------------
Ran 5 tests in 0.001s

OK
.....
----------------------------------------------------------------------
Ran 5 tests in 0.002s

OK
.....
----------------------------------------------------------------------
Ran 5 tests in 0.001s

OK
.....
----------------------------------------------------------------------
Ran 5 tests in 0.001s

OK
.....
----------------------------------------------------------------------
Ran 5 tests in 0.001s

OK
.
----------------------------------------------------------------------
Ran 1 test in 0.000s

OK
......
----------------------------------------------------------------------
Ran 6 tests in 0.000s

OK
.....
----------------------------------------------------------------------
Ran 5 tests in 0.000s

OK
.....
----------------------------------------------------------------------
Ran 5 tests in 0.000s

OK
.....
----------------------------------------------------------------------
Ran 5 tests in 0.000s

OK
.....
----------------------------------------------------------------------
Ran 5 tests in 0.000s

OK
.....
----------------------------------------------------------------------
Ran 5 tests in 0.000s

OK
.
----------------------------------------------------------------------
Ran 1 test in 0.000s

OK
......
----------------------------------------------------------------------
Ran 6 tests in 0.001s

OK
.....
----------------------------------------------------------------------
Ran 5 tests in 0.001s

OK
.....
----------------------------------------------------------------------
Ran 5 tests in 0.000s

OK
.....
----------------------------------------------------------------------
Ran 5 tests in 0.000s

OK
.....
----------------------------------------------------------------------
Ran 5 tests in 0.000s

OK
.....
----------------------------------------------------------------------
Ran 5 tests in 0.000s

OK
.
----------------------------------------------------------------------
Ran 1 test in 0.000s

OK
.......
----------------------------------------------------------------------
Ran 7 tests in 0.000s

OK
.....
----------------------------------------------------------------------
Ran 5 tests in 0.000s

OK
......
----------------------------------------------------------------------
Ran 6 tests in 0.000s

OK
......
----------------------------------------------------------------------
Ran 6 tests in 0.000s

OK
.
----------------------------------------------------------------------
Ran 1 test in 0.000s

OK
.......
----------------------------------------------------------------------
Ran 7 tests in 0.000s

OK
.....
----------------------------------------------------------------------
Ran 5 tests in 0.000s

OK
......
----------------------------------------------------------------------
Ran 6 tests in 0.000s

OK
......
----------------------------------------------------------------------
Ran 6 tests in 0.001s

OK
.
----------------------------------------------------------------------
Ran 1 test in 0.000s

OK
.......
----------------------------------------------------------------------
Ran 7 tests in 0.000s

OK
.....
----------------------------------------------------------------------
Ran 5 tests in 0.000s

OK
......
----------------------------------------------------------------------
Ran 6 tests in 0.000s

OK
......
----------------------------------------------------------------------
Ran 6 tests in 0.000s

OK
.
----------------------------------------------------------------------
Ran 1 test in 0.000s

OK
.......
----------------------------------------------------------------------
Ran 7 tests in 0.000s

OK
.....
----------------------------------------------------------------------
Ran 5 tests in 0.001s

OK
......
----------------------------------------------------------------------
Ran 6 tests in 0.001s

OK
......
----------------------------------------------------------------------
Ran 6 tests in 0.001s

OK
.
----------------------------------------------------------------------
Ran 1 test in 0.000s

OK
.......
----------------------------------------------------------------------
Ran 7 tests in 0.000s

OK
.....
----------------------------------------------------------------------
Ran 5 tests in 0.001s

OK
......
----------------------------------------------------------------------
Ran 6 tests in 0.005s

OK
......
----------------------------------------------------------------------
Ran 6 tests in 0.001s

OK
.
----------------------------------------------------------------------
Ran 1 test in 0.000s

OK
.....
----------------------------------------------------------------------
Ran 5 tests in 0.113s

OK
.....
----------------------------------------------------------------------
Ran 5 tests in 0.099s

OK
.....
----------------------------------------------------------------------
Ran 5 tests in 0.124s

OK
.
----------------------------------------------------------------------
Ran 1 test in 0.040s

OK
.....
----------------------------------------------------------------------
Ran 5 tests in 0.114s

OK
.....
----------------------------------------------------------------------
Ran 5 tests in 0.090s

OK
.....
----------------------------------------------------------------------
Ran 5 tests in 0.150s

OK
.
----------------------------------------------------------------------
Ran 1 test in 0.035s

OK
.....
----------------------------------------------------------------------
Ran 5 tests in 0.087s

OK
.....
----------------------------------------------------------------------
Ran 5 tests in 0.100s

OK
.....
----------------------------------------------------------------------
Ran 5 tests in 0.137s

OK
.
----------------------------------------------------------------------
Ran 1 test in 0.043s

OK
.....
----------------------------------------------------------------------
Ran 5 tests in 0.097s

OK
.....
----------------------------------------------------------------------
Ran 5 tests in 0.091s

OK
.....
----------------------------------------------------------------------
Ran 5 tests in 0.154s

OK
.
----------------------------------------------------------------------
Ran 1 test in 0.042s

OK
.....
----------------------------------------------------------------------
Ran 5 tests in 0.125s

OK
.....
----------------------------------------------------------------------
Ran 5 tests in 0.120s

OK
.....
----------------------------------------------------------------------
Ran 5 tests in 0.582s

OK
.
----------------------------------------------------------------------
Ran 1 test in 0.037s

OK
FFFFF
======================================================================
FAIL: test_insert_user_1 (ClassEval_92_0.UserLoginDBTestInsertUser)
----------------------------------------------------------------------
Traceback (most recent call last):
  File "C:\Users\tanuj\Desktop\CS540\repo\CS540\classeval_evaluation\ClassEval_92_0.py", line 115, in test_insert_user_1
    self.assertEqual(user[0], 'user1')
AssertionError: ('user1', 'pass1') != 'user1'

======================================================================
FAIL: test_insert_user_2 (ClassEval_92_0.UserLoginDBTestInsertUser)
----------------------------------------------------------------------
Traceback (most recent call last):
  File "C:\Users\tanuj\Desktop\CS540\repo\CS540\classeval_evaluation\ClassEval_92_0.py", line 122, in test_insert_user_2
    self.assertEqual(user[0], 'user2')
AssertionError: ('user2', 'pass2') != 'user2'

======================================================================
FAIL: test_insert_user_3 (ClassEval_92_0.UserLoginDBTestInsertUser)
----------------------------------------------------------------------
Traceback (most recent call last):
  File "C:\Users\tanuj\Desktop\CS540\repo\CS540\classeval_evaluation\ClassEval_92_0.py", line 129, in test_insert_user_3
    self.assertEqual(user[0], 'user3')
AssertionError: ('user3', 'pass3') != 'user3'

======================================================================
FAIL: test_insert_user_4 (ClassEval_92_0.UserLoginDBTestInsertUser)
----------------------------------------------------------------------
Traceback (most recent call last):
  File "C:\Users\tanuj\Desktop\CS540\repo\CS540\classeval_evaluation\ClassEval_92_0.py", line 136, in test_insert_user_4
    self.assertEqual(user[0], 'user4')
AssertionError: ('user4', 'pass4') != 'user4'

======================================================================
FAIL: test_insert_user_5 (ClassEval_92_0.UserLoginDBTestInsertUser)
----------------------------------------------------------------------
Traceback (most recent call last):
  File "C:\Users\tanuj\Desktop\CS540\repo\CS540\classeval_evaluation\ClassEval_92_0.py", line 143, in test_insert_user_5
    self.assertEqual(user[0], 'user5')
AssertionError: ('user5', 'pass5') != 'user5'

----------------------------------------------------------------------
Ran 5 tests in 0.070s

FAILED (failures=5)
FFFFF
======================================================================
FAIL: test_search_user_by_username_1 (ClassEval_92_0.UserLoginDBTestSearchUserByUsername)
----------------------------------------------------------------------
Traceback (most recent call last):
  File "C:\Users\tanuj\Desktop\CS540\repo\CS540\classeval_evaluation\ClassEval_92_0.py", line 172, in test_search_user_by_username_1
    self.assertEqual(user[0], 'user1')
AssertionError: ('user1', 'pass1') != 'user1'

======================================================================
FAIL: test_search_user_by_username_2 (ClassEval_92_0.UserLoginDBTestSearchUserByUsername)
----------------------------------------------------------------------
Traceback (most recent call last):
  File "C:\Users\tanuj\Desktop\CS540\repo\CS540\classeval_evaluation\ClassEval_92_0.py", line 179, in test_search_user_by_username_2
    self.assertEqual(user[0], 'user2')
AssertionError: ('user2', 'pass2') != 'user2'

======================================================================
FAIL: test_search_user_by_username_3 (ClassEval_92_0.UserLoginDBTestSearchUserByUsername)
----------------------------------------------------------------------
Traceback (most recent call last):
  File "C:\Users\tanuj\Desktop\CS540\repo\CS540\classeval_evaluation\ClassEval_92_0.py", line 186, in test_search_user_by_username_3
    self.assertEqual(user[0], 'user3')
AssertionError: ('user3', 'pass3') != 'user3'

======================================================================
FAIL: test_search_user_by_username_4 (ClassEval_92_0.UserLoginDBTestSearchUserByUsername)
----------------------------------------------------------------------
Traceback (most recent call last):
  File "C:\Users\tanuj\Desktop\CS540\repo\CS540\classeval_evaluation\ClassEval_92_0.py", line 193, in test_search_user_by_username_4
    self.assertEqual(user[0], 'user4')
AssertionError: ('user4', 'pass4') != 'user4'

======================================================================
FAIL: test_search_user_by_username_5 (ClassEval_92_0.UserLoginDBTestSearchUserByUsername)
----------------------------------------------------------------------
Traceback (most recent call last):
  File "C:\Users\tanuj\Desktop\CS540\repo\CS540\classeval_evaluation\ClassEval_92_0.py", line 200, in test_search_user_by_username_5
    self.assertEqual(user[0], 'user5')
AssertionError: ('user5', 'pass5') != 'user5'

----------------------------------------------------------------------
Ran 5 tests in 0.076s

FAILED (failures=5)
FFFFF
======================================================================
FAIL: test_delete_user_by_username_1 (ClassEval_92_0.UserLoginDBTestDeleteUserByUsername)
----------------------------------------------------------------------
Traceback (most recent call last):
  File "C:\Users\tanuj\Desktop\CS540\repo\CS540\classeval_evaluation\ClassEval_92_0.py", line 229, in test_delete_user_by_username_1
    self.assertIsNone(user)
AssertionError: [] is not None

======================================================================
FAIL: test_delete_user_by_username_2 (ClassEval_92_0.UserLoginDBTestDeleteUserByUsername)
----------------------------------------------------------------------
Traceback (most recent call last):
  File "C:\Users\tanuj\Desktop\CS540\repo\CS540\classeval_evaluation\ClassEval_92_0.py", line 235, in test_delete_user_by_username_2
    self.assertIsNone(user)
AssertionError: [] is not None

======================================================================
FAIL: test_delete_user_by_username_3 (ClassEval_92_0.UserLoginDBTestDeleteUserByUsername)
----------------------------------------------------------------------
Traceback (most recent call last):
  File "C:\Users\tanuj\Desktop\CS540\repo\CS540\classeval_evaluation\ClassEval_92_0.py", line 241, in test_delete_user_by_username_3
    self.assertIsNone(user)
AssertionError: [] is not None

======================================================================
FAIL: test_delete_user_by_username_4 (ClassEval_92_0.UserLoginDBTestDeleteUserByUsername)
----------------------------------------------------------------------
Traceback (most recent call last):
  File "C:\Users\tanuj\Desktop\CS540\repo\CS540\classeval_evaluation\ClassEval_92_0.py", line 247, in test_delete_user_by_username_4
    self.assertIsNone(user)
AssertionError: [] is not None

======================================================================
FAIL: test_delete_user_by_username_5 (ClassEval_92_0.UserLoginDBTestDeleteUserByUsername)
----------------------------------------------------------------------
Traceback (most recent call last):
  File "C:\Users\tanuj\Desktop\CS540\repo\CS540\classeval_evaluation\ClassEval_92_0.py", line 253, in test_delete_user_by_username_5
    self.assertIsNone(user)
AssertionError: [] is not None

----------------------------------------------------------------------
Ran 5 tests in 0.108s

FAILED (failures=5)
.....
----------------------------------------------------------------------
Ran 5 tests in 0.072s

OK
F
======================================================================
FAIL: test_UserLoginDB (ClassEval_92_0.UserLoginDBTest)
----------------------------------------------------------------------
Traceback (most recent call last):
  File "C:\Users\tanuj\Desktop\CS540\repo\CS540\classeval_evaluation\ClassEval_92_0.py", line 327, in test_UserLoginDB
    self.assertEqual(user[0], 'user1')
AssertionError: ('user1', 'pass1') != 'user1'

----------------------------------------------------------------------
Ran 1 test in 0.016s

FAILED (failures=1)
FFFFF
======================================================================
FAIL: test_insert_user_1 (ClassEval_92_1.UserLoginDBTestInsertUser)
----------------------------------------------------------------------
Traceback (most recent call last):
  File "C:\Users\tanuj\Desktop\CS540\repo\CS540\classeval_evaluation\ClassEval_92_1.py", line 128, in test_insert_user_1
    self.assertEqual(user[0], 'user1')
AssertionError: ('user1', 'pass1') != 'user1'

======================================================================
FAIL: test_insert_user_2 (ClassEval_92_1.UserLoginDBTestInsertUser)
----------------------------------------------------------------------
Traceback (most recent call last):
  File "C:\Users\tanuj\Desktop\CS540\repo\CS540\classeval_evaluation\ClassEval_92_1.py", line 135, in test_insert_user_2
    self.assertEqual(user[0], 'user2')
AssertionError: ('user2', 'pass2') != 'user2'

======================================================================
FAIL: test_insert_user_3 (ClassEval_92_1.UserLoginDBTestInsertUser)
----------------------------------------------------------------------
Traceback (most recent call last):
  File "C:\Users\tanuj\Desktop\CS540\repo\CS540\classeval_evaluation\ClassEval_92_1.py", line 142, in test_insert_user_3
    self.assertEqual(user[0], 'user3')
AssertionError: ('user3', 'pass3') != 'user3'

======================================================================
FAIL: test_insert_user_4 (ClassEval_92_1.UserLoginDBTestInsertUser)
----------------------------------------------------------------------
Traceback (most recent call last):
  File "C:\Users\tanuj\Desktop\CS540\repo\CS540\classeval_evaluation\ClassEval_92_1.py", line 149, in test_insert_user_4
    self.assertEqual(user[0], 'user4')
AssertionError: ('user4', 'pass4') != 'user4'

======================================================================
FAIL: test_insert_user_5 (ClassEval_92_1.UserLoginDBTestInsertUser)
----------------------------------------------------------------------
Traceback (most recent call last):
  File "C:\Users\tanuj\Desktop\CS540\repo\CS540\classeval_evaluation\ClassEval_92_1.py", line 156, in test_insert_user_5
    self.assertEqual(user[0], 'user5')
AssertionError: ('user5', 'pass5') != 'user5'

----------------------------------------------------------------------
Ran 5 tests in 0.080s

FAILED (failures=5)
FFFFF
======================================================================
FAIL: test_search_user_by_username_1 (ClassEval_92_1.UserLoginDBTestSearchUserByUsername)
----------------------------------------------------------------------
Traceback (most recent call last):
  File "C:\Users\tanuj\Desktop\CS540\repo\CS540\classeval_evaluation\ClassEval_92_1.py", line 185, in test_search_user_by_username_1
    self.assertEqual(user[0], 'user1')
AssertionError: ('user1', 'pass1') != 'user1'

======================================================================
FAIL: test_search_user_by_username_2 (ClassEval_92_1.UserLoginDBTestSearchUserByUsername)
----------------------------------------------------------------------
Traceback (most recent call last):
  File "C:\Users\tanuj\Desktop\CS540\repo\CS540\classeval_evaluation\ClassEval_92_1.py", line 192, in test_search_user_by_username_2
    self.assertEqual(user[0], 'user2')
AssertionError: ('user2', 'pass2') != 'user2'

======================================================================
FAIL: test_search_user_by_username_3 (ClassEval_92_1.UserLoginDBTestSearchUserByUsername)
----------------------------------------------------------------------
Traceback (most recent call last):
  File "C:\Users\tanuj\Desktop\CS540\repo\CS540\classeval_evaluation\ClassEval_92_1.py", line 199, in test_search_user_by_username_3
    self.assertEqual(user[0], 'user3')
AssertionError: ('user3', 'pass3') != 'user3'

======================================================================
FAIL: test_search_user_by_username_4 (ClassEval_92_1.UserLoginDBTestSearchUserByUsername)
----------------------------------------------------------------------
Traceback (most recent call last):
  File "C:\Users\tanuj\Desktop\CS540\repo\CS540\classeval_evaluation\ClassEval_92_1.py", line 206, in test_search_user_by_username_4
    self.assertEqual(user[0], 'user4')
AssertionError: ('user4', 'pass4') != 'user4'

======================================================================
FAIL: test_search_user_by_username_5 (ClassEval_92_1.UserLoginDBTestSearchUserByUsername)
----------------------------------------------------------------------
Traceback (most recent call last):
  File "C:\Users\tanuj\Desktop\CS540\repo\CS540\classeval_evaluation\ClassEval_92_1.py", line 213, in test_search_user_by_username_5
    self.assertEqual(user[0], 'user5')
AssertionError: ('user5', 'pass5') != 'user5'

----------------------------------------------------------------------
Ran 5 tests in 0.075s

FAILED (failures=5)
FFFFF
======================================================================
FAIL: test_delete_user_by_username_1 (ClassEval_92_1.UserLoginDBTestDeleteUserByUsername)
----------------------------------------------------------------------
Traceback (most recent call last):
  File "C:\Users\tanuj\Desktop\CS540\repo\CS540\classeval_evaluation\ClassEval_92_1.py", line 242, in test_delete_user_by_username_1
    self.assertIsNone(user)
AssertionError: [] is not None

======================================================================
FAIL: test_delete_user_by_username_2 (ClassEval_92_1.UserLoginDBTestDeleteUserByUsername)
----------------------------------------------------------------------
Traceback (most recent call last):
  File "C:\Users\tanuj\Desktop\CS540\repo\CS540\classeval_evaluation\ClassEval_92_1.py", line 248, in test_delete_user_by_username_2
    self.assertIsNone(user)
AssertionError: [] is not None

======================================================================
FAIL: test_delete_user_by_username_3 (ClassEval_92_1.UserLoginDBTestDeleteUserByUsername)
----------------------------------------------------------------------
Traceback (most recent call last):
  File "C:\Users\tanuj\Desktop\CS540\repo\CS540\classeval_evaluation\ClassEval_92_1.py", line 254, in test_delete_user_by_username_3
    self.assertIsNone(user)
AssertionError: [] is not None

======================================================================
FAIL: test_delete_user_by_username_4 (ClassEval_92_1.UserLoginDBTestDeleteUserByUsername)
----------------------------------------------------------------------
Traceback (most recent call last):
  File "C:\Users\tanuj\Desktop\CS540\repo\CS540\classeval_evaluation\ClassEval_92_1.py", line 260, in test_delete_user_by_username_4
    self.assertIsNone(user)
AssertionError: [] is not None

======================================================================
FAIL: test_delete_user_by_username_5 (ClassEval_92_1.UserLoginDBTestDeleteUserByUsername)
----------------------------------------------------------------------
Traceback (most recent call last):
  File "C:\Users\tanuj\Desktop\CS540\repo\CS540\classeval_evaluation\ClassEval_92_1.py", line 266, in test_delete_user_by_username_5
    self.assertIsNone(user)
AssertionError: [] is not None

----------------------------------------------------------------------
Ran 5 tests in 0.092s

FAILED (failures=5)
.....
----------------------------------------------------------------------
Ran 5 tests in 0.064s

OK
F
======================================================================
FAIL: test_UserLoginDB (ClassEval_92_1.UserLoginDBTest)
----------------------------------------------------------------------
Traceback (most recent call last):
  File "C:\Users\tanuj\Desktop\CS540\repo\CS540\classeval_evaluation\ClassEval_92_1.py", line 340, in test_UserLoginDB
    self.assertEqual(user[0], 'user1')
AssertionError: ('user1', 'pass1') != 'user1'

----------------------------------------------------------------------
Ran 1 test in 0.014s

FAILED (failures=1)
EEEEE
======================================================================
ERROR: test_insert_user_1 (ClassEval_92_2.UserLoginDBTestInsertUser)
----------------------------------------------------------------------
Traceback (most recent call last):
  File "C:\Users\tanuj\Desktop\CS540\repo\CS540\classeval_evaluation\ClassEval_92_2.py", line 131, in test_insert_user_1
    user = self.db.search_user_by_username('user1')
  File "C:\Users\tanuj\Desktop\CS540\repo\CS540\classeval_evaluation\ClassEval_92_2.py", line 58, in search_user_by_username
    self.cursor.execute(
sqlite3.OperationalError: no such column: id

======================================================================
ERROR: test_insert_user_2 (ClassEval_92_2.UserLoginDBTestInsertUser)
----------------------------------------------------------------------
Traceback (most recent call last):
  File "C:\Users\tanuj\Desktop\CS540\repo\CS540\classeval_evaluation\ClassEval_92_2.py", line 138, in test_insert_user_2
    user = self.db.search_user_by_username('user2')
  File "C:\Users\tanuj\Desktop\CS540\repo\CS540\classeval_evaluation\ClassEval_92_2.py", line 58, in search_user_by_username
    self.cursor.execute(
sqlite3.OperationalError: no such column: id

======================================================================
ERROR: test_insert_user_3 (ClassEval_92_2.UserLoginDBTestInsertUser)
----------------------------------------------------------------------
Traceback (most recent call last):
  File "C:\Users\tanuj\Desktop\CS540\repo\CS540\classeval_evaluation\ClassEval_92_2.py", line 145, in test_insert_user_3
    user = self.db.search_user_by_username('user3')
  File "C:\Users\tanuj\Desktop\CS540\repo\CS540\classeval_evaluation\ClassEval_92_2.py", line 58, in search_user_by_username
    self.cursor.execute(
sqlite3.OperationalError: no such column: id

======================================================================
ERROR: test_insert_user_4 (ClassEval_92_2.UserLoginDBTestInsertUser)
----------------------------------------------------------------------
Traceback (most recent call last):
  File "C:\Users\tanuj\Desktop\CS540\repo\CS540\classeval_evaluation\ClassEval_92_2.py", line 152, in test_insert_user_4
    user = self.db.search_user_by_username('user4')
  File "C:\Users\tanuj\Desktop\CS540\repo\CS540\classeval_evaluation\ClassEval_92_2.py", line 58, in search_user_by_username
    self.cursor.execute(
sqlite3.OperationalError: no such column: id

======================================================================
ERROR: test_insert_user_5 (ClassEval_92_2.UserLoginDBTestInsertUser)
----------------------------------------------------------------------
Traceback (most recent call last):
  File "C:\Users\tanuj\Desktop\CS540\repo\CS540\classeval_evaluation\ClassEval_92_2.py", line 159, in test_insert_user_5
    user = self.db.search_user_by_username('user5')
  File "C:\Users\tanuj\Desktop\CS540\repo\CS540\classeval_evaluation\ClassEval_92_2.py", line 58, in search_user_by_username
    self.cursor.execute(
sqlite3.OperationalError: no such column: id

----------------------------------------------------------------------
Ran 5 tests in 0.089s

FAILED (errors=5)
EEEEE
======================================================================
ERROR: test_search_user_by_username_1 (ClassEval_92_2.UserLoginDBTestSearchUserByUsername)
----------------------------------------------------------------------
Traceback (most recent call last):
  File "C:\Users\tanuj\Desktop\CS540\repo\CS540\classeval_evaluation\ClassEval_92_2.py", line 188, in test_search_user_by_username_1
    user = self.db.search_user_by_username('user1')
  File "C:\Users\tanuj\Desktop\CS540\repo\CS540\classeval_evaluation\ClassEval_92_2.py", line 58, in search_user_by_username
    self.cursor.execute(
sqlite3.OperationalError: no such column: id

======================================================================
ERROR: test_search_user_by_username_2 (ClassEval_92_2.UserLoginDBTestSearchUserByUsername)
----------------------------------------------------------------------
Traceback (most recent call last):
  File "C:\Users\tanuj\Desktop\CS540\repo\CS540\classeval_evaluation\ClassEval_92_2.py", line 195, in test_search_user_by_username_2
    user = self.db.search_user_by_username('user2')
  File "C:\Users\tanuj\Desktop\CS540\repo\CS540\classeval_evaluation\ClassEval_92_2.py", line 58, in search_user_by_username
    self.cursor.execute(
sqlite3.OperationalError: no such column: id

======================================================================
ERROR: test_search_user_by_username_3 (ClassEval_92_2.UserLoginDBTestSearchUserByUsername)
----------------------------------------------------------------------
Traceback (most recent call last):
  File "C:\Users\tanuj\Desktop\CS540\repo\CS540\classeval_evaluation\ClassEval_92_2.py", line 202, in test_search_user_by_username_3
    user = self.db.search_user_by_username('user3')
  File "C:\Users\tanuj\Desktop\CS540\repo\CS540\classeval_evaluation\ClassEval_92_2.py", line 58, in search_user_by_username
    self.cursor.execute(
sqlite3.OperationalError: no such column: id

======================================================================
ERROR: test_search_user_by_username_4 (ClassEval_92_2.UserLoginDBTestSearchUserByUsername)
----------------------------------------------------------------------
Traceback (most recent call last):
  File "C:\Users\tanuj\Desktop\CS540\repo\CS540\classeval_evaluation\ClassEval_92_2.py", line 209, in test_search_user_by_username_4
    user = self.db.search_user_by_username('user4')
  File "C:\Users\tanuj\Desktop\CS540\repo\CS540\classeval_evaluation\ClassEval_92_2.py", line 58, in search_user_by_username
    self.cursor.execute(
sqlite3.OperationalError: no such column: id

======================================================================
ERROR: test_search_user_by_username_5 (ClassEval_92_2.UserLoginDBTestSearchUserByUsername)
----------------------------------------------------------------------
Traceback (most recent call last):
  File "C:\Users\tanuj\Desktop\CS540\repo\CS540\classeval_evaluation\ClassEval_92_2.py", line 216, in test_search_user_by_username_5
    user = self.db.search_user_by_username('user5')
  File "C:\Users\tanuj\Desktop\CS540\repo\CS540\classeval_evaluation\ClassEval_92_2.py", line 58, in search_user_by_username
    self.cursor.execute(
sqlite3.OperationalError: no such column: id

----------------------------------------------------------------------
Ran 5 tests in 0.090s

FAILED (errors=5)
EEEEE
======================================================================
ERROR: test_delete_user_by_username_1 (ClassEval_92_2.UserLoginDBTestDeleteUserByUsername)
----------------------------------------------------------------------
Traceback (most recent call last):
  File "C:\Users\tanuj\Desktop\CS540\repo\CS540\classeval_evaluation\ClassEval_92_2.py", line 246, in test_delete_user_by_username_1
    user = self.db.search_user_by_username('user1')
  File "C:\Users\tanuj\Desktop\CS540\repo\CS540\classeval_evaluation\ClassEval_92_2.py", line 58, in search_user_by_username
    self.cursor.execute(
sqlite3.OperationalError: no such column: id

======================================================================
ERROR: test_delete_user_by_username_2 (ClassEval_92_2.UserLoginDBTestDeleteUserByUsername)
----------------------------------------------------------------------
Traceback (most recent call last):
  File "C:\Users\tanuj\Desktop\CS540\repo\CS540\classeval_evaluation\ClassEval_92_2.py", line 252, in test_delete_user_by_username_2
    user = self.db.search_user_by_username('user2')
  File "C:\Users\tanuj\Desktop\CS540\repo\CS540\classeval_evaluation\ClassEval_92_2.py", line 58, in search_user_by_username
    self.cursor.execute(
sqlite3.OperationalError: no such column: id

======================================================================
ERROR: test_delete_user_by_username_3 (ClassEval_92_2.UserLoginDBTestDeleteUserByUsername)
----------------------------------------------------------------------
Traceback (most recent call last):
  File "C:\Users\tanuj\Desktop\CS540\repo\CS540\classeval_evaluation\ClassEval_92_2.py", line 258, in test_delete_user_by_username_3
    user = self.db.search_user_by_username('user3')
  File "C:\Users\tanuj\Desktop\CS540\repo\CS540\classeval_evaluation\ClassEval_92_2.py", line 58, in search_user_by_username
    self.cursor.execute(
sqlite3.OperationalError: no such column: id

======================================================================
ERROR: test_delete_user_by_username_4 (ClassEval_92_2.UserLoginDBTestDeleteUserByUsername)
----------------------------------------------------------------------
Traceback (most recent call last):
  File "C:\Users\tanuj\Desktop\CS540\repo\CS540\classeval_evaluation\ClassEval_92_2.py", line 264, in test_delete_user_by_username_4
    user = self.db.search_user_by_username('user4')
  File "C:\Users\tanuj\Desktop\CS540\repo\CS540\classeval_evaluation\ClassEval_92_2.py", line 58, in search_user_by_username
    self.cursor.execute(
sqlite3.OperationalError: no such column: id

======================================================================
ERROR: test_delete_user_by_username_5 (ClassEval_92_2.UserLoginDBTestDeleteUserByUsername)
----------------------------------------------------------------------
Traceback (most recent call last):
  File "C:\Users\tanuj\Desktop\CS540\repo\CS540\classeval_evaluation\ClassEval_92_2.py", line 270, in test_delete_user_by_username_5
    user = self.db.search_user_by_username('user5')
  File "C:\Users\tanuj\Desktop\CS540\repo\CS540\classeval_evaluation\ClassEval_92_2.py", line 58, in search_user_by_username
    self.cursor.execute(
sqlite3.OperationalError: no such column: id

----------------------------------------------------------------------
Ran 5 tests in 0.114s

FAILED (errors=5)
.....
----------------------------------------------------------------------
Ran 5 tests in 0.080s

OK
E
======================================================================
ERROR: test_UserLoginDB (ClassEval_92_2.UserLoginDBTest)
----------------------------------------------------------------------
Traceback (most recent call last):
  File "C:\Users\tanuj\Desktop\CS540\repo\CS540\classeval_evaluation\ClassEval_92_2.py", line 343, in test_UserLoginDB
    user = self.db.search_user_by_username('user1')
  File "C:\Users\tanuj\Desktop\CS540\repo\CS540\classeval_evaluation\ClassEval_92_2.py", line 58, in search_user_by_username
    self.cursor.execute(
sqlite3.OperationalError: no such column: id

----------------------------------------------------------------------
Ran 1 test in 0.013s

FAILED (errors=1)
FFFFF
======================================================================
FAIL: test_insert_user_1 (ClassEval_92_3.UserLoginDBTestInsertUser)
----------------------------------------------------------------------
Traceback (most recent call last):
  File "C:\Users\tanuj\Desktop\CS540\repo\CS540\classeval_evaluation\ClassEval_92_3.py", line 127, in test_insert_user_1
    self.assertEqual(user[0], 'user1')
AssertionError: ('user1', 'pass1') != 'user1'

======================================================================
FAIL: test_insert_user_2 (ClassEval_92_3.UserLoginDBTestInsertUser)
----------------------------------------------------------------------
Traceback (most recent call last):
  File "C:\Users\tanuj\Desktop\CS540\repo\CS540\classeval_evaluation\ClassEval_92_3.py", line 134, in test_insert_user_2
    self.assertEqual(user[0], 'user2')
AssertionError: ('user2', 'pass2') != 'user2'

======================================================================
FAIL: test_insert_user_3 (ClassEval_92_3.UserLoginDBTestInsertUser)
----------------------------------------------------------------------
Traceback (most recent call last):
  File "C:\Users\tanuj\Desktop\CS540\repo\CS540\classeval_evaluation\ClassEval_92_3.py", line 141, in test_insert_user_3
    self.assertEqual(user[0], 'user3')
AssertionError: ('user3', 'pass3') != 'user3'

======================================================================
FAIL: test_insert_user_4 (ClassEval_92_3.UserLoginDBTestInsertUser)
----------------------------------------------------------------------
Traceback (most recent call last):
  File "C:\Users\tanuj\Desktop\CS540\repo\CS540\classeval_evaluation\ClassEval_92_3.py", line 148, in test_insert_user_4
    self.assertEqual(user[0], 'user4')
AssertionError: ('user4', 'pass4') != 'user4'

======================================================================
FAIL: test_insert_user_5 (ClassEval_92_3.UserLoginDBTestInsertUser)
----------------------------------------------------------------------
Traceback (most recent call last):
  File "C:\Users\tanuj\Desktop\CS540\repo\CS540\classeval_evaluation\ClassEval_92_3.py", line 155, in test_insert_user_5
    self.assertEqual(user[0], 'user5')
AssertionError: ('user5', 'pass5') != 'user5'

----------------------------------------------------------------------
Ran 5 tests in 0.092s

FAILED (failures=5)
FFFFF
======================================================================
FAIL: test_search_user_by_username_1 (ClassEval_92_3.UserLoginDBTestSearchUserByUsername)
----------------------------------------------------------------------
Traceback (most recent call last):
  File "C:\Users\tanuj\Desktop\CS540\repo\CS540\classeval_evaluation\ClassEval_92_3.py", line 184, in test_search_user_by_username_1
    self.assertEqual(user[0], 'user1')
AssertionError: ('user1', 'pass1') != 'user1'

======================================================================
FAIL: test_search_user_by_username_2 (ClassEval_92_3.UserLoginDBTestSearchUserByUsername)
----------------------------------------------------------------------
Traceback (most recent call last):
  File "C:\Users\tanuj\Desktop\CS540\repo\CS540\classeval_evaluation\ClassEval_92_3.py", line 191, in test_search_user_by_username_2
    self.assertEqual(user[0], 'user2')
AssertionError: ('user2', 'pass2') != 'user2'

======================================================================
FAIL: test_search_user_by_username_3 (ClassEval_92_3.UserLoginDBTestSearchUserByUsername)
----------------------------------------------------------------------
Traceback (most recent call last):
  File "C:\Users\tanuj\Desktop\CS540\repo\CS540\classeval_evaluation\ClassEval_92_3.py", line 198, in test_search_user_by_username_3
    self.assertEqual(user[0], 'user3')
AssertionError: ('user3', 'pass3') != 'user3'

======================================================================
FAIL: test_search_user_by_username_4 (ClassEval_92_3.UserLoginDBTestSearchUserByUsername)
----------------------------------------------------------------------
Traceback (most recent call last):
  File "C:\Users\tanuj\Desktop\CS540\repo\CS540\classeval_evaluation\ClassEval_92_3.py", line 205, in test_search_user_by_username_4
    self.assertEqual(user[0], 'user4')
AssertionError: ('user4', 'pass4') != 'user4'

======================================================================
FAIL: test_search_user_by_username_5 (ClassEval_92_3.UserLoginDBTestSearchUserByUsername)
----------------------------------------------------------------------
Traceback (most recent call last):
  File "C:\Users\tanuj\Desktop\CS540\repo\CS540\classeval_evaluation\ClassEval_92_3.py", line 212, in test_search_user_by_username_5
    self.assertEqual(user[0], 'user5')
AssertionError: ('user5', 'pass5') != 'user5'

----------------------------------------------------------------------
Ran 5 tests in 0.100s

FAILED (failures=5)
FFFFF
======================================================================
FAIL: test_delete_user_by_username_1 (ClassEval_92_3.UserLoginDBTestDeleteUserByUsername)
----------------------------------------------------------------------
Traceback (most recent call last):
  File "C:\Users\tanuj\Desktop\CS540\repo\CS540\classeval_evaluation\ClassEval_92_3.py", line 241, in test_delete_user_by_username_1
    self.assertIsNone(user)
AssertionError: [] is not None

======================================================================
FAIL: test_delete_user_by_username_2 (ClassEval_92_3.UserLoginDBTestDeleteUserByUsername)
----------------------------------------------------------------------
Traceback (most recent call last):
  File "C:\Users\tanuj\Desktop\CS540\repo\CS540\classeval_evaluation\ClassEval_92_3.py", line 247, in test_delete_user_by_username_2
    self.assertIsNone(user)
AssertionError: [] is not None

======================================================================
FAIL: test_delete_user_by_username_3 (ClassEval_92_3.UserLoginDBTestDeleteUserByUsername)
----------------------------------------------------------------------
Traceback (most recent call last):
  File "C:\Users\tanuj\Desktop\CS540\repo\CS540\classeval_evaluation\ClassEval_92_3.py", line 253, in test_delete_user_by_username_3
    self.assertIsNone(user)
AssertionError: [] is not None

======================================================================
FAIL: test_delete_user_by_username_4 (ClassEval_92_3.UserLoginDBTestDeleteUserByUsername)
----------------------------------------------------------------------
Traceback (most recent call last):
  File "C:\Users\tanuj\Desktop\CS540\repo\CS540\classeval_evaluation\ClassEval_92_3.py", line 259, in test_delete_user_by_username_4
    self.assertIsNone(user)
AssertionError: [] is not None

======================================================================
FAIL: test_delete_user_by_username_5 (ClassEval_92_3.UserLoginDBTestDeleteUserByUsername)
----------------------------------------------------------------------
Traceback (most recent call last):
  File "C:\Users\tanuj\Desktop\CS540\repo\CS540\classeval_evaluation\ClassEval_92_3.py", line 265, in test_delete_user_by_username_5
    self.assertIsNone(user)
AssertionError: [] is not None

----------------------------------------------------------------------
Ran 5 tests in 0.118s

FAILED (failures=5)
.....
----------------------------------------------------------------------
Ran 5 tests in 0.092s

OK
F
======================================================================
FAIL: test_UserLoginDB (ClassEval_92_3.UserLoginDBTest)
----------------------------------------------------------------------
Traceback (most recent call last):
  File "C:\Users\tanuj\Desktop\CS540\repo\CS540\classeval_evaluation\ClassEval_92_3.py", line 339, in test_UserLoginDB
    self.assertEqual(user[0], 'user1')
AssertionError: ('user1', 'pass1') != 'user1'

----------------------------------------------------------------------
Ran 1 test in 0.020s

FAILED (failures=1)
FFFFF
======================================================================
FAIL: test_insert_user_1 (ClassEval_92_4.UserLoginDBTestInsertUser)
----------------------------------------------------------------------
Traceback (most recent call last):
  File "C:\Users\tanuj\Desktop\CS540\repo\CS540\classeval_evaluation\ClassEval_92_4.py", line 119, in test_insert_user_1
    self.assertEqual(user[0], 'user1')
AssertionError: ('user1', 'pass1') != 'user1'

======================================================================
FAIL: test_insert_user_2 (ClassEval_92_4.UserLoginDBTestInsertUser)
----------------------------------------------------------------------
Traceback (most recent call last):
  File "C:\Users\tanuj\Desktop\CS540\repo\CS540\classeval_evaluation\ClassEval_92_4.py", line 126, in test_insert_user_2
    self.assertEqual(user[0], 'user2')
AssertionError: ('user2', 'pass2') != 'user2'

======================================================================
FAIL: test_insert_user_3 (ClassEval_92_4.UserLoginDBTestInsertUser)
----------------------------------------------------------------------
Traceback (most recent call last):
  File "C:\Users\tanuj\Desktop\CS540\repo\CS540\classeval_evaluation\ClassEval_92_4.py", line 133, in test_insert_user_3
    self.assertEqual(user[0], 'user3')
AssertionError: ('user3', 'pass3') != 'user3'

======================================================================
FAIL: test_insert_user_4 (ClassEval_92_4.UserLoginDBTestInsertUser)
----------------------------------------------------------------------
Traceback (most recent call last):
  File "C:\Users\tanuj\Desktop\CS540\repo\CS540\classeval_evaluation\ClassEval_92_4.py", line 140, in test_insert_user_4
    self.assertEqual(user[0], 'user4')
AssertionError: ('user4', 'pass4') != 'user4'

======================================================================
FAIL: test_insert_user_5 (ClassEval_92_4.UserLoginDBTestInsertUser)
----------------------------------------------------------------------
Traceback (most recent call last):
  File "C:\Users\tanuj\Desktop\CS540\repo\CS540\classeval_evaluation\ClassEval_92_4.py", line 147, in test_insert_user_5
    self.assertEqual(user[0], 'user5')
AssertionError: ('user5', 'pass5') != 'user5'

----------------------------------------------------------------------
Ran 5 tests in 0.082s

FAILED (failures=5)
FFFFF
======================================================================
FAIL: test_search_user_by_username_1 (ClassEval_92_4.UserLoginDBTestSearchUserByUsername)
----------------------------------------------------------------------
Traceback (most recent call last):
  File "C:\Users\tanuj\Desktop\CS540\repo\CS540\classeval_evaluation\ClassEval_92_4.py", line 176, in test_search_user_by_username_1
    self.assertEqual(user[0], 'user1')
AssertionError: ('user1', 'pass1') != 'user1'

======================================================================
FAIL: test_search_user_by_username_2 (ClassEval_92_4.UserLoginDBTestSearchUserByUsername)
----------------------------------------------------------------------
Traceback (most recent call last):
  File "C:\Users\tanuj\Desktop\CS540\repo\CS540\classeval_evaluation\ClassEval_92_4.py", line 183, in test_search_user_by_username_2
    self.assertEqual(user[0], 'user2')
AssertionError: ('user2', 'pass2') != 'user2'

======================================================================
FAIL: test_search_user_by_username_3 (ClassEval_92_4.UserLoginDBTestSearchUserByUsername)
----------------------------------------------------------------------
Traceback (most recent call last):
  File "C:\Users\tanuj\Desktop\CS540\repo\CS540\classeval_evaluation\ClassEval_92_4.py", line 190, in test_search_user_by_username_3
    self.assertEqual(user[0], 'user3')
AssertionError: ('user3', 'pass3') != 'user3'

======================================================================
FAIL: test_search_user_by_username_4 (ClassEval_92_4.UserLoginDBTestSearchUserByUsername)
----------------------------------------------------------------------
Traceback (most recent call last):
  File "C:\Users\tanuj\Desktop\CS540\repo\CS540\classeval_evaluation\ClassEval_92_4.py", line 197, in test_search_user_by_username_4
    self.assertEqual(user[0], 'user4')
AssertionError: ('user4', 'pass4') != 'user4'

======================================================================
FAIL: test_search_user_by_username_5 (ClassEval_92_4.UserLoginDBTestSearchUserByUsername)
----------------------------------------------------------------------
Traceback (most recent call last):
  File "C:\Users\tanuj\Desktop\CS540\repo\CS540\classeval_evaluation\ClassEval_92_4.py", line 204, in test_search_user_by_username_5
    self.assertEqual(user[0], 'user5')
AssertionError: ('user5', 'pass5') != 'user5'

----------------------------------------------------------------------
Ran 5 tests in 0.065s

FAILED (failures=5)
FFFFF
======================================================================
FAIL: test_delete_user_by_username_1 (ClassEval_92_4.UserLoginDBTestDeleteUserByUsername)
----------------------------------------------------------------------
Traceback (most recent call last):
  File "C:\Users\tanuj\Desktop\CS540\repo\CS540\classeval_evaluation\ClassEval_92_4.py", line 233, in test_delete_user_by_username_1
    self.assertIsNone(user)
AssertionError: [] is not None

======================================================================
FAIL: test_delete_user_by_username_2 (ClassEval_92_4.UserLoginDBTestDeleteUserByUsername)
----------------------------------------------------------------------
Traceback (most recent call last):
  File "C:\Users\tanuj\Desktop\CS540\repo\CS540\classeval_evaluation\ClassEval_92_4.py", line 239, in test_delete_user_by_username_2
    self.assertIsNone(user)
AssertionError: [] is not None

======================================================================
FAIL: test_delete_user_by_username_3 (ClassEval_92_4.UserLoginDBTestDeleteUserByUsername)
----------------------------------------------------------------------
Traceback (most recent call last):
  File "C:\Users\tanuj\Desktop\CS540\repo\CS540\classeval_evaluation\ClassEval_92_4.py", line 245, in test_delete_user_by_username_3
    self.assertIsNone(user)
AssertionError: [] is not None

======================================================================
FAIL: test_delete_user_by_username_4 (ClassEval_92_4.UserLoginDBTestDeleteUserByUsername)
----------------------------------------------------------------------
Traceback (most recent call last):
  File "C:\Users\tanuj\Desktop\CS540\repo\CS540\classeval_evaluation\ClassEval_92_4.py", line 251, in test_delete_user_by_username_4
    self.assertIsNone(user)
AssertionError: [] is not None

======================================================================
FAIL: test_delete_user_by_username_5 (ClassEval_92_4.UserLoginDBTestDeleteUserByUsername)
----------------------------------------------------------------------
Traceback (most recent call last):
  File "C:\Users\tanuj\Desktop\CS540\repo\CS540\classeval_evaluation\ClassEval_92_4.py", line 257, in test_delete_user_by_username_5
    self.assertIsNone(user)
AssertionError: [] is not None

----------------------------------------------------------------------
Ran 5 tests in 0.094s

FAILED (failures=5)
.....
----------------------------------------------------------------------
Ran 5 tests in 0.062s

OK
F
======================================================================
FAIL: test_UserLoginDB (ClassEval_92_4.UserLoginDBTest)
----------------------------------------------------------------------
Traceback (most recent call last):
  File "C:\Users\tanuj\Desktop\CS540\repo\CS540\classeval_evaluation\ClassEval_92_4.py", line 331, in test_UserLoginDB
    self.assertEqual(user[0], 'user1')
AssertionError: ('user1', 'pass1') != 'user1'

----------------------------------------------------------------------
Ran 1 test in 0.013s

FAILED (failures=1)
.F
======================================================================
FAIL: test_create_table_2 (ClassEval_14_0.BookManagementDBTestCreateTable)
----------------------------------------------------------------------
Traceback (most recent call last):
  File "C:\Users\tanuj\Desktop\CS540\repo\CS540\classeval_evaluation\ClassEval_14_0.py", line 113, in test_create_table_2
    self.assertEqual(column_names, expected_column_names)
AssertionError: Lists differ: ['id', 'title', 'author', 'availability'] != ['id', 'title', 'author', 'available']

First differing element 3:
'availability'
'available'

- ['id', 'title', 'author', 'availability']
?                                   - ^^^

+ ['id', 'title', 'author', 'available']
?                                    ^


----------------------------------------------------------------------
Ran 2 tests in 0.029s

FAILED (failures=1)
E
======================================================================
ERROR: test_add_book (ClassEval_14_0.BookManagementDBTestAddBook)
----------------------------------------------------------------------
Traceback (most recent call last):
  File "C:\Users\tanuj\Desktop\CS540\repo\CS540\classeval_evaluation\ClassEval_14_0.py", line 135, in test_add_book
    self.cursor.execute("SELECT title, author, available FROM books WHERE id=1")
sqlite3.OperationalError: no such column: available

----------------------------------------------------------------------
Ran 1 test in 0.023s

FAILED (errors=1)
.
----------------------------------------------------------------------
Ran 1 test in 0.035s

OK
E
======================================================================
ERROR: test_borrow_book (ClassEval_14_0.BookManagementDBTestBorrowBook)
----------------------------------------------------------------------
Traceback (most recent call last):
  File "C:\Users\tanuj\Desktop\CS540\repo\CS540\classeval_evaluation\ClassEval_14_0.py", line 186, in test_borrow_book
    self.cursor.execute("SELECT available FROM books WHERE id=1")
sqlite3.OperationalError: no such column: available

----------------------------------------------------------------------
Ran 1 test in 0.030s

FAILED (errors=1)
E
======================================================================
ERROR: test_return_book (ClassEval_14_0.BookManagementDBTestReturnBook)
----------------------------------------------------------------------
Traceback (most recent call last):
  File "C:\Users\tanuj\Desktop\CS540\repo\CS540\classeval_evaluation\ClassEval_14_0.py", line 211, in test_return_book
    self.cursor.execute("SELECT available FROM books WHERE id=1")
sqlite3.OperationalError: no such column: available

----------------------------------------------------------------------
Ran 1 test in 0.046s

FAILED (errors=1)
.
----------------------------------------------------------------------
Ran 1 test in 0.037s

OK
..
----------------------------------------------------------------------
Ran 2 tests in 0.028s

OK
.
----------------------------------------------------------------------
Ran 1 test in 0.018s

OK
.
----------------------------------------------------------------------
Ran 1 test in 0.026s

OK
.
----------------------------------------------------------------------
Ran 1 test in 0.025s

OK
.
----------------------------------------------------------------------
Ran 1 test in 0.033s

OK
.
----------------------------------------------------------------------
Ran 1 test in 0.033s

OK
FF
======================================================================
FAIL: test_create_table_1 (ClassEval_14_2.BookManagementDBTestCreateTable)
----------------------------------------------------------------------
Traceback (most recent call last):
  File "C:\Users\tanuj\Desktop\CS540\repo\CS540\classeval_evaluation\ClassEval_14_2.py", line 114, in test_create_table_1
    self.assertIsNotNone(result)
AssertionError: unexpectedly None

======================================================================
FAIL: test_create_table_2 (ClassEval_14_2.BookManagementDBTestCreateTable)
----------------------------------------------------------------------
Traceback (most recent call last):
  File "C:\Users\tanuj\Desktop\CS540\repo\CS540\classeval_evaluation\ClassEval_14_2.py", line 123, in test_create_table_2
    self.assertEqual(column_names, expected_column_names)
AssertionError: Lists differ: [] != ['id', 'title', 'author', 'available']

Second list contains 4 additional elements.
First extra element 0:
'id'

- []
+ ['id', 'title', 'author', 'available']

----------------------------------------------------------------------
Ran 2 tests in 0.023s

FAILED (failures=2)
E
======================================================================
ERROR: test_add_book (ClassEval_14_2.BookManagementDBTestAddBook)
----------------------------------------------------------------------
Traceback (most recent call last):
  File "C:\Users\tanuj\Desktop\CS540\repo\CS540\classeval_evaluation\ClassEval_14_2.py", line 145, in test_add_book
    self.cursor.execute("SELECT title, author, available FROM books WHERE id=1")
sqlite3.OperationalError: no such table: books

----------------------------------------------------------------------
Ran 1 test in 0.017s

FAILED (errors=1)
E
======================================================================
ERROR: test_remove_book (ClassEval_14_2.BookManagementDBTestRemoveBook)
----------------------------------------------------------------------
Traceback (most recent call last):
  File "C:\Users\tanuj\Desktop\CS540\repo\CS540\classeval_evaluation\ClassEval_14_2.py", line 172, in test_remove_book
    self.cursor.execute("SELECT * FROM books WHERE id=1")
sqlite3.OperationalError: no such table: books

----------------------------------------------------------------------
Ran 1 test in 0.024s

FAILED (errors=1)
E
======================================================================
ERROR: test_borrow_book (ClassEval_14_2.BookManagementDBTestBorrowBook)
----------------------------------------------------------------------
Traceback (most recent call last):
  File "C:\Users\tanuj\Desktop\CS540\repo\CS540\classeval_evaluation\ClassEval_14_2.py", line 196, in test_borrow_book
    self.cursor.execute("SELECT available FROM books WHERE id=1")
sqlite3.OperationalError: no such table: books

----------------------------------------------------------------------
Ran 1 test in 0.027s

FAILED (errors=1)
E
======================================================================
ERROR: test_return_book (ClassEval_14_2.BookManagementDBTestReturnBook)
----------------------------------------------------------------------
Traceback (most recent call last):
  File "C:\Users\tanuj\Desktop\CS540\repo\CS540\classeval_evaluation\ClassEval_14_2.py", line 221, in test_return_book
    self.cursor.execute("SELECT available FROM books WHERE id=1")
sqlite3.OperationalError: no such table: books

----------------------------------------------------------------------
Ran 1 test in 0.035s

FAILED (errors=1)
.
----------------------------------------------------------------------
Ran 1 test in 0.031s

OK
.F
======================================================================
FAIL: test_create_table_2 (ClassEval_14_3.BookManagementDBTestCreateTable)
----------------------------------------------------------------------
Traceback (most recent call last):
  File "C:\Users\tanuj\Desktop\CS540\repo\CS540\classeval_evaluation\ClassEval_14_3.py", line 113, in test_create_table_2
    self.assertEqual(column_names, expected_column_names)
AssertionError: Lists differ: ['id', 'title', 'author', 'availability'] != ['id', 'title', 'author', 'available']

First differing element 3:
'availability'
'available'

- ['id', 'title', 'author', 'availability']
?                                   - ^^^

+ ['id', 'title', 'author', 'available']
?                                    ^


----------------------------------------------------------------------
Ran 2 tests in 0.023s

FAILED (failures=1)
E
======================================================================
ERROR: test_add_book (ClassEval_14_3.BookManagementDBTestAddBook)
----------------------------------------------------------------------
Traceback (most recent call last):
  File "C:\Users\tanuj\Desktop\CS540\repo\CS540\classeval_evaluation\ClassEval_14_3.py", line 135, in test_add_book
    self.cursor.execute("SELECT title, author, available FROM books WHERE id=1")
sqlite3.OperationalError: no such column: available

----------------------------------------------------------------------
Ran 1 test in 0.017s

FAILED (errors=1)
.
----------------------------------------------------------------------
Ran 1 test in 0.025s

OK
E
======================================================================
ERROR: test_borrow_book (ClassEval_14_3.BookManagementDBTestBorrowBook)
----------------------------------------------------------------------
Traceback (most recent call last):
  File "C:\Users\tanuj\Desktop\CS540\repo\CS540\classeval_evaluation\ClassEval_14_3.py", line 186, in test_borrow_book
    self.cursor.execute("SELECT available FROM books WHERE id=1")
sqlite3.OperationalError: no such column: available

----------------------------------------------------------------------
Ran 1 test in 0.031s

FAILED (errors=1)
E
======================================================================
ERROR: test_return_book (ClassEval_14_3.BookManagementDBTestReturnBook)
----------------------------------------------------------------------
Traceback (most recent call last):
  File "C:\Users\tanuj\Desktop\CS540\repo\CS540\classeval_evaluation\ClassEval_14_3.py", line 211, in test_return_book
    self.cursor.execute("SELECT available FROM books WHERE id=1")
sqlite3.OperationalError: no such column: available

----------------------------------------------------------------------
Ran 1 test in 0.036s

FAILED (errors=1)
.
----------------------------------------------------------------------
Ran 1 test in 0.036s

OK
.F
======================================================================
FAIL: test_create_table_2 (ClassEval_14_4.BookManagementDBTestCreateTable)
----------------------------------------------------------------------
Traceback (most recent call last):
  File "C:\Users\tanuj\Desktop\CS540\repo\CS540\classeval_evaluation\ClassEval_14_4.py", line 122, in test_create_table_2
    self.assertEqual(column_names, expected_column_names)
AssertionError: Lists differ: ['id', 'title', 'author', 'availability'] != ['id', 'title', 'author', 'available']

First differing element 3:
'availability'
'available'

- ['id', 'title', 'author', 'availability']
?                                   - ^^^

+ ['id', 'title', 'author', 'available']
?                                    ^


----------------------------------------------------------------------
Ran 2 tests in 0.026s

FAILED (failures=1)
E
======================================================================
ERROR: test_add_book (ClassEval_14_4.BookManagementDBTestAddBook)
----------------------------------------------------------------------
Traceback (most recent call last):
  File "C:\Users\tanuj\Desktop\CS540\repo\CS540\classeval_evaluation\ClassEval_14_4.py", line 144, in test_add_book
    self.cursor.execute("SELECT title, author, available FROM books WHERE id=1")
sqlite3.OperationalError: no such column: available

----------------------------------------------------------------------
Ran 1 test in 0.021s

FAILED (errors=1)
.
----------------------------------------------------------------------
Ran 1 test in 0.035s

OK
E
======================================================================
ERROR: test_borrow_book (ClassEval_14_4.BookManagementDBTestBorrowBook)
----------------------------------------------------------------------
Traceback (most recent call last):
  File "C:\Users\tanuj\Desktop\CS540\repo\CS540\classeval_evaluation\ClassEval_14_4.py", line 195, in test_borrow_book
    self.cursor.execute("SELECT available FROM books WHERE id=1")
sqlite3.OperationalError: no such column: available

----------------------------------------------------------------------
Ran 1 test in 0.033s

FAILED (errors=1)
E
======================================================================
ERROR: test_return_book (ClassEval_14_4.BookManagementDBTestReturnBook)
----------------------------------------------------------------------
Traceback (most recent call last):
  File "C:\Users\tanuj\Desktop\CS540\repo\CS540\classeval_evaluation\ClassEval_14_4.py", line 220, in test_return_book
    self.cursor.execute("SELECT available FROM books WHERE id=1")
sqlite3.OperationalError: no such column: available

----------------------------------------------------------------------
Ran 1 test in 0.037s

FAILED (errors=1)
.
----------------------------------------------------------------------
Ran 1 test in 0.043s

OK
.....
----------------------------------------------------------------------
Ran 5 tests in 0.056s

OK
.....
----------------------------------------------------------------------
Ran 5 tests in 0.142s

OK
.....
----------------------------------------------------------------------
Ran 5 tests in 0.134s

OK
.....
----------------------------------------------------------------------
Ran 5 tests in 0.265s

OK
.
----------------------------------------------------------------------
Ran 1 test in 0.059s

OK
.....
----------------------------------------------------------------------
Ran 5 tests in 0.063s

OK
.....
----------------------------------------------------------------------
Ran 5 tests in 0.248s

OK
.....
----------------------------------------------------------------------
Ran 5 tests in 0.245s

OK
.....
----------------------------------------------------------------------
Ran 5 tests in 0.295s

OK
.
----------------------------------------------------------------------
Ran 1 test in 0.039s

OK
.....
----------------------------------------------------------------------
Ran 5 tests in 0.044s

OK
.....
----------------------------------------------------------------------
Ran 5 tests in 0.198s

OK
.....
----------------------------------------------------------------------
Ran 5 tests in 0.221s

OK
.....
----------------------------------------------------------------------
Ran 5 tests in 0.327s

OK
.
----------------------------------------------------------------------
Ran 1 test in 0.062s

OK
.....
----------------------------------------------------------------------
Ran 5 tests in 0.039s

OK
.....
----------------------------------------------------------------------
Ran 5 tests in 0.164s

OK
.....
----------------------------------------------------------------------
Ran 5 tests in 0.216s

OK
.....
----------------------------------------------------------------------
Ran 5 tests in 0.564s

OK
.
----------------------------------------------------------------------
Ran 1 test in 0.050s

OK
.....
----------------------------------------------------------------------
Ran 5 tests in 0.034s

OK
.....
----------------------------------------------------------------------
Ran 5 tests in 0.153s

OK
.....
----------------------------------------------------------------------
Ran 5 tests in 0.169s

OK
.....
----------------------------------------------------------------------
Ran 5 tests in 0.246s

OK
.
----------------------------------------------------------------------
Ran 1 test in 0.051s

OK
.....
----------------------------------------------------------------------
Ran 5 tests in 0.093s

OK
.....
----------------------------------------------------------------------
Ran 5 tests in 0.088s

OK
.....
----------------------------------------------------------------------
Ran 5 tests in 0.118s

OK
.
----------------------------------------------------------------------
Ran 1 test in 0.024s

OK
.....
----------------------------------------------------------------------
Ran 5 tests in 0.103s

OK
.....
----------------------------------------------------------------------
Ran 5 tests in 0.082s

OK
.....
----------------------------------------------------------------------
Ran 5 tests in 0.120s

OK
.
----------------------------------------------------------------------
Ran 1 test in 0.025s

OK
.....
----------------------------------------------------------------------
Ran 5 tests in 0.094s

OK
.....
----------------------------------------------------------------------
Ran 5 tests in 0.139s

OK
.....
----------------------------------------------------------------------
Ran 5 tests in 0.191s

OK
.
----------------------------------------------------------------------
Ran 1 test in 0.023s

OK
.....
----------------------------------------------------------------------
Ran 5 tests in 0.110s

OK
.....
----------------------------------------------------------------------
Ran 5 tests in 0.141s

OK
.....
----------------------------------------------------------------------
Ran 5 tests in 0.213s

OK
.
----------------------------------------------------------------------
Ran 1 test in 0.042s

OK
.....
----------------------------------------------------------------------
Ran 5 tests in 0.158s

OK
.....
----------------------------------------------------------------------
Ran 5 tests in 0.140s

OK
.....
----------------------------------------------------------------------
Ran 5 tests in 0.146s

OK
.
----------------------------------------------------------------------
Ran 1 test in 0.036s

OK
......
----------------------------------------------------------------------
Ran 6 tests in 0.001s

OK
.....
----------------------------------------------------------------------
Ran 5 tests in 0.001s

OK
.....
----------------------------------------------------------------------
Ran 5 tests in 0.001s

OK
.....
----------------------------------------------------------------------
Ran 5 tests in 0.001s

OK
.....
----------------------------------------------------------------------
Ran 5 tests in 0.001s

OK
.....
----------------------------------------------------------------------
Ran 5 tests in 0.001s

OK
.
----------------------------------------------------------------------
Ran 1 test in 0.000s

OK
......
----------------------------------------------------------------------
Ran 6 tests in 0.001s

OK
.....
----------------------------------------------------------------------
Ran 5 tests in 0.001s

OK
.....
----------------------------------------------------------------------
Ran 5 tests in 0.001s

OK
.....
----------------------------------------------------------------------
Ran 5 tests in 0.001s

OK
.....
----------------------------------------------------------------------
Ran 5 tests in 0.001s

OK
.....
----------------------------------------------------------------------
Ran 5 tests in 0.001s

OK
.
----------------------------------------------------------------------
Ran 1 test in 0.000s

OK
......
----------------------------------------------------------------------
Ran 6 tests in 0.001s

OK
.....
----------------------------------------------------------------------
Ran 5 tests in 0.001s

OK
.....
----------------------------------------------------------------------
Ran 5 tests in 0.001s

OK
.....
----------------------------------------------------------------------
Ran 5 tests in 0.001s

OK
.....
----------------------------------------------------------------------
Ran 5 tests in 0.001s

OK
.....
----------------------------------------------------------------------
Ran 5 tests in 0.001s

OK
.
----------------------------------------------------------------------
Ran 1 test in 0.000s

OK
......
----------------------------------------------------------------------
Ran 6 tests in 0.001s

OK
.....
----------------------------------------------------------------------
Ran 5 tests in 0.001s

OK
.....
----------------------------------------------------------------------
Ran 5 tests in 0.001s

OK
.....
----------------------------------------------------------------------
Ran 5 tests in 0.001s

OK
.....
----------------------------------------------------------------------
Ran 5 tests in 0.001s

OK
.....
----------------------------------------------------------------------
Ran 5 tests in 0.001s

OK
.
----------------------------------------------------------------------
Ran 1 test in 0.000s

OK
......
----------------------------------------------------------------------
Ran 6 tests in 0.001s

OK
.....
----------------------------------------------------------------------
Ran 5 tests in 0.001s

OK
.....
----------------------------------------------------------------------
Ran 5 tests in 0.001s

OK
.....
----------------------------------------------------------------------
Ran 5 tests in 0.002s

OK
.....
----------------------------------------------------------------------
Ran 5 tests in 0.001s

OK
.....
----------------------------------------------------------------------
Ran 5 tests in 0.001s

OK
.
----------------------------------------------------------------------
Ran 1 test in 0.000s

OK
.......
----------------------------------------------------------------------
Ran 7 tests in 0.001s

OK
.....
----------------------------------------------------------------------
Ran 5 tests in 0.001s

OK
......
----------------------------------------------------------------------
Ran 6 tests in 0.001s

OK
......
----------------------------------------------------------------------
Ran 6 tests in 0.001s

OK
.
----------------------------------------------------------------------
Ran 1 test in 0.000s

OK
.......
----------------------------------------------------------------------
Ran 7 tests in 0.001s

OK
.....
----------------------------------------------------------------------
Ran 5 tests in 0.001s

OK
......
----------------------------------------------------------------------
Ran 6 tests in 0.001s

OK
......
----------------------------------------------------------------------
Ran 6 tests in 0.001s

OK
.
----------------------------------------------------------------------
Ran 1 test in 0.000s

OK
.......
----------------------------------------------------------------------
Ran 7 tests in 0.001s

OK
.....
----------------------------------------------------------------------
Ran 5 tests in 0.001s

OK
......
----------------------------------------------------------------------
Ran 6 tests in 0.002s

OK
......
----------------------------------------------------------------------
Ran 6 tests in 0.001s

OK
.
----------------------------------------------------------------------
Ran 1 test in 0.001s

OK
.......
----------------------------------------------------------------------
Ran 7 tests in 0.002s

OK
.....
----------------------------------------------------------------------
Ran 5 tests in 0.001s

OK
......
----------------------------------------------------------------------
Ran 6 tests in 0.001s

OK
......
----------------------------------------------------------------------
Ran 6 tests in 0.001s

OK
.
----------------------------------------------------------------------
Ran 1 test in 0.001s

OK
.......
----------------------------------------------------------------------
Ran 7 tests in 0.002s

OK
.....
----------------------------------------------------------------------
Ran 5 tests in 0.001s

OK
......
----------------------------------------------------------------------
Ran 6 tests in 0.001s

OK
......
----------------------------------------------------------------------
Ran 6 tests in 0.001s

OK
.
----------------------------------------------------------------------
Ran 1 test in 0.000s

OK
.....
----------------------------------------------------------------------
Ran 5 tests in 0.221s

OK
.....
----------------------------------------------------------------------
Ran 5 tests in 0.141s

OK
.....
----------------------------------------------------------------------
Ran 5 tests in 0.199s

OK
.
----------------------------------------------------------------------
Ran 1 test in 0.069s

OK
.....
----------------------------------------------------------------------
Ran 5 tests in 0.210s

OK
.....
----------------------------------------------------------------------
Ran 5 tests in 0.249s

OK
.....
----------------------------------------------------------------------
Ran 5 tests in 0.213s

OK
.
----------------------------------------------------------------------
Ran 1 test in 0.254s

OK
.....
----------------------------------------------------------------------
Ran 5 tests in 0.308s

OK
.....
----------------------------------------------------------------------
Ran 5 tests in 0.229s

OK
.....
----------------------------------------------------------------------
Ran 5 tests in 0.306s

OK
.
----------------------------------------------------------------------
Ran 1 test in 0.096s

OK
.....
----------------------------------------------------------------------
Ran 5 tests in 0.192s

OK
.....
----------------------------------------------------------------------
Ran 5 tests in 0.213s

OK
.....
----------------------------------------------------------------------
Ran 5 tests in 0.321s

OK
.
----------------------------------------------------------------------
Ran 1 test in 0.106s

OK
.....
----------------------------------------------------------------------
Ran 5 tests in 0.200s

OK
.....
----------------------------------------------------------------------
Ran 5 tests in 0.178s

OK
.....
----------------------------------------------------------------------
Ran 5 tests in 0.294s

OK
.
----------------------------------------------------------------------
Ran 1 test in 0.068s

OK
FFFFF
======================================================================
FAIL: test_insert_user_1 (ClassEval_92_0.UserLoginDBTestInsertUser)
----------------------------------------------------------------------
Traceback (most recent call last):
  File "C:\Users\tanuj\Desktop\CS540\repo\CS540\classeval_evaluation\ClassEval_92_0.py", line 115, in test_insert_user_1
    self.assertEqual(user[0], 'user1')
AssertionError: ('user1', 'pass1') != 'user1'

======================================================================
FAIL: test_insert_user_2 (ClassEval_92_0.UserLoginDBTestInsertUser)
----------------------------------------------------------------------
Traceback (most recent call last):
  File "C:\Users\tanuj\Desktop\CS540\repo\CS540\classeval_evaluation\ClassEval_92_0.py", line 122, in test_insert_user_2
    self.assertEqual(user[0], 'user2')
AssertionError: ('user2', 'pass2') != 'user2'

======================================================================
FAIL: test_insert_user_3 (ClassEval_92_0.UserLoginDBTestInsertUser)
----------------------------------------------------------------------
Traceback (most recent call last):
  File "C:\Users\tanuj\Desktop\CS540\repo\CS540\classeval_evaluation\ClassEval_92_0.py", line 129, in test_insert_user_3
    self.assertEqual(user[0], 'user3')
AssertionError: ('user3', 'pass3') != 'user3'

======================================================================
FAIL: test_insert_user_4 (ClassEval_92_0.UserLoginDBTestInsertUser)
----------------------------------------------------------------------
Traceback (most recent call last):
  File "C:\Users\tanuj\Desktop\CS540\repo\CS540\classeval_evaluation\ClassEval_92_0.py", line 136, in test_insert_user_4
    self.assertEqual(user[0], 'user4')
AssertionError: ('user4', 'pass4') != 'user4'

======================================================================
FAIL: test_insert_user_5 (ClassEval_92_0.UserLoginDBTestInsertUser)
----------------------------------------------------------------------
Traceback (most recent call last):
  File "C:\Users\tanuj\Desktop\CS540\repo\CS540\classeval_evaluation\ClassEval_92_0.py", line 143, in test_insert_user_5
    self.assertEqual(user[0], 'user5')
AssertionError: ('user5', 'pass5') != 'user5'

----------------------------------------------------------------------
Ran 5 tests in 0.110s

FAILED (failures=5)
FFFFF
======================================================================
FAIL: test_search_user_by_username_1 (ClassEval_92_0.UserLoginDBTestSearchUserByUsername)
----------------------------------------------------------------------
Traceback (most recent call last):
  File "C:\Users\tanuj\Desktop\CS540\repo\CS540\classeval_evaluation\ClassEval_92_0.py", line 172, in test_search_user_by_username_1
    self.assertEqual(user[0], 'user1')
AssertionError: ('user1', 'pass1') != 'user1'

======================================================================
FAIL: test_search_user_by_username_2 (ClassEval_92_0.UserLoginDBTestSearchUserByUsername)
----------------------------------------------------------------------
Traceback (most recent call last):
  File "C:\Users\tanuj\Desktop\CS540\repo\CS540\classeval_evaluation\ClassEval_92_0.py", line 179, in test_search_user_by_username_2
    self.assertEqual(user[0], 'user2')
AssertionError: ('user2', 'pass2') != 'user2'

======================================================================
FAIL: test_search_user_by_username_3 (ClassEval_92_0.UserLoginDBTestSearchUserByUsername)
----------------------------------------------------------------------
Traceback (most recent call last):
  File "C:\Users\tanuj\Desktop\CS540\repo\CS540\classeval_evaluation\ClassEval_92_0.py", line 186, in test_search_user_by_username_3
    self.assertEqual(user[0], 'user3')
AssertionError: ('user3', 'pass3') != 'user3'

======================================================================
FAIL: test_search_user_by_username_4 (ClassEval_92_0.UserLoginDBTestSearchUserByUsername)
----------------------------------------------------------------------
Traceback (most recent call last):
  File "C:\Users\tanuj\Desktop\CS540\repo\CS540\classeval_evaluation\ClassEval_92_0.py", line 193, in test_search_user_by_username_4
    self.assertEqual(user[0], 'user4')
AssertionError: ('user4', 'pass4') != 'user4'

======================================================================
FAIL: test_search_user_by_username_5 (ClassEval_92_0.UserLoginDBTestSearchUserByUsername)
----------------------------------------------------------------------
Traceback (most recent call last):
  File "C:\Users\tanuj\Desktop\CS540\repo\CS540\classeval_evaluation\ClassEval_92_0.py", line 200, in test_search_user_by_username_5
    self.assertEqual(user[0], 'user5')
AssertionError: ('user5', 'pass5') != 'user5'

----------------------------------------------------------------------
Ran 5 tests in 0.151s

FAILED (failures=5)
FFFFF
======================================================================
FAIL: test_delete_user_by_username_1 (ClassEval_92_0.UserLoginDBTestDeleteUserByUsername)
----------------------------------------------------------------------
Traceback (most recent call last):
  File "C:\Users\tanuj\Desktop\CS540\repo\CS540\classeval_evaluation\ClassEval_92_0.py", line 229, in test_delete_user_by_username_1
    self.assertIsNone(user)
AssertionError: [] is not None

======================================================================
FAIL: test_delete_user_by_username_2 (ClassEval_92_0.UserLoginDBTestDeleteUserByUsername)
----------------------------------------------------------------------
Traceback (most recent call last):
  File "C:\Users\tanuj\Desktop\CS540\repo\CS540\classeval_evaluation\ClassEval_92_0.py", line 235, in test_delete_user_by_username_2
    self.assertIsNone(user)
AssertionError: [] is not None

======================================================================
FAIL: test_delete_user_by_username_3 (ClassEval_92_0.UserLoginDBTestDeleteUserByUsername)
----------------------------------------------------------------------
Traceback (most recent call last):
  File "C:\Users\tanuj\Desktop\CS540\repo\CS540\classeval_evaluation\ClassEval_92_0.py", line 241, in test_delete_user_by_username_3
    self.assertIsNone(user)
AssertionError: [] is not None

======================================================================
FAIL: test_delete_user_by_username_4 (ClassEval_92_0.UserLoginDBTestDeleteUserByUsername)
----------------------------------------------------------------------
Traceback (most recent call last):
  File "C:\Users\tanuj\Desktop\CS540\repo\CS540\classeval_evaluation\ClassEval_92_0.py", line 247, in test_delete_user_by_username_4
    self.assertIsNone(user)
AssertionError: [] is not None

======================================================================
FAIL: test_delete_user_by_username_5 (ClassEval_92_0.UserLoginDBTestDeleteUserByUsername)
----------------------------------------------------------------------
Traceback (most recent call last):
  File "C:\Users\tanuj\Desktop\CS540\repo\CS540\classeval_evaluation\ClassEval_92_0.py", line 253, in test_delete_user_by_username_5
    self.assertIsNone(user)
AssertionError: [] is not None

----------------------------------------------------------------------
Ran 5 tests in 0.171s

FAILED (failures=5)
.....
----------------------------------------------------------------------
Ran 5 tests in 0.095s

OK
F
======================================================================
FAIL: test_UserLoginDB (ClassEval_92_0.UserLoginDBTest)
----------------------------------------------------------------------
Traceback (most recent call last):
  File "C:\Users\tanuj\Desktop\CS540\repo\CS540\classeval_evaluation\ClassEval_92_0.py", line 327, in test_UserLoginDB
    self.assertEqual(user[0], 'user1')
AssertionError: ('user1', 'pass1') != 'user1'

----------------------------------------------------------------------
Ran 1 test in 0.024s

FAILED (failures=1)
FFFFF
======================================================================
FAIL: test_insert_user_1 (ClassEval_92_1.UserLoginDBTestInsertUser)
----------------------------------------------------------------------
Traceback (most recent call last):
  File "C:\Users\tanuj\Desktop\CS540\repo\CS540\classeval_evaluation\ClassEval_92_1.py", line 128, in test_insert_user_1
    self.assertEqual(user[0], 'user1')
AssertionError: ('user1', 'pass1') != 'user1'

======================================================================
FAIL: test_insert_user_2 (ClassEval_92_1.UserLoginDBTestInsertUser)
----------------------------------------------------------------------
Traceback (most recent call last):
  File "C:\Users\tanuj\Desktop\CS540\repo\CS540\classeval_evaluation\ClassEval_92_1.py", line 135, in test_insert_user_2
    self.assertEqual(user[0], 'user2')
AssertionError: ('user2', 'pass2') != 'user2'

======================================================================
FAIL: test_insert_user_3 (ClassEval_92_1.UserLoginDBTestInsertUser)
----------------------------------------------------------------------
Traceback (most recent call last):
  File "C:\Users\tanuj\Desktop\CS540\repo\CS540\classeval_evaluation\ClassEval_92_1.py", line 142, in test_insert_user_3
    self.assertEqual(user[0], 'user3')
AssertionError: ('user3', 'pass3') != 'user3'

======================================================================
FAIL: test_insert_user_4 (ClassEval_92_1.UserLoginDBTestInsertUser)
----------------------------------------------------------------------
Traceback (most recent call last):
  File "C:\Users\tanuj\Desktop\CS540\repo\CS540\classeval_evaluation\ClassEval_92_1.py", line 149, in test_insert_user_4
    self.assertEqual(user[0], 'user4')
AssertionError: ('user4', 'pass4') != 'user4'

======================================================================
FAIL: test_insert_user_5 (ClassEval_92_1.UserLoginDBTestInsertUser)
----------------------------------------------------------------------
Traceback (most recent call last):
  File "C:\Users\tanuj\Desktop\CS540\repo\CS540\classeval_evaluation\ClassEval_92_1.py", line 156, in test_insert_user_5
    self.assertEqual(user[0], 'user5')
AssertionError: ('user5', 'pass5') != 'user5'

----------------------------------------------------------------------
Ran 5 tests in 0.110s

FAILED (failures=5)
FFFFF
======================================================================
FAIL: test_search_user_by_username_1 (ClassEval_92_1.UserLoginDBTestSearchUserByUsername)
----------------------------------------------------------------------
Traceback (most recent call last):
  File "C:\Users\tanuj\Desktop\CS540\repo\CS540\classeval_evaluation\ClassEval_92_1.py", line 185, in test_search_user_by_username_1
    self.assertEqual(user[0], 'user1')
AssertionError: ('user1', 'pass1') != 'user1'

======================================================================
FAIL: test_search_user_by_username_2 (ClassEval_92_1.UserLoginDBTestSearchUserByUsername)
----------------------------------------------------------------------
Traceback (most recent call last):
  File "C:\Users\tanuj\Desktop\CS540\repo\CS540\classeval_evaluation\ClassEval_92_1.py", line 192, in test_search_user_by_username_2
    self.assertEqual(user[0], 'user2')
AssertionError: ('user2', 'pass2') != 'user2'

======================================================================
FAIL: test_search_user_by_username_3 (ClassEval_92_1.UserLoginDBTestSearchUserByUsername)
----------------------------------------------------------------------
Traceback (most recent call last):
  File "C:\Users\tanuj\Desktop\CS540\repo\CS540\classeval_evaluation\ClassEval_92_1.py", line 199, in test_search_user_by_username_3
    self.assertEqual(user[0], 'user3')
AssertionError: ('user3', 'pass3') != 'user3'

======================================================================
FAIL: test_search_user_by_username_4 (ClassEval_92_1.UserLoginDBTestSearchUserByUsername)
----------------------------------------------------------------------
Traceback (most recent call last):
  File "C:\Users\tanuj\Desktop\CS540\repo\CS540\classeval_evaluation\ClassEval_92_1.py", line 206, in test_search_user_by_username_4
    self.assertEqual(user[0], 'user4')
AssertionError: ('user4', 'pass4') != 'user4'

======================================================================
FAIL: test_search_user_by_username_5 (ClassEval_92_1.UserLoginDBTestSearchUserByUsername)
----------------------------------------------------------------------
Traceback (most recent call last):
  File "C:\Users\tanuj\Desktop\CS540\repo\CS540\classeval_evaluation\ClassEval_92_1.py", line 213, in test_search_user_by_username_5
    self.assertEqual(user[0], 'user5')
AssertionError: ('user5', 'pass5') != 'user5'

----------------------------------------------------------------------
Ran 5 tests in 0.101s

FAILED (failures=5)
FFFFF
======================================================================
FAIL: test_delete_user_by_username_1 (ClassEval_92_1.UserLoginDBTestDeleteUserByUsername)
----------------------------------------------------------------------
Traceback (most recent call last):
  File "C:\Users\tanuj\Desktop\CS540\repo\CS540\classeval_evaluation\ClassEval_92_1.py", line 242, in test_delete_user_by_username_1
    self.assertIsNone(user)
AssertionError: [] is not None

======================================================================
FAIL: test_delete_user_by_username_2 (ClassEval_92_1.UserLoginDBTestDeleteUserByUsername)
----------------------------------------------------------------------
Traceback (most recent call last):
  File "C:\Users\tanuj\Desktop\CS540\repo\CS540\classeval_evaluation\ClassEval_92_1.py", line 248, in test_delete_user_by_username_2
    self.assertIsNone(user)
AssertionError: [] is not None

======================================================================
FAIL: test_delete_user_by_username_3 (ClassEval_92_1.UserLoginDBTestDeleteUserByUsername)
----------------------------------------------------------------------
Traceback (most recent call last):
  File "C:\Users\tanuj\Desktop\CS540\repo\CS540\classeval_evaluation\ClassEval_92_1.py", line 254, in test_delete_user_by_username_3
    self.assertIsNone(user)
AssertionError: [] is not None

======================================================================
FAIL: test_delete_user_by_username_4 (ClassEval_92_1.UserLoginDBTestDeleteUserByUsername)
----------------------------------------------------------------------
Traceback (most recent call last):
  File "C:\Users\tanuj\Desktop\CS540\repo\CS540\classeval_evaluation\ClassEval_92_1.py", line 260, in test_delete_user_by_username_4
    self.assertIsNone(user)
AssertionError: [] is not None

======================================================================
FAIL: test_delete_user_by_username_5 (ClassEval_92_1.UserLoginDBTestDeleteUserByUsername)
----------------------------------------------------------------------
Traceback (most recent call last):
  File "C:\Users\tanuj\Desktop\CS540\repo\CS540\classeval_evaluation\ClassEval_92_1.py", line 266, in test_delete_user_by_username_5
    self.assertIsNone(user)
AssertionError: [] is not None

----------------------------------------------------------------------
Ran 5 tests in 0.150s

FAILED (failures=5)
.....
----------------------------------------------------------------------
Ran 5 tests in 0.114s

OK
F
======================================================================
FAIL: test_UserLoginDB (ClassEval_92_1.UserLoginDBTest)
----------------------------------------------------------------------
Traceback (most recent call last):
  File "C:\Users\tanuj\Desktop\CS540\repo\CS540\classeval_evaluation\ClassEval_92_1.py", line 340, in test_UserLoginDB
    self.assertEqual(user[0], 'user1')
AssertionError: ('user1', 'pass1') != 'user1'

----------------------------------------------------------------------
Ran 1 test in 0.035s

FAILED (failures=1)
EEEEE
======================================================================
ERROR: test_insert_user_1 (ClassEval_92_2.UserLoginDBTestInsertUser)
----------------------------------------------------------------------
Traceback (most recent call last):
  File "C:\Users\tanuj\Desktop\CS540\repo\CS540\classeval_evaluation\ClassEval_92_2.py", line 131, in test_insert_user_1
    user = self.db.search_user_by_username('user1')
  File "C:\Users\tanuj\Desktop\CS540\repo\CS540\classeval_evaluation\ClassEval_92_2.py", line 58, in search_user_by_username
    self.cursor.execute(
sqlite3.OperationalError: no such column: id

======================================================================
ERROR: test_insert_user_2 (ClassEval_92_2.UserLoginDBTestInsertUser)
----------------------------------------------------------------------
Traceback (most recent call last):
  File "C:\Users\tanuj\Desktop\CS540\repo\CS540\classeval_evaluation\ClassEval_92_2.py", line 138, in test_insert_user_2
    user = self.db.search_user_by_username('user2')
  File "C:\Users\tanuj\Desktop\CS540\repo\CS540\classeval_evaluation\ClassEval_92_2.py", line 58, in search_user_by_username
    self.cursor.execute(
sqlite3.OperationalError: no such column: id

======================================================================
ERROR: test_insert_user_3 (ClassEval_92_2.UserLoginDBTestInsertUser)
----------------------------------------------------------------------
Traceback (most recent call last):
  File "C:\Users\tanuj\Desktop\CS540\repo\CS540\classeval_evaluation\ClassEval_92_2.py", line 145, in test_insert_user_3
    user = self.db.search_user_by_username('user3')
  File "C:\Users\tanuj\Desktop\CS540\repo\CS540\classeval_evaluation\ClassEval_92_2.py", line 58, in search_user_by_username
    self.cursor.execute(
sqlite3.OperationalError: no such column: id

======================================================================
ERROR: test_insert_user_4 (ClassEval_92_2.UserLoginDBTestInsertUser)
----------------------------------------------------------------------
Traceback (most recent call last):
  File "C:\Users\tanuj\Desktop\CS540\repo\CS540\classeval_evaluation\ClassEval_92_2.py", line 152, in test_insert_user_4
    user = self.db.search_user_by_username('user4')
  File "C:\Users\tanuj\Desktop\CS540\repo\CS540\classeval_evaluation\ClassEval_92_2.py", line 58, in search_user_by_username
    self.cursor.execute(
sqlite3.OperationalError: no such column: id

======================================================================
ERROR: test_insert_user_5 (ClassEval_92_2.UserLoginDBTestInsertUser)
----------------------------------------------------------------------
Traceback (most recent call last):
  File "C:\Users\tanuj\Desktop\CS540\repo\CS540\classeval_evaluation\ClassEval_92_2.py", line 159, in test_insert_user_5
    user = self.db.search_user_by_username('user5')
  File "C:\Users\tanuj\Desktop\CS540\repo\CS540\classeval_evaluation\ClassEval_92_2.py", line 58, in search_user_by_username
    self.cursor.execute(
sqlite3.OperationalError: no such column: id

----------------------------------------------------------------------
Ran 5 tests in 0.162s

FAILED (errors=5)
EEEEE
======================================================================
ERROR: test_search_user_by_username_1 (ClassEval_92_2.UserLoginDBTestSearchUserByUsername)
----------------------------------------------------------------------
Traceback (most recent call last):
  File "C:\Users\tanuj\Desktop\CS540\repo\CS540\classeval_evaluation\ClassEval_92_2.py", line 188, in test_search_user_by_username_1
    user = self.db.search_user_by_username('user1')
  File "C:\Users\tanuj\Desktop\CS540\repo\CS540\classeval_evaluation\ClassEval_92_2.py", line 58, in search_user_by_username
    self.cursor.execute(
sqlite3.OperationalError: no such column: id

======================================================================
ERROR: test_search_user_by_username_2 (ClassEval_92_2.UserLoginDBTestSearchUserByUsername)
----------------------------------------------------------------------
Traceback (most recent call last):
  File "C:\Users\tanuj\Desktop\CS540\repo\CS540\classeval_evaluation\ClassEval_92_2.py", line 195, in test_search_user_by_username_2
    user = self.db.search_user_by_username('user2')
  File "C:\Users\tanuj\Desktop\CS540\repo\CS540\classeval_evaluation\ClassEval_92_2.py", line 58, in search_user_by_username
    self.cursor.execute(
sqlite3.OperationalError: no such column: id

======================================================================
ERROR: test_search_user_by_username_3 (ClassEval_92_2.UserLoginDBTestSearchUserByUsername)
----------------------------------------------------------------------
Traceback (most recent call last):
  File "C:\Users\tanuj\Desktop\CS540\repo\CS540\classeval_evaluation\ClassEval_92_2.py", line 202, in test_search_user_by_username_3
    user = self.db.search_user_by_username('user3')
  File "C:\Users\tanuj\Desktop\CS540\repo\CS540\classeval_evaluation\ClassEval_92_2.py", line 58, in search_user_by_username
    self.cursor.execute(
sqlite3.OperationalError: no such column: id

======================================================================
ERROR: test_search_user_by_username_4 (ClassEval_92_2.UserLoginDBTestSearchUserByUsername)
----------------------------------------------------------------------
Traceback (most recent call last):
  File "C:\Users\tanuj\Desktop\CS540\repo\CS540\classeval_evaluation\ClassEval_92_2.py", line 209, in test_search_user_by_username_4
    user = self.db.search_user_by_username('user4')
  File "C:\Users\tanuj\Desktop\CS540\repo\CS540\classeval_evaluation\ClassEval_92_2.py", line 58, in search_user_by_username
    self.cursor.execute(
sqlite3.OperationalError: no such column: id

======================================================================
ERROR: test_search_user_by_username_5 (ClassEval_92_2.UserLoginDBTestSearchUserByUsername)
----------------------------------------------------------------------
Traceback (most recent call last):
  File "C:\Users\tanuj\Desktop\CS540\repo\CS540\classeval_evaluation\ClassEval_92_2.py", line 216, in test_search_user_by_username_5
    user = self.db.search_user_by_username('user5')
  File "C:\Users\tanuj\Desktop\CS540\repo\CS540\classeval_evaluation\ClassEval_92_2.py", line 58, in search_user_by_username
    self.cursor.execute(
sqlite3.OperationalError: no such column: id

----------------------------------------------------------------------
Ran 5 tests in 0.159s

FAILED (errors=5)
EEEEE
======================================================================
ERROR: test_delete_user_by_username_1 (ClassEval_92_2.UserLoginDBTestDeleteUserByUsername)
----------------------------------------------------------------------
Traceback (most recent call last):
  File "C:\Users\tanuj\Desktop\CS540\repo\CS540\classeval_evaluation\ClassEval_92_2.py", line 246, in test_delete_user_by_username_1
    user = self.db.search_user_by_username('user1')
  File "C:\Users\tanuj\Desktop\CS540\repo\CS540\classeval_evaluation\ClassEval_92_2.py", line 58, in search_user_by_username
    self.cursor.execute(
sqlite3.OperationalError: no such column: id

======================================================================
ERROR: test_delete_user_by_username_2 (ClassEval_92_2.UserLoginDBTestDeleteUserByUsername)
----------------------------------------------------------------------
Traceback (most recent call last):
  File "C:\Users\tanuj\Desktop\CS540\repo\CS540\classeval_evaluation\ClassEval_92_2.py", line 252, in test_delete_user_by_username_2
    user = self.db.search_user_by_username('user2')
  File "C:\Users\tanuj\Desktop\CS540\repo\CS540\classeval_evaluation\ClassEval_92_2.py", line 58, in search_user_by_username
    self.cursor.execute(
sqlite3.OperationalError: no such column: id

======================================================================
ERROR: test_delete_user_by_username_3 (ClassEval_92_2.UserLoginDBTestDeleteUserByUsername)
----------------------------------------------------------------------
Traceback (most recent call last):
  File "C:\Users\tanuj\Desktop\CS540\repo\CS540\classeval_evaluation\ClassEval_92_2.py", line 258, in test_delete_user_by_username_3
    user = self.db.search_user_by_username('user3')
  File "C:\Users\tanuj\Desktop\CS540\repo\CS540\classeval_evaluation\ClassEval_92_2.py", line 58, in search_user_by_username
    self.cursor.execute(
sqlite3.OperationalError: no such column: id

======================================================================
ERROR: test_delete_user_by_username_4 (ClassEval_92_2.UserLoginDBTestDeleteUserByUsername)
----------------------------------------------------------------------
Traceback (most recent call last):
  File "C:\Users\tanuj\Desktop\CS540\repo\CS540\classeval_evaluation\ClassEval_92_2.py", line 264, in test_delete_user_by_username_4
    user = self.db.search_user_by_username('user4')
  File "C:\Users\tanuj\Desktop\CS540\repo\CS540\classeval_evaluation\ClassEval_92_2.py", line 58, in search_user_by_username
    self.cursor.execute(
sqlite3.OperationalError: no such column: id

======================================================================
ERROR: test_delete_user_by_username_5 (ClassEval_92_2.UserLoginDBTestDeleteUserByUsername)
----------------------------------------------------------------------
Traceback (most recent call last):
  File "C:\Users\tanuj\Desktop\CS540\repo\CS540\classeval_evaluation\ClassEval_92_2.py", line 270, in test_delete_user_by_username_5
    user = self.db.search_user_by_username('user5')
  File "C:\Users\tanuj\Desktop\CS540\repo\CS540\classeval_evaluation\ClassEval_92_2.py", line 58, in search_user_by_username
    self.cursor.execute(
sqlite3.OperationalError: no such column: id

----------------------------------------------------------------------
Ran 5 tests in 0.211s

FAILED (errors=5)
.....
----------------------------------------------------------------------
Ran 5 tests in 0.138s

OK
E
======================================================================
ERROR: test_UserLoginDB (ClassEval_92_2.UserLoginDBTest)
----------------------------------------------------------------------
Traceback (most recent call last):
  File "C:\Users\tanuj\Desktop\CS540\repo\CS540\classeval_evaluation\ClassEval_92_2.py", line 343, in test_UserLoginDB
    user = self.db.search_user_by_username('user1')
  File "C:\Users\tanuj\Desktop\CS540\repo\CS540\classeval_evaluation\ClassEval_92_2.py", line 58, in search_user_by_username
    self.cursor.execute(
sqlite3.OperationalError: no such column: id

----------------------------------------------------------------------
Ran 1 test in 0.034s

FAILED (errors=1)
FFFFF
======================================================================
FAIL: test_insert_user_1 (ClassEval_92_3.UserLoginDBTestInsertUser)
----------------------------------------------------------------------
Traceback (most recent call last):
  File "C:\Users\tanuj\Desktop\CS540\repo\CS540\classeval_evaluation\ClassEval_92_3.py", line 127, in test_insert_user_1
    self.assertEqual(user[0], 'user1')
AssertionError: ('user1', 'pass1') != 'user1'

======================================================================
FAIL: test_insert_user_2 (ClassEval_92_3.UserLoginDBTestInsertUser)
----------------------------------------------------------------------
Traceback (most recent call last):
  File "C:\Users\tanuj\Desktop\CS540\repo\CS540\classeval_evaluation\ClassEval_92_3.py", line 134, in test_insert_user_2
    self.assertEqual(user[0], 'user2')
AssertionError: ('user2', 'pass2') != 'user2'

======================================================================
FAIL: test_insert_user_3 (ClassEval_92_3.UserLoginDBTestInsertUser)
----------------------------------------------------------------------
Traceback (most recent call last):
  File "C:\Users\tanuj\Desktop\CS540\repo\CS540\classeval_evaluation\ClassEval_92_3.py", line 141, in test_insert_user_3
    self.assertEqual(user[0], 'user3')
AssertionError: ('user3', 'pass3') != 'user3'

======================================================================
FAIL: test_insert_user_4 (ClassEval_92_3.UserLoginDBTestInsertUser)
----------------------------------------------------------------------
Traceback (most recent call last):
  File "C:\Users\tanuj\Desktop\CS540\repo\CS540\classeval_evaluation\ClassEval_92_3.py", line 148, in test_insert_user_4
    self.assertEqual(user[0], 'user4')
AssertionError: ('user4', 'pass4') != 'user4'

======================================================================
FAIL: test_insert_user_5 (ClassEval_92_3.UserLoginDBTestInsertUser)
----------------------------------------------------------------------
Traceback (most recent call last):
  File "C:\Users\tanuj\Desktop\CS540\repo\CS540\classeval_evaluation\ClassEval_92_3.py", line 155, in test_insert_user_5
    self.assertEqual(user[0], 'user5')
AssertionError: ('user5', 'pass5') != 'user5'

----------------------------------------------------------------------
Ran 5 tests in 0.131s

FAILED (failures=5)
FFFFF
======================================================================
FAIL: test_search_user_by_username_1 (ClassEval_92_3.UserLoginDBTestSearchUserByUsername)
----------------------------------------------------------------------
Traceback (most recent call last):
  File "C:\Users\tanuj\Desktop\CS540\repo\CS540\classeval_evaluation\ClassEval_92_3.py", line 184, in test_search_user_by_username_1
    self.assertEqual(user[0], 'user1')
AssertionError: ('user1', 'pass1') != 'user1'

======================================================================
FAIL: test_search_user_by_username_2 (ClassEval_92_3.UserLoginDBTestSearchUserByUsername)
----------------------------------------------------------------------
Traceback (most recent call last):
  File "C:\Users\tanuj\Desktop\CS540\repo\CS540\classeval_evaluation\ClassEval_92_3.py", line 191, in test_search_user_by_username_2
    self.assertEqual(user[0], 'user2')
AssertionError: ('user2', 'pass2') != 'user2'

======================================================================
FAIL: test_search_user_by_username_3 (ClassEval_92_3.UserLoginDBTestSearchUserByUsername)
----------------------------------------------------------------------
Traceback (most recent call last):
  File "C:\Users\tanuj\Desktop\CS540\repo\CS540\classeval_evaluation\ClassEval_92_3.py", line 198, in test_search_user_by_username_3
    self.assertEqual(user[0], 'user3')
AssertionError: ('user3', 'pass3') != 'user3'

======================================================================
FAIL: test_search_user_by_username_4 (ClassEval_92_3.UserLoginDBTestSearchUserByUsername)
----------------------------------------------------------------------
Traceback (most recent call last):
  File "C:\Users\tanuj\Desktop\CS540\repo\CS540\classeval_evaluation\ClassEval_92_3.py", line 205, in test_search_user_by_username_4
    self.assertEqual(user[0], 'user4')
AssertionError: ('user4', 'pass4') != 'user4'

======================================================================
FAIL: test_search_user_by_username_5 (ClassEval_92_3.UserLoginDBTestSearchUserByUsername)
----------------------------------------------------------------------
Traceback (most recent call last):
  File "C:\Users\tanuj\Desktop\CS540\repo\CS540\classeval_evaluation\ClassEval_92_3.py", line 212, in test_search_user_by_username_5
    self.assertEqual(user[0], 'user5')
AssertionError: ('user5', 'pass5') != 'user5'

----------------------------------------------------------------------
Ran 5 tests in 0.111s

FAILED (failures=5)
FFFFF
======================================================================
FAIL: test_delete_user_by_username_1 (ClassEval_92_3.UserLoginDBTestDeleteUserByUsername)
----------------------------------------------------------------------
Traceback (most recent call last):
  File "C:\Users\tanuj\Desktop\CS540\repo\CS540\classeval_evaluation\ClassEval_92_3.py", line 241, in test_delete_user_by_username_1
    self.assertIsNone(user)
AssertionError: [] is not None

======================================================================
FAIL: test_delete_user_by_username_2 (ClassEval_92_3.UserLoginDBTestDeleteUserByUsername)
----------------------------------------------------------------------
Traceback (most recent call last):
  File "C:\Users\tanuj\Desktop\CS540\repo\CS540\classeval_evaluation\ClassEval_92_3.py", line 247, in test_delete_user_by_username_2
    self.assertIsNone(user)
AssertionError: [] is not None

======================================================================
FAIL: test_delete_user_by_username_3 (ClassEval_92_3.UserLoginDBTestDeleteUserByUsername)
----------------------------------------------------------------------
Traceback (most recent call last):
  File "C:\Users\tanuj\Desktop\CS540\repo\CS540\classeval_evaluation\ClassEval_92_3.py", line 253, in test_delete_user_by_username_3
    self.assertIsNone(user)
AssertionError: [] is not None

======================================================================
FAIL: test_delete_user_by_username_4 (ClassEval_92_3.UserLoginDBTestDeleteUserByUsername)
----------------------------------------------------------------------
Traceback (most recent call last):
  File "C:\Users\tanuj\Desktop\CS540\repo\CS540\classeval_evaluation\ClassEval_92_3.py", line 259, in test_delete_user_by_username_4
    self.assertIsNone(user)
AssertionError: [] is not None

======================================================================
FAIL: test_delete_user_by_username_5 (ClassEval_92_3.UserLoginDBTestDeleteUserByUsername)
----------------------------------------------------------------------
Traceback (most recent call last):
  File "C:\Users\tanuj\Desktop\CS540\repo\CS540\classeval_evaluation\ClassEval_92_3.py", line 265, in test_delete_user_by_username_5
    self.assertIsNone(user)
AssertionError: [] is not None

----------------------------------------------------------------------
Ran 5 tests in 0.190s

FAILED (failures=5)
.....
----------------------------------------------------------------------
Ran 5 tests in 0.126s

OK
F
======================================================================
FAIL: test_UserLoginDB (ClassEval_92_3.UserLoginDBTest)
----------------------------------------------------------------------
Traceback (most recent call last):
  File "C:\Users\tanuj\Desktop\CS540\repo\CS540\classeval_evaluation\ClassEval_92_3.py", line 339, in test_UserLoginDB
    self.assertEqual(user[0], 'user1')
AssertionError: ('user1', 'pass1') != 'user1'

----------------------------------------------------------------------
Ran 1 test in 0.028s

FAILED (failures=1)
FFFFF
======================================================================
FAIL: test_insert_user_1 (ClassEval_92_4.UserLoginDBTestInsertUser)
----------------------------------------------------------------------
Traceback (most recent call last):
  File "C:\Users\tanuj\Desktop\CS540\repo\CS540\classeval_evaluation\ClassEval_92_4.py", line 119, in test_insert_user_1
    self.assertEqual(user[0], 'user1')
AssertionError: ('user1', 'pass1') != 'user1'

======================================================================
FAIL: test_insert_user_2 (ClassEval_92_4.UserLoginDBTestInsertUser)
----------------------------------------------------------------------
Traceback (most recent call last):
  File "C:\Users\tanuj\Desktop\CS540\repo\CS540\classeval_evaluation\ClassEval_92_4.py", line 126, in test_insert_user_2
    self.assertEqual(user[0], 'user2')
AssertionError: ('user2', 'pass2') != 'user2'

======================================================================
FAIL: test_insert_user_3 (ClassEval_92_4.UserLoginDBTestInsertUser)
----------------------------------------------------------------------
Traceback (most recent call last):
  File "C:\Users\tanuj\Desktop\CS540\repo\CS540\classeval_evaluation\ClassEval_92_4.py", line 133, in test_insert_user_3
    self.assertEqual(user[0], 'user3')
AssertionError: ('user3', 'pass3') != 'user3'

======================================================================
FAIL: test_insert_user_4 (ClassEval_92_4.UserLoginDBTestInsertUser)
----------------------------------------------------------------------
Traceback (most recent call last):
  File "C:\Users\tanuj\Desktop\CS540\repo\CS540\classeval_evaluation\ClassEval_92_4.py", line 140, in test_insert_user_4
    self.assertEqual(user[0], 'user4')
AssertionError: ('user4', 'pass4') != 'user4'

======================================================================
FAIL: test_insert_user_5 (ClassEval_92_4.UserLoginDBTestInsertUser)
----------------------------------------------------------------------
Traceback (most recent call last):
  File "C:\Users\tanuj\Desktop\CS540\repo\CS540\classeval_evaluation\ClassEval_92_4.py", line 147, in test_insert_user_5
    self.assertEqual(user[0], 'user5')
AssertionError: ('user5', 'pass5') != 'user5'

----------------------------------------------------------------------
Ran 5 tests in 0.387s

FAILED (failures=5)
FFFFF
======================================================================
FAIL: test_search_user_by_username_1 (ClassEval_92_4.UserLoginDBTestSearchUserByUsername)
----------------------------------------------------------------------
Traceback (most recent call last):
  File "C:\Users\tanuj\Desktop\CS540\repo\CS540\classeval_evaluation\ClassEval_92_4.py", line 176, in test_search_user_by_username_1
    self.assertEqual(user[0], 'user1')
AssertionError: ('user1', 'pass1') != 'user1'

======================================================================
FAIL: test_search_user_by_username_2 (ClassEval_92_4.UserLoginDBTestSearchUserByUsername)
----------------------------------------------------------------------
Traceback (most recent call last):
  File "C:\Users\tanuj\Desktop\CS540\repo\CS540\classeval_evaluation\ClassEval_92_4.py", line 183, in test_search_user_by_username_2
    self.assertEqual(user[0], 'user2')
AssertionError: ('user2', 'pass2') != 'user2'

======================================================================
FAIL: test_search_user_by_username_3 (ClassEval_92_4.UserLoginDBTestSearchUserByUsername)
----------------------------------------------------------------------
Traceback (most recent call last):
  File "C:\Users\tanuj\Desktop\CS540\repo\CS540\classeval_evaluation\ClassEval_92_4.py", line 190, in test_search_user_by_username_3
    self.assertEqual(user[0], 'user3')
AssertionError: ('user3', 'pass3') != 'user3'

======================================================================
FAIL: test_search_user_by_username_4 (ClassEval_92_4.UserLoginDBTestSearchUserByUsername)
----------------------------------------------------------------------
Traceback (most recent call last):
  File "C:\Users\tanuj\Desktop\CS540\repo\CS540\classeval_evaluation\ClassEval_92_4.py", line 197, in test_search_user_by_username_4
    self.assertEqual(user[0], 'user4')
AssertionError: ('user4', 'pass4') != 'user4'

======================================================================
FAIL: test_search_user_by_username_5 (ClassEval_92_4.UserLoginDBTestSearchUserByUsername)
----------------------------------------------------------------------
Traceback (most recent call last):
  File "C:\Users\tanuj\Desktop\CS540\repo\CS540\classeval_evaluation\ClassEval_92_4.py", line 204, in test_search_user_by_username_5
    self.assertEqual(user[0], 'user5')
AssertionError: ('user5', 'pass5') != 'user5'

----------------------------------------------------------------------
Ran 5 tests in 0.146s

FAILED (failures=5)
FFFFF
======================================================================
FAIL: test_delete_user_by_username_1 (ClassEval_92_4.UserLoginDBTestDeleteUserByUsername)
----------------------------------------------------------------------
Traceback (most recent call last):
  File "C:\Users\tanuj\Desktop\CS540\repo\CS540\classeval_evaluation\ClassEval_92_4.py", line 233, in test_delete_user_by_username_1
    self.assertIsNone(user)
AssertionError: [] is not None

======================================================================
FAIL: test_delete_user_by_username_2 (ClassEval_92_4.UserLoginDBTestDeleteUserByUsername)
----------------------------------------------------------------------
Traceback (most recent call last):
  File "C:\Users\tanuj\Desktop\CS540\repo\CS540\classeval_evaluation\ClassEval_92_4.py", line 239, in test_delete_user_by_username_2
    self.assertIsNone(user)
AssertionError: [] is not None

======================================================================
FAIL: test_delete_user_by_username_3 (ClassEval_92_4.UserLoginDBTestDeleteUserByUsername)
----------------------------------------------------------------------
Traceback (most recent call last):
  File "C:\Users\tanuj\Desktop\CS540\repo\CS540\classeval_evaluation\ClassEval_92_4.py", line 245, in test_delete_user_by_username_3
    self.assertIsNone(user)
AssertionError: [] is not None

======================================================================
FAIL: test_delete_user_by_username_4 (ClassEval_92_4.UserLoginDBTestDeleteUserByUsername)
----------------------------------------------------------------------
Traceback (most recent call last):
  File "C:\Users\tanuj\Desktop\CS540\repo\CS540\classeval_evaluation\ClassEval_92_4.py", line 251, in test_delete_user_by_username_4
    self.assertIsNone(user)
AssertionError: [] is not None

======================================================================
FAIL: test_delete_user_by_username_5 (ClassEval_92_4.UserLoginDBTestDeleteUserByUsername)
----------------------------------------------------------------------
Traceback (most recent call last):
  File "C:\Users\tanuj\Desktop\CS540\repo\CS540\classeval_evaluation\ClassEval_92_4.py", line 257, in test_delete_user_by_username_5
    self.assertIsNone(user)
AssertionError: [] is not None

----------------------------------------------------------------------
Ran 5 tests in 0.195s

FAILED (failures=5)
.....
----------------------------------------------------------------------
Ran 5 tests in 0.137s

OK
F
======================================================================
FAIL: test_UserLoginDB (ClassEval_92_4.UserLoginDBTest)
----------------------------------------------------------------------
Traceback (most recent call last):
  File "C:\Users\tanuj\Desktop\CS540\repo\CS540\classeval_evaluation\ClassEval_92_4.py", line 331, in test_UserLoginDB
    self.assertEqual(user[0], 'user1')
AssertionError: ('user1', 'pass1') != 'user1'

----------------------------------------------------------------------
Ran 1 test in 0.025s

FAILED (failures=1)
