.F
======================================================================
FAIL: test_create_table_2 (ClassEval_14_0.BookManagementDBTestCreateTable.test_create_table_2)
----------------------------------------------------------------------
Traceback (most recent call last):
  File "/Users/snigdhaghoshdastidar/Desktop/CS540/classeval_evaluation/ClassEval_14_0.py", line 98, in test_create_table_2
    self.assertEqual(column_names, expected_column_names)
AssertionError: Lists differ: ['book_id', 'title', 'author', 'availability'] != ['id', 'title', 'author', 'available']

First differing element 0:
'book_id'
'id'

- ['book_id', 'title', 'author', 'availability']
?   -----                                - ^^^

+ ['id', 'title', 'author', 'available']
?                                    ^


----------------------------------------------------------------------
Ran 2 tests in 0.007s

FAILED (failures=1)
E
======================================================================
ERROR: test_add_book (ClassEval_14_0.BookManagementDBTestAddBook.test_add_book)
----------------------------------------------------------------------
Traceback (most recent call last):
  File "/Users/snigdhaghoshdastidar/Desktop/CS540/classeval_evaluation/ClassEval_14_0.py", line 120, in test_add_book
    self.cursor.execute("SELECT title, author, available FROM books WHERE id=1")
sqlite3.OperationalError: no such column: available

----------------------------------------------------------------------
Ran 1 test in 0.005s

FAILED (errors=1)
E
======================================================================
ERROR: test_remove_book (ClassEval_14_0.BookManagementDBTestRemoveBook.test_remove_book)
----------------------------------------------------------------------
Traceback (most recent call last):
  File "/Users/snigdhaghoshdastidar/Desktop/CS540/classeval_evaluation/ClassEval_14_0.py", line 147, in test_remove_book
    self.cursor.execute("SELECT * FROM books WHERE id=1")
sqlite3.OperationalError: no such column: id

----------------------------------------------------------------------
Ran 1 test in 0.006s

FAILED (errors=1)
E
======================================================================
ERROR: test_borrow_book (ClassEval_14_0.BookManagementDBTestBorrowBook.test_borrow_book)
----------------------------------------------------------------------
Traceback (most recent call last):
  File "/Users/snigdhaghoshdastidar/Desktop/CS540/classeval_evaluation/ClassEval_14_0.py", line 171, in test_borrow_book
    self.cursor.execute("SELECT available FROM books WHERE id=1")
sqlite3.OperationalError: no such column: available

----------------------------------------------------------------------
Ran 1 test in 0.005s

FAILED (errors=1)
E
======================================================================
ERROR: test_return_book (ClassEval_14_0.BookManagementDBTestReturnBook.test_return_book)
----------------------------------------------------------------------
Traceback (most recent call last):
  File "/Users/snigdhaghoshdastidar/Desktop/CS540/classeval_evaluation/ClassEval_14_0.py", line 196, in test_return_book
    self.cursor.execute("SELECT available FROM books WHERE id=1")
sqlite3.OperationalError: no such column: available

----------------------------------------------------------------------
Ran 1 test in 0.007s

FAILED (errors=1)
.
----------------------------------------------------------------------
Ran 1 test in 0.007s

OK
FF
======================================================================
FAIL: test_create_table_1 (ClassEval_14_1.BookManagementDBTestCreateTable.test_create_table_1)
----------------------------------------------------------------------
Traceback (most recent call last):
  File "/Users/snigdhaghoshdastidar/Desktop/CS540/classeval_evaluation/ClassEval_14_1.py", line 102, in test_create_table_1
    self.assertIsNotNone(result)
AssertionError: unexpectedly None

======================================================================
FAIL: test_create_table_2 (ClassEval_14_1.BookManagementDBTestCreateTable.test_create_table_2)
----------------------------------------------------------------------
Traceback (most recent call last):
  File "/Users/snigdhaghoshdastidar/Desktop/CS540/classeval_evaluation/ClassEval_14_1.py", line 111, in test_create_table_2
    self.assertEqual(column_names, expected_column_names)
AssertionError: Lists differ: [] != ['id', 'title', 'author', 'available']

Second list contains 4 additional elements.
First extra element 0:
'id'

- []
+ ['id', 'title', 'author', 'available']

----------------------------------------------------------------------
Ran 2 tests in 0.006s

FAILED (failures=2)
E
======================================================================
ERROR: test_add_book (ClassEval_14_1.BookManagementDBTestAddBook.test_add_book)
----------------------------------------------------------------------
Traceback (most recent call last):
  File "/Users/snigdhaghoshdastidar/Desktop/CS540/classeval_evaluation/ClassEval_14_1.py", line 133, in test_add_book
    self.cursor.execute("SELECT title, author, available FROM books WHERE id=1")
sqlite3.OperationalError: no such table: books

----------------------------------------------------------------------
Ran 1 test in 0.004s

FAILED (errors=1)
E
======================================================================
ERROR: test_remove_book (ClassEval_14_1.BookManagementDBTestRemoveBook.test_remove_book)
----------------------------------------------------------------------
Traceback (most recent call last):
  File "/Users/snigdhaghoshdastidar/Desktop/CS540/classeval_evaluation/ClassEval_14_1.py", line 160, in test_remove_book
    self.cursor.execute("SELECT * FROM books WHERE id=1")
sqlite3.OperationalError: no such table: books

----------------------------------------------------------------------
Ran 1 test in 0.005s

FAILED (errors=1)
E
======================================================================
ERROR: test_borrow_book (ClassEval_14_1.BookManagementDBTestBorrowBook.test_borrow_book)
----------------------------------------------------------------------
Traceback (most recent call last):
  File "/Users/snigdhaghoshdastidar/Desktop/CS540/classeval_evaluation/ClassEval_14_1.py", line 184, in test_borrow_book
    self.cursor.execute("SELECT available FROM books WHERE id=1")
sqlite3.OperationalError: no such table: books

----------------------------------------------------------------------
Ran 1 test in 0.007s

FAILED (errors=1)
E
======================================================================
ERROR: test_return_book (ClassEval_14_1.BookManagementDBTestReturnBook.test_return_book)
----------------------------------------------------------------------
Traceback (most recent call last):
  File "/Users/snigdhaghoshdastidar/Desktop/CS540/classeval_evaluation/ClassEval_14_1.py", line 209, in test_return_book
    self.cursor.execute("SELECT available FROM books WHERE id=1")
sqlite3.OperationalError: no such table: books

----------------------------------------------------------------------
Ran 1 test in 0.005s

FAILED (errors=1)
.
----------------------------------------------------------------------
Ran 1 test in 0.011s

OK
FF
======================================================================
FAIL: test_create_table_1 (ClassEval_14_2.BookManagementDBTestCreateTable.test_create_table_1)
----------------------------------------------------------------------
Traceback (most recent call last):
  File "/Users/snigdhaghoshdastidar/Desktop/CS540/classeval_evaluation/ClassEval_14_2.py", line 102, in test_create_table_1
    self.assertIsNotNone(result)
AssertionError: unexpectedly None

======================================================================
FAIL: test_create_table_2 (ClassEval_14_2.BookManagementDBTestCreateTable.test_create_table_2)
----------------------------------------------------------------------
Traceback (most recent call last):
  File "/Users/snigdhaghoshdastidar/Desktop/CS540/classeval_evaluation/ClassEval_14_2.py", line 111, in test_create_table_2
    self.assertEqual(column_names, expected_column_names)
AssertionError: Lists differ: [] != ['id', 'title', 'author', 'available']

Second list contains 4 additional elements.
First extra element 0:
'id'

- []
+ ['id', 'title', 'author', 'available']

----------------------------------------------------------------------
Ran 2 tests in 0.004s

FAILED (failures=2)
E
======================================================================
ERROR: test_add_book (ClassEval_14_2.BookManagementDBTestAddBook.test_add_book)
----------------------------------------------------------------------
Traceback (most recent call last):
  File "/Users/snigdhaghoshdastidar/Desktop/CS540/classeval_evaluation/ClassEval_14_2.py", line 133, in test_add_book
    self.cursor.execute("SELECT title, author, available FROM books WHERE id=1")
sqlite3.OperationalError: no such table: books

----------------------------------------------------------------------
Ran 1 test in 0.003s

FAILED (errors=1)
E
======================================================================
ERROR: test_remove_book (ClassEval_14_2.BookManagementDBTestRemoveBook.test_remove_book)
----------------------------------------------------------------------
Traceback (most recent call last):
  File "/Users/snigdhaghoshdastidar/Desktop/CS540/classeval_evaluation/ClassEval_14_2.py", line 160, in test_remove_book
    self.cursor.execute("SELECT * FROM books WHERE id=1")
sqlite3.OperationalError: no such table: books

----------------------------------------------------------------------
Ran 1 test in 0.004s

FAILED (errors=1)
E
======================================================================
ERROR: test_borrow_book (ClassEval_14_2.BookManagementDBTestBorrowBook.test_borrow_book)
----------------------------------------------------------------------
Traceback (most recent call last):
  File "/Users/snigdhaghoshdastidar/Desktop/CS540/classeval_evaluation/ClassEval_14_2.py", line 184, in test_borrow_book
    self.cursor.execute("SELECT available FROM books WHERE id=1")
sqlite3.OperationalError: no such table: books

----------------------------------------------------------------------
Ran 1 test in 0.004s

FAILED (errors=1)
E
======================================================================
ERROR: test_return_book (ClassEval_14_2.BookManagementDBTestReturnBook.test_return_book)
----------------------------------------------------------------------
Traceback (most recent call last):
  File "/Users/snigdhaghoshdastidar/Desktop/CS540/classeval_evaluation/ClassEval_14_2.py", line 209, in test_return_book
    self.cursor.execute("SELECT available FROM books WHERE id=1")
sqlite3.OperationalError: no such table: books

----------------------------------------------------------------------
Ran 1 test in 0.005s

FAILED (errors=1)
.
----------------------------------------------------------------------
Ran 1 test in 0.005s

OK
FF
======================================================================
FAIL: test_create_table_1 (ClassEval_14_3.BookManagementDBTestCreateTable.test_create_table_1)
----------------------------------------------------------------------
Traceback (most recent call last):
  File "/Users/snigdhaghoshdastidar/Desktop/CS540/classeval_evaluation/ClassEval_14_3.py", line 102, in test_create_table_1
    self.assertIsNotNone(result)
AssertionError: unexpectedly None

======================================================================
FAIL: test_create_table_2 (ClassEval_14_3.BookManagementDBTestCreateTable.test_create_table_2)
----------------------------------------------------------------------
Traceback (most recent call last):
  File "/Users/snigdhaghoshdastidar/Desktop/CS540/classeval_evaluation/ClassEval_14_3.py", line 111, in test_create_table_2
    self.assertEqual(column_names, expected_column_names)
AssertionError: Lists differ: [] != ['id', 'title', 'author', 'available']

Second list contains 4 additional elements.
First extra element 0:
'id'

- []
+ ['id', 'title', 'author', 'available']

----------------------------------------------------------------------
Ran 2 tests in 0.009s

FAILED (failures=2)
E
======================================================================
ERROR: test_add_book (ClassEval_14_3.BookManagementDBTestAddBook.test_add_book)
----------------------------------------------------------------------
Traceback (most recent call last):
  File "/Users/snigdhaghoshdastidar/Desktop/CS540/classeval_evaluation/ClassEval_14_3.py", line 133, in test_add_book
    self.cursor.execute("SELECT title, author, available FROM books WHERE id=1")
sqlite3.OperationalError: no such table: books

----------------------------------------------------------------------
Ran 1 test in 0.004s

FAILED (errors=1)
E
======================================================================
ERROR: test_remove_book (ClassEval_14_3.BookManagementDBTestRemoveBook.test_remove_book)
----------------------------------------------------------------------
Traceback (most recent call last):
  File "/Users/snigdhaghoshdastidar/Desktop/CS540/classeval_evaluation/ClassEval_14_3.py", line 160, in test_remove_book
    self.cursor.execute("SELECT * FROM books WHERE id=1")
sqlite3.OperationalError: no such table: books

----------------------------------------------------------------------
Ran 1 test in 0.005s

FAILED (errors=1)
E
======================================================================
ERROR: test_borrow_book (ClassEval_14_3.BookManagementDBTestBorrowBook.test_borrow_book)
----------------------------------------------------------------------
Traceback (most recent call last):
  File "/Users/snigdhaghoshdastidar/Desktop/CS540/classeval_evaluation/ClassEval_14_3.py", line 184, in test_borrow_book
    self.cursor.execute("SELECT available FROM books WHERE id=1")
sqlite3.OperationalError: no such table: books

----------------------------------------------------------------------
Ran 1 test in 0.005s

FAILED (errors=1)
E
======================================================================
ERROR: test_return_book (ClassEval_14_3.BookManagementDBTestReturnBook.test_return_book)
----------------------------------------------------------------------
Traceback (most recent call last):
  File "/Users/snigdhaghoshdastidar/Desktop/CS540/classeval_evaluation/ClassEval_14_3.py", line 209, in test_return_book
    self.cursor.execute("SELECT available FROM books WHERE id=1")
sqlite3.OperationalError: no such table: books

----------------------------------------------------------------------
Ran 1 test in 0.006s

FAILED (errors=1)
.
----------------------------------------------------------------------
Ran 1 test in 0.006s

OK
FF
======================================================================
FAIL: test_create_table_1 (ClassEval_14_4.BookManagementDBTestCreateTable.test_create_table_1)
----------------------------------------------------------------------
Traceback (most recent call last):
  File "/Users/snigdhaghoshdastidar/Desktop/CS540/classeval_evaluation/ClassEval_14_4.py", line 89, in test_create_table_1
    self.assertIsNotNone(result)
AssertionError: unexpectedly None

======================================================================
FAIL: test_create_table_2 (ClassEval_14_4.BookManagementDBTestCreateTable.test_create_table_2)
----------------------------------------------------------------------
Traceback (most recent call last):
  File "/Users/snigdhaghoshdastidar/Desktop/CS540/classeval_evaluation/ClassEval_14_4.py", line 98, in test_create_table_2
    self.assertEqual(column_names, expected_column_names)
AssertionError: Lists differ: [] != ['id', 'title', 'author', 'available']

Second list contains 4 additional elements.
First extra element 0:
'id'

- []
+ ['id', 'title', 'author', 'available']

----------------------------------------------------------------------
Ran 2 tests in 0.008s

FAILED (failures=2)
E
======================================================================
ERROR: test_add_book (ClassEval_14_4.BookManagementDBTestAddBook.test_add_book)
----------------------------------------------------------------------
Traceback (most recent call last):
  File "/Users/snigdhaghoshdastidar/Desktop/CS540/classeval_evaluation/ClassEval_14_4.py", line 120, in test_add_book
    self.cursor.execute("SELECT title, author, available FROM books WHERE id=1")
sqlite3.OperationalError: no such table: books

----------------------------------------------------------------------
Ran 1 test in 0.005s

FAILED (errors=1)
E
======================================================================
ERROR: test_remove_book (ClassEval_14_4.BookManagementDBTestRemoveBook.test_remove_book)
----------------------------------------------------------------------
Traceback (most recent call last):
  File "/Users/snigdhaghoshdastidar/Desktop/CS540/classeval_evaluation/ClassEval_14_4.py", line 147, in test_remove_book
    self.cursor.execute("SELECT * FROM books WHERE id=1")
sqlite3.OperationalError: no such table: books

----------------------------------------------------------------------
Ran 1 test in 0.006s

FAILED (errors=1)
E
======================================================================
ERROR: test_borrow_book (ClassEval_14_4.BookManagementDBTestBorrowBook.test_borrow_book)
----------------------------------------------------------------------
Traceback (most recent call last):
  File "/Users/snigdhaghoshdastidar/Desktop/CS540/classeval_evaluation/ClassEval_14_4.py", line 171, in test_borrow_book
    self.cursor.execute("SELECT available FROM books WHERE id=1")
sqlite3.OperationalError: no such table: books

----------------------------------------------------------------------
Ran 1 test in 0.006s

FAILED (errors=1)
E
======================================================================
ERROR: test_return_book (ClassEval_14_4.BookManagementDBTestReturnBook.test_return_book)
----------------------------------------------------------------------
Traceback (most recent call last):
  File "/Users/snigdhaghoshdastidar/Desktop/CS540/classeval_evaluation/ClassEval_14_4.py", line 196, in test_return_book
    self.cursor.execute("SELECT available FROM books WHERE id=1")
sqlite3.OperationalError: no such table: books

----------------------------------------------------------------------
Ran 1 test in 0.007s

FAILED (errors=1)
.
----------------------------------------------------------------------
Ran 1 test in 0.007s

OK
.....
----------------------------------------------------------------------
Ran 5 tests in 0.010s

OK
EEEEE
======================================================================
ERROR: test_insert_into_database_1 (ClassEval_28_0.DatabaseProcessorTestInsertIntoDatabase.test_insert_into_database_1)
----------------------------------------------------------------------
Traceback (most recent call last):
  File "/Users/snigdhaghoshdastidar/Desktop/CS540/classeval_evaluation/ClassEval_28_0.py", line 189, in test_insert_into_database_1
    self.processor.insert_into_database(table_name, data)
  File "/Users/snigdhaghoshdastidar/Desktop/CS540/classeval_evaluation/ClassEval_28_0.py", line 52, in insert_into_database
    INSERT INTO {table_name} ({item.keys()[0]}, {item.keys()[1]})
                               ~~~~~~~~~~~^^^
TypeError: 'dict_keys' object is not subscriptable

======================================================================
ERROR: test_insert_into_database_2 (ClassEval_28_0.DatabaseProcessorTestInsertIntoDatabase.test_insert_into_database_2)
----------------------------------------------------------------------
Traceback (most recent call last):
  File "/Users/snigdhaghoshdastidar/Desktop/CS540/classeval_evaluation/ClassEval_28_0.py", line 206, in test_insert_into_database_2
    self.processor.insert_into_database(table_name, data)
  File "/Users/snigdhaghoshdastidar/Desktop/CS540/classeval_evaluation/ClassEval_28_0.py", line 52, in insert_into_database
    INSERT INTO {table_name} ({item.keys()[0]}, {item.keys()[1]})
                               ~~~~~~~~~~~^^^
TypeError: 'dict_keys' object is not subscriptable

======================================================================
ERROR: test_insert_into_database_3 (ClassEval_28_0.DatabaseProcessorTestInsertIntoDatabase.test_insert_into_database_3)
----------------------------------------------------------------------
Traceback (most recent call last):
  File "/Users/snigdhaghoshdastidar/Desktop/CS540/classeval_evaluation/ClassEval_28_0.py", line 223, in test_insert_into_database_3
    self.processor.insert_into_database(table_name, data)
  File "/Users/snigdhaghoshdastidar/Desktop/CS540/classeval_evaluation/ClassEval_28_0.py", line 52, in insert_into_database
    INSERT INTO {table_name} ({item.keys()[0]}, {item.keys()[1]})
                               ~~~~~~~~~~~^^^
TypeError: 'dict_keys' object is not subscriptable

======================================================================
ERROR: test_insert_into_database_4 (ClassEval_28_0.DatabaseProcessorTestInsertIntoDatabase.test_insert_into_database_4)
----------------------------------------------------------------------
Traceback (most recent call last):
  File "/Users/snigdhaghoshdastidar/Desktop/CS540/classeval_evaluation/ClassEval_28_0.py", line 240, in test_insert_into_database_4
    self.processor.insert_into_database(table_name, data)
  File "/Users/snigdhaghoshdastidar/Desktop/CS540/classeval_evaluation/ClassEval_28_0.py", line 52, in insert_into_database
    INSERT INTO {table_name} ({item.keys()[0]}, {item.keys()[1]})
                               ~~~~~~~~~~~^^^
TypeError: 'dict_keys' object is not subscriptable

======================================================================
ERROR: test_insert_into_database_5 (ClassEval_28_0.DatabaseProcessorTestInsertIntoDatabase.test_insert_into_database_5)
----------------------------------------------------------------------
Traceback (most recent call last):
  File "/Users/snigdhaghoshdastidar/Desktop/CS540/classeval_evaluation/ClassEval_28_0.py", line 257, in test_insert_into_database_5
    self.processor.insert_into_database(table_name, data)
  File "/Users/snigdhaghoshdastidar/Desktop/CS540/classeval_evaluation/ClassEval_28_0.py", line 52, in insert_into_database
    INSERT INTO {table_name} ({item.keys()[0]}, {item.keys()[1]})
                               ~~~~~~~~~~~^^^
TypeError: 'dict_keys' object is not subscriptable

----------------------------------------------------------------------
Ran 5 tests in 0.017s

FAILED (errors=5)
EEEEE
======================================================================
ERROR: test_search_database_1 (ClassEval_28_0.DatabaseProcessorTestSearchDatabase.test_search_database_1)
----------------------------------------------------------------------
Traceback (most recent call last):
  File "/Users/snigdhaghoshdastidar/Desktop/CS540/classeval_evaluation/ClassEval_28_0.py", line 287, in test_search_database_1
    self.processor.insert_into_database(table_name, data)
  File "/Users/snigdhaghoshdastidar/Desktop/CS540/classeval_evaluation/ClassEval_28_0.py", line 52, in insert_into_database
    INSERT INTO {table_name} ({item.keys()[0]}, {item.keys()[1]})
                               ~~~~~~~~~~~^^^
TypeError: 'dict_keys' object is not subscriptable

======================================================================
ERROR: test_search_database_2 (ClassEval_28_0.DatabaseProcessorTestSearchDatabase.test_search_database_2)
----------------------------------------------------------------------
Traceback (most recent call last):
  File "/Users/snigdhaghoshdastidar/Desktop/CS540/classeval_evaluation/ClassEval_28_0.py", line 301, in test_search_database_2
    self.processor.insert_into_database(table_name, data)
  File "/Users/snigdhaghoshdastidar/Desktop/CS540/classeval_evaluation/ClassEval_28_0.py", line 52, in insert_into_database
    INSERT INTO {table_name} ({item.keys()[0]}, {item.keys()[1]})
                               ~~~~~~~~~~~^^^
TypeError: 'dict_keys' object is not subscriptable

======================================================================
ERROR: test_search_database_3 (ClassEval_28_0.DatabaseProcessorTestSearchDatabase.test_search_database_3)
----------------------------------------------------------------------
Traceback (most recent call last):
  File "/Users/snigdhaghoshdastidar/Desktop/CS540/classeval_evaluation/ClassEval_28_0.py", line 315, in test_search_database_3
    self.processor.insert_into_database(table_name, data)
  File "/Users/snigdhaghoshdastidar/Desktop/CS540/classeval_evaluation/ClassEval_28_0.py", line 52, in insert_into_database
    INSERT INTO {table_name} ({item.keys()[0]}, {item.keys()[1]})
                               ~~~~~~~~~~~^^^
TypeError: 'dict_keys' object is not subscriptable

======================================================================
ERROR: test_search_database_4 (ClassEval_28_0.DatabaseProcessorTestSearchDatabase.test_search_database_4)
----------------------------------------------------------------------
Traceback (most recent call last):
  File "/Users/snigdhaghoshdastidar/Desktop/CS540/classeval_evaluation/ClassEval_28_0.py", line 327, in test_search_database_4
    self.processor.insert_into_database(table_name, data)
  File "/Users/snigdhaghoshdastidar/Desktop/CS540/classeval_evaluation/ClassEval_28_0.py", line 52, in insert_into_database
    INSERT INTO {table_name} ({item.keys()[0]}, {item.keys()[1]})
                               ~~~~~~~~~~~^^^
TypeError: 'dict_keys' object is not subscriptable

======================================================================
ERROR: test_search_database_5 (ClassEval_28_0.DatabaseProcessorTestSearchDatabase.test_search_database_5)
----------------------------------------------------------------------
Traceback (most recent call last):
  File "/Users/snigdhaghoshdastidar/Desktop/CS540/classeval_evaluation/ClassEval_28_0.py", line 339, in test_search_database_5
    self.processor.insert_into_database(table_name, data)
  File "/Users/snigdhaghoshdastidar/Desktop/CS540/classeval_evaluation/ClassEval_28_0.py", line 52, in insert_into_database
    INSERT INTO {table_name} ({item.keys()[0]}, {item.keys()[1]})
                               ~~~~~~~~~~~^^^
TypeError: 'dict_keys' object is not subscriptable

----------------------------------------------------------------------
Ran 5 tests in 0.022s

FAILED (errors=5)
EEEEE
======================================================================
ERROR: test_delete_from_database_1 (ClassEval_28_0.DatabaseProcessorTestDeteleFromDatabase.test_delete_from_database_1)
----------------------------------------------------------------------
Traceback (most recent call last):
  File "/Users/snigdhaghoshdastidar/Desktop/CS540/classeval_evaluation/ClassEval_28_0.py", line 364, in test_delete_from_database_1
    self.processor.insert_into_database(table_name, data)
  File "/Users/snigdhaghoshdastidar/Desktop/CS540/classeval_evaluation/ClassEval_28_0.py", line 52, in insert_into_database
    INSERT INTO {table_name} ({item.keys()[0]}, {item.keys()[1]})
                               ~~~~~~~~~~~^^^
TypeError: 'dict_keys' object is not subscriptable

======================================================================
ERROR: test_delete_from_database_2 (ClassEval_28_0.DatabaseProcessorTestDeteleFromDatabase.test_delete_from_database_2)
----------------------------------------------------------------------
Traceback (most recent call last):
  File "/Users/snigdhaghoshdastidar/Desktop/CS540/classeval_evaluation/ClassEval_28_0.py", line 384, in test_delete_from_database_2
    self.processor.insert_into_database(table_name, data)
  File "/Users/snigdhaghoshdastidar/Desktop/CS540/classeval_evaluation/ClassEval_28_0.py", line 52, in insert_into_database
    INSERT INTO {table_name} ({item.keys()[0]}, {item.keys()[1]})
                               ~~~~~~~~~~~^^^
TypeError: 'dict_keys' object is not subscriptable

======================================================================
ERROR: test_delete_from_database_3 (ClassEval_28_0.DatabaseProcessorTestDeteleFromDatabase.test_delete_from_database_3)
----------------------------------------------------------------------
Traceback (most recent call last):
  File "/Users/snigdhaghoshdastidar/Desktop/CS540/classeval_evaluation/ClassEval_28_0.py", line 404, in test_delete_from_database_3
    self.processor.insert_into_database(table_name, data)
  File "/Users/snigdhaghoshdastidar/Desktop/CS540/classeval_evaluation/ClassEval_28_0.py", line 52, in insert_into_database
    INSERT INTO {table_name} ({item.keys()[0]}, {item.keys()[1]})
                               ~~~~~~~~~~~^^^
TypeError: 'dict_keys' object is not subscriptable

======================================================================
ERROR: test_delete_from_database_4 (ClassEval_28_0.DatabaseProcessorTestDeteleFromDatabase.test_delete_from_database_4)
----------------------------------------------------------------------
Traceback (most recent call last):
  File "/Users/snigdhaghoshdastidar/Desktop/CS540/classeval_evaluation/ClassEval_28_0.py", line 424, in test_delete_from_database_4
    self.processor.insert_into_database(table_name, data)
  File "/Users/snigdhaghoshdastidar/Desktop/CS540/classeval_evaluation/ClassEval_28_0.py", line 52, in insert_into_database
    INSERT INTO {table_name} ({item.keys()[0]}, {item.keys()[1]})
                               ~~~~~~~~~~~^^^
TypeError: 'dict_keys' object is not subscriptable

======================================================================
ERROR: test_delete_from_database_5 (ClassEval_28_0.DatabaseProcessorTestDeteleFromDatabase.test_delete_from_database_5)
----------------------------------------------------------------------
Traceback (most recent call last):
  File "/Users/snigdhaghoshdastidar/Desktop/CS540/classeval_evaluation/ClassEval_28_0.py", line 444, in test_delete_from_database_5
    self.processor.insert_into_database(table_name, data)
  File "/Users/snigdhaghoshdastidar/Desktop/CS540/classeval_evaluation/ClassEval_28_0.py", line 52, in insert_into_database
    INSERT INTO {table_name} ({item.keys()[0]}, {item.keys()[1]})
                               ~~~~~~~~~~~^^^
TypeError: 'dict_keys' object is not subscriptable

----------------------------------------------------------------------
Ran 5 tests in 0.021s

FAILED (errors=5)
E
======================================================================
ERROR: test_DatabaseProcessor (ClassEval_28_0.DatabaseProcessorTest.test_DatabaseProcessor)
----------------------------------------------------------------------
Traceback (most recent call last):
  File "/Users/snigdhaghoshdastidar/Desktop/CS540/classeval_evaluation/ClassEval_28_0.py", line 487, in test_DatabaseProcessor
    self.processor.insert_into_database(table_name, data)
  File "/Users/snigdhaghoshdastidar/Desktop/CS540/classeval_evaluation/ClassEval_28_0.py", line 52, in insert_into_database
    INSERT INTO {table_name} ({item.keys()[0]}, {item.keys()[1]})
                               ~~~~~~~~~~~^^^
TypeError: 'dict_keys' object is not subscriptable

----------------------------------------------------------------------
Ran 1 test in 0.005s

FAILED (errors=1)
.....
----------------------------------------------------------------------
Ran 5 tests in 0.010s

OK
EEEEE
======================================================================
ERROR: test_insert_into_database_1 (ClassEval_28_1.DatabaseProcessorTestInsertIntoDatabase.test_insert_into_database_1)
----------------------------------------------------------------------
Traceback (most recent call last):
  File "/Users/snigdhaghoshdastidar/Desktop/CS540/classeval_evaluation/ClassEval_28_1.py", line 187, in test_insert_into_database_1
    self.processor.insert_into_database(table_name, data)
  File "/Users/snigdhaghoshdastidar/Desktop/CS540/classeval_evaluation/ClassEval_28_1.py", line 46, in insert_into_database
    data_to_insert = [(row[key1], row[key2]) for row in data]
                           ^^^^
NameError: name 'key1' is not defined

======================================================================
ERROR: test_insert_into_database_2 (ClassEval_28_1.DatabaseProcessorTestInsertIntoDatabase.test_insert_into_database_2)
----------------------------------------------------------------------
Traceback (most recent call last):
  File "/Users/snigdhaghoshdastidar/Desktop/CS540/classeval_evaluation/ClassEval_28_1.py", line 204, in test_insert_into_database_2
    self.processor.insert_into_database(table_name, data)
  File "/Users/snigdhaghoshdastidar/Desktop/CS540/classeval_evaluation/ClassEval_28_1.py", line 46, in insert_into_database
    data_to_insert = [(row[key1], row[key2]) for row in data]
                           ^^^^
NameError: name 'key1' is not defined

======================================================================
ERROR: test_insert_into_database_3 (ClassEval_28_1.DatabaseProcessorTestInsertIntoDatabase.test_insert_into_database_3)
----------------------------------------------------------------------
Traceback (most recent call last):
  File "/Users/snigdhaghoshdastidar/Desktop/CS540/classeval_evaluation/ClassEval_28_1.py", line 221, in test_insert_into_database_3
    self.processor.insert_into_database(table_name, data)
  File "/Users/snigdhaghoshdastidar/Desktop/CS540/classeval_evaluation/ClassEval_28_1.py", line 46, in insert_into_database
    data_to_insert = [(row[key1], row[key2]) for row in data]
                           ^^^^
NameError: name 'key1' is not defined

======================================================================
ERROR: test_insert_into_database_4 (ClassEval_28_1.DatabaseProcessorTestInsertIntoDatabase.test_insert_into_database_4)
----------------------------------------------------------------------
Traceback (most recent call last):
  File "/Users/snigdhaghoshdastidar/Desktop/CS540/classeval_evaluation/ClassEval_28_1.py", line 238, in test_insert_into_database_4
    self.processor.insert_into_database(table_name, data)
  File "/Users/snigdhaghoshdastidar/Desktop/CS540/classeval_evaluation/ClassEval_28_1.py", line 46, in insert_into_database
    data_to_insert = [(row[key1], row[key2]) for row in data]
                           ^^^^
NameError: name 'key1' is not defined

======================================================================
ERROR: test_insert_into_database_5 (ClassEval_28_1.DatabaseProcessorTestInsertIntoDatabase.test_insert_into_database_5)
----------------------------------------------------------------------
Traceback (most recent call last):
  File "/Users/snigdhaghoshdastidar/Desktop/CS540/classeval_evaluation/ClassEval_28_1.py", line 255, in test_insert_into_database_5
    self.processor.insert_into_database(table_name, data)
  File "/Users/snigdhaghoshdastidar/Desktop/CS540/classeval_evaluation/ClassEval_28_1.py", line 46, in insert_into_database
    data_to_insert = [(row[key1], row[key2]) for row in data]
                           ^^^^
NameError: name 'key1' is not defined

----------------------------------------------------------------------
Ran 5 tests in 0.026s

FAILED (errors=5)
EEEEE
======================================================================
ERROR: test_search_database_1 (ClassEval_28_1.DatabaseProcessorTestSearchDatabase.test_search_database_1)
----------------------------------------------------------------------
Traceback (most recent call last):
  File "/Users/snigdhaghoshdastidar/Desktop/CS540/classeval_evaluation/ClassEval_28_1.py", line 285, in test_search_database_1
    self.processor.insert_into_database(table_name, data)
  File "/Users/snigdhaghoshdastidar/Desktop/CS540/classeval_evaluation/ClassEval_28_1.py", line 46, in insert_into_database
    data_to_insert = [(row[key1], row[key2]) for row in data]
                           ^^^^
NameError: name 'key1' is not defined

======================================================================
ERROR: test_search_database_2 (ClassEval_28_1.DatabaseProcessorTestSearchDatabase.test_search_database_2)
----------------------------------------------------------------------
Traceback (most recent call last):
  File "/Users/snigdhaghoshdastidar/Desktop/CS540/classeval_evaluation/ClassEval_28_1.py", line 299, in test_search_database_2
    self.processor.insert_into_database(table_name, data)
  File "/Users/snigdhaghoshdastidar/Desktop/CS540/classeval_evaluation/ClassEval_28_1.py", line 46, in insert_into_database
    data_to_insert = [(row[key1], row[key2]) for row in data]
                           ^^^^
NameError: name 'key1' is not defined

======================================================================
ERROR: test_search_database_3 (ClassEval_28_1.DatabaseProcessorTestSearchDatabase.test_search_database_3)
----------------------------------------------------------------------
Traceback (most recent call last):
  File "/Users/snigdhaghoshdastidar/Desktop/CS540/classeval_evaluation/ClassEval_28_1.py", line 313, in test_search_database_3
    self.processor.insert_into_database(table_name, data)
  File "/Users/snigdhaghoshdastidar/Desktop/CS540/classeval_evaluation/ClassEval_28_1.py", line 46, in insert_into_database
    data_to_insert = [(row[key1], row[key2]) for row in data]
                           ^^^^
NameError: name 'key1' is not defined

======================================================================
ERROR: test_search_database_4 (ClassEval_28_1.DatabaseProcessorTestSearchDatabase.test_search_database_4)
----------------------------------------------------------------------
Traceback (most recent call last):
  File "/Users/snigdhaghoshdastidar/Desktop/CS540/classeval_evaluation/ClassEval_28_1.py", line 325, in test_search_database_4
    self.processor.insert_into_database(table_name, data)
  File "/Users/snigdhaghoshdastidar/Desktop/CS540/classeval_evaluation/ClassEval_28_1.py", line 46, in insert_into_database
    data_to_insert = [(row[key1], row[key2]) for row in data]
                           ^^^^
NameError: name 'key1' is not defined

======================================================================
ERROR: test_search_database_5 (ClassEval_28_1.DatabaseProcessorTestSearchDatabase.test_search_database_5)
----------------------------------------------------------------------
Traceback (most recent call last):
  File "/Users/snigdhaghoshdastidar/Desktop/CS540/classeval_evaluation/ClassEval_28_1.py", line 337, in test_search_database_5
    self.processor.insert_into_database(table_name, data)
  File "/Users/snigdhaghoshdastidar/Desktop/CS540/classeval_evaluation/ClassEval_28_1.py", line 46, in insert_into_database
    data_to_insert = [(row[key1], row[key2]) for row in data]
                           ^^^^
NameError: name 'key1' is not defined

----------------------------------------------------------------------
Ran 5 tests in 0.020s

FAILED (errors=5)
EEEEE
======================================================================
ERROR: test_delete_from_database_1 (ClassEval_28_1.DatabaseProcessorTestDeteleFromDatabase.test_delete_from_database_1)
----------------------------------------------------------------------
Traceback (most recent call last):
  File "/Users/snigdhaghoshdastidar/Desktop/CS540/classeval_evaluation/ClassEval_28_1.py", line 362, in test_delete_from_database_1
    self.processor.insert_into_database(table_name, data)
  File "/Users/snigdhaghoshdastidar/Desktop/CS540/classeval_evaluation/ClassEval_28_1.py", line 46, in insert_into_database
    data_to_insert = [(row[key1], row[key2]) for row in data]
                           ^^^^
NameError: name 'key1' is not defined

======================================================================
ERROR: test_delete_from_database_2 (ClassEval_28_1.DatabaseProcessorTestDeteleFromDatabase.test_delete_from_database_2)
----------------------------------------------------------------------
Traceback (most recent call last):
  File "/Users/snigdhaghoshdastidar/Desktop/CS540/classeval_evaluation/ClassEval_28_1.py", line 382, in test_delete_from_database_2
    self.processor.insert_into_database(table_name, data)
  File "/Users/snigdhaghoshdastidar/Desktop/CS540/classeval_evaluation/ClassEval_28_1.py", line 46, in insert_into_database
    data_to_insert = [(row[key1], row[key2]) for row in data]
                           ^^^^
NameError: name 'key1' is not defined

======================================================================
ERROR: test_delete_from_database_3 (ClassEval_28_1.DatabaseProcessorTestDeteleFromDatabase.test_delete_from_database_3)
----------------------------------------------------------------------
Traceback (most recent call last):
  File "/Users/snigdhaghoshdastidar/Desktop/CS540/classeval_evaluation/ClassEval_28_1.py", line 402, in test_delete_from_database_3
    self.processor.insert_into_database(table_name, data)
  File "/Users/snigdhaghoshdastidar/Desktop/CS540/classeval_evaluation/ClassEval_28_1.py", line 46, in insert_into_database
    data_to_insert = [(row[key1], row[key2]) for row in data]
                           ^^^^
NameError: name 'key1' is not defined

======================================================================
ERROR: test_delete_from_database_4 (ClassEval_28_1.DatabaseProcessorTestDeteleFromDatabase.test_delete_from_database_4)
----------------------------------------------------------------------
Traceback (most recent call last):
  File "/Users/snigdhaghoshdastidar/Desktop/CS540/classeval_evaluation/ClassEval_28_1.py", line 422, in test_delete_from_database_4
    self.processor.insert_into_database(table_name, data)
  File "/Users/snigdhaghoshdastidar/Desktop/CS540/classeval_evaluation/ClassEval_28_1.py", line 46, in insert_into_database
    data_to_insert = [(row[key1], row[key2]) for row in data]
                           ^^^^
NameError: name 'key1' is not defined

======================================================================
ERROR: test_delete_from_database_5 (ClassEval_28_1.DatabaseProcessorTestDeteleFromDatabase.test_delete_from_database_5)
----------------------------------------------------------------------
Traceback (most recent call last):
  File "/Users/snigdhaghoshdastidar/Desktop/CS540/classeval_evaluation/ClassEval_28_1.py", line 442, in test_delete_from_database_5
    self.processor.insert_into_database(table_name, data)
  File "/Users/snigdhaghoshdastidar/Desktop/CS540/classeval_evaluation/ClassEval_28_1.py", line 46, in insert_into_database
    data_to_insert = [(row[key1], row[key2]) for row in data]
                           ^^^^
NameError: name 'key1' is not defined

----------------------------------------------------------------------
Ran 5 tests in 0.019s

FAILED (errors=5)
E
======================================================================
ERROR: test_DatabaseProcessor (ClassEval_28_1.DatabaseProcessorTest.test_DatabaseProcessor)
----------------------------------------------------------------------
Traceback (most recent call last):
  File "/Users/snigdhaghoshdastidar/Desktop/CS540/classeval_evaluation/ClassEval_28_1.py", line 485, in test_DatabaseProcessor
    self.processor.insert_into_database(table_name, data)
  File "/Users/snigdhaghoshdastidar/Desktop/CS540/classeval_evaluation/ClassEval_28_1.py", line 46, in insert_into_database
    data_to_insert = [(row[key1], row[key2]) for row in data]
                           ^^^^
NameError: name 'key1' is not defined

----------------------------------------------------------------------
Ran 1 test in 0.005s

FAILED (errors=1)
.....
----------------------------------------------------------------------
Ran 5 tests in 0.009s

OK
.....
----------------------------------------------------------------------
Ran 5 tests in 0.027s

OK
.....
----------------------------------------------------------------------
Ran 5 tests in 0.030s

OK
.....
----------------------------------------------------------------------
Ran 5 tests in 0.032s

OK
.
----------------------------------------------------------------------
Ran 1 test in 0.007s

OK
.....
----------------------------------------------------------------------
Ran 5 tests in 0.007s

OK
.....
----------------------------------------------------------------------
Ran 5 tests in 0.022s

OK
.....
----------------------------------------------------------------------
Ran 5 tests in 0.023s

OK
.....
----------------------------------------------------------------------
Ran 5 tests in 0.032s

OK
.
----------------------------------------------------------------------
Ran 1 test in 0.009s

OK
.....
----------------------------------------------------------------------
Ran 5 tests in 0.008s

OK
EEEEE
======================================================================
ERROR: test_insert_into_database_1 (ClassEval_28_4.DatabaseProcessorTestInsertIntoDatabase.test_insert_into_database_1)
----------------------------------------------------------------------
Traceback (most recent call last):
  File "/Users/snigdhaghoshdastidar/Desktop/CS540/classeval_evaluation/ClassEval_28_4.py", line 203, in test_insert_into_database_1
    self.processor.insert_into_database(table_name, data)
  File "/Users/snigdhaghoshdastidar/Desktop/CS540/classeval_evaluation/ClassEval_28_4.py", line 51, in insert_into_database
    INSERT INTO {table_name} ({key1}, {key2})
                               ^^^^
NameError: name 'key1' is not defined

======================================================================
ERROR: test_insert_into_database_2 (ClassEval_28_4.DatabaseProcessorTestInsertIntoDatabase.test_insert_into_database_2)
----------------------------------------------------------------------
Traceback (most recent call last):
  File "/Users/snigdhaghoshdastidar/Desktop/CS540/classeval_evaluation/ClassEval_28_4.py", line 220, in test_insert_into_database_2
    self.processor.insert_into_database(table_name, data)
  File "/Users/snigdhaghoshdastidar/Desktop/CS540/classeval_evaluation/ClassEval_28_4.py", line 51, in insert_into_database
    INSERT INTO {table_name} ({key1}, {key2})
                               ^^^^
NameError: name 'key1' is not defined

======================================================================
ERROR: test_insert_into_database_3 (ClassEval_28_4.DatabaseProcessorTestInsertIntoDatabase.test_insert_into_database_3)
----------------------------------------------------------------------
Traceback (most recent call last):
  File "/Users/snigdhaghoshdastidar/Desktop/CS540/classeval_evaluation/ClassEval_28_4.py", line 237, in test_insert_into_database_3
    self.processor.insert_into_database(table_name, data)
  File "/Users/snigdhaghoshdastidar/Desktop/CS540/classeval_evaluation/ClassEval_28_4.py", line 51, in insert_into_database
    INSERT INTO {table_name} ({key1}, {key2})
                               ^^^^
NameError: name 'key1' is not defined

======================================================================
ERROR: test_insert_into_database_4 (ClassEval_28_4.DatabaseProcessorTestInsertIntoDatabase.test_insert_into_database_4)
----------------------------------------------------------------------
Traceback (most recent call last):
  File "/Users/snigdhaghoshdastidar/Desktop/CS540/classeval_evaluation/ClassEval_28_4.py", line 254, in test_insert_into_database_4
    self.processor.insert_into_database(table_name, data)
  File "/Users/snigdhaghoshdastidar/Desktop/CS540/classeval_evaluation/ClassEval_28_4.py", line 51, in insert_into_database
    INSERT INTO {table_name} ({key1}, {key2})
                               ^^^^
NameError: name 'key1' is not defined

======================================================================
ERROR: test_insert_into_database_5 (ClassEval_28_4.DatabaseProcessorTestInsertIntoDatabase.test_insert_into_database_5)
----------------------------------------------------------------------
Traceback (most recent call last):
  File "/Users/snigdhaghoshdastidar/Desktop/CS540/classeval_evaluation/ClassEval_28_4.py", line 271, in test_insert_into_database_5
    self.processor.insert_into_database(table_name, data)
  File "/Users/snigdhaghoshdastidar/Desktop/CS540/classeval_evaluation/ClassEval_28_4.py", line 51, in insert_into_database
    INSERT INTO {table_name} ({key1}, {key2})
                               ^^^^
NameError: name 'key1' is not defined

----------------------------------------------------------------------
Ran 5 tests in 0.017s

FAILED (errors=5)
EEEEE
======================================================================
ERROR: test_search_database_1 (ClassEval_28_4.DatabaseProcessorTestSearchDatabase.test_search_database_1)
----------------------------------------------------------------------
Traceback (most recent call last):
  File "/Users/snigdhaghoshdastidar/Desktop/CS540/classeval_evaluation/ClassEval_28_4.py", line 301, in test_search_database_1
    self.processor.insert_into_database(table_name, data)
  File "/Users/snigdhaghoshdastidar/Desktop/CS540/classeval_evaluation/ClassEval_28_4.py", line 51, in insert_into_database
    INSERT INTO {table_name} ({key1}, {key2})
                               ^^^^
NameError: name 'key1' is not defined

======================================================================
ERROR: test_search_database_2 (ClassEval_28_4.DatabaseProcessorTestSearchDatabase.test_search_database_2)
----------------------------------------------------------------------
Traceback (most recent call last):
  File "/Users/snigdhaghoshdastidar/Desktop/CS540/classeval_evaluation/ClassEval_28_4.py", line 315, in test_search_database_2
    self.processor.insert_into_database(table_name, data)
  File "/Users/snigdhaghoshdastidar/Desktop/CS540/classeval_evaluation/ClassEval_28_4.py", line 51, in insert_into_database
    INSERT INTO {table_name} ({key1}, {key2})
                               ^^^^
NameError: name 'key1' is not defined

======================================================================
ERROR: test_search_database_3 (ClassEval_28_4.DatabaseProcessorTestSearchDatabase.test_search_database_3)
----------------------------------------------------------------------
Traceback (most recent call last):
  File "/Users/snigdhaghoshdastidar/Desktop/CS540/classeval_evaluation/ClassEval_28_4.py", line 329, in test_search_database_3
    self.processor.insert_into_database(table_name, data)
  File "/Users/snigdhaghoshdastidar/Desktop/CS540/classeval_evaluation/ClassEval_28_4.py", line 51, in insert_into_database
    INSERT INTO {table_name} ({key1}, {key2})
                               ^^^^
NameError: name 'key1' is not defined

======================================================================
ERROR: test_search_database_4 (ClassEval_28_4.DatabaseProcessorTestSearchDatabase.test_search_database_4)
----------------------------------------------------------------------
Traceback (most recent call last):
  File "/Users/snigdhaghoshdastidar/Desktop/CS540/classeval_evaluation/ClassEval_28_4.py", line 341, in test_search_database_4
    self.processor.insert_into_database(table_name, data)
  File "/Users/snigdhaghoshdastidar/Desktop/CS540/classeval_evaluation/ClassEval_28_4.py", line 51, in insert_into_database
    INSERT INTO {table_name} ({key1}, {key2})
                               ^^^^
NameError: name 'key1' is not defined

======================================================================
ERROR: test_search_database_5 (ClassEval_28_4.DatabaseProcessorTestSearchDatabase.test_search_database_5)
----------------------------------------------------------------------
Traceback (most recent call last):
  File "/Users/snigdhaghoshdastidar/Desktop/CS540/classeval_evaluation/ClassEval_28_4.py", line 353, in test_search_database_5
    self.processor.insert_into_database(table_name, data)
  File "/Users/snigdhaghoshdastidar/Desktop/CS540/classeval_evaluation/ClassEval_28_4.py", line 51, in insert_into_database
    INSERT INTO {table_name} ({key1}, {key2})
                               ^^^^
NameError: name 'key1' is not defined

----------------------------------------------------------------------
Ran 5 tests in 0.019s

FAILED (errors=5)
EEEEE
======================================================================
ERROR: test_delete_from_database_1 (ClassEval_28_4.DatabaseProcessorTestDeteleFromDatabase.test_delete_from_database_1)
----------------------------------------------------------------------
Traceback (most recent call last):
  File "/Users/snigdhaghoshdastidar/Desktop/CS540/classeval_evaluation/ClassEval_28_4.py", line 378, in test_delete_from_database_1
    self.processor.insert_into_database(table_name, data)
  File "/Users/snigdhaghoshdastidar/Desktop/CS540/classeval_evaluation/ClassEval_28_4.py", line 51, in insert_into_database
    INSERT INTO {table_name} ({key1}, {key2})
                               ^^^^
NameError: name 'key1' is not defined

======================================================================
ERROR: test_delete_from_database_2 (ClassEval_28_4.DatabaseProcessorTestDeteleFromDatabase.test_delete_from_database_2)
----------------------------------------------------------------------
Traceback (most recent call last):
  File "/Users/snigdhaghoshdastidar/Desktop/CS540/classeval_evaluation/ClassEval_28_4.py", line 398, in test_delete_from_database_2
    self.processor.insert_into_database(table_name, data)
  File "/Users/snigdhaghoshdastidar/Desktop/CS540/classeval_evaluation/ClassEval_28_4.py", line 51, in insert_into_database
    INSERT INTO {table_name} ({key1}, {key2})
                               ^^^^
NameError: name 'key1' is not defined

======================================================================
ERROR: test_delete_from_database_3 (ClassEval_28_4.DatabaseProcessorTestDeteleFromDatabase.test_delete_from_database_3)
----------------------------------------------------------------------
Traceback (most recent call last):
  File "/Users/snigdhaghoshdastidar/Desktop/CS540/classeval_evaluation/ClassEval_28_4.py", line 418, in test_delete_from_database_3
    self.processor.insert_into_database(table_name, data)
  File "/Users/snigdhaghoshdastidar/Desktop/CS540/classeval_evaluation/ClassEval_28_4.py", line 51, in insert_into_database
    INSERT INTO {table_name} ({key1}, {key2})
                               ^^^^
NameError: name 'key1' is not defined

======================================================================
ERROR: test_delete_from_database_4 (ClassEval_28_4.DatabaseProcessorTestDeteleFromDatabase.test_delete_from_database_4)
----------------------------------------------------------------------
Traceback (most recent call last):
  File "/Users/snigdhaghoshdastidar/Desktop/CS540/classeval_evaluation/ClassEval_28_4.py", line 438, in test_delete_from_database_4
    self.processor.insert_into_database(table_name, data)
  File "/Users/snigdhaghoshdastidar/Desktop/CS540/classeval_evaluation/ClassEval_28_4.py", line 51, in insert_into_database
    INSERT INTO {table_name} ({key1}, {key2})
                               ^^^^
NameError: name 'key1' is not defined

======================================================================
ERROR: test_delete_from_database_5 (ClassEval_28_4.DatabaseProcessorTestDeteleFromDatabase.test_delete_from_database_5)
----------------------------------------------------------------------
Traceback (most recent call last):
  File "/Users/snigdhaghoshdastidar/Desktop/CS540/classeval_evaluation/ClassEval_28_4.py", line 458, in test_delete_from_database_5
    self.processor.insert_into_database(table_name, data)
  File "/Users/snigdhaghoshdastidar/Desktop/CS540/classeval_evaluation/ClassEval_28_4.py", line 51, in insert_into_database
    INSERT INTO {table_name} ({key1}, {key2})
                               ^^^^
NameError: name 'key1' is not defined

----------------------------------------------------------------------
Ran 5 tests in 0.018s

FAILED (errors=5)
E
======================================================================
ERROR: test_DatabaseProcessor (ClassEval_28_4.DatabaseProcessorTest.test_DatabaseProcessor)
----------------------------------------------------------------------
Traceback (most recent call last):
  File "/Users/snigdhaghoshdastidar/Desktop/CS540/classeval_evaluation/ClassEval_28_4.py", line 501, in test_DatabaseProcessor
    self.processor.insert_into_database(table_name, data)
  File "/Users/snigdhaghoshdastidar/Desktop/CS540/classeval_evaluation/ClassEval_28_4.py", line 51, in insert_into_database
    INSERT INTO {table_name} ({key1}, {key2})
                               ^^^^
NameError: name 'key1' is not defined

----------------------------------------------------------------------
Ran 1 test in 0.005s

FAILED (errors=1)
.....
----------------------------------------------------------------------
Ran 5 tests in 0.013s

OK
.....
----------------------------------------------------------------------
Ran 5 tests in 0.012s

OK
.....
----------------------------------------------------------------------
Ran 5 tests in 0.020s

OK
.
----------------------------------------------------------------------
Ran 1 test in 0.004s

OK
.....
----------------------------------------------------------------------
Ran 5 tests in 0.028s

OK
.....
----------------------------------------------------------------------
Ran 5 tests in 0.015s

OK
.....
----------------------------------------------------------------------
Ran 5 tests in 0.034s

OK
.
----------------------------------------------------------------------
Ran 1 test in 0.006s

OK
.....
----------------------------------------------------------------------
Ran 5 tests in 0.024s

OK
.....
----------------------------------------------------------------------
Ran 5 tests in 0.017s

OK
.....
----------------------------------------------------------------------
Ran 5 tests in 0.024s

OK
.
----------------------------------------------------------------------
Ran 1 test in 0.005s

OK
.....
----------------------------------------------------------------------
Ran 5 tests in 0.018s

OK
.....
----------------------------------------------------------------------
Ran 5 tests in 0.019s

OK
.....
----------------------------------------------------------------------
Ran 5 tests in 0.041s

OK
.
----------------------------------------------------------------------
Ran 1 test in 0.005s

OK
.....
----------------------------------------------------------------------
Ran 5 tests in 0.020s

OK
.....
----------------------------------------------------------------------
Ran 5 tests in 0.020s

OK
.....
----------------------------------------------------------------------
Ran 5 tests in 0.029s

OK
.
----------------------------------------------------------------------
Ran 1 test in 0.005s

OK
......
----------------------------------------------------------------------
Ran 6 tests in 0.000s

OK
.....
----------------------------------------------------------------------
Ran 5 tests in 0.000s

OK
.....
----------------------------------------------------------------------
Ran 5 tests in 0.000s

OK
.....
----------------------------------------------------------------------
Ran 5 tests in 0.000s

OK
.....
----------------------------------------------------------------------
Ran 5 tests in 0.000s

OK
.....
----------------------------------------------------------------------
Ran 5 tests in 0.000s

OK
.
----------------------------------------------------------------------
Ran 1 test in 0.000s

OK
......
----------------------------------------------------------------------
Ran 6 tests in 0.000s

OK
.....
----------------------------------------------------------------------
Ran 5 tests in 0.000s

OK
.....
----------------------------------------------------------------------
Ran 5 tests in 0.000s

OK
.....
----------------------------------------------------------------------
Ran 5 tests in 0.000s

OK
.....
----------------------------------------------------------------------
Ran 5 tests in 0.000s

OK
.....
----------------------------------------------------------------------
Ran 5 tests in 0.000s

OK
.
----------------------------------------------------------------------
Ran 1 test in 0.000s

OK
......
----------------------------------------------------------------------
Ran 6 tests in 0.000s

OK
.....
----------------------------------------------------------------------
Ran 5 tests in 0.000s

OK
.....
----------------------------------------------------------------------
Ran 5 tests in 0.000s

OK
.....
----------------------------------------------------------------------
Ran 5 tests in 0.000s

OK
.....
----------------------------------------------------------------------
Ran 5 tests in 0.000s

OK
.....
----------------------------------------------------------------------
Ran 5 tests in 0.000s

OK
.
----------------------------------------------------------------------
Ran 1 test in 0.000s

OK
......
----------------------------------------------------------------------
Ran 6 tests in 0.000s

OK
.....
----------------------------------------------------------------------
Ran 5 tests in 0.000s

OK
.....
----------------------------------------------------------------------
Ran 5 tests in 0.000s

OK
.....
----------------------------------------------------------------------
Ran 5 tests in 0.000s

OK
.....
----------------------------------------------------------------------
Ran 5 tests in 0.000s

OK
.....
----------------------------------------------------------------------
Ran 5 tests in 0.000s

OK
.
----------------------------------------------------------------------
Ran 1 test in 0.000s

OK
......
----------------------------------------------------------------------
Ran 6 tests in 0.000s

OK
.....
----------------------------------------------------------------------
Ran 5 tests in 0.000s

OK
.....
----------------------------------------------------------------------
Ran 5 tests in 0.000s

OK
.....
----------------------------------------------------------------------
Ran 5 tests in 0.000s

OK
.....
----------------------------------------------------------------------
Ran 5 tests in 0.000s

OK
.....
----------------------------------------------------------------------
Ran 5 tests in 0.000s

OK
.
----------------------------------------------------------------------
Ran 1 test in 0.000s

OK
.......
----------------------------------------------------------------------
Ran 7 tests in 0.000s

OK
.....
----------------------------------------------------------------------
Ran 5 tests in 0.000s

OK
......
----------------------------------------------------------------------
Ran 6 tests in 0.000s

OK
......
----------------------------------------------------------------------
Ran 6 tests in 0.000s

OK
.
----------------------------------------------------------------------
Ran 1 test in 0.000s

OK
.......
----------------------------------------------------------------------
Ran 7 tests in 0.000s

OK
.....
----------------------------------------------------------------------
Ran 5 tests in 0.000s

OK
......
----------------------------------------------------------------------
Ran 6 tests in 0.000s

OK
......
----------------------------------------------------------------------
Ran 6 tests in 0.000s

OK
.
----------------------------------------------------------------------
Ran 1 test in 0.000s

OK
.......
----------------------------------------------------------------------
Ran 7 tests in 0.000s

OK
.....
----------------------------------------------------------------------
Ran 5 tests in 0.000s

OK
......
----------------------------------------------------------------------
Ran 6 tests in 0.000s

OK
......
----------------------------------------------------------------------
Ran 6 tests in 0.000s

OK
.
----------------------------------------------------------------------
Ran 1 test in 0.000s

OK
.......
----------------------------------------------------------------------
Ran 7 tests in 0.000s

OK
.....
----------------------------------------------------------------------
Ran 5 tests in 0.000s

OK
......
----------------------------------------------------------------------
Ran 6 tests in 0.000s

OK
......
----------------------------------------------------------------------
Ran 6 tests in 0.000s

OK
.
----------------------------------------------------------------------
Ran 1 test in 0.000s

OK
.......
----------------------------------------------------------------------
Ran 7 tests in 0.000s

OK
.....
----------------------------------------------------------------------
Ran 5 tests in 0.000s

OK
......
----------------------------------------------------------------------
Ran 6 tests in 0.000s

OK
......
----------------------------------------------------------------------
Ran 6 tests in 0.000s

OK
.
----------------------------------------------------------------------
Ran 1 test in 0.000s

OK
.....
----------------------------------------------------------------------
Ran 5 tests in 0.023s

OK
.....
----------------------------------------------------------------------
Ran 5 tests in 0.022s

OK
.....
----------------------------------------------------------------------
Ran 5 tests in 0.030s

OK
.
----------------------------------------------------------------------
Ran 1 test in 0.009s

OK
.....
----------------------------------------------------------------------
Ran 5 tests in 0.023s

OK
.....
----------------------------------------------------------------------
Ran 5 tests in 0.027s

OK
.....
----------------------------------------------------------------------
Ran 5 tests in 0.035s

OK
.
----------------------------------------------------------------------
Ran 1 test in 0.012s

OK
.....
----------------------------------------------------------------------
Ran 5 tests in 0.024s

OK
.....
----------------------------------------------------------------------
Ran 5 tests in 0.023s

OK
.....
----------------------------------------------------------------------
Ran 5 tests in 0.031s

OK
.
----------------------------------------------------------------------
Ran 1 test in 0.010s

OK
.....
----------------------------------------------------------------------
Ran 5 tests in 0.030s

OK
.....
----------------------------------------------------------------------
Ran 5 tests in 0.027s

OK
.....
----------------------------------------------------------------------
Ran 5 tests in 0.028s

OK
.
----------------------------------------------------------------------
Ran 1 test in 0.009s

OK
.....
----------------------------------------------------------------------
Ran 5 tests in 0.022s

OK
.....
----------------------------------------------------------------------
Ran 5 tests in 0.039s

OK
.....
----------------------------------------------------------------------
Ran 5 tests in 0.034s

OK
.
----------------------------------------------------------------------
Ran 1 test in 0.010s

OK
FFFFF
======================================================================
FAIL: test_insert_user_1 (ClassEval_92_0.UserLoginDBTestInsertUser.test_insert_user_1)
----------------------------------------------------------------------
Traceback (most recent call last):
  File "/Users/snigdhaghoshdastidar/Desktop/CS540/classeval_evaluation/ClassEval_92_0.py", line 93, in test_insert_user_1
    self.assertEqual(user[0], 'user1')
AssertionError: ('user1', 'pass1') != 'user1'

======================================================================
FAIL: test_insert_user_2 (ClassEval_92_0.UserLoginDBTestInsertUser.test_insert_user_2)
----------------------------------------------------------------------
Traceback (most recent call last):
  File "/Users/snigdhaghoshdastidar/Desktop/CS540/classeval_evaluation/ClassEval_92_0.py", line 100, in test_insert_user_2
    self.assertEqual(user[0], 'user2')
AssertionError: ('user2', 'pass2') != 'user2'

======================================================================
FAIL: test_insert_user_3 (ClassEval_92_0.UserLoginDBTestInsertUser.test_insert_user_3)
----------------------------------------------------------------------
Traceback (most recent call last):
  File "/Users/snigdhaghoshdastidar/Desktop/CS540/classeval_evaluation/ClassEval_92_0.py", line 107, in test_insert_user_3
    self.assertEqual(user[0], 'user3')
AssertionError: ('user3', 'pass3') != 'user3'

======================================================================
FAIL: test_insert_user_4 (ClassEval_92_0.UserLoginDBTestInsertUser.test_insert_user_4)
----------------------------------------------------------------------
Traceback (most recent call last):
  File "/Users/snigdhaghoshdastidar/Desktop/CS540/classeval_evaluation/ClassEval_92_0.py", line 114, in test_insert_user_4
    self.assertEqual(user[0], 'user4')
AssertionError: ('user4', 'pass4') != 'user4'

======================================================================
FAIL: test_insert_user_5 (ClassEval_92_0.UserLoginDBTestInsertUser.test_insert_user_5)
----------------------------------------------------------------------
Traceback (most recent call last):
  File "/Users/snigdhaghoshdastidar/Desktop/CS540/classeval_evaluation/ClassEval_92_0.py", line 121, in test_insert_user_5
    self.assertEqual(user[0], 'user5')
AssertionError: ('user5', 'pass5') != 'user5'

----------------------------------------------------------------------
Ran 5 tests in 0.018s

FAILED (failures=5)
FFFFF
======================================================================
FAIL: test_search_user_by_username_1 (ClassEval_92_0.UserLoginDBTestSearchUserByUsername.test_search_user_by_username_1)
----------------------------------------------------------------------
Traceback (most recent call last):
  File "/Users/snigdhaghoshdastidar/Desktop/CS540/classeval_evaluation/ClassEval_92_0.py", line 150, in test_search_user_by_username_1
    self.assertEqual(user[0], 'user1')
AssertionError: ('user1', 'pass1') != 'user1'

======================================================================
FAIL: test_search_user_by_username_2 (ClassEval_92_0.UserLoginDBTestSearchUserByUsername.test_search_user_by_username_2)
----------------------------------------------------------------------
Traceback (most recent call last):
  File "/Users/snigdhaghoshdastidar/Desktop/CS540/classeval_evaluation/ClassEval_92_0.py", line 157, in test_search_user_by_username_2
    self.assertEqual(user[0], 'user2')
AssertionError: ('user2', 'pass2') != 'user2'

======================================================================
FAIL: test_search_user_by_username_3 (ClassEval_92_0.UserLoginDBTestSearchUserByUsername.test_search_user_by_username_3)
----------------------------------------------------------------------
Traceback (most recent call last):
  File "/Users/snigdhaghoshdastidar/Desktop/CS540/classeval_evaluation/ClassEval_92_0.py", line 164, in test_search_user_by_username_3
    self.assertEqual(user[0], 'user3')
AssertionError: ('user3', 'pass3') != 'user3'

======================================================================
FAIL: test_search_user_by_username_4 (ClassEval_92_0.UserLoginDBTestSearchUserByUsername.test_search_user_by_username_4)
----------------------------------------------------------------------
Traceback (most recent call last):
  File "/Users/snigdhaghoshdastidar/Desktop/CS540/classeval_evaluation/ClassEval_92_0.py", line 171, in test_search_user_by_username_4
    self.assertEqual(user[0], 'user4')
AssertionError: ('user4', 'pass4') != 'user4'

======================================================================
FAIL: test_search_user_by_username_5 (ClassEval_92_0.UserLoginDBTestSearchUserByUsername.test_search_user_by_username_5)
----------------------------------------------------------------------
Traceback (most recent call last):
  File "/Users/snigdhaghoshdastidar/Desktop/CS540/classeval_evaluation/ClassEval_92_0.py", line 178, in test_search_user_by_username_5
    self.assertEqual(user[0], 'user5')
AssertionError: ('user5', 'pass5') != 'user5'

----------------------------------------------------------------------
Ran 5 tests in 0.024s

FAILED (failures=5)
FFFFF
======================================================================
FAIL: test_delete_user_by_username_1 (ClassEval_92_0.UserLoginDBTestDeleteUserByUsername.test_delete_user_by_username_1)
----------------------------------------------------------------------
Traceback (most recent call last):
  File "/Users/snigdhaghoshdastidar/Desktop/CS540/classeval_evaluation/ClassEval_92_0.py", line 207, in test_delete_user_by_username_1
    self.assertIsNone(user)
AssertionError: [] is not None

======================================================================
FAIL: test_delete_user_by_username_2 (ClassEval_92_0.UserLoginDBTestDeleteUserByUsername.test_delete_user_by_username_2)
----------------------------------------------------------------------
Traceback (most recent call last):
  File "/Users/snigdhaghoshdastidar/Desktop/CS540/classeval_evaluation/ClassEval_92_0.py", line 213, in test_delete_user_by_username_2
    self.assertIsNone(user)
AssertionError: [] is not None

======================================================================
FAIL: test_delete_user_by_username_3 (ClassEval_92_0.UserLoginDBTestDeleteUserByUsername.test_delete_user_by_username_3)
----------------------------------------------------------------------
Traceback (most recent call last):
  File "/Users/snigdhaghoshdastidar/Desktop/CS540/classeval_evaluation/ClassEval_92_0.py", line 219, in test_delete_user_by_username_3
    self.assertIsNone(user)
AssertionError: [] is not None

======================================================================
FAIL: test_delete_user_by_username_4 (ClassEval_92_0.UserLoginDBTestDeleteUserByUsername.test_delete_user_by_username_4)
----------------------------------------------------------------------
Traceback (most recent call last):
  File "/Users/snigdhaghoshdastidar/Desktop/CS540/classeval_evaluation/ClassEval_92_0.py", line 225, in test_delete_user_by_username_4
    self.assertIsNone(user)
AssertionError: [] is not None

======================================================================
FAIL: test_delete_user_by_username_5 (ClassEval_92_0.UserLoginDBTestDeleteUserByUsername.test_delete_user_by_username_5)
----------------------------------------------------------------------
Traceback (most recent call last):
  File "/Users/snigdhaghoshdastidar/Desktop/CS540/classeval_evaluation/ClassEval_92_0.py", line 231, in test_delete_user_by_username_5
    self.assertIsNone(user)
AssertionError: [] is not None

----------------------------------------------------------------------
Ran 5 tests in 0.028s

FAILED (failures=5)
.....
----------------------------------------------------------------------
Ran 5 tests in 0.023s

OK
F
======================================================================
FAIL: test_UserLoginDB (ClassEval_92_0.UserLoginDBTest.test_UserLoginDB)
----------------------------------------------------------------------
Traceback (most recent call last):
  File "/Users/snigdhaghoshdastidar/Desktop/CS540/classeval_evaluation/ClassEval_92_0.py", line 305, in test_UserLoginDB
    self.assertEqual(user[0], 'user1')
AssertionError: ('user1', 'pass1') != 'user1'

----------------------------------------------------------------------
Ran 1 test in 0.004s

FAILED (failures=1)
FFFFF
======================================================================
FAIL: test_insert_user_1 (ClassEval_92_1.UserLoginDBTestInsertUser.test_insert_user_1)
----------------------------------------------------------------------
Traceback (most recent call last):
  File "/Users/snigdhaghoshdastidar/Desktop/CS540/classeval_evaluation/ClassEval_92_1.py", line 101, in test_insert_user_1
    self.assertEqual(user[0], 'user1')
AssertionError: ('user1', 'pass1') != 'user1'

======================================================================
FAIL: test_insert_user_2 (ClassEval_92_1.UserLoginDBTestInsertUser.test_insert_user_2)
----------------------------------------------------------------------
Traceback (most recent call last):
  File "/Users/snigdhaghoshdastidar/Desktop/CS540/classeval_evaluation/ClassEval_92_1.py", line 108, in test_insert_user_2
    self.assertEqual(user[0], 'user2')
AssertionError: ('user2', 'pass2') != 'user2'

======================================================================
FAIL: test_insert_user_3 (ClassEval_92_1.UserLoginDBTestInsertUser.test_insert_user_3)
----------------------------------------------------------------------
Traceback (most recent call last):
  File "/Users/snigdhaghoshdastidar/Desktop/CS540/classeval_evaluation/ClassEval_92_1.py", line 115, in test_insert_user_3
    self.assertEqual(user[0], 'user3')
AssertionError: ('user3', 'pass3') != 'user3'

======================================================================
FAIL: test_insert_user_4 (ClassEval_92_1.UserLoginDBTestInsertUser.test_insert_user_4)
----------------------------------------------------------------------
Traceback (most recent call last):
  File "/Users/snigdhaghoshdastidar/Desktop/CS540/classeval_evaluation/ClassEval_92_1.py", line 122, in test_insert_user_4
    self.assertEqual(user[0], 'user4')
AssertionError: ('user4', 'pass4') != 'user4'

======================================================================
FAIL: test_insert_user_5 (ClassEval_92_1.UserLoginDBTestInsertUser.test_insert_user_5)
----------------------------------------------------------------------
Traceback (most recent call last):
  File "/Users/snigdhaghoshdastidar/Desktop/CS540/classeval_evaluation/ClassEval_92_1.py", line 129, in test_insert_user_5
    self.assertEqual(user[0], 'user5')
AssertionError: ('user5', 'pass5') != 'user5'

----------------------------------------------------------------------
Ran 5 tests in 0.025s

FAILED (failures=5)
FFFFF
======================================================================
FAIL: test_search_user_by_username_1 (ClassEval_92_1.UserLoginDBTestSearchUserByUsername.test_search_user_by_username_1)
----------------------------------------------------------------------
Traceback (most recent call last):
  File "/Users/snigdhaghoshdastidar/Desktop/CS540/classeval_evaluation/ClassEval_92_1.py", line 158, in test_search_user_by_username_1
    self.assertEqual(user[0], 'user1')
AssertionError: ('user1', 'pass1') != 'user1'

======================================================================
FAIL: test_search_user_by_username_2 (ClassEval_92_1.UserLoginDBTestSearchUserByUsername.test_search_user_by_username_2)
----------------------------------------------------------------------
Traceback (most recent call last):
  File "/Users/snigdhaghoshdastidar/Desktop/CS540/classeval_evaluation/ClassEval_92_1.py", line 165, in test_search_user_by_username_2
    self.assertEqual(user[0], 'user2')
AssertionError: ('user2', 'pass2') != 'user2'

======================================================================
FAIL: test_search_user_by_username_3 (ClassEval_92_1.UserLoginDBTestSearchUserByUsername.test_search_user_by_username_3)
----------------------------------------------------------------------
Traceback (most recent call last):
  File "/Users/snigdhaghoshdastidar/Desktop/CS540/classeval_evaluation/ClassEval_92_1.py", line 172, in test_search_user_by_username_3
    self.assertEqual(user[0], 'user3')
AssertionError: ('user3', 'pass3') != 'user3'

======================================================================
FAIL: test_search_user_by_username_4 (ClassEval_92_1.UserLoginDBTestSearchUserByUsername.test_search_user_by_username_4)
----------------------------------------------------------------------
Traceback (most recent call last):
  File "/Users/snigdhaghoshdastidar/Desktop/CS540/classeval_evaluation/ClassEval_92_1.py", line 179, in test_search_user_by_username_4
    self.assertEqual(user[0], 'user4')
AssertionError: ('user4', 'pass4') != 'user4'

======================================================================
FAIL: test_search_user_by_username_5 (ClassEval_92_1.UserLoginDBTestSearchUserByUsername.test_search_user_by_username_5)
----------------------------------------------------------------------
Traceback (most recent call last):
  File "/Users/snigdhaghoshdastidar/Desktop/CS540/classeval_evaluation/ClassEval_92_1.py", line 186, in test_search_user_by_username_5
    self.assertEqual(user[0], 'user5')
AssertionError: ('user5', 'pass5') != 'user5'

----------------------------------------------------------------------
Ran 5 tests in 0.026s

FAILED (failures=5)
FFFFF
======================================================================
FAIL: test_delete_user_by_username_1 (ClassEval_92_1.UserLoginDBTestDeleteUserByUsername.test_delete_user_by_username_1)
----------------------------------------------------------------------
Traceback (most recent call last):
  File "/Users/snigdhaghoshdastidar/Desktop/CS540/classeval_evaluation/ClassEval_92_1.py", line 215, in test_delete_user_by_username_1
    self.assertIsNone(user)
AssertionError: [] is not None

======================================================================
FAIL: test_delete_user_by_username_2 (ClassEval_92_1.UserLoginDBTestDeleteUserByUsername.test_delete_user_by_username_2)
----------------------------------------------------------------------
Traceback (most recent call last):
  File "/Users/snigdhaghoshdastidar/Desktop/CS540/classeval_evaluation/ClassEval_92_1.py", line 221, in test_delete_user_by_username_2
    self.assertIsNone(user)
AssertionError: [] is not None

======================================================================
FAIL: test_delete_user_by_username_3 (ClassEval_92_1.UserLoginDBTestDeleteUserByUsername.test_delete_user_by_username_3)
----------------------------------------------------------------------
Traceback (most recent call last):
  File "/Users/snigdhaghoshdastidar/Desktop/CS540/classeval_evaluation/ClassEval_92_1.py", line 227, in test_delete_user_by_username_3
    self.assertIsNone(user)
AssertionError: [] is not None

======================================================================
FAIL: test_delete_user_by_username_4 (ClassEval_92_1.UserLoginDBTestDeleteUserByUsername.test_delete_user_by_username_4)
----------------------------------------------------------------------
Traceback (most recent call last):
  File "/Users/snigdhaghoshdastidar/Desktop/CS540/classeval_evaluation/ClassEval_92_1.py", line 233, in test_delete_user_by_username_4
    self.assertIsNone(user)
AssertionError: [] is not None

======================================================================
FAIL: test_delete_user_by_username_5 (ClassEval_92_1.UserLoginDBTestDeleteUserByUsername.test_delete_user_by_username_5)
----------------------------------------------------------------------
Traceback (most recent call last):
  File "/Users/snigdhaghoshdastidar/Desktop/CS540/classeval_evaluation/ClassEval_92_1.py", line 239, in test_delete_user_by_username_5
    self.assertIsNone(user)
AssertionError: [] is not None

----------------------------------------------------------------------
Ran 5 tests in 0.028s

FAILED (failures=5)
.....
----------------------------------------------------------------------
Ran 5 tests in 0.020s

OK
F
======================================================================
FAIL: test_UserLoginDB (ClassEval_92_1.UserLoginDBTest.test_UserLoginDB)
----------------------------------------------------------------------
Traceback (most recent call last):
  File "/Users/snigdhaghoshdastidar/Desktop/CS540/classeval_evaluation/ClassEval_92_1.py", line 313, in test_UserLoginDB
    self.assertEqual(user[0], 'user1')
AssertionError: ('user1', 'pass1') != 'user1'

----------------------------------------------------------------------
Ran 1 test in 0.003s

FAILED (failures=1)
FFFFF
======================================================================
FAIL: test_insert_user_1 (ClassEval_92_2.UserLoginDBTestInsertUser.test_insert_user_1)
----------------------------------------------------------------------
Traceback (most recent call last):
  File "/Users/snigdhaghoshdastidar/Desktop/CS540/classeval_evaluation/ClassEval_92_2.py", line 103, in test_insert_user_1
    self.assertEqual(user[0], 'user1')
AssertionError: ('user1', 'pass1') != 'user1'

======================================================================
FAIL: test_insert_user_2 (ClassEval_92_2.UserLoginDBTestInsertUser.test_insert_user_2)
----------------------------------------------------------------------
Traceback (most recent call last):
  File "/Users/snigdhaghoshdastidar/Desktop/CS540/classeval_evaluation/ClassEval_92_2.py", line 110, in test_insert_user_2
    self.assertEqual(user[0], 'user2')
AssertionError: ('user2', 'pass2') != 'user2'

======================================================================
FAIL: test_insert_user_3 (ClassEval_92_2.UserLoginDBTestInsertUser.test_insert_user_3)
----------------------------------------------------------------------
Traceback (most recent call last):
  File "/Users/snigdhaghoshdastidar/Desktop/CS540/classeval_evaluation/ClassEval_92_2.py", line 117, in test_insert_user_3
    self.assertEqual(user[0], 'user3')
AssertionError: ('user3', 'pass3') != 'user3'

======================================================================
FAIL: test_insert_user_4 (ClassEval_92_2.UserLoginDBTestInsertUser.test_insert_user_4)
----------------------------------------------------------------------
Traceback (most recent call last):
  File "/Users/snigdhaghoshdastidar/Desktop/CS540/classeval_evaluation/ClassEval_92_2.py", line 124, in test_insert_user_4
    self.assertEqual(user[0], 'user4')
AssertionError: ('user4', 'pass4') != 'user4'

======================================================================
FAIL: test_insert_user_5 (ClassEval_92_2.UserLoginDBTestInsertUser.test_insert_user_5)
----------------------------------------------------------------------
Traceback (most recent call last):
  File "/Users/snigdhaghoshdastidar/Desktop/CS540/classeval_evaluation/ClassEval_92_2.py", line 131, in test_insert_user_5
    self.assertEqual(user[0], 'user5')
AssertionError: ('user5', 'pass5') != 'user5'

----------------------------------------------------------------------
Ran 5 tests in 0.023s

FAILED (failures=5)
FFFFF
======================================================================
FAIL: test_search_user_by_username_1 (ClassEval_92_2.UserLoginDBTestSearchUserByUsername.test_search_user_by_username_1)
----------------------------------------------------------------------
Traceback (most recent call last):
  File "/Users/snigdhaghoshdastidar/Desktop/CS540/classeval_evaluation/ClassEval_92_2.py", line 160, in test_search_user_by_username_1
    self.assertEqual(user[0], 'user1')
AssertionError: ('user1', 'pass1') != 'user1'

======================================================================
FAIL: test_search_user_by_username_2 (ClassEval_92_2.UserLoginDBTestSearchUserByUsername.test_search_user_by_username_2)
----------------------------------------------------------------------
Traceback (most recent call last):
  File "/Users/snigdhaghoshdastidar/Desktop/CS540/classeval_evaluation/ClassEval_92_2.py", line 167, in test_search_user_by_username_2
    self.assertEqual(user[0], 'user2')
AssertionError: ('user2', 'pass2') != 'user2'

======================================================================
FAIL: test_search_user_by_username_3 (ClassEval_92_2.UserLoginDBTestSearchUserByUsername.test_search_user_by_username_3)
----------------------------------------------------------------------
Traceback (most recent call last):
  File "/Users/snigdhaghoshdastidar/Desktop/CS540/classeval_evaluation/ClassEval_92_2.py", line 174, in test_search_user_by_username_3
    self.assertEqual(user[0], 'user3')
AssertionError: ('user3', 'pass3') != 'user3'

======================================================================
FAIL: test_search_user_by_username_4 (ClassEval_92_2.UserLoginDBTestSearchUserByUsername.test_search_user_by_username_4)
----------------------------------------------------------------------
Traceback (most recent call last):
  File "/Users/snigdhaghoshdastidar/Desktop/CS540/classeval_evaluation/ClassEval_92_2.py", line 181, in test_search_user_by_username_4
    self.assertEqual(user[0], 'user4')
AssertionError: ('user4', 'pass4') != 'user4'

======================================================================
FAIL: test_search_user_by_username_5 (ClassEval_92_2.UserLoginDBTestSearchUserByUsername.test_search_user_by_username_5)
----------------------------------------------------------------------
Traceback (most recent call last):
  File "/Users/snigdhaghoshdastidar/Desktop/CS540/classeval_evaluation/ClassEval_92_2.py", line 188, in test_search_user_by_username_5
    self.assertEqual(user[0], 'user5')
AssertionError: ('user5', 'pass5') != 'user5'

----------------------------------------------------------------------
Ran 5 tests in 0.020s

FAILED (failures=5)
FFFFF
======================================================================
FAIL: test_delete_user_by_username_1 (ClassEval_92_2.UserLoginDBTestDeleteUserByUsername.test_delete_user_by_username_1)
----------------------------------------------------------------------
Traceback (most recent call last):
  File "/Users/snigdhaghoshdastidar/Desktop/CS540/classeval_evaluation/ClassEval_92_2.py", line 217, in test_delete_user_by_username_1
    self.assertIsNone(user)
AssertionError: [] is not None

======================================================================
FAIL: test_delete_user_by_username_2 (ClassEval_92_2.UserLoginDBTestDeleteUserByUsername.test_delete_user_by_username_2)
----------------------------------------------------------------------
Traceback (most recent call last):
  File "/Users/snigdhaghoshdastidar/Desktop/CS540/classeval_evaluation/ClassEval_92_2.py", line 223, in test_delete_user_by_username_2
    self.assertIsNone(user)
AssertionError: [] is not None

======================================================================
FAIL: test_delete_user_by_username_3 (ClassEval_92_2.UserLoginDBTestDeleteUserByUsername.test_delete_user_by_username_3)
----------------------------------------------------------------------
Traceback (most recent call last):
  File "/Users/snigdhaghoshdastidar/Desktop/CS540/classeval_evaluation/ClassEval_92_2.py", line 229, in test_delete_user_by_username_3
    self.assertIsNone(user)
AssertionError: [] is not None

======================================================================
FAIL: test_delete_user_by_username_4 (ClassEval_92_2.UserLoginDBTestDeleteUserByUsername.test_delete_user_by_username_4)
----------------------------------------------------------------------
Traceback (most recent call last):
  File "/Users/snigdhaghoshdastidar/Desktop/CS540/classeval_evaluation/ClassEval_92_2.py", line 235, in test_delete_user_by_username_4
    self.assertIsNone(user)
AssertionError: [] is not None

======================================================================
FAIL: test_delete_user_by_username_5 (ClassEval_92_2.UserLoginDBTestDeleteUserByUsername.test_delete_user_by_username_5)
----------------------------------------------------------------------
Traceback (most recent call last):
  File "/Users/snigdhaghoshdastidar/Desktop/CS540/classeval_evaluation/ClassEval_92_2.py", line 241, in test_delete_user_by_username_5
    self.assertIsNone(user)
AssertionError: [] is not None

----------------------------------------------------------------------
Ran 5 tests in 0.027s

FAILED (failures=5)
.....
----------------------------------------------------------------------
Ran 5 tests in 0.016s

OK
F
======================================================================
FAIL: test_UserLoginDB (ClassEval_92_2.UserLoginDBTest.test_UserLoginDB)
----------------------------------------------------------------------
Traceback (most recent call last):
  File "/Users/snigdhaghoshdastidar/Desktop/CS540/classeval_evaluation/ClassEval_92_2.py", line 315, in test_UserLoginDB
    self.assertEqual(user[0], 'user1')
AssertionError: ('user1', 'pass1') != 'user1'

----------------------------------------------------------------------
Ran 1 test in 0.003s

FAILED (failures=1)
FFFFF
======================================================================
FAIL: test_insert_user_1 (ClassEval_92_3.UserLoginDBTestInsertUser.test_insert_user_1)
----------------------------------------------------------------------
Traceback (most recent call last):
  File "/Users/snigdhaghoshdastidar/Desktop/CS540/classeval_evaluation/ClassEval_92_3.py", line 117, in test_insert_user_1
    self.assertEqual(user[0], 'user1')
AssertionError: ('user1', 'pass1') != 'user1'

======================================================================
FAIL: test_insert_user_2 (ClassEval_92_3.UserLoginDBTestInsertUser.test_insert_user_2)
----------------------------------------------------------------------
Traceback (most recent call last):
  File "/Users/snigdhaghoshdastidar/Desktop/CS540/classeval_evaluation/ClassEval_92_3.py", line 124, in test_insert_user_2
    self.assertEqual(user[0], 'user2')
AssertionError: ('user2', 'pass2') != 'user2'

======================================================================
FAIL: test_insert_user_3 (ClassEval_92_3.UserLoginDBTestInsertUser.test_insert_user_3)
----------------------------------------------------------------------
Traceback (most recent call last):
  File "/Users/snigdhaghoshdastidar/Desktop/CS540/classeval_evaluation/ClassEval_92_3.py", line 131, in test_insert_user_3
    self.assertEqual(user[0], 'user3')
AssertionError: ('user3', 'pass3') != 'user3'

======================================================================
FAIL: test_insert_user_4 (ClassEval_92_3.UserLoginDBTestInsertUser.test_insert_user_4)
----------------------------------------------------------------------
Traceback (most recent call last):
  File "/Users/snigdhaghoshdastidar/Desktop/CS540/classeval_evaluation/ClassEval_92_3.py", line 138, in test_insert_user_4
    self.assertEqual(user[0], 'user4')
AssertionError: ('user4', 'pass4') != 'user4'

======================================================================
FAIL: test_insert_user_5 (ClassEval_92_3.UserLoginDBTestInsertUser.test_insert_user_5)
----------------------------------------------------------------------
Traceback (most recent call last):
  File "/Users/snigdhaghoshdastidar/Desktop/CS540/classeval_evaluation/ClassEval_92_3.py", line 145, in test_insert_user_5
    self.assertEqual(user[0], 'user5')
AssertionError: ('user5', 'pass5') != 'user5'

----------------------------------------------------------------------
Ran 5 tests in 0.018s

FAILED (failures=5)
FFFFF
======================================================================
FAIL: test_search_user_by_username_1 (ClassEval_92_3.UserLoginDBTestSearchUserByUsername.test_search_user_by_username_1)
----------------------------------------------------------------------
Traceback (most recent call last):
  File "/Users/snigdhaghoshdastidar/Desktop/CS540/classeval_evaluation/ClassEval_92_3.py", line 174, in test_search_user_by_username_1
    self.assertEqual(user[0], 'user1')
AssertionError: ('user1', 'pass1') != 'user1'

======================================================================
FAIL: test_search_user_by_username_2 (ClassEval_92_3.UserLoginDBTestSearchUserByUsername.test_search_user_by_username_2)
----------------------------------------------------------------------
Traceback (most recent call last):
  File "/Users/snigdhaghoshdastidar/Desktop/CS540/classeval_evaluation/ClassEval_92_3.py", line 181, in test_search_user_by_username_2
    self.assertEqual(user[0], 'user2')
AssertionError: ('user2', 'pass2') != 'user2'

======================================================================
FAIL: test_search_user_by_username_3 (ClassEval_92_3.UserLoginDBTestSearchUserByUsername.test_search_user_by_username_3)
----------------------------------------------------------------------
Traceback (most recent call last):
  File "/Users/snigdhaghoshdastidar/Desktop/CS540/classeval_evaluation/ClassEval_92_3.py", line 188, in test_search_user_by_username_3
    self.assertEqual(user[0], 'user3')
AssertionError: ('user3', 'pass3') != 'user3'

======================================================================
FAIL: test_search_user_by_username_4 (ClassEval_92_3.UserLoginDBTestSearchUserByUsername.test_search_user_by_username_4)
----------------------------------------------------------------------
Traceback (most recent call last):
  File "/Users/snigdhaghoshdastidar/Desktop/CS540/classeval_evaluation/ClassEval_92_3.py", line 195, in test_search_user_by_username_4
    self.assertEqual(user[0], 'user4')
AssertionError: ('user4', 'pass4') != 'user4'

======================================================================
FAIL: test_search_user_by_username_5 (ClassEval_92_3.UserLoginDBTestSearchUserByUsername.test_search_user_by_username_5)
----------------------------------------------------------------------
Traceback (most recent call last):
  File "/Users/snigdhaghoshdastidar/Desktop/CS540/classeval_evaluation/ClassEval_92_3.py", line 202, in test_search_user_by_username_5
    self.assertEqual(user[0], 'user5')
AssertionError: ('user5', 'pass5') != 'user5'

----------------------------------------------------------------------
Ran 5 tests in 0.019s

FAILED (failures=5)
FFFFF
======================================================================
FAIL: test_delete_user_by_username_1 (ClassEval_92_3.UserLoginDBTestDeleteUserByUsername.test_delete_user_by_username_1)
----------------------------------------------------------------------
Traceback (most recent call last):
  File "/Users/snigdhaghoshdastidar/Desktop/CS540/classeval_evaluation/ClassEval_92_3.py", line 231, in test_delete_user_by_username_1
    self.assertIsNone(user)
AssertionError: [] is not None

======================================================================
FAIL: test_delete_user_by_username_2 (ClassEval_92_3.UserLoginDBTestDeleteUserByUsername.test_delete_user_by_username_2)
----------------------------------------------------------------------
Traceback (most recent call last):
  File "/Users/snigdhaghoshdastidar/Desktop/CS540/classeval_evaluation/ClassEval_92_3.py", line 237, in test_delete_user_by_username_2
    self.assertIsNone(user)
AssertionError: [] is not None

======================================================================
FAIL: test_delete_user_by_username_3 (ClassEval_92_3.UserLoginDBTestDeleteUserByUsername.test_delete_user_by_username_3)
----------------------------------------------------------------------
Traceback (most recent call last):
  File "/Users/snigdhaghoshdastidar/Desktop/CS540/classeval_evaluation/ClassEval_92_3.py", line 243, in test_delete_user_by_username_3
    self.assertIsNone(user)
AssertionError: [] is not None

======================================================================
FAIL: test_delete_user_by_username_4 (ClassEval_92_3.UserLoginDBTestDeleteUserByUsername.test_delete_user_by_username_4)
----------------------------------------------------------------------
Traceback (most recent call last):
  File "/Users/snigdhaghoshdastidar/Desktop/CS540/classeval_evaluation/ClassEval_92_3.py", line 249, in test_delete_user_by_username_4
    self.assertIsNone(user)
AssertionError: [] is not None

======================================================================
FAIL: test_delete_user_by_username_5 (ClassEval_92_3.UserLoginDBTestDeleteUserByUsername.test_delete_user_by_username_5)
----------------------------------------------------------------------
Traceback (most recent call last):
  File "/Users/snigdhaghoshdastidar/Desktop/CS540/classeval_evaluation/ClassEval_92_3.py", line 255, in test_delete_user_by_username_5
    self.assertIsNone(user)
AssertionError: [] is not None

----------------------------------------------------------------------
Ran 5 tests in 0.028s

FAILED (failures=5)
.....
----------------------------------------------------------------------
Ran 5 tests in 0.018s

OK
F
======================================================================
FAIL: test_UserLoginDB (ClassEval_92_3.UserLoginDBTest.test_UserLoginDB)
----------------------------------------------------------------------
Traceback (most recent call last):
  File "/Users/snigdhaghoshdastidar/Desktop/CS540/classeval_evaluation/ClassEval_92_3.py", line 329, in test_UserLoginDB
    self.assertEqual(user[0], 'user1')
AssertionError: ('user1', 'pass1') != 'user1'

----------------------------------------------------------------------
Ran 1 test in 0.004s

FAILED (failures=1)
FFFFF
======================================================================
FAIL: test_insert_user_1 (ClassEval_92_4.UserLoginDBTestInsertUser.test_insert_user_1)
----------------------------------------------------------------------
Traceback (most recent call last):
  File "/Users/snigdhaghoshdastidar/Desktop/CS540/classeval_evaluation/ClassEval_92_4.py", line 60, in test_insert_user_1
    self.assertEqual(user[0], 'user1')
AssertionError: ('user1', 'pass1') != 'user1'

======================================================================
FAIL: test_insert_user_2 (ClassEval_92_4.UserLoginDBTestInsertUser.test_insert_user_2)
----------------------------------------------------------------------
Traceback (most recent call last):
  File "/Users/snigdhaghoshdastidar/Desktop/CS540/classeval_evaluation/ClassEval_92_4.py", line 67, in test_insert_user_2
    self.assertEqual(user[0], 'user2')
AssertionError: ('user2', 'pass2') != 'user2'

======================================================================
FAIL: test_insert_user_3 (ClassEval_92_4.UserLoginDBTestInsertUser.test_insert_user_3)
----------------------------------------------------------------------
Traceback (most recent call last):
  File "/Users/snigdhaghoshdastidar/Desktop/CS540/classeval_evaluation/ClassEval_92_4.py", line 74, in test_insert_user_3
    self.assertEqual(user[0], 'user3')
AssertionError: ('user3', 'pass3') != 'user3'

======================================================================
FAIL: test_insert_user_4 (ClassEval_92_4.UserLoginDBTestInsertUser.test_insert_user_4)
----------------------------------------------------------------------
Traceback (most recent call last):
  File "/Users/snigdhaghoshdastidar/Desktop/CS540/classeval_evaluation/ClassEval_92_4.py", line 81, in test_insert_user_4
    self.assertEqual(user[0], 'user4')
AssertionError: ('user4', 'pass4') != 'user4'

======================================================================
FAIL: test_insert_user_5 (ClassEval_92_4.UserLoginDBTestInsertUser.test_insert_user_5)
----------------------------------------------------------------------
Traceback (most recent call last):
  File "/Users/snigdhaghoshdastidar/Desktop/CS540/classeval_evaluation/ClassEval_92_4.py", line 88, in test_insert_user_5
    self.assertEqual(user[0], 'user5')
AssertionError: ('user5', 'pass5') != 'user5'

----------------------------------------------------------------------
Ran 5 tests in 0.022s

FAILED (failures=5)
FFFFF
======================================================================
FAIL: test_search_user_by_username_1 (ClassEval_92_4.UserLoginDBTestSearchUserByUsername.test_search_user_by_username_1)
----------------------------------------------------------------------
Traceback (most recent call last):
  File "/Users/snigdhaghoshdastidar/Desktop/CS540/classeval_evaluation/ClassEval_92_4.py", line 117, in test_search_user_by_username_1
    self.assertEqual(user[0], 'user1')
AssertionError: ('user1', 'pass1') != 'user1'

======================================================================
FAIL: test_search_user_by_username_2 (ClassEval_92_4.UserLoginDBTestSearchUserByUsername.test_search_user_by_username_2)
----------------------------------------------------------------------
Traceback (most recent call last):
  File "/Users/snigdhaghoshdastidar/Desktop/CS540/classeval_evaluation/ClassEval_92_4.py", line 124, in test_search_user_by_username_2
    self.assertEqual(user[0], 'user2')
AssertionError: ('user2', 'pass2') != 'user2'

======================================================================
FAIL: test_search_user_by_username_3 (ClassEval_92_4.UserLoginDBTestSearchUserByUsername.test_search_user_by_username_3)
----------------------------------------------------------------------
Traceback (most recent call last):
  File "/Users/snigdhaghoshdastidar/Desktop/CS540/classeval_evaluation/ClassEval_92_4.py", line 131, in test_search_user_by_username_3
    self.assertEqual(user[0], 'user3')
AssertionError: ('user3', 'pass3') != 'user3'

======================================================================
FAIL: test_search_user_by_username_4 (ClassEval_92_4.UserLoginDBTestSearchUserByUsername.test_search_user_by_username_4)
----------------------------------------------------------------------
Traceback (most recent call last):
  File "/Users/snigdhaghoshdastidar/Desktop/CS540/classeval_evaluation/ClassEval_92_4.py", line 138, in test_search_user_by_username_4
    self.assertEqual(user[0], 'user4')
AssertionError: ('user4', 'pass4') != 'user4'

======================================================================
FAIL: test_search_user_by_username_5 (ClassEval_92_4.UserLoginDBTestSearchUserByUsername.test_search_user_by_username_5)
----------------------------------------------------------------------
Traceback (most recent call last):
  File "/Users/snigdhaghoshdastidar/Desktop/CS540/classeval_evaluation/ClassEval_92_4.py", line 145, in test_search_user_by_username_5
    self.assertEqual(user[0], 'user5')
AssertionError: ('user5', 'pass5') != 'user5'

----------------------------------------------------------------------
Ran 5 tests in 0.019s

FAILED (failures=5)
FFFFF
======================================================================
FAIL: test_delete_user_by_username_1 (ClassEval_92_4.UserLoginDBTestDeleteUserByUsername.test_delete_user_by_username_1)
----------------------------------------------------------------------
Traceback (most recent call last):
  File "/Users/snigdhaghoshdastidar/Desktop/CS540/classeval_evaluation/ClassEval_92_4.py", line 174, in test_delete_user_by_username_1
    self.assertIsNone(user)
AssertionError: [] is not None

======================================================================
FAIL: test_delete_user_by_username_2 (ClassEval_92_4.UserLoginDBTestDeleteUserByUsername.test_delete_user_by_username_2)
----------------------------------------------------------------------
Traceback (most recent call last):
  File "/Users/snigdhaghoshdastidar/Desktop/CS540/classeval_evaluation/ClassEval_92_4.py", line 180, in test_delete_user_by_username_2
    self.assertIsNone(user)
AssertionError: [] is not None

======================================================================
FAIL: test_delete_user_by_username_3 (ClassEval_92_4.UserLoginDBTestDeleteUserByUsername.test_delete_user_by_username_3)
----------------------------------------------------------------------
Traceback (most recent call last):
  File "/Users/snigdhaghoshdastidar/Desktop/CS540/classeval_evaluation/ClassEval_92_4.py", line 186, in test_delete_user_by_username_3
    self.assertIsNone(user)
AssertionError: [] is not None

======================================================================
FAIL: test_delete_user_by_username_4 (ClassEval_92_4.UserLoginDBTestDeleteUserByUsername.test_delete_user_by_username_4)
----------------------------------------------------------------------
Traceback (most recent call last):
  File "/Users/snigdhaghoshdastidar/Desktop/CS540/classeval_evaluation/ClassEval_92_4.py", line 192, in test_delete_user_by_username_4
    self.assertIsNone(user)
AssertionError: [] is not None

======================================================================
FAIL: test_delete_user_by_username_5 (ClassEval_92_4.UserLoginDBTestDeleteUserByUsername.test_delete_user_by_username_5)
----------------------------------------------------------------------
Traceback (most recent call last):
  File "/Users/snigdhaghoshdastidar/Desktop/CS540/classeval_evaluation/ClassEval_92_4.py", line 198, in test_delete_user_by_username_5
    self.assertIsNone(user)
AssertionError: [] is not None

----------------------------------------------------------------------
Ran 5 tests in 0.025s

FAILED (failures=5)
EE.EE
======================================================================
ERROR: test_validate_user_login_1 (ClassEval_92_4.UserLoginDBTestValidateUserLogin.test_validate_user_login_1)
----------------------------------------------------------------------
Traceback (most recent call last):
  File "/Users/snigdhaghoshdastidar/Desktop/CS540/classeval_evaluation/ClassEval_92_4.py", line 224, in test_validate_user_login_1
    valid = self.db.validate_user_login('user1', 'pass1')
            ^^^^^^^^^^^^^^^^^^^^^^^^^^^^^^^^^^^^^^^^^^^^^
  File "/Users/snigdhaghoshdastidar/Desktop/CS540/classeval_evaluation/ClassEval_92_4.py", line 26, in validate_user_login
    if user and user[2] == password:
                ~~~~^^^
IndexError: tuple index out of range

======================================================================
ERROR: test_validate_user_login_2 (ClassEval_92_4.UserLoginDBTestValidateUserLogin.test_validate_user_login_2)
----------------------------------------------------------------------
Traceback (most recent call last):
  File "/Users/snigdhaghoshdastidar/Desktop/CS540/classeval_evaluation/ClassEval_92_4.py", line 229, in test_validate_user_login_2
    invalid = self.db.validate_user_login('user1', 'wrongpass')
              ^^^^^^^^^^^^^^^^^^^^^^^^^^^^^^^^^^^^^^^^^^^^^^^^^
  File "/Users/snigdhaghoshdastidar/Desktop/CS540/classeval_evaluation/ClassEval_92_4.py", line 26, in validate_user_login
    if user and user[2] == password:
                ~~~~^^^
IndexError: tuple index out of range

======================================================================
ERROR: test_validate_user_login_4 (ClassEval_92_4.UserLoginDBTestValidateUserLogin.test_validate_user_login_4)
----------------------------------------------------------------------
Traceback (most recent call last):
  File "/Users/snigdhaghoshdastidar/Desktop/CS540/classeval_evaluation/ClassEval_92_4.py", line 238, in test_validate_user_login_4
    valid = self.db.validate_user_login('user2', 'pass2')
            ^^^^^^^^^^^^^^^^^^^^^^^^^^^^^^^^^^^^^^^^^^^^^
  File "/Users/snigdhaghoshdastidar/Desktop/CS540/classeval_evaluation/ClassEval_92_4.py", line 26, in validate_user_login
    if user and user[2] == password:
                ~~~~^^^
IndexError: tuple index out of range

======================================================================
ERROR: test_validate_user_login_5 (ClassEval_92_4.UserLoginDBTestValidateUserLogin.test_validate_user_login_5)
----------------------------------------------------------------------
Traceback (most recent call last):
  File "/Users/snigdhaghoshdastidar/Desktop/CS540/classeval_evaluation/ClassEval_92_4.py", line 243, in test_validate_user_login_5
    valid = self.db.validate_user_login('user3', 'pass3')
            ^^^^^^^^^^^^^^^^^^^^^^^^^^^^^^^^^^^^^^^^^^^^^
  File "/Users/snigdhaghoshdastidar/Desktop/CS540/classeval_evaluation/ClassEval_92_4.py", line 26, in validate_user_login
    if user and user[2] == password:
                ~~~~^^^
IndexError: tuple index out of range

----------------------------------------------------------------------
Ran 5 tests in 0.019s

FAILED (errors=4)
F
======================================================================
FAIL: test_UserLoginDB (ClassEval_92_4.UserLoginDBTest.test_UserLoginDB)
----------------------------------------------------------------------
Traceback (most recent call last):
  File "/Users/snigdhaghoshdastidar/Desktop/CS540/classeval_evaluation/ClassEval_92_4.py", line 272, in test_UserLoginDB
    self.assertEqual(user[0], 'user1')
AssertionError: ('user1', 'pass1') != 'user1'

----------------------------------------------------------------------
Ran 1 test in 0.004s

FAILED (failures=1)
