.F
======================================================================
FAIL: test_create_table_2 (ClassEval_14_0.BookManagementDBTestCreateTable.test_create_table_2)
----------------------------------------------------------------------
Traceback (most recent call last):
  File "/Users/snigdhaghoshdastidar/Desktop/CS540/classeval_evaluation/ClassEval_14_0.py", line 98, in test_create_table_2
    self.assertEqual(column_names, expected_column_names)
AssertionError: Lists differ: ['book_id', 'title', 'author', 'availability'] != ['id', 'title', 'author', 'available']

First differing element 0:
'book_id'
'id'

- ['book_id', 'title', 'author', 'availability']
?   -----                                - ^^^

+ ['id', 'title', 'author', 'available']
?                                    ^


----------------------------------------------------------------------
Ran 2 tests in 0.006s

FAILED (failures=1)
E
======================================================================
ERROR: test_add_book (ClassEval_14_0.BookManagementDBTestAddBook.test_add_book)
----------------------------------------------------------------------
Traceback (most recent call last):
  File "/Users/snigdhaghoshdastidar/Desktop/CS540/classeval_evaluation/ClassEval_14_0.py", line 120, in test_add_book
    self.cursor.execute("SELECT title, author, available FROM books WHERE id=1")
sqlite3.OperationalError: no such column: available

----------------------------------------------------------------------
Ran 1 test in 0.004s

FAILED (errors=1)
E
======================================================================
ERROR: test_remove_book (ClassEval_14_0.BookManagementDBTestRemoveBook.test_remove_book)
----------------------------------------------------------------------
Traceback (most recent call last):
  File "/Users/snigdhaghoshdastidar/Desktop/CS540/classeval_evaluation/ClassEval_14_0.py", line 147, in test_remove_book
    self.cursor.execute("SELECT * FROM books WHERE id=1")
sqlite3.OperationalError: no such column: id

----------------------------------------------------------------------
Ran 1 test in 0.005s

FAILED (errors=1)
E
======================================================================
ERROR: test_borrow_book (ClassEval_14_0.BookManagementDBTestBorrowBook.test_borrow_book)
----------------------------------------------------------------------
Traceback (most recent call last):
  File "/Users/snigdhaghoshdastidar/Desktop/CS540/classeval_evaluation/ClassEval_14_0.py", line 171, in test_borrow_book
    self.cursor.execute("SELECT available FROM books WHERE id=1")
sqlite3.OperationalError: no such column: available

----------------------------------------------------------------------
Ran 1 test in 0.004s

FAILED (errors=1)
E
======================================================================
ERROR: test_return_book (ClassEval_14_0.BookManagementDBTestReturnBook.test_return_book)
----------------------------------------------------------------------
Traceback (most recent call last):
  File "/Users/snigdhaghoshdastidar/Desktop/CS540/classeval_evaluation/ClassEval_14_0.py", line 196, in test_return_book
    self.cursor.execute("SELECT available FROM books WHERE id=1")
sqlite3.OperationalError: no such column: available

----------------------------------------------------------------------
Ran 1 test in 0.006s

FAILED (errors=1)
.
----------------------------------------------------------------------
Ran 1 test in 0.009s

OK
.....
----------------------------------------------------------------------
Ran 5 tests in 0.012s

OK
EEEEE
======================================================================
ERROR: test_insert_into_database_1 (ClassEval_28_0.DatabaseProcessorTestInsertIntoDatabase.test_insert_into_database_1)
----------------------------------------------------------------------
Traceback (most recent call last):
  File "/Users/snigdhaghoshdastidar/Desktop/CS540/classeval_evaluation/ClassEval_28_0.py", line 189, in test_insert_into_database_1
    self.processor.insert_into_database(table_name, data)
  File "/Users/snigdhaghoshdastidar/Desktop/CS540/classeval_evaluation/ClassEval_28_0.py", line 52, in insert_into_database
    INSERT INTO {table_name} ({item.keys()[0]}, {item.keys()[1]})
                               ~~~~~~~~~~~^^^
TypeError: 'dict_keys' object is not subscriptable

======================================================================
ERROR: test_insert_into_database_2 (ClassEval_28_0.DatabaseProcessorTestInsertIntoDatabase.test_insert_into_database_2)
----------------------------------------------------------------------
Traceback (most recent call last):
  File "/Users/snigdhaghoshdastidar/Desktop/CS540/classeval_evaluation/ClassEval_28_0.py", line 206, in test_insert_into_database_2
    self.processor.insert_into_database(table_name, data)
  File "/Users/snigdhaghoshdastidar/Desktop/CS540/classeval_evaluation/ClassEval_28_0.py", line 52, in insert_into_database
    INSERT INTO {table_name} ({item.keys()[0]}, {item.keys()[1]})
                               ~~~~~~~~~~~^^^
TypeError: 'dict_keys' object is not subscriptable

======================================================================
ERROR: test_insert_into_database_3 (ClassEval_28_0.DatabaseProcessorTestInsertIntoDatabase.test_insert_into_database_3)
----------------------------------------------------------------------
Traceback (most recent call last):
  File "/Users/snigdhaghoshdastidar/Desktop/CS540/classeval_evaluation/ClassEval_28_0.py", line 223, in test_insert_into_database_3
    self.processor.insert_into_database(table_name, data)
  File "/Users/snigdhaghoshdastidar/Desktop/CS540/classeval_evaluation/ClassEval_28_0.py", line 52, in insert_into_database
    INSERT INTO {table_name} ({item.keys()[0]}, {item.keys()[1]})
                               ~~~~~~~~~~~^^^
TypeError: 'dict_keys' object is not subscriptable

======================================================================
ERROR: test_insert_into_database_4 (ClassEval_28_0.DatabaseProcessorTestInsertIntoDatabase.test_insert_into_database_4)
----------------------------------------------------------------------
Traceback (most recent call last):
  File "/Users/snigdhaghoshdastidar/Desktop/CS540/classeval_evaluation/ClassEval_28_0.py", line 240, in test_insert_into_database_4
    self.processor.insert_into_database(table_name, data)
  File "/Users/snigdhaghoshdastidar/Desktop/CS540/classeval_evaluation/ClassEval_28_0.py", line 52, in insert_into_database
    INSERT INTO {table_name} ({item.keys()[0]}, {item.keys()[1]})
                               ~~~~~~~~~~~^^^
TypeError: 'dict_keys' object is not subscriptable

======================================================================
ERROR: test_insert_into_database_5 (ClassEval_28_0.DatabaseProcessorTestInsertIntoDatabase.test_insert_into_database_5)
----------------------------------------------------------------------
Traceback (most recent call last):
  File "/Users/snigdhaghoshdastidar/Desktop/CS540/classeval_evaluation/ClassEval_28_0.py", line 257, in test_insert_into_database_5
    self.processor.insert_into_database(table_name, data)
  File "/Users/snigdhaghoshdastidar/Desktop/CS540/classeval_evaluation/ClassEval_28_0.py", line 52, in insert_into_database
    INSERT INTO {table_name} ({item.keys()[0]}, {item.keys()[1]})
                               ~~~~~~~~~~~^^^
TypeError: 'dict_keys' object is not subscriptable

----------------------------------------------------------------------
Ran 5 tests in 0.018s

FAILED (errors=5)
EEEEE
======================================================================
ERROR: test_search_database_1 (ClassEval_28_0.DatabaseProcessorTestSearchDatabase.test_search_database_1)
----------------------------------------------------------------------
Traceback (most recent call last):
  File "/Users/snigdhaghoshdastidar/Desktop/CS540/classeval_evaluation/ClassEval_28_0.py", line 287, in test_search_database_1
    self.processor.insert_into_database(table_name, data)
  File "/Users/snigdhaghoshdastidar/Desktop/CS540/classeval_evaluation/ClassEval_28_0.py", line 52, in insert_into_database
    INSERT INTO {table_name} ({item.keys()[0]}, {item.keys()[1]})
                               ~~~~~~~~~~~^^^
TypeError: 'dict_keys' object is not subscriptable

======================================================================
ERROR: test_search_database_2 (ClassEval_28_0.DatabaseProcessorTestSearchDatabase.test_search_database_2)
----------------------------------------------------------------------
Traceback (most recent call last):
  File "/Users/snigdhaghoshdastidar/Desktop/CS540/classeval_evaluation/ClassEval_28_0.py", line 301, in test_search_database_2
    self.processor.insert_into_database(table_name, data)
  File "/Users/snigdhaghoshdastidar/Desktop/CS540/classeval_evaluation/ClassEval_28_0.py", line 52, in insert_into_database
    INSERT INTO {table_name} ({item.keys()[0]}, {item.keys()[1]})
                               ~~~~~~~~~~~^^^
TypeError: 'dict_keys' object is not subscriptable

======================================================================
ERROR: test_search_database_3 (ClassEval_28_0.DatabaseProcessorTestSearchDatabase.test_search_database_3)
----------------------------------------------------------------------
Traceback (most recent call last):
  File "/Users/snigdhaghoshdastidar/Desktop/CS540/classeval_evaluation/ClassEval_28_0.py", line 315, in test_search_database_3
    self.processor.insert_into_database(table_name, data)
  File "/Users/snigdhaghoshdastidar/Desktop/CS540/classeval_evaluation/ClassEval_28_0.py", line 52, in insert_into_database
    INSERT INTO {table_name} ({item.keys()[0]}, {item.keys()[1]})
                               ~~~~~~~~~~~^^^
TypeError: 'dict_keys' object is not subscriptable

======================================================================
ERROR: test_search_database_4 (ClassEval_28_0.DatabaseProcessorTestSearchDatabase.test_search_database_4)
----------------------------------------------------------------------
Traceback (most recent call last):
  File "/Users/snigdhaghoshdastidar/Desktop/CS540/classeval_evaluation/ClassEval_28_0.py", line 327, in test_search_database_4
    self.processor.insert_into_database(table_name, data)
  File "/Users/snigdhaghoshdastidar/Desktop/CS540/classeval_evaluation/ClassEval_28_0.py", line 52, in insert_into_database
    INSERT INTO {table_name} ({item.keys()[0]}, {item.keys()[1]})
                               ~~~~~~~~~~~^^^
TypeError: 'dict_keys' object is not subscriptable

======================================================================
ERROR: test_search_database_5 (ClassEval_28_0.DatabaseProcessorTestSearchDatabase.test_search_database_5)
----------------------------------------------------------------------
Traceback (most recent call last):
  File "/Users/snigdhaghoshdastidar/Desktop/CS540/classeval_evaluation/ClassEval_28_0.py", line 339, in test_search_database_5
    self.processor.insert_into_database(table_name, data)
  File "/Users/snigdhaghoshdastidar/Desktop/CS540/classeval_evaluation/ClassEval_28_0.py", line 52, in insert_into_database
    INSERT INTO {table_name} ({item.keys()[0]}, {item.keys()[1]})
                               ~~~~~~~~~~~^^^
TypeError: 'dict_keys' object is not subscriptable

----------------------------------------------------------------------
Ran 5 tests in 0.031s

FAILED (errors=5)
EEEEE
======================================================================
ERROR: test_delete_from_database_1 (ClassEval_28_0.DatabaseProcessorTestDeteleFromDatabase.test_delete_from_database_1)
----------------------------------------------------------------------
Traceback (most recent call last):
  File "/Users/snigdhaghoshdastidar/Desktop/CS540/classeval_evaluation/ClassEval_28_0.py", line 364, in test_delete_from_database_1
    self.processor.insert_into_database(table_name, data)
  File "/Users/snigdhaghoshdastidar/Desktop/CS540/classeval_evaluation/ClassEval_28_0.py", line 52, in insert_into_database
    INSERT INTO {table_name} ({item.keys()[0]}, {item.keys()[1]})
                               ~~~~~~~~~~~^^^
TypeError: 'dict_keys' object is not subscriptable

======================================================================
ERROR: test_delete_from_database_2 (ClassEval_28_0.DatabaseProcessorTestDeteleFromDatabase.test_delete_from_database_2)
----------------------------------------------------------------------
Traceback (most recent call last):
  File "/Users/snigdhaghoshdastidar/Desktop/CS540/classeval_evaluation/ClassEval_28_0.py", line 384, in test_delete_from_database_2
    self.processor.insert_into_database(table_name, data)
  File "/Users/snigdhaghoshdastidar/Desktop/CS540/classeval_evaluation/ClassEval_28_0.py", line 52, in insert_into_database
    INSERT INTO {table_name} ({item.keys()[0]}, {item.keys()[1]})
                               ~~~~~~~~~~~^^^
TypeError: 'dict_keys' object is not subscriptable

======================================================================
ERROR: test_delete_from_database_3 (ClassEval_28_0.DatabaseProcessorTestDeteleFromDatabase.test_delete_from_database_3)
----------------------------------------------------------------------
Traceback (most recent call last):
  File "/Users/snigdhaghoshdastidar/Desktop/CS540/classeval_evaluation/ClassEval_28_0.py", line 404, in test_delete_from_database_3
    self.processor.insert_into_database(table_name, data)
  File "/Users/snigdhaghoshdastidar/Desktop/CS540/classeval_evaluation/ClassEval_28_0.py", line 52, in insert_into_database
    INSERT INTO {table_name} ({item.keys()[0]}, {item.keys()[1]})
                               ~~~~~~~~~~~^^^
TypeError: 'dict_keys' object is not subscriptable

======================================================================
ERROR: test_delete_from_database_4 (ClassEval_28_0.DatabaseProcessorTestDeteleFromDatabase.test_delete_from_database_4)
----------------------------------------------------------------------
Traceback (most recent call last):
  File "/Users/snigdhaghoshdastidar/Desktop/CS540/classeval_evaluation/ClassEval_28_0.py", line 424, in test_delete_from_database_4
    self.processor.insert_into_database(table_name, data)
  File "/Users/snigdhaghoshdastidar/Desktop/CS540/classeval_evaluation/ClassEval_28_0.py", line 52, in insert_into_database
    INSERT INTO {table_name} ({item.keys()[0]}, {item.keys()[1]})
                               ~~~~~~~~~~~^^^
TypeError: 'dict_keys' object is not subscriptable

======================================================================
ERROR: test_delete_from_database_5 (ClassEval_28_0.DatabaseProcessorTestDeteleFromDatabase.test_delete_from_database_5)
----------------------------------------------------------------------
Traceback (most recent call last):
  File "/Users/snigdhaghoshdastidar/Desktop/CS540/classeval_evaluation/ClassEval_28_0.py", line 444, in test_delete_from_database_5
    self.processor.insert_into_database(table_name, data)
  File "/Users/snigdhaghoshdastidar/Desktop/CS540/classeval_evaluation/ClassEval_28_0.py", line 52, in insert_into_database
    INSERT INTO {table_name} ({item.keys()[0]}, {item.keys()[1]})
                               ~~~~~~~~~~~^^^
TypeError: 'dict_keys' object is not subscriptable

----------------------------------------------------------------------
Ran 5 tests in 0.018s

FAILED (errors=5)
E
======================================================================
ERROR: test_DatabaseProcessor (ClassEval_28_0.DatabaseProcessorTest.test_DatabaseProcessor)
----------------------------------------------------------------------
Traceback (most recent call last):
  File "/Users/snigdhaghoshdastidar/Desktop/CS540/classeval_evaluation/ClassEval_28_0.py", line 487, in test_DatabaseProcessor
    self.processor.insert_into_database(table_name, data)
  File "/Users/snigdhaghoshdastidar/Desktop/CS540/classeval_evaluation/ClassEval_28_0.py", line 52, in insert_into_database
    INSERT INTO {table_name} ({item.keys()[0]}, {item.keys()[1]})
                               ~~~~~~~~~~~^^^
TypeError: 'dict_keys' object is not subscriptable

----------------------------------------------------------------------
Ran 1 test in 0.008s

FAILED (errors=1)
.....
----------------------------------------------------------------------
Ran 5 tests in 0.022s

OK
.....
----------------------------------------------------------------------
Ran 5 tests in 0.016s

OK
.....
----------------------------------------------------------------------
Ran 5 tests in 0.021s

OK
.
----------------------------------------------------------------------
Ran 1 test in 0.005s

OK
......
----------------------------------------------------------------------
Ran 6 tests in 0.000s

OK
.....
----------------------------------------------------------------------
Ran 5 tests in 0.000s

OK
.....
----------------------------------------------------------------------
Ran 5 tests in 0.000s

OK
.....
----------------------------------------------------------------------
Ran 5 tests in 0.000s

OK
.....
----------------------------------------------------------------------
Ran 5 tests in 0.000s

OK
.....
----------------------------------------------------------------------
Ran 5 tests in 0.000s

OK
.
----------------------------------------------------------------------
Ran 1 test in 0.000s

OK
.......
----------------------------------------------------------------------
Ran 7 tests in 0.000s

OK
.....
----------------------------------------------------------------------
Ran 5 tests in 0.000s

OK
......
----------------------------------------------------------------------
Ran 6 tests in 0.000s

OK
......
----------------------------------------------------------------------
Ran 6 tests in 0.000s

OK
.
----------------------------------------------------------------------
Ran 1 test in 0.000s

OK
.....
----------------------------------------------------------------------
Ran 5 tests in 0.054s

OK
.....
----------------------------------------------------------------------
Ran 5 tests in 0.023s

OK
.....
----------------------------------------------------------------------
Ran 5 tests in 0.033s

OK
.
----------------------------------------------------------------------
Ran 1 test in 0.009s

OK
FFFFF
======================================================================
FAIL: test_insert_user_1 (ClassEval_92_0.UserLoginDBTestInsertUser.test_insert_user_1)
----------------------------------------------------------------------
Traceback (most recent call last):
  File "/Users/snigdhaghoshdastidar/Desktop/CS540/classeval_evaluation/ClassEval_92_0.py", line 93, in test_insert_user_1
    self.assertEqual(user[0], 'user1')
AssertionError: ('user1', 'pass1') != 'user1'

======================================================================
FAIL: test_insert_user_2 (ClassEval_92_0.UserLoginDBTestInsertUser.test_insert_user_2)
----------------------------------------------------------------------
Traceback (most recent call last):
  File "/Users/snigdhaghoshdastidar/Desktop/CS540/classeval_evaluation/ClassEval_92_0.py", line 100, in test_insert_user_2
    self.assertEqual(user[0], 'user2')
AssertionError: ('user2', 'pass2') != 'user2'

======================================================================
FAIL: test_insert_user_3 (ClassEval_92_0.UserLoginDBTestInsertUser.test_insert_user_3)
----------------------------------------------------------------------
Traceback (most recent call last):
  File "/Users/snigdhaghoshdastidar/Desktop/CS540/classeval_evaluation/ClassEval_92_0.py", line 107, in test_insert_user_3
    self.assertEqual(user[0], 'user3')
AssertionError: ('user3', 'pass3') != 'user3'

======================================================================
FAIL: test_insert_user_4 (ClassEval_92_0.UserLoginDBTestInsertUser.test_insert_user_4)
----------------------------------------------------------------------
Traceback (most recent call last):
  File "/Users/snigdhaghoshdastidar/Desktop/CS540/classeval_evaluation/ClassEval_92_0.py", line 114, in test_insert_user_4
    self.assertEqual(user[0], 'user4')
AssertionError: ('user4', 'pass4') != 'user4'

======================================================================
FAIL: test_insert_user_5 (ClassEval_92_0.UserLoginDBTestInsertUser.test_insert_user_5)
----------------------------------------------------------------------
Traceback (most recent call last):
  File "/Users/snigdhaghoshdastidar/Desktop/CS540/classeval_evaluation/ClassEval_92_0.py", line 121, in test_insert_user_5
    self.assertEqual(user[0], 'user5')
AssertionError: ('user5', 'pass5') != 'user5'

----------------------------------------------------------------------
Ran 5 tests in 0.021s

FAILED (failures=5)
FFFFF
======================================================================
FAIL: test_search_user_by_username_1 (ClassEval_92_0.UserLoginDBTestSearchUserByUsername.test_search_user_by_username_1)
----------------------------------------------------------------------
Traceback (most recent call last):
  File "/Users/snigdhaghoshdastidar/Desktop/CS540/classeval_evaluation/ClassEval_92_0.py", line 150, in test_search_user_by_username_1
    self.assertEqual(user[0], 'user1')
AssertionError: ('user1', 'pass1') != 'user1'

======================================================================
FAIL: test_search_user_by_username_2 (ClassEval_92_0.UserLoginDBTestSearchUserByUsername.test_search_user_by_username_2)
----------------------------------------------------------------------
Traceback (most recent call last):
  File "/Users/snigdhaghoshdastidar/Desktop/CS540/classeval_evaluation/ClassEval_92_0.py", line 157, in test_search_user_by_username_2
    self.assertEqual(user[0], 'user2')
AssertionError: ('user2', 'pass2') != 'user2'

======================================================================
FAIL: test_search_user_by_username_3 (ClassEval_92_0.UserLoginDBTestSearchUserByUsername.test_search_user_by_username_3)
----------------------------------------------------------------------
Traceback (most recent call last):
  File "/Users/snigdhaghoshdastidar/Desktop/CS540/classeval_evaluation/ClassEval_92_0.py", line 164, in test_search_user_by_username_3
    self.assertEqual(user[0], 'user3')
AssertionError: ('user3', 'pass3') != 'user3'

======================================================================
FAIL: test_search_user_by_username_4 (ClassEval_92_0.UserLoginDBTestSearchUserByUsername.test_search_user_by_username_4)
----------------------------------------------------------------------
Traceback (most recent call last):
  File "/Users/snigdhaghoshdastidar/Desktop/CS540/classeval_evaluation/ClassEval_92_0.py", line 171, in test_search_user_by_username_4
    self.assertEqual(user[0], 'user4')
AssertionError: ('user4', 'pass4') != 'user4'

======================================================================
FAIL: test_search_user_by_username_5 (ClassEval_92_0.UserLoginDBTestSearchUserByUsername.test_search_user_by_username_5)
----------------------------------------------------------------------
Traceback (most recent call last):
  File "/Users/snigdhaghoshdastidar/Desktop/CS540/classeval_evaluation/ClassEval_92_0.py", line 178, in test_search_user_by_username_5
    self.assertEqual(user[0], 'user5')
AssertionError: ('user5', 'pass5') != 'user5'

----------------------------------------------------------------------
Ran 5 tests in 0.019s

FAILED (failures=5)
FFFFF
======================================================================
FAIL: test_delete_user_by_username_1 (ClassEval_92_0.UserLoginDBTestDeleteUserByUsername.test_delete_user_by_username_1)
----------------------------------------------------------------------
Traceback (most recent call last):
  File "/Users/snigdhaghoshdastidar/Desktop/CS540/classeval_evaluation/ClassEval_92_0.py", line 207, in test_delete_user_by_username_1
    self.assertIsNone(user)
AssertionError: [] is not None

======================================================================
FAIL: test_delete_user_by_username_2 (ClassEval_92_0.UserLoginDBTestDeleteUserByUsername.test_delete_user_by_username_2)
----------------------------------------------------------------------
Traceback (most recent call last):
  File "/Users/snigdhaghoshdastidar/Desktop/CS540/classeval_evaluation/ClassEval_92_0.py", line 213, in test_delete_user_by_username_2
    self.assertIsNone(user)
AssertionError: [] is not None

======================================================================
FAIL: test_delete_user_by_username_3 (ClassEval_92_0.UserLoginDBTestDeleteUserByUsername.test_delete_user_by_username_3)
----------------------------------------------------------------------
Traceback (most recent call last):
  File "/Users/snigdhaghoshdastidar/Desktop/CS540/classeval_evaluation/ClassEval_92_0.py", line 219, in test_delete_user_by_username_3
    self.assertIsNone(user)
AssertionError: [] is not None

======================================================================
FAIL: test_delete_user_by_username_4 (ClassEval_92_0.UserLoginDBTestDeleteUserByUsername.test_delete_user_by_username_4)
----------------------------------------------------------------------
Traceback (most recent call last):
  File "/Users/snigdhaghoshdastidar/Desktop/CS540/classeval_evaluation/ClassEval_92_0.py", line 225, in test_delete_user_by_username_4
    self.assertIsNone(user)
AssertionError: [] is not None

======================================================================
FAIL: test_delete_user_by_username_5 (ClassEval_92_0.UserLoginDBTestDeleteUserByUsername.test_delete_user_by_username_5)
----------------------------------------------------------------------
Traceback (most recent call last):
  File "/Users/snigdhaghoshdastidar/Desktop/CS540/classeval_evaluation/ClassEval_92_0.py", line 231, in test_delete_user_by_username_5
    self.assertIsNone(user)
AssertionError: [] is not None

----------------------------------------------------------------------
Ran 5 tests in 0.023s

FAILED (failures=5)
.....
----------------------------------------------------------------------
Ran 5 tests in 0.015s

OK
F
======================================================================
FAIL: test_UserLoginDB (ClassEval_92_0.UserLoginDBTest.test_UserLoginDB)
----------------------------------------------------------------------
Traceback (most recent call last):
  File "/Users/snigdhaghoshdastidar/Desktop/CS540/classeval_evaluation/ClassEval_92_0.py", line 305, in test_UserLoginDB
    self.assertEqual(user[0], 'user1')
AssertionError: ('user1', 'pass1') != 'user1'

----------------------------------------------------------------------
Ran 1 test in 0.003s

FAILED (failures=1)
