..
----------------------------------------------------------------------
Ran 2 tests in 0.006s

OK
.
----------------------------------------------------------------------
Ran 1 test in 0.004s

OK
.
----------------------------------------------------------------------
Ran 1 test in 0.005s

OK
.
----------------------------------------------------------------------
Ran 1 test in 0.004s

OK
.
----------------------------------------------------------------------
Ran 1 test in 0.005s

OK
.
----------------------------------------------------------------------
Ran 1 test in 0.005s

OK
.F
======================================================================
FAIL: test_create_table_2 (ClassEval_14_1.BookManagementDBTestCreateTable.test_create_table_2)
----------------------------------------------------------------------
Traceback (most recent call last):
  File "/Users/snigdhaghoshdastidar/Desktop/CS540/classeval_evaluation/ClassEval_14_1.py", line 80, in test_create_table_2
    self.assertEqual(column_names, expected_column_names)
AssertionError: Lists differ: ['id', 'title', 'author', 'availability'] != ['id', 'title', 'author', 'available']

First differing element 3:
'availability'
'available'

- ['id', 'title', 'author', 'availability']
?                                   - ^^^

+ ['id', 'title', 'author', 'available']
?                                    ^


----------------------------------------------------------------------
Ran 2 tests in 0.005s

FAILED (failures=1)
E
======================================================================
ERROR: test_add_book (ClassEval_14_1.BookManagementDBTestAddBook.test_add_book)
----------------------------------------------------------------------
Traceback (most recent call last):
  File "/Users/snigdhaghoshdastidar/Desktop/CS540/classeval_evaluation/ClassEval_14_1.py", line 102, in test_add_book
    self.cursor.execute("SELECT title, author, available FROM books WHERE id=1")
sqlite3.OperationalError: no such column: available

----------------------------------------------------------------------
Ran 1 test in 0.004s

FAILED (errors=1)
.
----------------------------------------------------------------------
Ran 1 test in 0.004s

OK
E
======================================================================
ERROR: test_borrow_book (ClassEval_14_1.BookManagementDBTestBorrowBook.test_borrow_book)
----------------------------------------------------------------------
Traceback (most recent call last):
  File "/Users/snigdhaghoshdastidar/Desktop/CS540/classeval_evaluation/ClassEval_14_1.py", line 153, in test_borrow_book
    self.cursor.execute("SELECT available FROM books WHERE id=1")
sqlite3.OperationalError: no such column: available

----------------------------------------------------------------------
Ran 1 test in 0.005s

FAILED (errors=1)
E
======================================================================
ERROR: test_return_book (ClassEval_14_1.BookManagementDBTestReturnBook.test_return_book)
----------------------------------------------------------------------
Traceback (most recent call last):
  File "/Users/snigdhaghoshdastidar/Desktop/CS540/classeval_evaluation/ClassEval_14_1.py", line 178, in test_return_book
    self.cursor.execute("SELECT available FROM books WHERE id=1")
sqlite3.OperationalError: no such column: available

----------------------------------------------------------------------
Ran 1 test in 0.004s

FAILED (errors=1)
.
----------------------------------------------------------------------
Ran 1 test in 0.004s

OK
.F
======================================================================
FAIL: test_create_table_2 (ClassEval_14_2.BookManagementDBTestCreateTable.test_create_table_2)
----------------------------------------------------------------------
Traceback (most recent call last):
  File "/Users/snigdhaghoshdastidar/Desktop/CS540/classeval_evaluation/ClassEval_14_2.py", line 76, in test_create_table_2
    self.assertEqual(column_names, expected_column_names)
AssertionError: Lists differ: ['id', 'title', 'author', 'is_available'] != ['id', 'title', 'author', 'available']

First differing element 3:
'is_available'
'available'

- ['id', 'title', 'author', 'is_available']
?                            ---

+ ['id', 'title', 'author', 'available']

----------------------------------------------------------------------
Ran 2 tests in 0.005s

FAILED (failures=1)
E
======================================================================
ERROR: test_add_book (ClassEval_14_2.BookManagementDBTestAddBook.test_add_book)
----------------------------------------------------------------------
Traceback (most recent call last):
  File "/Users/snigdhaghoshdastidar/Desktop/CS540/classeval_evaluation/ClassEval_14_2.py", line 98, in test_add_book
    self.cursor.execute("SELECT title, author, available FROM books WHERE id=1")
sqlite3.OperationalError: no such column: available

----------------------------------------------------------------------
Ran 1 test in 0.004s

FAILED (errors=1)
.
----------------------------------------------------------------------
Ran 1 test in 0.005s

OK
E
======================================================================
ERROR: test_borrow_book (ClassEval_14_2.BookManagementDBTestBorrowBook.test_borrow_book)
----------------------------------------------------------------------
Traceback (most recent call last):
  File "/Users/snigdhaghoshdastidar/Desktop/CS540/classeval_evaluation/ClassEval_14_2.py", line 149, in test_borrow_book
    self.cursor.execute("SELECT available FROM books WHERE id=1")
sqlite3.OperationalError: no such column: available

----------------------------------------------------------------------
Ran 1 test in 0.005s

FAILED (errors=1)
E
======================================================================
ERROR: test_return_book (ClassEval_14_2.BookManagementDBTestReturnBook.test_return_book)
----------------------------------------------------------------------
Traceback (most recent call last):
  File "/Users/snigdhaghoshdastidar/Desktop/CS540/classeval_evaluation/ClassEval_14_2.py", line 174, in test_return_book
    self.cursor.execute("SELECT available FROM books WHERE id=1")
sqlite3.OperationalError: no such column: available

----------------------------------------------------------------------
Ran 1 test in 0.006s

FAILED (errors=1)
.
----------------------------------------------------------------------
Ran 1 test in 0.007s

OK
.F
======================================================================
FAIL: test_create_table_2 (ClassEval_14_3.BookManagementDBTestCreateTable.test_create_table_2)
----------------------------------------------------------------------
Traceback (most recent call last):
  File "/Users/snigdhaghoshdastidar/Desktop/CS540/classeval_evaluation/ClassEval_14_3.py", line 62, in test_create_table_2
    self.assertEqual(column_names, expected_column_names)
AssertionError: Lists differ: ['id', 'title', 'author', 'availability'] != ['id', 'title', 'author', 'available']

First differing element 3:
'availability'
'available'

- ['id', 'title', 'author', 'availability']
?                                   - ^^^

+ ['id', 'title', 'author', 'available']
?                                    ^


----------------------------------------------------------------------
Ran 2 tests in 0.007s

FAILED (failures=1)
E
======================================================================
ERROR: test_add_book (ClassEval_14_3.BookManagementDBTestAddBook.test_add_book)
----------------------------------------------------------------------
Traceback (most recent call last):
  File "/Users/snigdhaghoshdastidar/Desktop/CS540/classeval_evaluation/ClassEval_14_3.py", line 84, in test_add_book
    self.cursor.execute("SELECT title, author, available FROM books WHERE id=1")
sqlite3.OperationalError: no such column: available

----------------------------------------------------------------------
Ran 1 test in 0.007s

FAILED (errors=1)
.
----------------------------------------------------------------------
Ran 1 test in 0.005s

OK
E
======================================================================
ERROR: test_borrow_book (ClassEval_14_3.BookManagementDBTestBorrowBook.test_borrow_book)
----------------------------------------------------------------------
Traceback (most recent call last):
  File "/Users/snigdhaghoshdastidar/Desktop/CS540/classeval_evaluation/ClassEval_14_3.py", line 135, in test_borrow_book
    self.cursor.execute("SELECT available FROM books WHERE id=1")
sqlite3.OperationalError: no such column: available

----------------------------------------------------------------------
Ran 1 test in 0.005s

FAILED (errors=1)
E
======================================================================
ERROR: test_return_book (ClassEval_14_3.BookManagementDBTestReturnBook.test_return_book)
----------------------------------------------------------------------
Traceback (most recent call last):
  File "/Users/snigdhaghoshdastidar/Desktop/CS540/classeval_evaluation/ClassEval_14_3.py", line 160, in test_return_book
    self.cursor.execute("SELECT available FROM books WHERE id=1")
sqlite3.OperationalError: no such column: available

----------------------------------------------------------------------
Ran 1 test in 0.007s

FAILED (errors=1)
.
----------------------------------------------------------------------
Ran 1 test in 0.007s

OK
.F
======================================================================
FAIL: test_create_table_2 (ClassEval_14_4.BookManagementDBTestCreateTable.test_create_table_2)
----------------------------------------------------------------------
Traceback (most recent call last):
  File "/Users/snigdhaghoshdastidar/Desktop/CS540/classeval_evaluation/ClassEval_14_4.py", line 62, in test_create_table_2
    self.assertEqual(column_names, expected_column_names)
AssertionError: Lists differ: ['id', 'title', 'author', 'availability'] != ['id', 'title', 'author', 'available']

First differing element 3:
'availability'
'available'

- ['id', 'title', 'author', 'availability']
?                                   - ^^^

+ ['id', 'title', 'author', 'available']
?                                    ^


----------------------------------------------------------------------
Ran 2 tests in 0.006s

FAILED (failures=1)
E
======================================================================
ERROR: test_add_book (ClassEval_14_4.BookManagementDBTestAddBook.test_add_book)
----------------------------------------------------------------------
Traceback (most recent call last):
  File "/Users/snigdhaghoshdastidar/Desktop/CS540/classeval_evaluation/ClassEval_14_4.py", line 84, in test_add_book
    self.cursor.execute("SELECT title, author, available FROM books WHERE id=1")
sqlite3.OperationalError: no such column: available

----------------------------------------------------------------------
Ran 1 test in 0.004s

FAILED (errors=1)
.
----------------------------------------------------------------------
Ran 1 test in 0.008s

OK
E
======================================================================
ERROR: test_borrow_book (ClassEval_14_4.BookManagementDBTestBorrowBook.test_borrow_book)
----------------------------------------------------------------------
Traceback (most recent call last):
  File "/Users/snigdhaghoshdastidar/Desktop/CS540/classeval_evaluation/ClassEval_14_4.py", line 135, in test_borrow_book
    self.cursor.execute("SELECT available FROM books WHERE id=1")
sqlite3.OperationalError: no such column: available

----------------------------------------------------------------------
Ran 1 test in 0.005s

FAILED (errors=1)
E
======================================================================
ERROR: test_return_book (ClassEval_14_4.BookManagementDBTestReturnBook.test_return_book)
----------------------------------------------------------------------
Traceback (most recent call last):
  File "/Users/snigdhaghoshdastidar/Desktop/CS540/classeval_evaluation/ClassEval_14_4.py", line 160, in test_return_book
    self.cursor.execute("SELECT available FROM books WHERE id=1")
sqlite3.OperationalError: no such column: available

----------------------------------------------------------------------
Ran 1 test in 0.009s

FAILED (errors=1)
.
----------------------------------------------------------------------
Ran 1 test in 0.007s

OK
.....
----------------------------------------------------------------------
Ran 5 tests in 0.016s

OK
.....
----------------------------------------------------------------------
Ran 5 tests in 0.020s

OK
..FFF
======================================================================
FAIL: test_search_database_3 (ClassEval_28_0.DatabaseProcessorTestSearchDatabase.test_search_database_3)
----------------------------------------------------------------------
Traceback (most recent call last):
  File "/Users/snigdhaghoshdastidar/Desktop/CS540/classeval_evaluation/ClassEval_28_0.py", line 288, in test_search_database_3
    self.assertIsNone(result)
AssertionError: [] is not None

======================================================================
FAIL: test_search_database_4 (ClassEval_28_0.DatabaseProcessorTestSearchDatabase.test_search_database_4)
----------------------------------------------------------------------
Traceback (most recent call last):
  File "/Users/snigdhaghoshdastidar/Desktop/CS540/classeval_evaluation/ClassEval_28_0.py", line 300, in test_search_database_4
    self.assertIsNone(result)
AssertionError: [] is not None

======================================================================
FAIL: test_search_database_5 (ClassEval_28_0.DatabaseProcessorTestSearchDatabase.test_search_database_5)
----------------------------------------------------------------------
Traceback (most recent call last):
  File "/Users/snigdhaghoshdastidar/Desktop/CS540/classeval_evaluation/ClassEval_28_0.py", line 312, in test_search_database_5
    self.assertIsNone(result)
AssertionError: [] is not None

----------------------------------------------------------------------
Ran 5 tests in 0.021s

FAILED (failures=3)
.....
----------------------------------------------------------------------
Ran 5 tests in 0.040s

OK
.
----------------------------------------------------------------------
Ran 1 test in 0.009s

OK
.....
----------------------------------------------------------------------
Ran 5 tests in 0.007s

OK
.....
----------------------------------------------------------------------
Ran 5 tests in 0.022s

OK
..FFF
======================================================================
FAIL: test_search_database_3 (ClassEval_28_1.DatabaseProcessorTestSearchDatabase.test_search_database_3)
----------------------------------------------------------------------
Traceback (most recent call last):
  File "/Users/snigdhaghoshdastidar/Desktop/CS540/classeval_evaluation/ClassEval_28_1.py", line 277, in test_search_database_3
    self.assertIsNone(result)
AssertionError: [] is not None

======================================================================
FAIL: test_search_database_4 (ClassEval_28_1.DatabaseProcessorTestSearchDatabase.test_search_database_4)
----------------------------------------------------------------------
Traceback (most recent call last):
  File "/Users/snigdhaghoshdastidar/Desktop/CS540/classeval_evaluation/ClassEval_28_1.py", line 289, in test_search_database_4
    self.assertIsNone(result)
AssertionError: [] is not None

======================================================================
FAIL: test_search_database_5 (ClassEval_28_1.DatabaseProcessorTestSearchDatabase.test_search_database_5)
----------------------------------------------------------------------
Traceback (most recent call last):
  File "/Users/snigdhaghoshdastidar/Desktop/CS540/classeval_evaluation/ClassEval_28_1.py", line 301, in test_search_database_5
    self.assertIsNone(result)
AssertionError: [] is not None

----------------------------------------------------------------------
Ran 5 tests in 0.026s

FAILED (failures=3)
.....
----------------------------------------------------------------------
Ran 5 tests in 0.031s

OK
.
----------------------------------------------------------------------
Ran 1 test in 0.006s

OK
.....
----------------------------------------------------------------------
Ran 5 tests in 0.010s

OK
.....
----------------------------------------------------------------------
Ran 5 tests in 0.028s

OK
..FFF
======================================================================
FAIL: test_search_database_3 (ClassEval_28_2.DatabaseProcessorTestSearchDatabase.test_search_database_3)
----------------------------------------------------------------------
Traceback (most recent call last):
  File "/Users/snigdhaghoshdastidar/Desktop/CS540/classeval_evaluation/ClassEval_28_2.py", line 277, in test_search_database_3
    self.assertIsNone(result)
AssertionError: [] is not None

======================================================================
FAIL: test_search_database_4 (ClassEval_28_2.DatabaseProcessorTestSearchDatabase.test_search_database_4)
----------------------------------------------------------------------
Traceback (most recent call last):
  File "/Users/snigdhaghoshdastidar/Desktop/CS540/classeval_evaluation/ClassEval_28_2.py", line 289, in test_search_database_4
    self.assertIsNone(result)
AssertionError: [] is not None

======================================================================
FAIL: test_search_database_5 (ClassEval_28_2.DatabaseProcessorTestSearchDatabase.test_search_database_5)
----------------------------------------------------------------------
Traceback (most recent call last):
  File "/Users/snigdhaghoshdastidar/Desktop/CS540/classeval_evaluation/ClassEval_28_2.py", line 301, in test_search_database_5
    self.assertIsNone(result)
AssertionError: [] is not None

----------------------------------------------------------------------
Ran 5 tests in 0.027s

FAILED (failures=3)
.....
----------------------------------------------------------------------
Ran 5 tests in 0.026s

OK
.
----------------------------------------------------------------------
Ran 1 test in 0.006s

OK
.....
----------------------------------------------------------------------
Ran 5 tests in 0.011s

OK
.....
----------------------------------------------------------------------
Ran 5 tests in 0.018s

OK
..FFF
======================================================================
FAIL: test_search_database_3 (ClassEval_28_3.DatabaseProcessorTestSearchDatabase.test_search_database_3)
----------------------------------------------------------------------
Traceback (most recent call last):
  File "/Users/snigdhaghoshdastidar/Desktop/CS540/classeval_evaluation/ClassEval_28_3.py", line 279, in test_search_database_3
    self.assertIsNone(result)
AssertionError: [] is not None

======================================================================
FAIL: test_search_database_4 (ClassEval_28_3.DatabaseProcessorTestSearchDatabase.test_search_database_4)
----------------------------------------------------------------------
Traceback (most recent call last):
  File "/Users/snigdhaghoshdastidar/Desktop/CS540/classeval_evaluation/ClassEval_28_3.py", line 291, in test_search_database_4
    self.assertIsNone(result)
AssertionError: [] is not None

======================================================================
FAIL: test_search_database_5 (ClassEval_28_3.DatabaseProcessorTestSearchDatabase.test_search_database_5)
----------------------------------------------------------------------
Traceback (most recent call last):
  File "/Users/snigdhaghoshdastidar/Desktop/CS540/classeval_evaluation/ClassEval_28_3.py", line 303, in test_search_database_5
    self.assertIsNone(result)
AssertionError: [] is not None

----------------------------------------------------------------------
Ran 5 tests in 0.015s

FAILED (failures=3)
.....
----------------------------------------------------------------------
Ran 5 tests in 0.021s

OK
.
----------------------------------------------------------------------
Ran 1 test in 0.005s

OK
.....
----------------------------------------------------------------------
Ran 5 tests in 0.012s

OK
.....
----------------------------------------------------------------------
Ran 5 tests in 0.030s

OK
..FFF
======================================================================
FAIL: test_search_database_3 (ClassEval_28_4.DatabaseProcessorTestSearchDatabase.test_search_database_3)
----------------------------------------------------------------------
Traceback (most recent call last):
  File "/Users/snigdhaghoshdastidar/Desktop/CS540/classeval_evaluation/ClassEval_28_4.py", line 277, in test_search_database_3
    self.assertIsNone(result)
AssertionError: [] is not None

======================================================================
FAIL: test_search_database_4 (ClassEval_28_4.DatabaseProcessorTestSearchDatabase.test_search_database_4)
----------------------------------------------------------------------
Traceback (most recent call last):
  File "/Users/snigdhaghoshdastidar/Desktop/CS540/classeval_evaluation/ClassEval_28_4.py", line 289, in test_search_database_4
    self.assertIsNone(result)
AssertionError: [] is not None

======================================================================
FAIL: test_search_database_5 (ClassEval_28_4.DatabaseProcessorTestSearchDatabase.test_search_database_5)
----------------------------------------------------------------------
Traceback (most recent call last):
  File "/Users/snigdhaghoshdastidar/Desktop/CS540/classeval_evaluation/ClassEval_28_4.py", line 301, in test_search_database_5
    self.assertIsNone(result)
AssertionError: [] is not None

----------------------------------------------------------------------
Ran 5 tests in 0.025s

FAILED (failures=3)
.....
----------------------------------------------------------------------
Ran 5 tests in 0.037s

OK
.
----------------------------------------------------------------------
Ran 1 test in 0.008s

OK
.....
----------------------------------------------------------------------
Ran 5 tests in 0.018s

OK
.....
----------------------------------------------------------------------
Ran 5 tests in 0.016s

OK
.....
----------------------------------------------------------------------
Ran 5 tests in 0.023s

OK
.
----------------------------------------------------------------------
Ran 1 test in 0.004s

OK
.....
----------------------------------------------------------------------
Ran 5 tests in 0.015s

OK
.....
----------------------------------------------------------------------
Ran 5 tests in 0.013s

OK
.....
----------------------------------------------------------------------
Ran 5 tests in 0.017s

OK
.
----------------------------------------------------------------------
Ran 1 test in 0.005s

OK
.....
----------------------------------------------------------------------
Ran 5 tests in 0.015s

OK
.....
----------------------------------------------------------------------
Ran 5 tests in 0.016s

OK
.....
----------------------------------------------------------------------
Ran 5 tests in 0.024s

OK
.
----------------------------------------------------------------------
Ran 1 test in 0.005s

OK
.....
----------------------------------------------------------------------
Ran 5 tests in 0.017s

OK
.....
----------------------------------------------------------------------
Ran 5 tests in 0.014s

OK
.....
----------------------------------------------------------------------
Ran 5 tests in 0.020s

OK
.
----------------------------------------------------------------------
Ran 1 test in 0.003s

OK
.....
----------------------------------------------------------------------
Ran 5 tests in 0.012s

OK
.....
----------------------------------------------------------------------
Ran 5 tests in 0.010s

OK
.....
----------------------------------------------------------------------
Ran 5 tests in 0.013s

OK
.
----------------------------------------------------------------------
Ran 1 test in 0.003s

OK
......
----------------------------------------------------------------------
Ran 6 tests in 0.000s

OK
.....
----------------------------------------------------------------------
Ran 5 tests in 0.000s

OK
.....
----------------------------------------------------------------------
Ran 5 tests in 0.000s

OK
.....
----------------------------------------------------------------------
Ran 5 tests in 0.000s

OK
.....
----------------------------------------------------------------------
Ran 5 tests in 0.000s

OK
.....
----------------------------------------------------------------------
Ran 5 tests in 0.000s

OK
.
----------------------------------------------------------------------
Ran 1 test in 0.000s

OK
......
----------------------------------------------------------------------
Ran 6 tests in 0.000s

OK
.....
----------------------------------------------------------------------
Ran 5 tests in 0.000s

OK
.....
----------------------------------------------------------------------
Ran 5 tests in 0.000s

OK
.....
----------------------------------------------------------------------
Ran 5 tests in 0.000s

OK
.....
----------------------------------------------------------------------
Ran 5 tests in 0.000s

OK
.....
----------------------------------------------------------------------
Ran 5 tests in 0.000s

OK
.
----------------------------------------------------------------------
Ran 1 test in 0.000s

OK
......
----------------------------------------------------------------------
Ran 6 tests in 0.000s

OK
.....
----------------------------------------------------------------------
Ran 5 tests in 0.000s

OK
.....
----------------------------------------------------------------------
Ran 5 tests in 0.000s

OK
.....
----------------------------------------------------------------------
Ran 5 tests in 0.000s

OK
.....
----------------------------------------------------------------------
Ran 5 tests in 0.000s

OK
.....
----------------------------------------------------------------------
Ran 5 tests in 0.000s

OK
.
----------------------------------------------------------------------
Ran 1 test in 0.000s

OK
......
----------------------------------------------------------------------
Ran 6 tests in 0.000s

OK
.....
----------------------------------------------------------------------
Ran 5 tests in 0.000s

OK
.....
----------------------------------------------------------------------
Ran 5 tests in 0.000s

OK
.....
----------------------------------------------------------------------
Ran 5 tests in 0.000s

OK
.....
----------------------------------------------------------------------
Ran 5 tests in 0.000s

OK
.....
----------------------------------------------------------------------
Ran 5 tests in 0.000s

OK
.
----------------------------------------------------------------------
Ran 1 test in 0.000s

OK
......
----------------------------------------------------------------------
Ran 6 tests in 0.000s

OK
.....
----------------------------------------------------------------------
Ran 5 tests in 0.000s

OK
.....
----------------------------------------------------------------------
Ran 5 tests in 0.000s

OK
.....
----------------------------------------------------------------------
Ran 5 tests in 0.000s

OK
.....
----------------------------------------------------------------------
Ran 5 tests in 0.000s

OK
.....
----------------------------------------------------------------------
Ran 5 tests in 0.000s

OK
.
----------------------------------------------------------------------
Ran 1 test in 0.000s

OK
.......
----------------------------------------------------------------------
Ran 7 tests in 0.000s

OK
.....
----------------------------------------------------------------------
Ran 5 tests in 0.000s

OK
......
----------------------------------------------------------------------
Ran 6 tests in 0.000s

OK
......
----------------------------------------------------------------------
Ran 6 tests in 0.000s

OK
.
----------------------------------------------------------------------
Ran 1 test in 0.000s

OK
.......
----------------------------------------------------------------------
Ran 7 tests in 0.000s

OK
.....
----------------------------------------------------------------------
Ran 5 tests in 0.000s

OK
......
----------------------------------------------------------------------
Ran 6 tests in 0.000s

OK
......
----------------------------------------------------------------------
Ran 6 tests in 0.000s

OK
.
----------------------------------------------------------------------
Ran 1 test in 0.000s

OK
.......
----------------------------------------------------------------------
Ran 7 tests in 0.000s

OK
.....
----------------------------------------------------------------------
Ran 5 tests in 0.001s

OK
......
----------------------------------------------------------------------
Ran 6 tests in 0.000s

OK
......
----------------------------------------------------------------------
Ran 6 tests in 0.000s

OK
.
----------------------------------------------------------------------
Ran 1 test in 0.000s

OK
.......
----------------------------------------------------------------------
Ran 7 tests in 0.000s

OK
.....
----------------------------------------------------------------------
Ran 5 tests in 0.000s

OK
......
----------------------------------------------------------------------
Ran 6 tests in 0.000s

OK
......
----------------------------------------------------------------------
Ran 6 tests in 0.000s

OK
.
----------------------------------------------------------------------
Ran 1 test in 0.000s

OK
.......
----------------------------------------------------------------------
Ran 7 tests in 0.001s

OK
.....
----------------------------------------------------------------------
Ran 5 tests in 0.005s

OK
......
----------------------------------------------------------------------
Ran 6 tests in 0.002s

OK
......
----------------------------------------------------------------------
Ran 6 tests in 0.000s

OK
.
----------------------------------------------------------------------
Ran 1 test in 0.000s

OK
.....
----------------------------------------------------------------------
Ran 5 tests in 0.023s

OK
.....
----------------------------------------------------------------------
Ran 5 tests in 0.020s

OK
.....
----------------------------------------------------------------------
Ran 5 tests in 0.022s

OK
.
----------------------------------------------------------------------
Ran 1 test in 0.007s

OK
.....
----------------------------------------------------------------------
Ran 5 tests in 0.025s

OK
.....
----------------------------------------------------------------------
Ran 5 tests in 0.021s

OK
.....
----------------------------------------------------------------------
Ran 5 tests in 0.037s

OK
.
----------------------------------------------------------------------
Ran 1 test in 0.012s

OK
.....
----------------------------------------------------------------------
Ran 5 tests in 0.025s

OK
.....
----------------------------------------------------------------------
Ran 5 tests in 0.027s

OK
.....
----------------------------------------------------------------------
Ran 5 tests in 0.034s

OK
.
----------------------------------------------------------------------
Ran 1 test in 0.008s

OK
.....
----------------------------------------------------------------------
Ran 5 tests in 0.018s

OK
.....
----------------------------------------------------------------------
Ran 5 tests in 0.020s

OK
.....
----------------------------------------------------------------------
Ran 5 tests in 0.023s

OK
.
----------------------------------------------------------------------
Ran 1 test in 0.007s

OK
.....
----------------------------------------------------------------------
Ran 5 tests in 0.018s

OK
.....
----------------------------------------------------------------------
Ran 5 tests in 0.019s

OK
.....
----------------------------------------------------------------------
Ran 5 tests in 0.021s

OK
.
----------------------------------------------------------------------
Ran 1 test in 0.015s

OK
FFFFF
======================================================================
FAIL: test_insert_user_1 (ClassEval_92_0.UserLoginDBTestInsertUser.test_insert_user_1)
----------------------------------------------------------------------
Traceback (most recent call last):
  File "/Users/snigdhaghoshdastidar/Desktop/CS540/classeval_evaluation/ClassEval_92_0.py", line 91, in test_insert_user_1
    self.assertEqual(user[0], 'user1')
AssertionError: ('user1', 'pass1') != 'user1'

======================================================================
FAIL: test_insert_user_2 (ClassEval_92_0.UserLoginDBTestInsertUser.test_insert_user_2)
----------------------------------------------------------------------
Traceback (most recent call last):
  File "/Users/snigdhaghoshdastidar/Desktop/CS540/classeval_evaluation/ClassEval_92_0.py", line 98, in test_insert_user_2
    self.assertEqual(user[0], 'user2')
AssertionError: ('user2', 'pass2') != 'user2'

======================================================================
FAIL: test_insert_user_3 (ClassEval_92_0.UserLoginDBTestInsertUser.test_insert_user_3)
----------------------------------------------------------------------
Traceback (most recent call last):
  File "/Users/snigdhaghoshdastidar/Desktop/CS540/classeval_evaluation/ClassEval_92_0.py", line 105, in test_insert_user_3
    self.assertEqual(user[0], 'user3')
AssertionError: ('user3', 'pass3') != 'user3'

======================================================================
FAIL: test_insert_user_4 (ClassEval_92_0.UserLoginDBTestInsertUser.test_insert_user_4)
----------------------------------------------------------------------
Traceback (most recent call last):
  File "/Users/snigdhaghoshdastidar/Desktop/CS540/classeval_evaluation/ClassEval_92_0.py", line 112, in test_insert_user_4
    self.assertEqual(user[0], 'user4')
AssertionError: ('user4', 'pass4') != 'user4'

======================================================================
FAIL: test_insert_user_5 (ClassEval_92_0.UserLoginDBTestInsertUser.test_insert_user_5)
----------------------------------------------------------------------
Traceback (most recent call last):
  File "/Users/snigdhaghoshdastidar/Desktop/CS540/classeval_evaluation/ClassEval_92_0.py", line 119, in test_insert_user_5
    self.assertEqual(user[0], 'user5')
AssertionError: ('user5', 'pass5') != 'user5'

----------------------------------------------------------------------
Ran 5 tests in 0.016s

FAILED (failures=5)
FFFFF
======================================================================
FAIL: test_search_user_by_username_1 (ClassEval_92_0.UserLoginDBTestSearchUserByUsername.test_search_user_by_username_1)
----------------------------------------------------------------------
Traceback (most recent call last):
  File "/Users/snigdhaghoshdastidar/Desktop/CS540/classeval_evaluation/ClassEval_92_0.py", line 148, in test_search_user_by_username_1
    self.assertEqual(user[0], 'user1')
AssertionError: ('user1', 'pass1') != 'user1'

======================================================================
FAIL: test_search_user_by_username_2 (ClassEval_92_0.UserLoginDBTestSearchUserByUsername.test_search_user_by_username_2)
----------------------------------------------------------------------
Traceback (most recent call last):
  File "/Users/snigdhaghoshdastidar/Desktop/CS540/classeval_evaluation/ClassEval_92_0.py", line 155, in test_search_user_by_username_2
    self.assertEqual(user[0], 'user2')
AssertionError: ('user2', 'pass2') != 'user2'

======================================================================
FAIL: test_search_user_by_username_3 (ClassEval_92_0.UserLoginDBTestSearchUserByUsername.test_search_user_by_username_3)
----------------------------------------------------------------------
Traceback (most recent call last):
  File "/Users/snigdhaghoshdastidar/Desktop/CS540/classeval_evaluation/ClassEval_92_0.py", line 162, in test_search_user_by_username_3
    self.assertEqual(user[0], 'user3')
AssertionError: ('user3', 'pass3') != 'user3'

======================================================================
FAIL: test_search_user_by_username_4 (ClassEval_92_0.UserLoginDBTestSearchUserByUsername.test_search_user_by_username_4)
----------------------------------------------------------------------
Traceback (most recent call last):
  File "/Users/snigdhaghoshdastidar/Desktop/CS540/classeval_evaluation/ClassEval_92_0.py", line 169, in test_search_user_by_username_4
    self.assertEqual(user[0], 'user4')
AssertionError: ('user4', 'pass4') != 'user4'

======================================================================
FAIL: test_search_user_by_username_5 (ClassEval_92_0.UserLoginDBTestSearchUserByUsername.test_search_user_by_username_5)
----------------------------------------------------------------------
Traceback (most recent call last):
  File "/Users/snigdhaghoshdastidar/Desktop/CS540/classeval_evaluation/ClassEval_92_0.py", line 176, in test_search_user_by_username_5
    self.assertEqual(user[0], 'user5')
AssertionError: ('user5', 'pass5') != 'user5'

----------------------------------------------------------------------
Ran 5 tests in 0.016s

FAILED (failures=5)
FFFFF
======================================================================
FAIL: test_delete_user_by_username_1 (ClassEval_92_0.UserLoginDBTestDeleteUserByUsername.test_delete_user_by_username_1)
----------------------------------------------------------------------
Traceback (most recent call last):
  File "/Users/snigdhaghoshdastidar/Desktop/CS540/classeval_evaluation/ClassEval_92_0.py", line 205, in test_delete_user_by_username_1
    self.assertIsNone(user)
AssertionError: [] is not None

======================================================================
FAIL: test_delete_user_by_username_2 (ClassEval_92_0.UserLoginDBTestDeleteUserByUsername.test_delete_user_by_username_2)
----------------------------------------------------------------------
Traceback (most recent call last):
  File "/Users/snigdhaghoshdastidar/Desktop/CS540/classeval_evaluation/ClassEval_92_0.py", line 211, in test_delete_user_by_username_2
    self.assertIsNone(user)
AssertionError: [] is not None

======================================================================
FAIL: test_delete_user_by_username_3 (ClassEval_92_0.UserLoginDBTestDeleteUserByUsername.test_delete_user_by_username_3)
----------------------------------------------------------------------
Traceback (most recent call last):
  File "/Users/snigdhaghoshdastidar/Desktop/CS540/classeval_evaluation/ClassEval_92_0.py", line 217, in test_delete_user_by_username_3
    self.assertIsNone(user)
AssertionError: [] is not None

======================================================================
FAIL: test_delete_user_by_username_4 (ClassEval_92_0.UserLoginDBTestDeleteUserByUsername.test_delete_user_by_username_4)
----------------------------------------------------------------------
Traceback (most recent call last):
  File "/Users/snigdhaghoshdastidar/Desktop/CS540/classeval_evaluation/ClassEval_92_0.py", line 223, in test_delete_user_by_username_4
    self.assertIsNone(user)
AssertionError: [] is not None

======================================================================
FAIL: test_delete_user_by_username_5 (ClassEval_92_0.UserLoginDBTestDeleteUserByUsername.test_delete_user_by_username_5)
----------------------------------------------------------------------
Traceback (most recent call last):
  File "/Users/snigdhaghoshdastidar/Desktop/CS540/classeval_evaluation/ClassEval_92_0.py", line 229, in test_delete_user_by_username_5
    self.assertIsNone(user)
AssertionError: [] is not None

----------------------------------------------------------------------
Ran 5 tests in 0.021s

FAILED (failures=5)
.....
----------------------------------------------------------------------
Ran 5 tests in 0.015s

OK
F
======================================================================
FAIL: test_UserLoginDB (ClassEval_92_0.UserLoginDBTest.test_UserLoginDB)
----------------------------------------------------------------------
Traceback (most recent call last):
  File "/Users/snigdhaghoshdastidar/Desktop/CS540/classeval_evaluation/ClassEval_92_0.py", line 303, in test_UserLoginDB
    self.assertEqual(user[0], 'user1')
AssertionError: ('user1', 'pass1') != 'user1'

----------------------------------------------------------------------
Ran 1 test in 0.003s

FAILED (failures=1)
FFFFF
======================================================================
FAIL: test_insert_user_1 (ClassEval_92_1.UserLoginDBTestInsertUser.test_insert_user_1)
----------------------------------------------------------------------
Traceback (most recent call last):
  File "/Users/snigdhaghoshdastidar/Desktop/CS540/classeval_evaluation/ClassEval_92_1.py", line 85, in test_insert_user_1
    self.assertEqual(user[0], 'user1')
AssertionError: ('user1', 'pass1') != 'user1'

======================================================================
FAIL: test_insert_user_2 (ClassEval_92_1.UserLoginDBTestInsertUser.test_insert_user_2)
----------------------------------------------------------------------
Traceback (most recent call last):
  File "/Users/snigdhaghoshdastidar/Desktop/CS540/classeval_evaluation/ClassEval_92_1.py", line 92, in test_insert_user_2
    self.assertEqual(user[0], 'user2')
AssertionError: ('user2', 'pass2') != 'user2'

======================================================================
FAIL: test_insert_user_3 (ClassEval_92_1.UserLoginDBTestInsertUser.test_insert_user_3)
----------------------------------------------------------------------
Traceback (most recent call last):
  File "/Users/snigdhaghoshdastidar/Desktop/CS540/classeval_evaluation/ClassEval_92_1.py", line 99, in test_insert_user_3
    self.assertEqual(user[0], 'user3')
AssertionError: ('user3', 'pass3') != 'user3'

======================================================================
FAIL: test_insert_user_4 (ClassEval_92_1.UserLoginDBTestInsertUser.test_insert_user_4)
----------------------------------------------------------------------
Traceback (most recent call last):
  File "/Users/snigdhaghoshdastidar/Desktop/CS540/classeval_evaluation/ClassEval_92_1.py", line 106, in test_insert_user_4
    self.assertEqual(user[0], 'user4')
AssertionError: ('user4', 'pass4') != 'user4'

======================================================================
FAIL: test_insert_user_5 (ClassEval_92_1.UserLoginDBTestInsertUser.test_insert_user_5)
----------------------------------------------------------------------
Traceback (most recent call last):
  File "/Users/snigdhaghoshdastidar/Desktop/CS540/classeval_evaluation/ClassEval_92_1.py", line 113, in test_insert_user_5
    self.assertEqual(user[0], 'user5')
AssertionError: ('user5', 'pass5') != 'user5'

----------------------------------------------------------------------
Ran 5 tests in 0.016s

FAILED (failures=5)
FFFFF
======================================================================
FAIL: test_search_user_by_username_1 (ClassEval_92_1.UserLoginDBTestSearchUserByUsername.test_search_user_by_username_1)
----------------------------------------------------------------------
Traceback (most recent call last):
  File "/Users/snigdhaghoshdastidar/Desktop/CS540/classeval_evaluation/ClassEval_92_1.py", line 142, in test_search_user_by_username_1
    self.assertEqual(user[0], 'user1')
AssertionError: ('user1', 'pass1') != 'user1'

======================================================================
FAIL: test_search_user_by_username_2 (ClassEval_92_1.UserLoginDBTestSearchUserByUsername.test_search_user_by_username_2)
----------------------------------------------------------------------
Traceback (most recent call last):
  File "/Users/snigdhaghoshdastidar/Desktop/CS540/classeval_evaluation/ClassEval_92_1.py", line 149, in test_search_user_by_username_2
    self.assertEqual(user[0], 'user2')
AssertionError: ('user2', 'pass2') != 'user2'

======================================================================
FAIL: test_search_user_by_username_3 (ClassEval_92_1.UserLoginDBTestSearchUserByUsername.test_search_user_by_username_3)
----------------------------------------------------------------------
Traceback (most recent call last):
  File "/Users/snigdhaghoshdastidar/Desktop/CS540/classeval_evaluation/ClassEval_92_1.py", line 156, in test_search_user_by_username_3
    self.assertEqual(user[0], 'user3')
AssertionError: ('user3', 'pass3') != 'user3'

======================================================================
FAIL: test_search_user_by_username_4 (ClassEval_92_1.UserLoginDBTestSearchUserByUsername.test_search_user_by_username_4)
----------------------------------------------------------------------
Traceback (most recent call last):
  File "/Users/snigdhaghoshdastidar/Desktop/CS540/classeval_evaluation/ClassEval_92_1.py", line 163, in test_search_user_by_username_4
    self.assertEqual(user[0], 'user4')
AssertionError: ('user4', 'pass4') != 'user4'

======================================================================
FAIL: test_search_user_by_username_5 (ClassEval_92_1.UserLoginDBTestSearchUserByUsername.test_search_user_by_username_5)
----------------------------------------------------------------------
Traceback (most recent call last):
  File "/Users/snigdhaghoshdastidar/Desktop/CS540/classeval_evaluation/ClassEval_92_1.py", line 170, in test_search_user_by_username_5
    self.assertEqual(user[0], 'user5')
AssertionError: ('user5', 'pass5') != 'user5'

----------------------------------------------------------------------
Ran 5 tests in 0.016s

FAILED (failures=5)
FFFFF
======================================================================
FAIL: test_delete_user_by_username_1 (ClassEval_92_1.UserLoginDBTestDeleteUserByUsername.test_delete_user_by_username_1)
----------------------------------------------------------------------
Traceback (most recent call last):
  File "/Users/snigdhaghoshdastidar/Desktop/CS540/classeval_evaluation/ClassEval_92_1.py", line 199, in test_delete_user_by_username_1
    self.assertIsNone(user)
AssertionError: [] is not None

======================================================================
FAIL: test_delete_user_by_username_2 (ClassEval_92_1.UserLoginDBTestDeleteUserByUsername.test_delete_user_by_username_2)
----------------------------------------------------------------------
Traceback (most recent call last):
  File "/Users/snigdhaghoshdastidar/Desktop/CS540/classeval_evaluation/ClassEval_92_1.py", line 205, in test_delete_user_by_username_2
    self.assertIsNone(user)
AssertionError: [] is not None

======================================================================
FAIL: test_delete_user_by_username_3 (ClassEval_92_1.UserLoginDBTestDeleteUserByUsername.test_delete_user_by_username_3)
----------------------------------------------------------------------
Traceback (most recent call last):
  File "/Users/snigdhaghoshdastidar/Desktop/CS540/classeval_evaluation/ClassEval_92_1.py", line 211, in test_delete_user_by_username_3
    self.assertIsNone(user)
AssertionError: [] is not None

======================================================================
FAIL: test_delete_user_by_username_4 (ClassEval_92_1.UserLoginDBTestDeleteUserByUsername.test_delete_user_by_username_4)
----------------------------------------------------------------------
Traceback (most recent call last):
  File "/Users/snigdhaghoshdastidar/Desktop/CS540/classeval_evaluation/ClassEval_92_1.py", line 217, in test_delete_user_by_username_4
    self.assertIsNone(user)
AssertionError: [] is not None

======================================================================
FAIL: test_delete_user_by_username_5 (ClassEval_92_1.UserLoginDBTestDeleteUserByUsername.test_delete_user_by_username_5)
----------------------------------------------------------------------
Traceback (most recent call last):
  File "/Users/snigdhaghoshdastidar/Desktop/CS540/classeval_evaluation/ClassEval_92_1.py", line 223, in test_delete_user_by_username_5
    self.assertIsNone(user)
AssertionError: [] is not None

----------------------------------------------------------------------
Ran 5 tests in 0.020s

FAILED (failures=5)
.....
----------------------------------------------------------------------
Ran 5 tests in 0.012s

OK
F
======================================================================
FAIL: test_UserLoginDB (ClassEval_92_1.UserLoginDBTest.test_UserLoginDB)
----------------------------------------------------------------------
Traceback (most recent call last):
  File "/Users/snigdhaghoshdastidar/Desktop/CS540/classeval_evaluation/ClassEval_92_1.py", line 297, in test_UserLoginDB
    self.assertEqual(user[0], 'user1')
AssertionError: ('user1', 'pass1') != 'user1'

----------------------------------------------------------------------
Ran 1 test in 0.003s

FAILED (failures=1)
FFFFF
======================================================================
FAIL: test_insert_user_1 (ClassEval_92_2.UserLoginDBTestInsertUser.test_insert_user_1)
----------------------------------------------------------------------
Traceback (most recent call last):
  File "/Users/snigdhaghoshdastidar/Desktop/CS540/classeval_evaluation/ClassEval_92_2.py", line 85, in test_insert_user_1
    self.assertEqual(user[0], 'user1')
AssertionError: ('user1', 'pass1') != 'user1'

======================================================================
FAIL: test_insert_user_2 (ClassEval_92_2.UserLoginDBTestInsertUser.test_insert_user_2)
----------------------------------------------------------------------
Traceback (most recent call last):
  File "/Users/snigdhaghoshdastidar/Desktop/CS540/classeval_evaluation/ClassEval_92_2.py", line 92, in test_insert_user_2
    self.assertEqual(user[0], 'user2')
AssertionError: ('user2', 'pass2') != 'user2'

======================================================================
FAIL: test_insert_user_3 (ClassEval_92_2.UserLoginDBTestInsertUser.test_insert_user_3)
----------------------------------------------------------------------
Traceback (most recent call last):
  File "/Users/snigdhaghoshdastidar/Desktop/CS540/classeval_evaluation/ClassEval_92_2.py", line 99, in test_insert_user_3
    self.assertEqual(user[0], 'user3')
AssertionError: ('user3', 'pass3') != 'user3'

======================================================================
FAIL: test_insert_user_4 (ClassEval_92_2.UserLoginDBTestInsertUser.test_insert_user_4)
----------------------------------------------------------------------
Traceback (most recent call last):
  File "/Users/snigdhaghoshdastidar/Desktop/CS540/classeval_evaluation/ClassEval_92_2.py", line 106, in test_insert_user_4
    self.assertEqual(user[0], 'user4')
AssertionError: ('user4', 'pass4') != 'user4'

======================================================================
FAIL: test_insert_user_5 (ClassEval_92_2.UserLoginDBTestInsertUser.test_insert_user_5)
----------------------------------------------------------------------
Traceback (most recent call last):
  File "/Users/snigdhaghoshdastidar/Desktop/CS540/classeval_evaluation/ClassEval_92_2.py", line 113, in test_insert_user_5
    self.assertEqual(user[0], 'user5')
AssertionError: ('user5', 'pass5') != 'user5'

----------------------------------------------------------------------
Ran 5 tests in 0.014s

FAILED (failures=5)
FFFFF
======================================================================
FAIL: test_search_user_by_username_1 (ClassEval_92_2.UserLoginDBTestSearchUserByUsername.test_search_user_by_username_1)
----------------------------------------------------------------------
Traceback (most recent call last):
  File "/Users/snigdhaghoshdastidar/Desktop/CS540/classeval_evaluation/ClassEval_92_2.py", line 142, in test_search_user_by_username_1
    self.assertEqual(user[0], 'user1')
AssertionError: ('user1', 'pass1') != 'user1'

======================================================================
FAIL: test_search_user_by_username_2 (ClassEval_92_2.UserLoginDBTestSearchUserByUsername.test_search_user_by_username_2)
----------------------------------------------------------------------
Traceback (most recent call last):
  File "/Users/snigdhaghoshdastidar/Desktop/CS540/classeval_evaluation/ClassEval_92_2.py", line 149, in test_search_user_by_username_2
    self.assertEqual(user[0], 'user2')
AssertionError: ('user2', 'pass2') != 'user2'

======================================================================
FAIL: test_search_user_by_username_3 (ClassEval_92_2.UserLoginDBTestSearchUserByUsername.test_search_user_by_username_3)
----------------------------------------------------------------------
Traceback (most recent call last):
  File "/Users/snigdhaghoshdastidar/Desktop/CS540/classeval_evaluation/ClassEval_92_2.py", line 156, in test_search_user_by_username_3
    self.assertEqual(user[0], 'user3')
AssertionError: ('user3', 'pass3') != 'user3'

======================================================================
FAIL: test_search_user_by_username_4 (ClassEval_92_2.UserLoginDBTestSearchUserByUsername.test_search_user_by_username_4)
----------------------------------------------------------------------
Traceback (most recent call last):
  File "/Users/snigdhaghoshdastidar/Desktop/CS540/classeval_evaluation/ClassEval_92_2.py", line 163, in test_search_user_by_username_4
    self.assertEqual(user[0], 'user4')
AssertionError: ('user4', 'pass4') != 'user4'

======================================================================
FAIL: test_search_user_by_username_5 (ClassEval_92_2.UserLoginDBTestSearchUserByUsername.test_search_user_by_username_5)
----------------------------------------------------------------------
Traceback (most recent call last):
  File "/Users/snigdhaghoshdastidar/Desktop/CS540/classeval_evaluation/ClassEval_92_2.py", line 170, in test_search_user_by_username_5
    self.assertEqual(user[0], 'user5')
AssertionError: ('user5', 'pass5') != 'user5'

----------------------------------------------------------------------
Ran 5 tests in 0.014s

FAILED (failures=5)
FFFFF
======================================================================
FAIL: test_delete_user_by_username_1 (ClassEval_92_2.UserLoginDBTestDeleteUserByUsername.test_delete_user_by_username_1)
----------------------------------------------------------------------
Traceback (most recent call last):
  File "/Users/snigdhaghoshdastidar/Desktop/CS540/classeval_evaluation/ClassEval_92_2.py", line 199, in test_delete_user_by_username_1
    self.assertIsNone(user)
AssertionError: [] is not None

======================================================================
FAIL: test_delete_user_by_username_2 (ClassEval_92_2.UserLoginDBTestDeleteUserByUsername.test_delete_user_by_username_2)
----------------------------------------------------------------------
Traceback (most recent call last):
  File "/Users/snigdhaghoshdastidar/Desktop/CS540/classeval_evaluation/ClassEval_92_2.py", line 205, in test_delete_user_by_username_2
    self.assertIsNone(user)
AssertionError: [] is not None

======================================================================
FAIL: test_delete_user_by_username_3 (ClassEval_92_2.UserLoginDBTestDeleteUserByUsername.test_delete_user_by_username_3)
----------------------------------------------------------------------
Traceback (most recent call last):
  File "/Users/snigdhaghoshdastidar/Desktop/CS540/classeval_evaluation/ClassEval_92_2.py", line 211, in test_delete_user_by_username_3
    self.assertIsNone(user)
AssertionError: [] is not None

======================================================================
FAIL: test_delete_user_by_username_4 (ClassEval_92_2.UserLoginDBTestDeleteUserByUsername.test_delete_user_by_username_4)
----------------------------------------------------------------------
Traceback (most recent call last):
  File "/Users/snigdhaghoshdastidar/Desktop/CS540/classeval_evaluation/ClassEval_92_2.py", line 217, in test_delete_user_by_username_4
    self.assertIsNone(user)
AssertionError: [] is not None

======================================================================
FAIL: test_delete_user_by_username_5 (ClassEval_92_2.UserLoginDBTestDeleteUserByUsername.test_delete_user_by_username_5)
----------------------------------------------------------------------
Traceback (most recent call last):
  File "/Users/snigdhaghoshdastidar/Desktop/CS540/classeval_evaluation/ClassEval_92_2.py", line 223, in test_delete_user_by_username_5
    self.assertIsNone(user)
AssertionError: [] is not None

----------------------------------------------------------------------
Ran 5 tests in 0.019s

FAILED (failures=5)
.....
----------------------------------------------------------------------
Ran 5 tests in 0.013s

OK
F
======================================================================
FAIL: test_UserLoginDB (ClassEval_92_2.UserLoginDBTest.test_UserLoginDB)
----------------------------------------------------------------------
Traceback (most recent call last):
  File "/Users/snigdhaghoshdastidar/Desktop/CS540/classeval_evaluation/ClassEval_92_2.py", line 297, in test_UserLoginDB
    self.assertEqual(user[0], 'user1')
AssertionError: ('user1', 'pass1') != 'user1'

----------------------------------------------------------------------
Ran 1 test in 0.003s

FAILED (failures=1)
FFFFF
======================================================================
FAIL: test_insert_user_1 (ClassEval_92_3.UserLoginDBTestInsertUser.test_insert_user_1)
----------------------------------------------------------------------
Traceback (most recent call last):
  File "/Users/snigdhaghoshdastidar/Desktop/CS540/classeval_evaluation/ClassEval_92_3.py", line 91, in test_insert_user_1
    self.assertEqual(user[0], 'user1')
AssertionError: ('user1', 'pass1') != 'user1'

======================================================================
FAIL: test_insert_user_2 (ClassEval_92_3.UserLoginDBTestInsertUser.test_insert_user_2)
----------------------------------------------------------------------
Traceback (most recent call last):
  File "/Users/snigdhaghoshdastidar/Desktop/CS540/classeval_evaluation/ClassEval_92_3.py", line 98, in test_insert_user_2
    self.assertEqual(user[0], 'user2')
AssertionError: ('user2', 'pass2') != 'user2'

======================================================================
FAIL: test_insert_user_3 (ClassEval_92_3.UserLoginDBTestInsertUser.test_insert_user_3)
----------------------------------------------------------------------
Traceback (most recent call last):
  File "/Users/snigdhaghoshdastidar/Desktop/CS540/classeval_evaluation/ClassEval_92_3.py", line 105, in test_insert_user_3
    self.assertEqual(user[0], 'user3')
AssertionError: ('user3', 'pass3') != 'user3'

======================================================================
FAIL: test_insert_user_4 (ClassEval_92_3.UserLoginDBTestInsertUser.test_insert_user_4)
----------------------------------------------------------------------
Traceback (most recent call last):
  File "/Users/snigdhaghoshdastidar/Desktop/CS540/classeval_evaluation/ClassEval_92_3.py", line 112, in test_insert_user_4
    self.assertEqual(user[0], 'user4')
AssertionError: ('user4', 'pass4') != 'user4'

======================================================================
FAIL: test_insert_user_5 (ClassEval_92_3.UserLoginDBTestInsertUser.test_insert_user_5)
----------------------------------------------------------------------
Traceback (most recent call last):
  File "/Users/snigdhaghoshdastidar/Desktop/CS540/classeval_evaluation/ClassEval_92_3.py", line 119, in test_insert_user_5
    self.assertEqual(user[0], 'user5')
AssertionError: ('user5', 'pass5') != 'user5'

----------------------------------------------------------------------
Ran 5 tests in 0.027s

FAILED (failures=5)
FFFFF
======================================================================
FAIL: test_search_user_by_username_1 (ClassEval_92_3.UserLoginDBTestSearchUserByUsername.test_search_user_by_username_1)
----------------------------------------------------------------------
Traceback (most recent call last):
  File "/Users/snigdhaghoshdastidar/Desktop/CS540/classeval_evaluation/ClassEval_92_3.py", line 148, in test_search_user_by_username_1
    self.assertEqual(user[0], 'user1')
AssertionError: ('user1', 'pass1') != 'user1'

======================================================================
FAIL: test_search_user_by_username_2 (ClassEval_92_3.UserLoginDBTestSearchUserByUsername.test_search_user_by_username_2)
----------------------------------------------------------------------
Traceback (most recent call last):
  File "/Users/snigdhaghoshdastidar/Desktop/CS540/classeval_evaluation/ClassEval_92_3.py", line 155, in test_search_user_by_username_2
    self.assertEqual(user[0], 'user2')
AssertionError: ('user2', 'pass2') != 'user2'

======================================================================
FAIL: test_search_user_by_username_3 (ClassEval_92_3.UserLoginDBTestSearchUserByUsername.test_search_user_by_username_3)
----------------------------------------------------------------------
Traceback (most recent call last):
  File "/Users/snigdhaghoshdastidar/Desktop/CS540/classeval_evaluation/ClassEval_92_3.py", line 162, in test_search_user_by_username_3
    self.assertEqual(user[0], 'user3')
AssertionError: ('user3', 'pass3') != 'user3'

======================================================================
FAIL: test_search_user_by_username_4 (ClassEval_92_3.UserLoginDBTestSearchUserByUsername.test_search_user_by_username_4)
----------------------------------------------------------------------
Traceback (most recent call last):
  File "/Users/snigdhaghoshdastidar/Desktop/CS540/classeval_evaluation/ClassEval_92_3.py", line 169, in test_search_user_by_username_4
    self.assertEqual(user[0], 'user4')
AssertionError: ('user4', 'pass4') != 'user4'

======================================================================
FAIL: test_search_user_by_username_5 (ClassEval_92_3.UserLoginDBTestSearchUserByUsername.test_search_user_by_username_5)
----------------------------------------------------------------------
Traceback (most recent call last):
  File "/Users/snigdhaghoshdastidar/Desktop/CS540/classeval_evaluation/ClassEval_92_3.py", line 176, in test_search_user_by_username_5
    self.assertEqual(user[0], 'user5')
AssertionError: ('user5', 'pass5') != 'user5'

----------------------------------------------------------------------
Ran 5 tests in 0.025s

FAILED (failures=5)
FFFFF
======================================================================
FAIL: test_delete_user_by_username_1 (ClassEval_92_3.UserLoginDBTestDeleteUserByUsername.test_delete_user_by_username_1)
----------------------------------------------------------------------
Traceback (most recent call last):
  File "/Users/snigdhaghoshdastidar/Desktop/CS540/classeval_evaluation/ClassEval_92_3.py", line 205, in test_delete_user_by_username_1
    self.assertIsNone(user)
AssertionError: [] is not None

======================================================================
FAIL: test_delete_user_by_username_2 (ClassEval_92_3.UserLoginDBTestDeleteUserByUsername.test_delete_user_by_username_2)
----------------------------------------------------------------------
Traceback (most recent call last):
  File "/Users/snigdhaghoshdastidar/Desktop/CS540/classeval_evaluation/ClassEval_92_3.py", line 211, in test_delete_user_by_username_2
    self.assertIsNone(user)
AssertionError: [] is not None

======================================================================
FAIL: test_delete_user_by_username_3 (ClassEval_92_3.UserLoginDBTestDeleteUserByUsername.test_delete_user_by_username_3)
----------------------------------------------------------------------
Traceback (most recent call last):
  File "/Users/snigdhaghoshdastidar/Desktop/CS540/classeval_evaluation/ClassEval_92_3.py", line 217, in test_delete_user_by_username_3
    self.assertIsNone(user)
AssertionError: [] is not None

======================================================================
FAIL: test_delete_user_by_username_4 (ClassEval_92_3.UserLoginDBTestDeleteUserByUsername.test_delete_user_by_username_4)
----------------------------------------------------------------------
Traceback (most recent call last):
  File "/Users/snigdhaghoshdastidar/Desktop/CS540/classeval_evaluation/ClassEval_92_3.py", line 223, in test_delete_user_by_username_4
    self.assertIsNone(user)
AssertionError: [] is not None

======================================================================
FAIL: test_delete_user_by_username_5 (ClassEval_92_3.UserLoginDBTestDeleteUserByUsername.test_delete_user_by_username_5)
----------------------------------------------------------------------
Traceback (most recent call last):
  File "/Users/snigdhaghoshdastidar/Desktop/CS540/classeval_evaluation/ClassEval_92_3.py", line 229, in test_delete_user_by_username_5
    self.assertIsNone(user)
AssertionError: [] is not None

----------------------------------------------------------------------
Ran 5 tests in 0.021s

FAILED (failures=5)
.....
----------------------------------------------------------------------
Ran 5 tests in 0.015s

OK
F
======================================================================
FAIL: test_UserLoginDB (ClassEval_92_3.UserLoginDBTest.test_UserLoginDB)
----------------------------------------------------------------------
Traceback (most recent call last):
  File "/Users/snigdhaghoshdastidar/Desktop/CS540/classeval_evaluation/ClassEval_92_3.py", line 303, in test_UserLoginDB
    self.assertEqual(user[0], 'user1')
AssertionError: ('user1', 'pass1') != 'user1'

----------------------------------------------------------------------
Ran 1 test in 0.003s

FAILED (failures=1)
FFFFF
======================================================================
FAIL: test_insert_user_1 (ClassEval_92_4.UserLoginDBTestInsertUser.test_insert_user_1)
----------------------------------------------------------------------
Traceback (most recent call last):
  File "/Users/snigdhaghoshdastidar/Desktop/CS540/classeval_evaluation/ClassEval_92_4.py", line 91, in test_insert_user_1
    self.assertEqual(user[0], 'user1')
AssertionError: ('user1', 'pass1') != 'user1'

======================================================================
FAIL: test_insert_user_2 (ClassEval_92_4.UserLoginDBTestInsertUser.test_insert_user_2)
----------------------------------------------------------------------
Traceback (most recent call last):
  File "/Users/snigdhaghoshdastidar/Desktop/CS540/classeval_evaluation/ClassEval_92_4.py", line 98, in test_insert_user_2
    self.assertEqual(user[0], 'user2')
AssertionError: ('user2', 'pass2') != 'user2'

======================================================================
FAIL: test_insert_user_3 (ClassEval_92_4.UserLoginDBTestInsertUser.test_insert_user_3)
----------------------------------------------------------------------
Traceback (most recent call last):
  File "/Users/snigdhaghoshdastidar/Desktop/CS540/classeval_evaluation/ClassEval_92_4.py", line 105, in test_insert_user_3
    self.assertEqual(user[0], 'user3')
AssertionError: ('user3', 'pass3') != 'user3'

======================================================================
FAIL: test_insert_user_4 (ClassEval_92_4.UserLoginDBTestInsertUser.test_insert_user_4)
----------------------------------------------------------------------
Traceback (most recent call last):
  File "/Users/snigdhaghoshdastidar/Desktop/CS540/classeval_evaluation/ClassEval_92_4.py", line 112, in test_insert_user_4
    self.assertEqual(user[0], 'user4')
AssertionError: ('user4', 'pass4') != 'user4'

======================================================================
FAIL: test_insert_user_5 (ClassEval_92_4.UserLoginDBTestInsertUser.test_insert_user_5)
----------------------------------------------------------------------
Traceback (most recent call last):
  File "/Users/snigdhaghoshdastidar/Desktop/CS540/classeval_evaluation/ClassEval_92_4.py", line 119, in test_insert_user_5
    self.assertEqual(user[0], 'user5')
AssertionError: ('user5', 'pass5') != 'user5'

----------------------------------------------------------------------
Ran 5 tests in 0.016s

FAILED (failures=5)
FFFFF
======================================================================
FAIL: test_search_user_by_username_1 (ClassEval_92_4.UserLoginDBTestSearchUserByUsername.test_search_user_by_username_1)
----------------------------------------------------------------------
Traceback (most recent call last):
  File "/Users/snigdhaghoshdastidar/Desktop/CS540/classeval_evaluation/ClassEval_92_4.py", line 148, in test_search_user_by_username_1
    self.assertEqual(user[0], 'user1')
AssertionError: ('user1', 'pass1') != 'user1'

======================================================================
FAIL: test_search_user_by_username_2 (ClassEval_92_4.UserLoginDBTestSearchUserByUsername.test_search_user_by_username_2)
----------------------------------------------------------------------
Traceback (most recent call last):
  File "/Users/snigdhaghoshdastidar/Desktop/CS540/classeval_evaluation/ClassEval_92_4.py", line 155, in test_search_user_by_username_2
    self.assertEqual(user[0], 'user2')
AssertionError: ('user2', 'pass2') != 'user2'

======================================================================
FAIL: test_search_user_by_username_3 (ClassEval_92_4.UserLoginDBTestSearchUserByUsername.test_search_user_by_username_3)
----------------------------------------------------------------------
Traceback (most recent call last):
  File "/Users/snigdhaghoshdastidar/Desktop/CS540/classeval_evaluation/ClassEval_92_4.py", line 162, in test_search_user_by_username_3
    self.assertEqual(user[0], 'user3')
AssertionError: ('user3', 'pass3') != 'user3'

======================================================================
FAIL: test_search_user_by_username_4 (ClassEval_92_4.UserLoginDBTestSearchUserByUsername.test_search_user_by_username_4)
----------------------------------------------------------------------
Traceback (most recent call last):
  File "/Users/snigdhaghoshdastidar/Desktop/CS540/classeval_evaluation/ClassEval_92_4.py", line 169, in test_search_user_by_username_4
    self.assertEqual(user[0], 'user4')
AssertionError: ('user4', 'pass4') != 'user4'

======================================================================
FAIL: test_search_user_by_username_5 (ClassEval_92_4.UserLoginDBTestSearchUserByUsername.test_search_user_by_username_5)
----------------------------------------------------------------------
Traceback (most recent call last):
  File "/Users/snigdhaghoshdastidar/Desktop/CS540/classeval_evaluation/ClassEval_92_4.py", line 176, in test_search_user_by_username_5
    self.assertEqual(user[0], 'user5')
AssertionError: ('user5', 'pass5') != 'user5'

----------------------------------------------------------------------
Ran 5 tests in 0.016s

FAILED (failures=5)
FFFFF
======================================================================
FAIL: test_delete_user_by_username_1 (ClassEval_92_4.UserLoginDBTestDeleteUserByUsername.test_delete_user_by_username_1)
----------------------------------------------------------------------
Traceback (most recent call last):
  File "/Users/snigdhaghoshdastidar/Desktop/CS540/classeval_evaluation/ClassEval_92_4.py", line 205, in test_delete_user_by_username_1
    self.assertIsNone(user)
AssertionError: [] is not None

======================================================================
FAIL: test_delete_user_by_username_2 (ClassEval_92_4.UserLoginDBTestDeleteUserByUsername.test_delete_user_by_username_2)
----------------------------------------------------------------------
Traceback (most recent call last):
  File "/Users/snigdhaghoshdastidar/Desktop/CS540/classeval_evaluation/ClassEval_92_4.py", line 211, in test_delete_user_by_username_2
    self.assertIsNone(user)
AssertionError: [] is not None

======================================================================
FAIL: test_delete_user_by_username_3 (ClassEval_92_4.UserLoginDBTestDeleteUserByUsername.test_delete_user_by_username_3)
----------------------------------------------------------------------
Traceback (most recent call last):
  File "/Users/snigdhaghoshdastidar/Desktop/CS540/classeval_evaluation/ClassEval_92_4.py", line 217, in test_delete_user_by_username_3
    self.assertIsNone(user)
AssertionError: [] is not None

======================================================================
FAIL: test_delete_user_by_username_4 (ClassEval_92_4.UserLoginDBTestDeleteUserByUsername.test_delete_user_by_username_4)
----------------------------------------------------------------------
Traceback (most recent call last):
  File "/Users/snigdhaghoshdastidar/Desktop/CS540/classeval_evaluation/ClassEval_92_4.py", line 223, in test_delete_user_by_username_4
    self.assertIsNone(user)
AssertionError: [] is not None

======================================================================
FAIL: test_delete_user_by_username_5 (ClassEval_92_4.UserLoginDBTestDeleteUserByUsername.test_delete_user_by_username_5)
----------------------------------------------------------------------
Traceback (most recent call last):
  File "/Users/snigdhaghoshdastidar/Desktop/CS540/classeval_evaluation/ClassEval_92_4.py", line 229, in test_delete_user_by_username_5
    self.assertIsNone(user)
AssertionError: [] is not None

----------------------------------------------------------------------
Ran 5 tests in 0.018s

FAILED (failures=5)
.....
----------------------------------------------------------------------
Ran 5 tests in 0.010s

OK
F
======================================================================
FAIL: test_UserLoginDB (ClassEval_92_4.UserLoginDBTest.test_UserLoginDB)
----------------------------------------------------------------------
Traceback (most recent call last):
  File "/Users/snigdhaghoshdastidar/Desktop/CS540/classeval_evaluation/ClassEval_92_4.py", line 303, in test_UserLoginDB
    self.assertEqual(user[0], 'user1')
AssertionError: ('user1', 'pass1') != 'user1'

----------------------------------------------------------------------
Ran 1 test in 0.002s

FAILED (failures=1)
