.....
----------------------------------------------------------------------
Ran 5 tests in 0.001s

OK
.....E
======================================================================
ERROR: test_calculate_hand_value_6 (ClassEval_12_0.BlackjackGameTestCalculateHandValue.test_calculate_hand_value_6)
----------------------------------------------------------------------
Traceback (most recent call last):
  File "/Users/snigdhaghoshdastidar/Desktop/CS540/classeval_evaluation/ClassEval_12_0.py", line 112, in test_calculate_hand_value_6
    self.assertEqual(blackjackGame.calculate_hand_value(hand), 20)
                     ^^^^^^^^^^^^^^^^^^^^^^^^^^^^^^^^^^^^^^^^
  File "/Users/snigdhaghoshdastidar/Desktop/CS540/classeval_evaluation/ClassEval_12_0.py", line 23, in calculate_hand_value
    value += values[rank]
             ~~~~~~^^^^^^
KeyError: 'B'

----------------------------------------------------------------------
Ran 6 tests in 0.001s

FAILED (errors=1)
F..F..
======================================================================
FAIL: test_check_winner_1 (ClassEval_12_0.BlackjackGameTestCheckWinner.test_check_winner_1)
----------------------------------------------------------------------
Traceback (most recent call last):
  File "/Users/snigdhaghoshdastidar/Desktop/CS540/classeval_evaluation/ClassEval_12_0.py", line 123, in test_check_winner_1
    self.assertEqual(self.blackjackGame.check_winner(player_hand, dealer_hand), 'Dealer wins')
AssertionError: 'Player wins' != 'Dealer wins'
- Player wins
? ^ --
+ Dealer wins
? ^^^


======================================================================
FAIL: test_check_winner_4 (ClassEval_12_0.BlackjackGameTestCheckWinner.test_check_winner_4)
----------------------------------------------------------------------
Traceback (most recent call last):
  File "/Users/snigdhaghoshdastidar/Desktop/CS540/classeval_evaluation/ClassEval_12_0.py", line 141, in test_check_winner_4
    self.assertEqual(self.blackjackGame.check_winner(player_hand, dealer_hand), 'Player wins')
AssertionError: 'Dealer wins' != 'Player wins'
- Dealer wins
? ^^ ^
+ Player wins
? ^^ ^


----------------------------------------------------------------------
Ran 6 tests in 0.002s

FAILED (failures=2)
F
======================================================================
FAIL: test_main_1 (ClassEval_12_0.BlackjackGameTestMain.test_main_1)
----------------------------------------------------------------------
Traceback (most recent call last):
  File "/Users/snigdhaghoshdastidar/Desktop/CS540/classeval_evaluation/ClassEval_12_0.py", line 168, in test_main_1
    self.assertEqual(blackjackGame.check_winner(player_hand, dealer_hand), 'Dealer wins')
AssertionError: 'Player wins' != 'Dealer wins'
- Player wins
? ^ --
+ Dealer wins
? ^^^


----------------------------------------------------------------------
Ran 1 test in 0.001s

FAILED (failures=1)
.....
----------------------------------------------------------------------
Ran 5 tests in 0.000s

OK
.....
----------------------------------------------------------------------
Ran 5 tests in 0.000s

OK
.....
----------------------------------------------------------------------
Ran 5 tests in 0.000s

OK
..E...
======================================================================
ERROR: test_solve_3 (ClassEval_35_0.EightPuzzleTestSolve.test_solve_3)
----------------------------------------------------------------------
Traceback (most recent call last):
  File "/Users/snigdhaghoshdastidar/Desktop/CS540/classeval_evaluation/ClassEval_35_0.py", line 171, in test_solve_3
    result = eightPuzzle.solve()
             ^^^^^^^^^^^^^^^^^^^
  File "/Users/snigdhaghoshdastidar/Desktop/CS540/classeval_evaluation/ClassEval_35_0.py", line 51, in solve
    visited_states.append(new_state)
func_timeout.dafunc.FunctionTimedOut-2466733453057520007: Function run_unit_test (args=(<test_pipeline.AutoTest object at 0x11558aab0>, 'ClassEval_35_0', 'EightPuzzleTestSolve', 'GPT-4_greedy_Game_Development')) (kwargs={}) timed out after 5.000000 seconds.


----------------------------------------------------------------------
Ran 6 tests in 5.021s

FAILED (errors=1)
EEEEE
======================================================================
ERROR: test_make_move_1 (ClassEval_41_0.GomokuGameTestMakeMove.test_make_move_1)
----------------------------------------------------------------------
Traceback (most recent call last):
  File "/Users/snigdhaghoshdastidar/Desktop/CS540/classeval_evaluation/ClassEval_41_0.py", line 36, in setUp
    self.gomokuGame = GomokuGame(self.board_size)
                      ^^^^^^^^^^
NameError: name 'GomokuGame' is not defined

======================================================================
ERROR: test_make_move_2 (ClassEval_41_0.GomokuGameTestMakeMove.test_make_move_2)
----------------------------------------------------------------------
Traceback (most recent call last):
  File "/Users/snigdhaghoshdastidar/Desktop/CS540/classeval_evaluation/ClassEval_41_0.py", line 36, in setUp
    self.gomokuGame = GomokuGame(self.board_size)
                      ^^^^^^^^^^
NameError: name 'GomokuGame' is not defined

======================================================================
ERROR: test_make_move_3 (ClassEval_41_0.GomokuGameTestMakeMove.test_make_move_3)
----------------------------------------------------------------------
Traceback (most recent call last):
  File "/Users/snigdhaghoshdastidar/Desktop/CS540/classeval_evaluation/ClassEval_41_0.py", line 36, in setUp
    self.gomokuGame = GomokuGame(self.board_size)
                      ^^^^^^^^^^
NameError: name 'GomokuGame' is not defined

======================================================================
ERROR: test_make_move_4 (ClassEval_41_0.GomokuGameTestMakeMove.test_make_move_4)
----------------------------------------------------------------------
Traceback (most recent call last):
  File "/Users/snigdhaghoshdastidar/Desktop/CS540/classeval_evaluation/ClassEval_41_0.py", line 36, in setUp
    self.gomokuGame = GomokuGame(self.board_size)
                      ^^^^^^^^^^
NameError: name 'GomokuGame' is not defined

======================================================================
ERROR: test_make_move_5 (ClassEval_41_0.GomokuGameTestMakeMove.test_make_move_5)
----------------------------------------------------------------------
Traceback (most recent call last):
  File "/Users/snigdhaghoshdastidar/Desktop/CS540/classeval_evaluation/ClassEval_41_0.py", line 36, in setUp
    self.gomokuGame = GomokuGame(self.board_size)
                      ^^^^^^^^^^
NameError: name 'GomokuGame' is not defined

----------------------------------------------------------------------
Ran 5 tests in 0.011s

FAILED (errors=5)
EEEEE
======================================================================
ERROR: test_check_winner_1 (ClassEval_41_0.GomokuGameTestCheckWinner.test_check_winner_1)
----------------------------------------------------------------------
Traceback (most recent call last):
  File "/Users/snigdhaghoshdastidar/Desktop/CS540/classeval_evaluation/ClassEval_41_0.py", line 81, in test_check_winner_1
    gomokuGame = GomokuGame(10)
                 ^^^^^^^^^^
NameError: name 'GomokuGame' is not defined

======================================================================
ERROR: test_check_winner_2 (ClassEval_41_0.GomokuGameTestCheckWinner.test_check_winner_2)
----------------------------------------------------------------------
Traceback (most recent call last):
  File "/Users/snigdhaghoshdastidar/Desktop/CS540/classeval_evaluation/ClassEval_41_0.py", line 85, in test_check_winner_2
    gomokuGame = GomokuGame(10)
                 ^^^^^^^^^^
NameError: name 'GomokuGame' is not defined

======================================================================
ERROR: test_check_winner_3 (ClassEval_41_0.GomokuGameTestCheckWinner.test_check_winner_3)
----------------------------------------------------------------------
Traceback (most recent call last):
  File "/Users/snigdhaghoshdastidar/Desktop/CS540/classeval_evaluation/ClassEval_41_0.py", line 92, in test_check_winner_3
    gomokuGame = GomokuGame(10)
                 ^^^^^^^^^^
NameError: name 'GomokuGame' is not defined

======================================================================
ERROR: test_check_winner_4 (ClassEval_41_0.GomokuGameTestCheckWinner.test_check_winner_4)
----------------------------------------------------------------------
Traceback (most recent call last):
  File "/Users/snigdhaghoshdastidar/Desktop/CS540/classeval_evaluation/ClassEval_41_0.py", line 99, in test_check_winner_4
    gomokuGame = GomokuGame(10)
                 ^^^^^^^^^^
NameError: name 'GomokuGame' is not defined

======================================================================
ERROR: test_check_winner_5 (ClassEval_41_0.GomokuGameTestCheckWinner.test_check_winner_5)
----------------------------------------------------------------------
Traceback (most recent call last):
  File "/Users/snigdhaghoshdastidar/Desktop/CS540/classeval_evaluation/ClassEval_41_0.py", line 106, in test_check_winner_5
    gomokuGame = GomokuGame(10)
                 ^^^^^^^^^^
NameError: name 'GomokuGame' is not defined

----------------------------------------------------------------------
Ran 5 tests in 0.011s

FAILED (errors=5)
EEEEE
======================================================================
ERROR: test_check_five_in_a_row_1 (ClassEval_41_0.GomokuGameTestCheckFiveInARow.test_check_five_in_a_row_1)
----------------------------------------------------------------------
Traceback (most recent call last):
  File "/Users/snigdhaghoshdastidar/Desktop/CS540/classeval_evaluation/ClassEval_41_0.py", line 115, in setUp
    self.gomokuGame = GomokuGame(10)
                      ^^^^^^^^^^
NameError: name 'GomokuGame' is not defined

======================================================================
ERROR: test_check_five_in_a_row_2 (ClassEval_41_0.GomokuGameTestCheckFiveInARow.test_check_five_in_a_row_2)
----------------------------------------------------------------------
Traceback (most recent call last):
  File "/Users/snigdhaghoshdastidar/Desktop/CS540/classeval_evaluation/ClassEval_41_0.py", line 115, in setUp
    self.gomokuGame = GomokuGame(10)
                      ^^^^^^^^^^
NameError: name 'GomokuGame' is not defined

======================================================================
ERROR: test_check_five_in_a_row_3 (ClassEval_41_0.GomokuGameTestCheckFiveInARow.test_check_five_in_a_row_3)
----------------------------------------------------------------------
Traceback (most recent call last):
  File "/Users/snigdhaghoshdastidar/Desktop/CS540/classeval_evaluation/ClassEval_41_0.py", line 115, in setUp
    self.gomokuGame = GomokuGame(10)
                      ^^^^^^^^^^
NameError: name 'GomokuGame' is not defined

======================================================================
ERROR: test_check_five_in_a_row_4 (ClassEval_41_0.GomokuGameTestCheckFiveInARow.test_check_five_in_a_row_4)
----------------------------------------------------------------------
Traceback (most recent call last):
  File "/Users/snigdhaghoshdastidar/Desktop/CS540/classeval_evaluation/ClassEval_41_0.py", line 115, in setUp
    self.gomokuGame = GomokuGame(10)
                      ^^^^^^^^^^
NameError: name 'GomokuGame' is not defined

======================================================================
ERROR: test_check_five_in_a_row_5 (ClassEval_41_0.GomokuGameTestCheckFiveInARow.test_check_five_in_a_row_5)
----------------------------------------------------------------------
Traceback (most recent call last):
  File "/Users/snigdhaghoshdastidar/Desktop/CS540/classeval_evaluation/ClassEval_41_0.py", line 115, in setUp
    self.gomokuGame = GomokuGame(10)
                      ^^^^^^^^^^
NameError: name 'GomokuGame' is not defined

----------------------------------------------------------------------
Ran 5 tests in 0.011s

FAILED (errors=5)
E
======================================================================
ERROR: test_main (ClassEval_41_0.GomokuGameTestMain.test_main)
----------------------------------------------------------------------
Traceback (most recent call last):
  File "/Users/snigdhaghoshdastidar/Desktop/CS540/classeval_evaluation/ClassEval_41_0.py", line 137, in test_main
    gomokuGame = GomokuGame(10)
                 ^^^^^^^^^^
NameError: name 'GomokuGame' is not defined

----------------------------------------------------------------------
Ran 1 test in 0.002s

FAILED (errors=1)
.....
----------------------------------------------------------------------
Ran 5 tests in 0.000s

OK
.....F
======================================================================
FAIL: test_is_valid_move_6 (ClassEval_54_0.MahjongConnectTestIsValidMove.test_is_valid_move_6)
----------------------------------------------------------------------
Traceback (most recent call last):
  File "/Users/snigdhaghoshdastidar/Desktop/CS540/classeval_evaluation/ClassEval_54_0.py", line 144, in test_is_valid_move_6
    self.assertEqual(res, False)
AssertionError: True != False

----------------------------------------------------------------------
Ran 6 tests in 0.001s

FAILED (failures=1)
...FF.
======================================================================
FAIL: test_has_path_4 (ClassEval_54_0.MahjongConnectTestHasPath.test_has_path_4)
----------------------------------------------------------------------
Traceback (most recent call last):
  File "/Users/snigdhaghoshdastidar/Desktop/CS540/classeval_evaluation/ClassEval_54_0.py", line 182, in test_has_path_4
    self.assertEqual(res, False)
AssertionError: True != False

======================================================================
FAIL: test_has_path_5 (ClassEval_54_0.MahjongConnectTestHasPath.test_has_path_5)
----------------------------------------------------------------------
Traceback (most recent call last):
  File "/Users/snigdhaghoshdastidar/Desktop/CS540/classeval_evaluation/ClassEval_54_0.py", line 191, in test_has_path_5
    self.assertEqual(res, False)
AssertionError: True != False

----------------------------------------------------------------------
Ran 6 tests in 0.001s

FAILED (failures=2)
.....
----------------------------------------------------------------------
Ran 5 tests in 0.000s

OK
.....
----------------------------------------------------------------------
Ran 5 tests in 0.000s

OK
.
----------------------------------------------------------------------
Ran 1 test in 0.000s

OK
.....
----------------------------------------------------------------------
Ran 5 tests in 0.000s

OK
...EE
======================================================================
ERROR: test_generate_playerMap_4 (ClassEval_58_0.MinesweeperGameTestGeneratePlayerMap.test_generate_playerMap_4)
----------------------------------------------------------------------
Traceback (most recent call last):
  File "/Users/snigdhaghoshdastidar/Desktop/CS540/classeval_evaluation/ClassEval_58_0.py", line 118, in test_generate_playerMap_4
    minesweeper_game = MinesweeperGame(1, 4)
                       ^^^^^^^^^^^^^^^^^^^^^
  File "/Users/snigdhaghoshdastidar/Desktop/CS540/classeval_evaluation/ClassEval_58_0.py", line 9, in __init__
    self.minesweeper_map = self.generate_mine_sweeper_map()
                           ^^^^^^^^^^^^^^^^^^^^^^^^^^^^^^^^
  File "/Users/snigdhaghoshdastidar/Desktop/CS540/classeval_evaluation/ClassEval_58_0.py", line 15, in generate_mine_sweeper_map
    mines = random.sample(range(self.n*self.n), self.k)
            ^^^^^^^^^^^^^^^^^^^^^^^^^^^^^^^^^^^^^^^^^^^
  File "/opt/miniconda3/lib/python3.12/random.py", line 430, in sample
    raise ValueError("Sample larger than population or is negative")
ValueError: Sample larger than population or is negative

======================================================================
ERROR: test_generate_playerMap_5 (ClassEval_58_0.MinesweeperGameTestGeneratePlayerMap.test_generate_playerMap_5)
----------------------------------------------------------------------
Traceback (most recent call last):
  File "/Users/snigdhaghoshdastidar/Desktop/CS540/classeval_evaluation/ClassEval_58_0.py", line 122, in test_generate_playerMap_5
    minesweeper_game = MinesweeperGame(2, 5)
                       ^^^^^^^^^^^^^^^^^^^^^
  File "/Users/snigdhaghoshdastidar/Desktop/CS540/classeval_evaluation/ClassEval_58_0.py", line 9, in __init__
    self.minesweeper_map = self.generate_mine_sweeper_map()
                           ^^^^^^^^^^^^^^^^^^^^^^^^^^^^^^^^
  File "/Users/snigdhaghoshdastidar/Desktop/CS540/classeval_evaluation/ClassEval_58_0.py", line 15, in generate_mine_sweeper_map
    mines = random.sample(range(self.n*self.n), self.k)
            ^^^^^^^^^^^^^^^^^^^^^^^^^^^^^^^^^^^^^^^^^^^
  File "/opt/miniconda3/lib/python3.12/random.py", line 430, in sample
    raise ValueError("Sample larger than population or is negative")
ValueError: Sample larger than population or is negative

----------------------------------------------------------------------
Ran 5 tests in 0.002s

FAILED (errors=2)
EEEEE
======================================================================
ERROR: test_check_won (ClassEval_58_0.MinesweeperGameTestCheckWon.test_check_won)
----------------------------------------------------------------------
Traceback (most recent call last):
  File "/Users/snigdhaghoshdastidar/Desktop/CS540/classeval_evaluation/ClassEval_58_0.py", line 130, in test_check_won
    self.assertEqual(minesweeper_game.check_won(minesweeper_game.player_map), False)
                     ^^^^^^^^^^^^^^^^^^^^^^^^^^^^^^^^^^^^^^^^^^^^^^^^^^^^^^^
TypeError: MinesweeperGame.check_won() takes 1 positional argument but 2 were given

======================================================================
ERROR: test_check_won_2 (ClassEval_58_0.MinesweeperGameTestCheckWon.test_check_won_2)
----------------------------------------------------------------------
Traceback (most recent call last):
  File "/Users/snigdhaghoshdastidar/Desktop/CS540/classeval_evaluation/ClassEval_58_0.py", line 136, in test_check_won_2
    self.assertEqual(minesweeper_game.check_won(minesweeper_game.player_map), False)
                     ^^^^^^^^^^^^^^^^^^^^^^^^^^^^^^^^^^^^^^^^^^^^^^^^^^^^^^^
TypeError: MinesweeperGame.check_won() takes 1 positional argument but 2 were given

======================================================================
ERROR: test_check_won_3 (ClassEval_58_0.MinesweeperGameTestCheckWon.test_check_won_3)
----------------------------------------------------------------------
Traceback (most recent call last):
  File "/Users/snigdhaghoshdastidar/Desktop/CS540/classeval_evaluation/ClassEval_58_0.py", line 142, in test_check_won_3
    self.assertEqual(minesweeper_game.check_won(minesweeper_game.player_map), False)
                     ^^^^^^^^^^^^^^^^^^^^^^^^^^^^^^^^^^^^^^^^^^^^^^^^^^^^^^^
TypeError: MinesweeperGame.check_won() takes 1 positional argument but 2 were given

======================================================================
ERROR: test_check_won_4 (ClassEval_58_0.MinesweeperGameTestCheckWon.test_check_won_4)
----------------------------------------------------------------------
Traceback (most recent call last):
  File "/Users/snigdhaghoshdastidar/Desktop/CS540/classeval_evaluation/ClassEval_58_0.py", line 148, in test_check_won_4
    self.assertEqual(minesweeper_game.check_won(minesweeper_game.player_map), True)
                     ^^^^^^^^^^^^^^^^^^^^^^^^^^^^^^^^^^^^^^^^^^^^^^^^^^^^^^^
TypeError: MinesweeperGame.check_won() takes 1 positional argument but 2 were given

======================================================================
ERROR: test_check_won_5 (ClassEval_58_0.MinesweeperGameTestCheckWon.test_check_won_5)
----------------------------------------------------------------------
Traceback (most recent call last):
  File "/Users/snigdhaghoshdastidar/Desktop/CS540/classeval_evaluation/ClassEval_58_0.py", line 154, in test_check_won_5
    self.assertEqual(minesweeper_game.check_won(minesweeper_game.player_map), False)
                     ^^^^^^^^^^^^^^^^^^^^^^^^^^^^^^^^^^^^^^^^^^^^^^^^^^^^^^^
TypeError: MinesweeperGame.check_won() takes 1 positional argument but 2 were given

----------------------------------------------------------------------
Ran 5 tests in 0.001s

FAILED (errors=5)
F.FFF
======================================================================
FAIL: test_sweep (ClassEval_58_0.MinesweeperGameTestSweep.test_sweep)
----------------------------------------------------------------------
Traceback (most recent call last):
  File "/Users/snigdhaghoshdastidar/Desktop/CS540/classeval_evaluation/ClassEval_58_0.py", line 162, in test_sweep
    self.assertEqual(minesweeper_game.score, 1)
AssertionError: 0 != 1

======================================================================
FAIL: test_sweep_3 (ClassEval_58_0.MinesweeperGameTestSweep.test_sweep_3)
----------------------------------------------------------------------
Traceback (most recent call last):
  File "/Users/snigdhaghoshdastidar/Desktop/CS540/classeval_evaluation/ClassEval_58_0.py", line 176, in test_sweep_3
    self.assertEqual(minesweeper_game.score, 1)
AssertionError: 0 != 1

======================================================================
FAIL: test_sweep_4 (ClassEval_58_0.MinesweeperGameTestSweep.test_sweep_4)
----------------------------------------------------------------------
Traceback (most recent call last):
  File "/Users/snigdhaghoshdastidar/Desktop/CS540/classeval_evaluation/ClassEval_58_0.py", line 183, in test_sweep_4
    self.assertEqual(minesweeper_game.score, 1)
AssertionError: 0 != 1

======================================================================
FAIL: test_sweep_5 (ClassEval_58_0.MinesweeperGameTestSweep.test_sweep_5)
----------------------------------------------------------------------
Traceback (most recent call last):
  File "/Users/snigdhaghoshdastidar/Desktop/CS540/classeval_evaluation/ClassEval_58_0.py", line 190, in test_sweep_5
    self.assertEqual(minesweeper_game.score, 1)
AssertionError: 0 != 1

----------------------------------------------------------------------
Ran 5 tests in 0.001s

FAILED (failures=4)
EE
======================================================================
ERROR: test_minesweeper_main (ClassEval_58_0.MinesweeperGameTestMain.test_minesweeper_main)
----------------------------------------------------------------------
Traceback (most recent call last):
  File "/Users/snigdhaghoshdastidar/Desktop/CS540/classeval_evaluation/ClassEval_58_0.py", line 206, in test_minesweeper_main
    self.assertEqual(minesweeper_game.check_won(minesweeper_game.player_map), False)
                     ^^^^^^^^^^^^^^^^^^^^^^^^^^^^^^^^^^^^^^^^^^^^^^^^^^^^^^^
TypeError: MinesweeperGame.check_won() takes 1 positional argument but 2 were given

======================================================================
ERROR: test_minesweeper_main_2 (ClassEval_58_0.MinesweeperGameTestMain.test_minesweeper_main_2)
----------------------------------------------------------------------
Traceback (most recent call last):
  File "/Users/snigdhaghoshdastidar/Desktop/CS540/classeval_evaluation/ClassEval_58_0.py", line 222, in test_minesweeper_main_2
    self.assertEqual(minesweeper_game.check_won(minesweeper_game.player_map), False)
                     ^^^^^^^^^^^^^^^^^^^^^^^^^^^^^^^^^^^^^^^^^^^^^^^^^^^^^^^
TypeError: MinesweeperGame.check_won() takes 1 positional argument but 2 were given

----------------------------------------------------------------------
Ran 2 tests in 0.000s

FAILED (errors=2)
.....
----------------------------------------------------------------------
Ran 5 tests in 0.000s

OK
.....
----------------------------------------------------------------------
Ran 5 tests in 0.000s

OK
.....
----------------------------------------------------------------------
Ran 5 tests in 0.000s

OK
.....
----------------------------------------------------------------------
Ran 5 tests in 0.000s

OK
.....
----------------------------------------------------------------------
Ran 5 tests in 0.000s

OK
.
----------------------------------------------------------------------
Ran 1 test in 0.000s

OK
EEEEE
======================================================================
ERROR: test_move_1 (ClassEval_77_0.SnakeTestMove.test_move_1)
----------------------------------------------------------------------
Traceback (most recent call last):
  File "/Users/snigdhaghoshdastidar/Desktop/CS540/classeval_evaluation/ClassEval_77_0.py", line 41, in test_move_1
    snake = Snake(100, 100, 1, (51, 51))
            ^^^^^
NameError: name 'Snake' is not defined

======================================================================
ERROR: test_move_2 (ClassEval_77_0.SnakeTestMove.test_move_2)
----------------------------------------------------------------------
Traceback (most recent call last):
  File "/Users/snigdhaghoshdastidar/Desktop/CS540/classeval_evaluation/ClassEval_77_0.py", line 49, in test_move_2
    snake = Snake(100, 100, 1, (80, 80))
            ^^^^^
NameError: name 'Snake' is not defined

======================================================================
ERROR: test_move_3 (ClassEval_77_0.SnakeTestMove.test_move_3)
----------------------------------------------------------------------
Traceback (most recent call last):
  File "/Users/snigdhaghoshdastidar/Desktop/CS540/classeval_evaluation/ClassEval_77_0.py", line 56, in test_move_3
    snake = Snake(100, 100, 1, (51, 51))
            ^^^^^
NameError: name 'Snake' is not defined

======================================================================
ERROR: test_move_4 (ClassEval_77_0.SnakeTestMove.test_move_4)
----------------------------------------------------------------------
Traceback (most recent call last):
  File "/Users/snigdhaghoshdastidar/Desktop/CS540/classeval_evaluation/ClassEval_77_0.py", line 63, in test_move_4
    snake = Snake(100, 100, 1, (51, 51))
            ^^^^^
NameError: name 'Snake' is not defined

======================================================================
ERROR: test_move_5 (ClassEval_77_0.SnakeTestMove.test_move_5)
----------------------------------------------------------------------
Traceback (most recent call last):
  File "/Users/snigdhaghoshdastidar/Desktop/CS540/classeval_evaluation/ClassEval_77_0.py", line 70, in test_move_5
    snake = Snake(100, 100, 1, (99, 99))
            ^^^^^
NameError: name 'Snake' is not defined

----------------------------------------------------------------------
Ran 5 tests in 0.004s

FAILED (errors=5)
EEEEE
======================================================================
ERROR: test_random_food_position_1 (ClassEval_77_0.SnakeTestRandomFoodPosition.test_random_food_position_1)
----------------------------------------------------------------------
Traceback (most recent call last):
  File "/Users/snigdhaghoshdastidar/Desktop/CS540/classeval_evaluation/ClassEval_77_0.py", line 79, in test_random_food_position_1
    snake = Snake(100, 100, 1, (51, 51))
            ^^^^^
NameError: name 'Snake' is not defined

======================================================================
ERROR: test_random_food_position_2 (ClassEval_77_0.SnakeTestRandomFoodPosition.test_random_food_position_2)
----------------------------------------------------------------------
Traceback (most recent call last):
  File "/Users/snigdhaghoshdastidar/Desktop/CS540/classeval_evaluation/ClassEval_77_0.py", line 89, in test_random_food_position_2
    snake = Snake(100, 100, 1, (99, 99))
            ^^^^^
NameError: name 'Snake' is not defined

======================================================================
ERROR: test_random_food_position_3 (ClassEval_77_0.SnakeTestRandomFoodPosition.test_random_food_position_3)
----------------------------------------------------------------------
Traceback (most recent call last):
  File "/Users/snigdhaghoshdastidar/Desktop/CS540/classeval_evaluation/ClassEval_77_0.py", line 99, in test_random_food_position_3
    snake = Snake(100, 100, 1, (0, 0))
            ^^^^^
NameError: name 'Snake' is not defined

======================================================================
ERROR: test_random_food_position_4 (ClassEval_77_0.SnakeTestRandomFoodPosition.test_random_food_position_4)
----------------------------------------------------------------------
Traceback (most recent call last):
  File "/Users/snigdhaghoshdastidar/Desktop/CS540/classeval_evaluation/ClassEval_77_0.py", line 109, in test_random_food_position_4
    snake = Snake(100, 100, 1, (40, 40))
            ^^^^^
NameError: name 'Snake' is not defined

======================================================================
ERROR: test_random_food_position_5 (ClassEval_77_0.SnakeTestRandomFoodPosition.test_random_food_position_5)
----------------------------------------------------------------------
Traceback (most recent call last):
  File "/Users/snigdhaghoshdastidar/Desktop/CS540/classeval_evaluation/ClassEval_77_0.py", line 119, in test_random_food_position_5
    snake = Snake(100, 100, 1, (60, 60))
            ^^^^^
NameError: name 'Snake' is not defined

----------------------------------------------------------------------
Ran 5 tests in 0.004s

FAILED (errors=5)
EEEEE
======================================================================
ERROR: test_reset_1 (ClassEval_77_0.SnakeTestReset.test_reset_1)
----------------------------------------------------------------------
Traceback (most recent call last):
  File "/Users/snigdhaghoshdastidar/Desktop/CS540/classeval_evaluation/ClassEval_77_0.py", line 131, in test_reset_1
    snake = Snake(100, 100, 1, (51, 51))
            ^^^^^
NameError: name 'Snake' is not defined

======================================================================
ERROR: test_reset_2 (ClassEval_77_0.SnakeTestReset.test_reset_2)
----------------------------------------------------------------------
Traceback (most recent call last):
  File "/Users/snigdhaghoshdastidar/Desktop/CS540/classeval_evaluation/ClassEval_77_0.py", line 139, in test_reset_2
    snake = Snake(100, 100, 1, (51, 51))
            ^^^^^
NameError: name 'Snake' is not defined

======================================================================
ERROR: test_reset_3 (ClassEval_77_0.SnakeTestReset.test_reset_3)
----------------------------------------------------------------------
Traceback (most recent call last):
  File "/Users/snigdhaghoshdastidar/Desktop/CS540/classeval_evaluation/ClassEval_77_0.py", line 147, in test_reset_3
    snake = Snake(100, 100, 1, (51, 51))
            ^^^^^
NameError: name 'Snake' is not defined

======================================================================
ERROR: test_reset_4 (ClassEval_77_0.SnakeTestReset.test_reset_4)
----------------------------------------------------------------------
Traceback (most recent call last):
  File "/Users/snigdhaghoshdastidar/Desktop/CS540/classeval_evaluation/ClassEval_77_0.py", line 155, in test_reset_4
    snake = Snake(100, 100, 1, (51, 51))
            ^^^^^
NameError: name 'Snake' is not defined

======================================================================
ERROR: test_reset_5 (ClassEval_77_0.SnakeTestReset.test_reset_5)
----------------------------------------------------------------------
Traceback (most recent call last):
  File "/Users/snigdhaghoshdastidar/Desktop/CS540/classeval_evaluation/ClassEval_77_0.py", line 163, in test_reset_5
    snake = Snake(100, 100, 1, (51, 51))
            ^^^^^
NameError: name 'Snake' is not defined

----------------------------------------------------------------------
Ran 5 tests in 0.004s

FAILED (errors=5)
EEEEE
======================================================================
ERROR: test_eat_food_1 (ClassEval_77_0.SnakeTestEatFood.test_eat_food_1)
----------------------------------------------------------------------
Traceback (most recent call last):
  File "/Users/snigdhaghoshdastidar/Desktop/CS540/classeval_evaluation/ClassEval_77_0.py", line 173, in test_eat_food_1
    snake = Snake(100, 100, 1, (51, 51))
            ^^^^^
NameError: name 'Snake' is not defined

======================================================================
ERROR: test_eat_food_2 (ClassEval_77_0.SnakeTestEatFood.test_eat_food_2)
----------------------------------------------------------------------
Traceback (most recent call last):
  File "/Users/snigdhaghoshdastidar/Desktop/CS540/classeval_evaluation/ClassEval_77_0.py", line 181, in test_eat_food_2
    snake = Snake(100, 100, 1, (51, 51))
            ^^^^^
NameError: name 'Snake' is not defined

======================================================================
ERROR: test_eat_food_3 (ClassEval_77_0.SnakeTestEatFood.test_eat_food_3)
----------------------------------------------------------------------
Traceback (most recent call last):
  File "/Users/snigdhaghoshdastidar/Desktop/CS540/classeval_evaluation/ClassEval_77_0.py", line 190, in test_eat_food_3
    snake = Snake(100, 100, 1, (51, 51))
            ^^^^^
NameError: name 'Snake' is not defined

======================================================================
ERROR: test_eat_food_4 (ClassEval_77_0.SnakeTestEatFood.test_eat_food_4)
----------------------------------------------------------------------
Traceback (most recent call last):
  File "/Users/snigdhaghoshdastidar/Desktop/CS540/classeval_evaluation/ClassEval_77_0.py", line 200, in test_eat_food_4
    snake = Snake(100, 100, 1, (51, 51))
            ^^^^^
NameError: name 'Snake' is not defined

======================================================================
ERROR: test_eat_food_5 (ClassEval_77_0.SnakeTestEatFood.test_eat_food_5)
----------------------------------------------------------------------
Traceback (most recent call last):
  File "/Users/snigdhaghoshdastidar/Desktop/CS540/classeval_evaluation/ClassEval_77_0.py", line 211, in test_eat_food_5
    snake = Snake(100, 100, 1, (51, 51))
            ^^^^^
NameError: name 'Snake' is not defined

----------------------------------------------------------------------
Ran 5 tests in 0.004s

FAILED (errors=5)
E
======================================================================
ERROR: test_snake (ClassEval_77_0.SnakeTest.test_snake)
----------------------------------------------------------------------
Traceback (most recent call last):
  File "/Users/snigdhaghoshdastidar/Desktop/CS540/classeval_evaluation/ClassEval_77_0.py", line 225, in test_snake
    snake = Snake(100, 100, 1, (51, 51))
            ^^^^^
NameError: name 'Snake' is not defined

----------------------------------------------------------------------
Ran 1 test in 0.001s

FAILED (errors=1)
.....
----------------------------------------------------------------------
Ran 5 tests in 0.000s

OK
.....
----------------------------------------------------------------------
Ran 5 tests in 0.000s

OK
.....
----------------------------------------------------------------------
Ran 5 tests in 0.000s

OK
.
----------------------------------------------------------------------
Ran 1 test in 0.000s

OK
.....
----------------------------------------------------------------------
Ran 5 tests in 0.000s

OK
E......
======================================================================
ERROR: test_answer_1 (ClassEval_89_0.TwentyFourPointGameTestAnswer.test_answer_1)
----------------------------------------------------------------------
Traceback (most recent call last):
  File "/Users/snigdhaghoshdastidar/Desktop/CS540/classeval_evaluation/ClassEval_89_0.py", line 89, in test_answer_1
    self.assertEqual(len(cards), 4)
                     ^^^^^^^^^^
TypeError: object of type 'bool' has no len()

----------------------------------------------------------------------
Ran 7 tests in 0.001s

FAILED (errors=1)
.....
----------------------------------------------------------------------
Ran 5 tests in 0.000s

OK
.
----------------------------------------------------------------------
Ran 1 test in 0.000s

OK
